Workbook

Sheet 説明
B1: 第52期上期 担当者コード（予算策定用）
B3: ■ 元データ
B4: ・「20260905 1頁」シート（第52期上期担当者ファイル）の907得意先を、第51期上期担当者コードファイルと同じ構成で「全体」と部門別5シートに分割しています。
B5: ・前年度 = 第51期上期（2024/10〜2025/03）、今年度 = 第52期上期（2025/10〜2026/03）。金額の単位は元データのまま（千円）です。
B6: ・各シートは 担当者コード → 得意先コード の順に並んでいます。合計・集計・総計はすべて数式です。
B8: ■ 2026年10月以降の担当者の設定方法
B9: 1. 各部門シート（水産部X／鳥栖・静岡・東京／松江・境港／下関／石見）の E列「新担当者コード」（黄色セル）に、新しい担当者コードを入力します。
B10: 2. F列「新担当者」は「担当者マスタ」シートから自動表示されます。「※マスタ未登録」と出た場合は担当者マスタにコードを追加してください。
B11: 3. 新しい担当者（新規コード）は「担当者マスタ」シートの黄色の空行に コード・氏名・部門 を追加します。
B12: 4. 「全体」シートの E列・F列は部門別シートの入力を自動で反映します（全体シートでは入力不要）。
B13: 5. 「担当者別集計」シートで、現担当者ベース／新担当者ベースの得意先数・売上・粗利の合計を確認できます。「未設定」行が 0 になれば全得意先の割当完了です。
B15: ■ 部門と担当者コードの対応（第51期ファイルの部門別シート構成を踏襲）
... B25: ・黄色 = 入力欄（部門別シートのE列、担当者マスタの空行） ・緑文字 = 他シート参照 ・灰色 = 集計／総計行

Sheet 全体
A1: 得意先コード | B1: 得意先略称 | C1: 担当者コード | D1: 担当者名 | E1: 新担当者コード | F1: 新担当者 | G1: 2024/10売上 | H1: 2024/11売上 | I1: 2024/12売上 | J1: 2025/01売上 | K1: 2025/02売上 | L1: 2025/03売上 | M1: 前年度売上合計 | N1: 2024/10粗利益 | O1: 2024/11粗利益 | P1: 2024/12粗利益 | Q1: 2025/01粗利益 | R1: 2025/02粗利益 | S1: 2025/03粗利益 | T1: 前年度粗利益合計 | U1: 2025/10売上 | V1: 2025/11売上 | W1: 2025/12売上 | X1: 2026/01売上 | Y1: 2026/02売上 | Z1: 2026/03売上 | AA1: 今年度売上合計 | AB1: 2025/10粗利益 | AC1: 2025/11粗利益 | AD1: 2025/12粗利益 | AE1: 2026/01粗利益 | AF1: 2026/02粗利益 | AG1: 2026/03粗利益 | AH1: 今年度粗利益合計 | AI1: 部門
A2: 0000000000541 | B2: JFしまね冷蔵庫 | C2: 0010 | D2: JF | E2: =IFERROR(IF(INDEX(INDIRECT("'"&$AI2&"'!$E$2:$E$118"),MATCH($A2,INDIRECT("'"&$AI2&"'!$A$2:$A$118"),0))="","",INDEX(INDIRECT("'"&$AI2&"'!$E$2:$E$118"),MATCH($A2,INDIRECT("'"&$AI2&"'!$A$2:$A$118"),0))),"") | F2: =IF($E2="","",IFERROR(INDEX(担当者マスタ!$B$2:$B$101,MATCH($E2,担当者マスタ!$A$2:$A$101,0)),"※マスタ未登録")) | G2: 1727.964 | H2: 1845.035 | I2: 1015.906 | J2: 861.896 | K2: 1167.74 | L2: 1096.898 | M2: =SUM(G2:L2) -> 7715.439 | N2: 328.751 | O2: 408.366 | P2: 254.265 | Q2: 212.557 | R2: 257.125 | S2: 195.312 | T2: =SUM(N2:S2) -> 1656.376 | U2: 2143.798 | V2: 2047.515 | W2: 1351.109 | X2: 572.291 | Y2: 606.598 | Z2: 1948.328 | AA2: =SUM(U2:Z2) -> 8669.639 | AB2: 453.995 | AC2: 419.149 | AD2: 269.7 | AE2: 114.237 | AF2: 168.409 | AG2: 474.166 | AH2: =SUM(AB2:AG2) -> 1899.656 | AI2: 水産部X
A3: 0000000000561 | B3: JFしまねｻｰﾋﾞｽ | C3: 0010 | D3: JF | E3: =IFERROR(IF(INDEX(INDIRECT("'"&$AI3&"'!$E$2:$E$118"),MATCH($A3,INDIRECT("'"&$AI3&"'!$A$2:$A$118"),0))="","",INDEX(INDIRECT("'"&$AI3&"'!$E$2:$E$118"),MATCH($A3,INDIRECT("'"&$AI3&"'!$A$2:$A$118"),0))),"") | F3: =IF($E3="","",IFERROR(INDEX(担当者マスタ!$B$2:$B$101,MATCH($E3,担当者マスタ!$A$2:$A$101,0)),"※マスタ未登録")) | G3: 4904.582 | H3: 4227.566 | I3: 5001.807 | J3: 4524.559 | K3: 4927.58 | L3: 3992.029 | M3: =SUM(G3:L3) -> 27578.123 | N3: 663.403 | O3: 582.982 | P3: 684.031 | Q3: 611.08 | R3: 681.929 | S3: 542.967 | T3: =SUM(N3:S3) -> 3766.392 | U3: 4015.689 | V3: 4119.32 | W3: 3764.454 | X3: 3419.529 | Y3: 4470.593 | Z3: 4581.308 | AA3: =SUM(U3:Z3) -> 24370.893 | AB3: 658.181 | AC3: 719.382 | AD3: 647.591 | AE3: 587.202 | AF3: 722.863 | AG3: 793.162 | AH3: =SUM(AB3:AG3) -> 4128.381 | AI3: 水産部X
A4: 0000000000691 | B4: JFしまね浜田支所総務 | C4: 0010 | D4: JF | E4: =IFERROR(IF(INDEX(INDIRECT("'"&$AI4&"'!$E$2:$E$118"),MATCH($A4,INDIRECT("'"&$AI4&"'!$A$2:$A$118"),0))="","",INDEX(INDIRECT("'"&$AI4&"'!$E$2:$E$118"),MATCH($A4,INDIRECT("'"&$AI4&"'!$A$2:$A$118"),0))),"") | F4: =IF($E4="","",IFERROR(INDEX(担当者マスタ!$B$2:$B$101,MATCH($E4,担当者マスタ!$A$2:$A$101,0)),"※マスタ未登録")) | G4: 28.35 | H4: 0 | I4: 0 | J4: 0 | K4: 0 | L4: 0 | M4: =SUM(G4:L4) -> 28.35 | N4: 10.95 | O4: 0 | P4: 0 | Q4: 0 | R4: 0 | S4: 0 | T4: =SUM(N4:S4) -> 10.95 | U4: 0 | V4: 0 | W4: 0 | X4: 0 | Y4: 0 | Z4: 0 | AA4: =SUM(U4:Z4) -> 0 | AB4: 0 | AC4: 0 | AD4: 0 | AE4: 0 | AF4: 0 | AG4: 0 | AH4: =SUM(AB4:AG4) -> 0 | AI4: 水産部X
A5: 0000000100191 | B5: JF浜田販売部 | C5: 0010 | D5: JF | E5: =IFERROR(IF(INDEX(INDIRECT("'"&$AI5&"'!$E$2:$E$118"),MATCH($A5,INDIRECT("'"&$AI5&"'!$A$2:$A$118"),0))="","",INDEX(INDIRECT("'"&$AI5&"'!$E$2:$E$118"),MATCH($A5,INDIRECT("'"&$AI5&"'!$A$2:$A$118"),0))),"") | F5: =IF($E5="","",IFERROR(INDEX(担当者マスタ!$B$2:$B$101,MATCH($E5,担当者マスタ!$A$2:$A$101,0)),"※マスタ未登録")) | G5: 490.36 | H5: 417.535 | I5: 372.735 | J5: 367.135 | K5: 355.935 | L5: 378.334 | M5: =SUM(G5:L5) -> 2382.034 | N5: 371.089 | O5: 295.464 | P5: 253.464 | Q5: 247.864 | R5: 236.664 | S5: 258.34 | T5: =SUM(N5:S5) -> 1662.885 | U5: 371.533 | V5: 354.732 | W5: 168 | X5: 128.8 | Y5: 145.6 | Z5: 140 | AA5: =SUM(U5:Z5) -> 1308.665 | AB5: 361.641 | AC5: 344.84 | AD5: 168 | AE5: 128.8 | AF5: 145.6 | AG5: 140 | AH5: =SUM(AB5:AG5) -> 1288.881 | AI5: 水産部X
A6: 0000000015661 | B6: 156 中山 圭司 | C6: 0011 | D6: 佐々木邦 | E6: =IFERROR(IF(INDEX(INDIRECT("'"&$AI6&"'!$E$2:$E$320"),MATCH($A6,INDIRECT("'"&$AI6&"'!$A$2:$A$320"),0))="","",INDEX(INDIRECT("'"&$AI6&"'!$E$2:$E$320"),MATCH($A6,INDIRECT("'"&$AI6&"'!$A$2:$A$320"),0))),"") | F6: =IF($E6="","",IFERROR(INDEX(担当者マスタ!$B$2:$B$101,MATCH($E6,担当者マスタ!$A$2:$A$101,0)),"※マスタ未登録")) | G6: 66.139 | H6: 111.017 | I6: 36.415 | J6: 95.814 | K6: 187.302 | L6: 18.073 | M6: =SUM(G6:L6) -> 514.76 | N6: 35.007 | O6: 66.715 | P6: 21.262 | Q6: 52.948 | R6: 43.271 | S6: 8.333 | T6: =SUM(N6:S6) -> 227.536 | U6: 90.974 | V6: 139.449 | W6: 22.066 | X6: 70.992 | Y6: 38.098 | Z6: 9.843 | AA6: =SUM(U6:Z6) -> 371.422 | AB6: 65.217 | AC6: 100.891 | AD6: 13.616 | AE6: 46.68 | AF6: 18.406 | AG6: 4.806 | AH6: =SUM(AB6:AG6) -> 249.616 | AI6: 石見
A7: 0000000034561 | B7: 345 田中乾魚店 | C7: 0011 | D7: 佐々木邦 | E7: =IFERROR(IF(INDEX(INDIRECT("'"&$AI7&"'!$E$2:$E$320"),MATCH($A7,INDIRECT("'"&$AI7&"'!$A$2:$A$320"),0))="","",INDEX(INDIRECT("'"&$AI7&"'!$E$2:$E$320"),MATCH($A7,INDIRECT("'"&$AI7&"'!$A$2:$A$320"),0))),"") | F7: =IF($E7="","",IFERROR(INDEX(担当者マスタ!$B$2:$B$101,MATCH($E7,担当者マスタ!$A$2:$A$101,0)),"※マスタ未登録")) | G7: 3.4 | H7: 14.955 | I7: 6.375 | J7: 0 | K7: 3.08 | L7: 0 | M7: =SUM(G7:L7) -> 27.81 | N7: 3.4 | O7: 7.717 | P7: 2.8 | Q7: 0 | R7: 1.473 | S7: 0 | T7: =SUM(N7:S7) -> 15.39 | U7: 0 | V7: 0 | W7: 0 | X7: 0.5 | Y7: 0 | Z7: 3.05 | AA7: =SUM(U7:Z7) -> 3.55 | AB7: 0 | AC7: 0 | AD7: 0 | AE7: 0.5 | AF7: 0 | AG7: 1.721 | AH7: =SUM(AB7:AG7) -> 2.221 | AI7: 石見
A8: 0000000038561 | B8: 385 (有)吉本重義商店 | C8: 0011 | D8: 佐々木邦 | E8: =IFERROR(IF(INDEX(INDIRECT("'"&$AI8&"'!$E$2:$E$320"),MATCH($A8,INDIRECT("'"&$AI8&"'!$A$2:$A$320"),0))="","",INDEX(INDIRECT("'"&$AI8&"'!$E$2:$E$320"),MATCH($A8,INDIRECT("'"&$AI8&"'!$A$2:$A$320"),0))),"") | F8: =IF($E8="","",IFERROR(INDEX(担当者マスタ!$B$2:$B$101,MATCH($E8,担当者マスタ!$A$2:$A$101,0)),"※マスタ未登録")) | G8: 32.432 | H8: 0 | I8: 0 | J8: 11.35 | K8: 0 | L8: 3.339 | M8: =SUM(G8:L8) -> 47.121 | N8: 23.326 | O8: 0 | P8: 0 | Q8: 4.85 | R8: 0 | S8: 1.854 | T8: =SUM(N8:S8) -> 30.03 | U8: 36.111 | V8: 11.04 | W8: 3.339 | X8: 0 | Y8: 0 | Z8: 0 | AA8: =SUM(U8:Z8) -> 50.49 | AB8: 22.156 | AC8: 5.556 | AD8: 1.659 | AE8: 0 | AF8: 0 | AG8: 0 | AH8: =SUM(AB8:AG8) -> 29.371 | AI8: 石見
A9: 0000000052561 | B9: 525 植野 信幸 | C9: 0011 | D9: 佐々木邦 | E9: =IFERROR(IF(INDEX(INDIRECT("'"&$AI9&"'!$E$2:$E$320"),MATCH($A9,INDIRECT("'"&$AI9&"'!$A$2:$A$320"),0))="","",INDEX(INDIRECT("'"&$AI9&"'!$E$2:$E$320"),MATCH($A9,INDIRECT("'"&$AI9&"'!$A$2:$A$320"),0))),"") | F9: =IF($E9="","",IFERROR(INDEX(担当者マスタ!$B$2:$B$101,MATCH($E9,担当者マスタ!$A$2:$A$101,0)),"※マスタ未登録")) | G9: 0 | H9: 1.52 | I9: 7.25 | J9: 0 | K9: 0 | L9: 1.36 | M9: =SUM(G9:L9) -> 10.13 | N9: 0 | O9: 0.852 | P9: 3.783 | Q9: 0 | R9: 0 | S9: 0.38 | T9: =SUM(N9:S9) -> 5.015 | U9: 0 | V9: 0 | W9: 5.11 | X9: 0 | Y9: 0 | Z9: 0 | AA9: =SUM(U9:Z9) -> 5.11 | AB9: 0 | AC9: 0 | AD9: 2.757 | AE9: 0 | AF9: 0 | AG9: 0 | AH9: =SUM(AB9:AG9) -> 2.757 | AI9: 石見
A10: 0000000052761 | B10: ※527 中井 浩 | C10: 0011 | D10: 佐々木邦 | E10: =IFERROR(IF(INDEX(INDIRECT("'"&$AI10&"'!$E$2:$E$320"),MATCH($A10,INDIRECT("'"&$AI10&"'!$A$2:$A$320"),0))="","",INDEX(INDIRECT("'"&$AI10&"'!$E$2:$E$320"),MATCH($A10,INDIRECT("'"&$AI10&"'!$A$2:$A$320"),0))),"") | F10: =IF($E10="","",IFERROR(INDEX(担当者マスタ!$B$2:$B$101,MATCH($E10,担当者マスタ!$A$2:$A$101,0)),"※マスタ未登録")) | G10: 209.322 | H10: 83.69 | I10: 103.08 | J10: 3.621 | K10: 73.377 | L10: 62.471 | M10: =SUM(G10:L10) -> 535.561 | N10: 82.094 | O10: 52.626 | P10: 54.96 | Q10: 1.926 | R10: 36.533 | S10: 36.068 | T10: =SUM(N10:S10) -> 264.207 | U10: 40.799 | V10: 62.98 | W10: 83.153 | X10: 0 | Y10: 0 | Z10: 0 | AA10: =SUM(U10:Z10) -> 186.932 | AB10: 23.037 | AC10: 38.526 | AD10: 50.38 | AE10: 0 | AF10: 0 | AG10: 0 | AH10: =SUM(AB10:AG10) -> 111.943 | AI10: 石見
A11: 0000000053661 | B11: 536 新田健二 (魚新) | C11: 0011 | D11: 佐々木邦 | E11: =IFERROR(IF(INDEX(INDIRECT("'"&$AI11&"'!$E$2:$E$320"),MATCH($A11,INDIRECT("'"&$AI11&"'!$A$2:$A$320"),0))="","",INDEX(INDIRECT("'"&$AI11&"'!$E$2:$E$320"),MATCH($A11,INDIRECT("'"&$AI11&"'!$A$2:$A$320"),0))),"") | F11: =IF($E11="","",IFERROR(INDEX(担当者マスタ!$B$2:$B$101,MATCH($E11,担当者マスタ!$A$2:$A$101,0)),"※マスタ未登録")) | G11: 4.239 | H11: 6.693 | I11: 2.34 | J11: 0 | K11: 2.34 | L11: 6.693 | M11: =SUM(G11:L11) -> 22.305 | N11: 2.392 | O11: 2.848 | P11: 1.273 | Q11: 0 | R11: 1.273 | S11: 2.848 | T11: =SUM(N11:S11) -> 10.634 | U11: 1.128 | V11: 0 | W11: 11.332 | X11: 0 | Y11: 3.468 | Z11: 5.565 | AA11: =SUM(U11:Z11) -> 21.493 | AB11: 0.733 | AC11: 0 | AD11: 5.413 | AE11: 0 | AF11: 2.006 | AG11: 2.115 | AH11: =SUM(AB11:AG11) -> 10.267 | AI11: 石見
A12: 0000000054061 | B12: 540 浜原 | C12: 0011 | D12: 佐々木邦 | E12: =IFERROR(IF(INDEX(INDIRECT("'"&$AI12&"'!$E$2:$E$320"),MATCH($A12,INDIRECT("'"&$AI12&"'!$A$2:$A$320"),0))="","",INDEX(INDIRECT("'"&$AI12&"'!$E$2:$E$320"),MATCH($A12,INDIRECT("'"&$AI12&"'!$A$2:$A$320"),0))),"") | F12: =IF($E12="","",IFERROR(INDEX(担当者マスタ!$B$2:$B$101,MATCH($E12,担当者マスタ!$A$2:$A$101,0)),"※マスタ未登録")) | G12: 0 | H12: 0 | I12: 0 | J12: 5.565 | K12: 0 | L12: 1.36 | M12: =SUM(G12:L12) -> 6.925 | N12: 0 | O12: 0 | P12: 0 | Q12: 2.115 | R12: 0 | S12: 0.38 | T12: =SUM(N12:S12) -> 2.495 | U12: 12.3 | V12: 0 | W12: 0 | X12: 0 | Y12: 0 | Z12: 0 | AA12: =SUM(U12:Z12) -> 12.3 | AB12: 7.36 | AC12: 0 | AD12: 0 | AE12: 0 | AF12: 0 | AG12: 0 | AH12: =SUM(AB12:AG12) -> 7.36 | AI12: 石見
A13: 0000000055761 | B13: 557山末鮮魚店 | C13: 0011 | D13: 佐々木邦 | E13: =IFERROR(IF(INDEX(INDIRECT("'"&$AI13&"'!$E$2:$E$320"),MATCH($A13,INDIRECT("'"&$AI13&"'!$A$2:$A$320"),0))="","",INDEX(INDIRECT("'"&$AI13&"'!$E$2:$E$320"),MATCH($A13,INDIRECT("'"&$AI13&"'!$A$2:$A$320"),0))),"") | F13: =IF($E13="","",IFERROR(INDEX(担当者マスタ!$B$2:$B$101,MATCH($E13,担当者マスタ!$A$2:$A$101,0)),"※マスタ未登録")) | G13: 12.138 | H13: 42.301 | I13: 203.145 | J13: -30.188 | K13: 25.386 | L13: 84.022 | M13: =SUM(G13:L13) -> 336.804 | N13: 6.817 | O13: 23.374 | P13: 102.421 | Q13: -15.475 | R13: 12.409 | S13: 23.692 | T13: =SUM(N13:S13) -> 153.238 | U13: 35.263 | V13: 24.819 | W13: 116.324 | X13: 5.615 | Y13: 101.697 | Z13: 21.525 | AA13: =SUM(U13:Z13) -> 305.243 | AB13: 18.983 | AC13: 13.872 | AD13: 49.442 | AE13: 2.946 | AF13: 32.017 | AG13: 8.522 | AH13: =SUM(AB13:AG13) -> 125.782 | AI13: 石見
A14: 0000000056461 | B14: 564渡辺鮮魚店㈱ | C14: 0011 | D14: 佐々木邦 | E14: =IFERROR(IF(INDEX(INDIRECT("'"&$AI14&"'!$E$2:$E$320"),MATCH($A14,INDIRECT("'"&$AI14&"'!$A$2:$A$320"),0))="","",INDEX(INDIRECT("'"&$AI14&"'!$E$2:$E$320"),MATCH($A14,INDIRECT("'"&$AI14&"'!$A$2:$A$320"),0))),"") | F14: =IF($E14="","",IFERROR(INDEX(担当者マスタ!$B$2:$B$101,MATCH($E14,担当者マスタ!$A$2:$A$101,0)),"※マスタ未登録")) | G14: 199.66 | H14: 85.905 | I14: 106.962 | J14: 61.555 | K14: 72.31 | L14: 78.24 | M14: =SUM(G14:L14) -> 604.632 | N14: 72.783 | O14: 29.191 | P14: 34.663 | Q14: 21.201 | R14: 22.532 | S14: 20.17 | T14: =SUM(N14:S14) -> 200.54 | U14: 83.7 | V14: 41.17 | W14: 112.518 | X14: 52.6 | Y14: 75.59 | Z14: 115.225 | AA14: =SUM(U14:Z14) -> 480.803 | AB14: 23.787 | AC14: 10.86 | AD14: 36.634 | AE14: 16.819 | AF14: 21.22 | AG14: 37.85 | AH14: =SUM(AB14:AG14) -> 147.17 | AI14: 石見
A15: 0000000090081 | B15: ｾﾌﾞﾝｲﾚﾌﾞﾝ浅利店 | C15: 0011 | D15: 佐々木邦 | E15: =IFERROR(IF(INDEX(INDIRECT("'"&$AI15&"'!$E$2:$E$320"),MATCH($A15,INDIRECT("'"&$AI15&"'!$A$2:$A$320"),0))="","",INDEX(INDIRECT("'"&$AI15&"'!$E$2:$E$320"),MATCH($A15,INDIRECT("'"&$AI15&"'!$A$2:$A$320"),0))),"") | F15: =IF($E15="","",IFERROR(INDEX(担当者マスタ!$B$2:$B$101,MATCH($E15,担当者マスタ!$A$2:$A$101,0)),"※マスタ未登録")) | G15: 0 | H15: 0 | I15: 23.1 | J15: 0 | K15: 0 | L15: 8.96 | M15: =SUM(G15:L15) -> 32.06 | N15: 0 | O15: 0 | P15: 4.95 | Q15: 0 | R15: 0 | S15: 1.8 | T15: =SUM(N15:S15) -> 6.75 | U15: 0 | V15: 0 | W15: 0 | X15: 0 | Y15: 0 | Z15: 0 | AA15: =SUM(U15:Z15) -> 0 | AB15: 0 | AC15: 0 | AD15: 0 | AE15: 0 | AF15: 0 | AG15: 0 | AH15: =SUM(AB15:AG15) -> 0 | AI15: 石見
A16: 0000000100481 | B16: (有)江木蒲鉾店 | C16: 0011 | D16: 佐々木邦 | E16: =IFERROR(IF(INDEX(INDIRECT("'"&$AI16&"'!$E$2:$E$320"),MATCH($A16,INDIRECT("'"&$AI16&"'!$A$2:$A$320"),0))="","",INDEX(INDIRECT("'"&$AI16&"'!$E$2:$E$320"),MATCH($A16,INDIRECT("'"&$AI16&"'!$A$2:$A$320"),0))),"") | F16: =IF($E16="","",IFERROR(INDEX(担当者マスタ!$B$2:$B$101,MATCH($E16,担当者マスタ!$A$2:$A$101,0)),"※マスタ未登録")) | G16: 1150.858 | H16: 598 | I16: 0 | J16: 237.8 | K16: 479.33 | L16: 125.88 | M16: =SUM(G16:L16) -> 2591.868 | N16: 228.633 | O16: 33 | P16: 0 | Q16: 38.1 | R16: 97.446 | S16: 19.84 | T16: =SUM(N16:S16) -> 417.019 | U16: 4.2 | V16: 0 | W16: 8.4 | X16: 0 | Y16: 6.3 | Z16: 4.2 | AA16: =SUM(U16:Z16) -> 23.1 | AB16: 0.6 | AC16: 0 | AD16: 1.2 | AE16: 0 | AF16: 0.9 | AG16: 0.6 | AH16: =SUM(AB16:AG16) -> 3.3 | AI16: 石見
A17: 0000000100691 | B17: 石見糀屋 発酵-LABO | C17: 0011 | D17: 佐々木邦 | E17: =IFERROR(IF(INDEX(INDIRECT("'"&$AI17&"'!$E$2:$E$320"),MATCH($A17,INDIRECT("'"&$AI17&"'!$A$2:$A$320"),0))="","",INDEX(INDIRECT("'"&$AI17&"'!$E$2:$E$320"),MATCH($A17,INDIRECT("'"&$AI17&"'!$A$2:$A$320"),0))),"") | F17: =IF($E17="","",IFERROR(INDEX(担当者マスタ!$B$2:$B$101,MATCH($E17,担当者マスタ!$A$2:$A$101,0)),"※マスタ未登録")) | G17: 11.328 | H17: 10.152 | I17: 13.992 | J17: 10.896 | K17: 14.712 | L17: 10.896 | M17: =SUM(G17:L17) -> 71.976 | N17: 2.376 | O17: 2.136 | P17: 3.048 | Q17: 2.352 | R17: 3.096 | S17: 2.352 | T17: =SUM(N17:S17) -> 15.36 | U17: 9.912 | V17: 8.616 | W17: 6.48 | X17: 12.048 | Y17: 8.616 | Z17: 8.616 | AA17: =SUM(U17:Z17) -> 54.288 | AB17: 2.832 | AC17: 2.472 | AD17: 1.8 | AE17: 2.928 | AF17: 1.992 | AG17: 1.992 | AH17: =SUM(AB17:AG17) -> 14.016 | AI17: 石見
... A284: 0000000909031 | B284: ㈱大磯-機械- | C284: 0014 | D284: 木村 | E284: =IFERROR(IF(INDEX(INDIRECT("'"&$AI284&"'!$E$2:$E$320"),MATCH($A284,INDIRECT("'"&$AI284&"'!$A$2:$A$320"),0))="","",INDEX(INDIRECT("'"&$AI284&"'!$E$2:$E$320"),MATCH($A284,INDIRECT("'"&$AI284&"'!$A$2:$A$320"),0))),"") | F284: =IF($E284="","",IFERROR(INDEX(担当者マスタ!$B$2:$B$101,MATCH($E284,担当者マスタ!$A$2:$A$101,0)),"※マスタ未登録")) | G284: 0 | H284: 0 | I284: 94.1 | J284: 20 | K284: 133 | L284: 0 | M284: =SUM(G284:L284) -> 247.1 | N284: 0 | O284: 0 | P284: 16.36 | Q284: 4 | R284: 37.8 | S284: 0 | T284: =SUM(N284:S284) -> 58.16 | U284: 0 | V284: 0 | W284: 302.802 | X284: 0 | Y284: 0 | Z284: 33.52 | AA284: =SUM(U284:Z284) -> 336.322 | AB284: 0 | AC284: 0 | AD284: 98.457 | AE284: 0 | AF284: 0 | AG284: 9.62 | AH284: =SUM(AB284:AG284) -> 108.077 | AI284: 石見
A285: 0000000000341 | B285: 153 新家商店 | C285: 0017 | D285: 鮮魚 | E285: =IFERROR(IF(INDEX(INDIRECT("'"&$AI285&"'!$E$2:$E$118"),MATCH($A285,INDIRECT("'"&$AI285&"'!$A$2:$A$118"),0))="","",INDEX(INDIRECT("'"&$AI285&"'!$E$2:$E$118"),MATCH($A285,INDIRECT("'"&$AI285&"'!$A$2:$A$118"),0))),"") | F285: =IF($E285="","",IFERROR(INDEX(担当者マスタ!$B$2:$B$101,MATCH($E285,担当者マスタ!$A$2:$A$101,0)),"※マスタ未登録")) | G285: 39.1 | H285: 14.423 | I285: 11.76 | J285: 17.036 | K285: 11.688 | L285: 8.097 | M285: =SUM(G285:L285) -> 102.104 | N285: 20.201 | O285: 6.885 | P285: 5.061 | Q285: 7.85 | R285: 5.304 | S285: 3.461 | T285: =SUM(N285:S285) -> 48.762 | U285: 26.513 | V285: 14.266 | W285: 18.887 | X285: 5.19 | Y285: 19.191 | Z285: 11.024 | AA285: =SUM(U285:Z285) -> 95.071 | AB285: 12.505 | AC285: 5.797 | AD285: 8.625 | AE285: 2.248 | AF285: 9.099 | AG285: 4.024 | AH285: =SUM(AB285:AG285) -> 42.298 | AI285: 水産部X
A286: 0000000090221 | B286: 西部農林水産振興ｾﾝﾀｰ | C286: 0017 | D286: 鮮魚 | E286: =IFERROR(IF(INDEX(INDIRECT("'"&$AI286&"'!$E$2:$E$118"),MATCH($A286,INDIRECT("'"&$AI286&"'!$A$2:$A$118"),0))="","",INDEX(INDIRECT("'"&$AI286&"'!$E$2:$E$118"),MATCH($A286,INDIRECT("'"&$AI286&"'!$A$2:$A$118"),0))),"") | F286: =IF($E286="","",IFERROR(INDEX(担当者マスタ!$B$2:$B$101,MATCH($E286,担当者マスタ!$A$2:$A$101,0)),"※マスタ未登録")) | G286: 0 | H286: 0 | I286: 0 | J286: 0 | K286: 0 | L286: 0 | M286: =SUM(G286:L286) -> 0 | N286: 0 | O286: 0 | P286: 0 | Q286: 0 | R286: 0 | S286: 0 | T286: =SUM(N286:S286) -> 0 | U286: 7 | V286: 0 | W286: 0 | X286: 0 | Y286: 0 | Z286: 0 | AA286: =SUM(U286:Z286) -> 7 | AB286: 1.72 | AC286: 0 | AD286: 0 | AE286: 0 | AF286: 0 | AG286: 0 | AH286: =SUM(AB286:AG286) -> 1.72 | AI286: 水産部X
A287: 0000000103121 | B287: (有)浜田運送 | C287: 0017 | D287: 鮮魚 | E287: =IFERROR(IF(INDEX(INDIRECT("'"&$AI287&"'!$E$2:$E$118"),MATCH($A287,INDIRECT("'"&$AI287&"'!$A$2:$A$118"),0))="","",INDEX(INDIRECT("'"&$AI287&"'!$E$2:$E$118"),MATCH($A287,INDIRECT("'"&$AI287&"'!$A$2:$A$118"),0))),"") | F287: =IF($E287="","",IFERROR(INDEX(担当者マスタ!$B$2:$B$101,MATCH($E287,担当者マスタ!$A$2:$A$101,0)),"※マスタ未登録")) | G287: 0 | H287: 0 | I287: 0 | J287: 0 | K287: 0 | L287: 0 | M287: =SUM(G287:L287) -> 0 | N287: 0 | O287: 0 | P287: 0 | Q287: 0 | R287: 0 | S287: 0 | T287: =SUM(N287:S287) -> 0 | U287: 0 | V287: 0 | W287: 0 | X287: 0 | Y287: 0 | Z287: 1.164 | AA287: =SUM(U287:Z287) -> 1.164 | AB287: 0 | AC287: 0 | AD287: 0 | AE287: 0 | AF287: 0 | AG287: 0.495 | AH287: =SUM(AB287:AG287) -> 0.495 | AI287: 水産部X
A288: 0000000202131 | B288: 220 福田水産㈱ | C288: 0017 | D288: 鮮魚 | E288: =IFERROR(IF(INDEX(INDIRECT("'"&$AI288&"'!$E$2:$E$118"),MATCH($A288,INDIRECT("'"&$AI288&"'!$A$2:$A$118"),0))="","",INDEX(INDIRECT("'"&$AI288&"'!$E$2:$E$118"),MATCH($A288,INDIRECT("'"&$AI288&"'!$A$2:$A$118"),0))),"") | F288: =IF($E288="","",IFERROR(INDEX(担当者マスタ!$B$2:$B$101,MATCH($E288,担当者マスタ!$A$2:$A$101,0)),"※マスタ未登録")) | G288: 69.5 | H288: 80.845 | I288: 29.36 | J288: 20.562 | K288: 114.97 | L288: 71.34 | M288: =SUM(G288:L288) -> 386.577 | N288: 68.25 | O288: 64.478 | P288: 16.16 | Q288: 20.03 | R288: 114.97 | S288: 71.34 | T288: =SUM(N288:S288) -> 355.228 | U288: 44 | V288: 142.4 | W288: 62.66 | X288: 20 | Y288: 10.6 | Z288: 3 | AA288: =SUM(U288:Z288) -> 282.66 | AB288: 44 | AC288: 141.15 | AD288: 62.243 | AE288: 20 | AF288: 10.6 | AG288: 3 | AH288: =SUM(AB288:AG288) -> 280.993 | AI288: 水産部X
A289: 0000000202471 | B289: ㈱浜田あけぼの水産 | C289: 0017 | D289: 鮮魚 | E289: =IFERROR(IF(INDEX(INDIRECT("'"&$AI289&"'!$E$2:$E$118"),MATCH($A289,INDIRECT("'"&$AI289&"'!$A$2:$A$118"),0))="","",INDEX(INDIRECT("'"&$AI289&"'!$E$2:$E$118"),MATCH($A289,INDIRECT("'"&$AI289&"'!$A$2:$A$118"),0))),"") | F289: =IF($E289="","",IFERROR(INDEX(担当者マスタ!$B$2:$B$101,MATCH($E289,担当者マスタ!$A$2:$A$101,0)),"※マスタ未登録")) | G289: 0 | H289: 0 | I289: 0 | J289: 0 | K289: 0 | L289: 0 | M289: =SUM(G289:L289) -> 0 | N289: 0 | O289: 0 | P289: 0 | Q289: 0 | R289: 0 | S289: 0 | T289: =SUM(N289:S289) -> 0 | U289: 0 | V289: 0 | W289: 0 | X289: 0 | Y289: 473.2 | Z289: 0 | AA289: =SUM(U289:Z289) -> 473.2 | AB289: 0 | AC289: 0 | AD289: 0 | AE289: 0 | AF289: 92.4 | AG289: 0 | AH289: =SUM(AB289:AG289) -> 92.4 | AI289: 水産部X
A290: 0000000202601 | B290: 103㈲山本一枝(鮮魚) | C290: 0017 | D290: 鮮魚 | E290: =IFERROR(IF(INDEX(INDIRECT("'"&$AI290&"'!$E$2:$E$118"),MATCH($A290,INDIRECT("'"&$AI290&"'!$A$2:$A$118"),0))="","",INDEX(INDIRECT("'"&$AI290&"'!$E$2:$E$118"),MATCH($A290,INDIRECT("'"&$AI290&"'!$A$2:$A$118"),0))),"") | F290: =IF($E290="","",IFERROR(INDEX(担当者マスタ!$B$2:$B$101,MATCH($E290,担当者マスタ!$A$2:$A$101,0)),"※マスタ未登録")) | G290: 496.65 | H290: 231.55 | I290: 55.45 | J290: 66.2 | K290: 34.25 | L290: 41.25 | M290: =SUM(G290:L290) -> 925.35 | N290: 449.596 | O290: 213.992 | P290: 55.45 | Q290: 59.177 | R290: 34.25 | S290: 41.25 | T290: =SUM(N290:S290) -> 853.715 | U290: 27.9 | V290: 84.5 | W290: 561.75 | X290: 412.4 | Y290: 546.4 | Z290: 51.7 | AA290: =SUM(U290:Z290) -> 1684.65 | AB290: 27.9 | AC290: 84.5 | AD290: 326.811 | AE290: 365.409 | AF290: 405.898 | AG290: 46.894 | AH290: =SUM(AB290:AG290) -> 1257.412 | AI290: 水産部X
A291: 0000000202891 | B291: ㈱かもしま資材 | C291: 0017 | D291: 鮮魚 | E291: =IFERROR(IF(INDEX(INDIRECT("'"&$AI291&"'!$E$2:$E$118"),MATCH($A291,INDIRECT("'"&$AI291&"'!$A$2:$A$118"),0))="","",INDEX(INDIRECT("'"&$AI291&"'!$E$2:$E$118"),MATCH($A291,INDIRECT("'"&$AI291&"'!$A$2:$A$118"),0))),"") | F291: =IF($E291="","",IFERROR(INDEX(担当者マスタ!$B$2:$B$101,MATCH($E291,担当者マスタ!$A$2:$A$101,0)),"※マスタ未登録")) | G291: 1927.301 | H291: 896.31 | I291: 384.75 | J291: 232.53 | K291: 131.08 | L291: 304.45 | M291: =SUM(G291:L291) -> 3876.421 | N291: 432.615 | O291: 199.95 | P291: 87.61 | Q291: 53.55 | R291: 30.92 | S291: 71.28 | T291: =SUM(N291:S291) -> 875.925 | U291: 1160.935 | V291: 696.99 | W291: 540.014 | X291: 434.97 | Y291: 266.45 | Z291: 417.96 | AA291: =SUM(U291:Z291) -> 3517.319 | AB291: 252.081 | AC291: 151.96 | AD291: 117.586 | AE291: 99.88 | AF291: 60.93 | AG291: 93.45 | AH291: =SUM(AB291:AG291) -> 775.887 | AI291: 水産部X
A292: 0000000820021 | B292: 116ﾏﾙｾｲ商店 ｽﾁﾛｰﾙ他 | C292: 0017 | D292: 鮮魚 | E292: =IFERROR(IF(INDEX(INDIRECT("'"&$AI292&"'!$E$2:$E$118"),MATCH($A292,INDIRECT("'"&$AI292&"'!$A$2:$A$118"),0))="","",INDEX(INDIRECT("'"&$AI292&"'!$E$2:$E$118"),MATCH($A292,INDIRECT("'"&$AI292&"'!$A$2:$A$118"),0))),"") | F292: =IF($E292="","",IFERROR(INDEX(担当者マスタ!$B$2:$B$101,MATCH($E292,担当者マスタ!$A$2:$A$101,0)),"※マスタ未登録")) | G292: 0 | H292: 0 | I292: 0 | J292: 0 | K292: 0 | L292: 0 | M292: =SUM(G292:L292) -> 0 | N292: 0 | O292: 0 | P292: 0 | Q292: 0 | R292: 0 | S292: 0 | T292: =SUM(N292:S292) -> 0 | U292: 5041.8 | V292: 6213.805 | W292: 4525.811 | X292: 4430.911 | Y292: 3797.025 | Z292: 4362.168 | AA292: =SUM(U292:Z292) -> 28371.52 | AB292: 1982.663 | AC292: 2331.152 | AD292: 1754.948 | AE292: 1655.38 | AF292: 1390.295 | AG292: 1680.919 | AH292: =SUM(AB292:AG292) -> 10795.357 | AI292: 水産部X
A293: 0000000000011 | B293: 現金 | C293: 0019 | D293: その他 | E293: =IFERROR(IF(INDEX(INDIRECT("'"&$AI293&"'!$E$2:$E$320"),MATCH($A293,INDIRECT("'"&$AI293&"'!$A$2:$A$320"),0))="","",INDEX(INDIRECT("'"&$AI293&"'!$E$2:$E$320"),MATCH($A293,INDIRECT("'"&$AI293&"'!$A$2:$A$320"),0))),"") | F293: =IF($E293="","",IFERROR(INDEX(担当者マスタ!$B$2:$B$101,MATCH($E293,担当者マスタ!$A$2:$A$101,0)),"※マスタ未登録")) | G293: 219.564 | H293: 77.791 | I293: 183.928 | J293: 52.388 | K293: 42.213 | L293: 73.638 | M293: =SUM(G293:L293) -> 649.522 | N293: 146.58 | O293: 31.779 | P293: 83.206 | Q293: 31.447 | R293: 21.221 | S293: 37.945 | T293: =SUM(N293:S293) -> 352.178 | U293: 30.176 | V293: 201.538 | W293: 192.535 | X293: 58.168 | Y293: 6.56 | Z293: 154.97 | AA293: =SUM(U293:Z293) -> 643.947 | AB293: 13.8 | AC293: 73.075 | AD293: 78.541 | AE293: 29.898 | AF293: 3.921 | AG293: 68.503 | AH293: =SUM(AB293:AG293) -> 267.738 | AI293: 石見
A294: 0000000000031 | B294: 現金(営業) | C294: 0019 | D294: その他 | E294: =IFERROR(IF(INDEX(INDIRECT("'"&$AI294&"'!$E$2:$E$320"),MATCH($A294,INDIRECT("'"&$AI294&"'!$A$2:$A$320"),0))="","",INDEX(INDIRECT("'"&$AI294&"'!$E$2:$E$320"),MATCH($A294,INDIRECT("'"&$AI294&"'!$A$2:$A$320"),0))),"") | F294: =IF($E294="","",IFERROR(INDEX(担当者マスタ!$B$2:$B$101,MATCH($E294,担当者マスタ!$A$2:$A$101,0)),"※マスタ未登録")) | G294: 0 | H294: 0 | I294: 0 | J294: 0 | K294: 0 | L294: 0 | M294: =SUM(G294:L294) -> 0 | N294: 0 | O294: 0 | P294: 0 | Q294: 0 | R294: 0 | S294: 0 | T294: =SUM(N294:S294) -> 0 | U294: 0 | V294: 0 | W294: 30 | X294: 0 | Y294: 0 | Z294: 0 | AA294: =SUM(U294:Z294) -> 30 | AB294: 0 | AC294: 0 | AD294: 30 | AE294: 0 | AF294: 0 | AG294: 0 | AH294: =SUM(AB294:AG294) -> 30 | AI294: 石見
A295: 0000000009001 | B295: ㈱ｴﾌﾋﾟｺ ﾍﾟｯﾄﾎﾞﾄﾙ回収 | C295: 0019 | D295: その他 | E295: =IFERROR(IF(INDEX(INDIRECT("'"&$AI295&"'!$E$2:$E$320"),MATCH($A295,INDIRECT("'"&$AI295&"'!$A$2:$A$320"),0))="","",INDEX(INDIRECT("'"&$AI295&"'!$E$2:$E$320"),MATCH($A295,INDIRECT("'"&$AI295&"'!$A$2:$A$320"),0))),"") | F295: =IF($E295="","",IFERROR(INDEX(担当者マスタ!$B$2:$B$101,MATCH($E295,担当者マスタ!$A$2:$A$101,0)),"※マスタ未登録")) | G295: 21.6 | H295: 0 | I295: 0 | J295: 15.9 | K295: 0 | L295: 0 | M295: =SUM(G295:L295) -> 37.5 | N295: 2.592 | O295: 0 | P295: 0 | Q295: 1.908 | R295: 0 | S295: 0 | T295: =SUM(N295:S295) -> 4.5 | U295: 20.85 | V295: 0 | W295: 0 | X295: 13.95 | Y295: 0 | Z295: 0 | AA295: =SUM(U295:Z295) -> 34.8 | AB295: 2.502 | AC295: 0 | AD295: 0 | AE295: 1.674 | AF295: 0 | AG295: 0 | AH295: =SUM(AB295:AG295) -> 4.176 | AI295: 石見
A296: 0000000090011 | B296: 杉の森ﾃﾞｲｻｰﾋﾞｽ *運 | C296: 0019 | D296: その他 | E296: =IFERROR(IF(INDEX(INDIRECT("'"&$AI296&"'!$E$2:$E$320"),MATCH($A296,INDIRECT("'"&$AI296&"'!$A$2:$A$320"),0))="","",INDEX(INDIRECT("'"&$AI296&"'!$E$2:$E$320"),MATCH($A296,INDIRECT("'"&$AI296&"'!$A$2:$A$320"),0))),"") | F296: =IF($E296="","",IFERROR(INDEX(担当者マスタ!$B$2:$B$101,MATCH($E296,担当者マスタ!$A$2:$A$101,0)),"※マスタ未登録")) | G296: 18.708 | H296: 18.708 | I296: 10.143 | J296: 0 | K296: 0 | L296: 0 | M296: =SUM(G296:L296) -> 47.559 | N296: 6.828 | O296: 6.828 | P296: 3.753 | Q296: 0 | R296: 0 | S296: 0 | T296: =SUM(N296:S296) -> 17.409 | U296: 0 | V296: 0 | W296: 0 | X296: 0 | Y296: 10.143 | Z296: 18.708 | AA296: =SUM(U296:Z296) -> 28.851 | AB296: 0 | AC296: 0 | AD296: 0 | AE296: 0 | AF296: 3.753 | AG296: 6.828 | AH296: =SUM(AB296:AG296) -> 10.581 | AI296: 石見
A297: 0000000090061 | B297: 金城支所産業建設課 | C297: 0019 | D297: その他 | E297: =IFERROR(IF(INDEX(INDIRECT("'"&$AI297&"'!$E$2:$E$320"),MATCH($A297,INDIRECT("'"&$AI297&"'!$A$2:$A$320"),0))="","",INDEX(INDIRECT("'"&$AI297&"'!$E$2:$E$320"),MATCH($A297,INDIRECT("'"&$AI297&"'!$A$2:$A$320"),0))),"") | F297: =IF($E297="","",IFERROR(INDEX(担当者マスタ!$B$2:$B$101,MATCH($E297,担当者マスタ!$A$2:$A$101,0)),"※マスタ未登録")) | G297: 15.515 | H297: 0 | I297: 0 | J297: 0 | K297: 0 | L297: 0 | M297: =SUM(G297:L297) -> 15.515 | N297: 6.195 | O297: 0 | P297: 0 | Q297: 0 | R297: 0 | S297: 0 | T297: =SUM(N297:S297) -> 6.195 | U297: 0 | V297: 0 | W297: 0 | X297: 0 | Y297: 0 | Z297: 0 | AA297: =SUM(U297:Z297) -> 0 | AB297: 0 | AC297: 0 | AD297: 0 | AE297: 0 | AF297: 0 | AG297: 0 | AH297: =SUM(AB297:AG297) -> 0 | AI297: 石見
A298: 0000000090091 | B298: 浜田市社会福祉協金城 | C298: 0019 | D298: その他 | E298: =IFERROR(IF(INDEX(INDIRECT("'"&$AI298&"'!$E$2:$E$320"),MATCH($A298,INDIRECT("'"&$AI298&"'!$A$2:$A$320"),0))="","",INDEX(INDIRECT("'"&$AI298&"'!$E$2:$E$320"),MATCH($A298,INDIRECT("'"&$AI298&"'!$A$2:$A$320"),0))),"") | F298: =IF($E298="","",IFERROR(INDEX(担当者マスタ!$B$2:$B$101,MATCH($E298,担当者マスタ!$A$2:$A$101,0)),"※マスタ未登録")) | G298: 0 | H298: 19.35 | I298: 0 | J298: 0 | K298: 0 | L298: 0 | M298: =SUM(G298:L298) -> 19.35 | N298: 0 | O298: 7.434 | P298: 0 | Q298: 0 | R298: 0 | S298: 0 | T298: =SUM(N298:S298) -> 7.434 | U298: 0 | V298: 0 | W298: 0 | X298: 0 | Y298: 0 | Z298: 0 | AA298: =SUM(U298:Z298) -> 0 | AB298: 0 | AC298: 0 | AD298: 0 | AE298: 0 | AF298: 0 | AG298: 0 | AH298: =SUM(AB298:AG298) -> 0 | AI298: 石見
A299: 0000000090131 | B299: 土井屋 | C299: 0019 | D299: その他 | E299: =IFERROR(IF(INDEX(INDIRECT("'"&$AI299&"'!$E$2:$E$320"),MATCH($A299,INDIRECT("'"&$AI299&"'!$A$2:$A$320"),0))="","",INDEX(INDIRECT("'"&$AI299&"'!$E$2:$E$320"),MATCH($A299,INDIRECT("'"&$AI299&"'!$A$2:$A$320"),0))),"") | F299: =IF($E299="","",IFERROR(INDEX(担当者マスタ!$B$2:$B$101,MATCH($E299,担当者マスタ!$A$2:$A$101,0)),"※マスタ未登録")) | G299: 0 | H299: 0 | I299: 9.81 | J299: 0 | K299: 0 | L299: 0 | M299: =SUM(G299:L299) -> 9.81 | N299: 0 | O299: 0 | P299: 2.123 | Q299: 0 | R299: 0 | S299: 0 | T299: =SUM(N299:S299) -> 2.123 | U299: 0 | V299: 0 | W299: 0 | X299: 0 | Y299: 0 | Z299: 0 | AA299: =SUM(U299:Z299) -> 0 | AB299: 0 | AC299: 0 | AD299: 0 | AE299: 0 | AF299: 0 | AG299: 0 | AH299: =SUM(AB299:AG299) -> 0 | AI299: 石見
A300: 0000000100601 | B300: 大下船具店 *ﾚｼﾞ* | C300: 0019 | D300: その他 | E300: =IFERROR(IF(INDEX(INDIRECT("'"&$AI300&"'!$E$2:$E$320"),MATCH($A300,INDIRECT("'"&$AI300&"'!$A$2:$A$320"),0))="","",INDEX(INDIRECT("'"&$AI300&"'!$E$2:$E$320"),MATCH($A300,INDIRECT("'"&$AI300&"'!$A$2:$A$320"),0))),"") | F300: =IF($E300="","",IFERROR(INDEX(担当者マスタ!$B$2:$B$101,MATCH($E300,担当者マスタ!$A$2:$A$101,0)),"※マスタ未登録")) | G300: 3.5 | H300: 0 | I300: 0 | J300: 0 | K300: 0 | L300: 4.22 | M300: =SUM(G300:L300) -> 7.72 | N300: 2.27 | O300: 0 | P300: 0 | Q300: 0 | R300: 0 | S300: 2.99 | T300: =SUM(N300:S300) -> 5.26 | U300: 0 | V300: 0 | W300: 0 | X300: 0 | Y300: 0 | Z300: 0 | AA300: =SUM(U300:Z300) -> 0 | AB300: 0 | AC300: 0 | AD300: 0 | AE300: 0 | AF300: 0 | AG300: 0 | AH300: =SUM(AB300:AG300) -> 0 | AI300: 石見
A301: 0000000100751 | B301: くいしん坊 *ﾚｼﾞ* | C301: 0019 | D301: その他 | E301: =IFERROR(IF(INDEX(INDIRECT("'"&$AI301&"'!$E$2:$E$320"),MATCH($A301,INDIRECT("'"&$AI301&"'!$A$2:$A$320"),0))="","",INDEX(INDIRECT("'"&$AI301&"'!$E$2:$E$320"),MATCH($A301,INDIRECT("'"&$AI301&"'!$A$2:$A$320"),0))),"") | F301: =IF($E301="","",IFERROR(INDEX(担当者マスタ!$B$2:$B$101,MATCH($E301,担当者マスタ!$A$2:$A$101,0)),"※マスタ未登録")) | G301: 0 | H301: 0 | I301: 0 | J301: 0 | K301: 0 | L301: 0 | M301: =SUM(G301:L301) -> 0 | N301: 0 | O301: 0 | P301: 0 | Q301: 0 | R301: 0 | S301: 0 | T301: =SUM(N301:S301) -> 0 | U301: 0 | V301: 0 | W301: 0 | X301: 13.12 | Y301: 0 | Z301: 0 | AA301: =SUM(U301:Z301) -> 13.12 | AB301: 0 | AC301: 0 | AD301: 0 | AE301: 4.12 | AF301: 0 | AG301: 0 | AH301: =SUM(AB301:AG301) -> 4.12 | AI301: 石見
A302: 0000000101101 | B302: ｽｰﾊﾟｰさいとう | C302: 0019 | D302: その他 | E302: =IFERROR(IF(INDEX(INDIRECT("'"&$AI302&"'!$E$2:$E$320"),MATCH($A302,INDIRECT("'"&$AI302&"'!$A$2:$A$320"),0))="","",INDEX(INDIRECT("'"&$AI302&"'!$E$2:$E$320"),MATCH($A302,INDIRECT("'"&$AI302&"'!$A$2:$A$320"),0))),"") | F302: =IF($E302="","",IFERROR(INDEX(担当者マスタ!$B$2:$B$101,MATCH($E302,担当者マスタ!$A$2:$A$101,0)),"※マスタ未登録")) | G302: 3.21 | H302: 5.378 | I302: 16 | J302: 7.52 | K302: 3.12 | L302: 8.82 | M302: =SUM(G302:L302) -> 44.048 | N302: 1.54 | O302: 2.644 | P302: 12.54 | Q302: 4.05 | R302: 2.22 | S302: 6.46 | T302: =SUM(N302:S302) -> 29.454 | U302: 15.193 | V302: 11.63 | W302: 0 | X302: 7.987 | Y302: 1.8 | Z302: 7.11 | AA302: =SUM(U302:Z302) -> 43.72 | AB302: 7.895 | AC302: 8.39 | AD302: 0 | AE302: 3.748 | AF302: 0.7 | AG302: 5.5 | AH302: =SUM(AB302:AG302) -> 26.233 | AI302: 石見
A303: 0000000120181 | B303: むさしの *ﾚｼﾞ* | C303: 0019 | D303: その他 | E303: =IFERROR(IF(INDEX(INDIRECT("'"&$AI303&"'!$E$2:$E$320"),MATCH($A303,INDIRECT("'"&$AI303&"'!$A$2:$A$320"),0))="","",INDEX(INDIRECT("'"&$AI303&"'!$E$2:$E$320"),MATCH($A303,INDIRECT("'"&$AI303&"'!$A$2:$A$320"),0))),"") | F303: =IF($E303="","",IFERROR(INDEX(担当者マスタ!$B$2:$B$101,MATCH($E303,担当者マスタ!$A$2:$A$101,0)),"※マスタ未登録")) | G303: 8.046 | H303: 0 | I303: 1.98 | J303: 0.8 | K303: 4.986 | L303: 16.304 | M303: =SUM(G303:L303) -> 32.116 | N303: 3.488 | O303: 0 | P303: 1.068 | Q303: 0.324 | R303: 2.347 | S303: 6.589 | T303: =SUM(N303:S303) -> 13.816 | U303: 6.84 | V303: 2.49 | W303: 7.84 | X303: 19.963 | Y303: 0 | Z303: 17.876 | AA303: =SUM(U303:Z303) -> 55.009 | AB303: 2.759 | AC303: 1.074 | AD303: 2.745 | AE303: 8.792 | AF303: 0 | AG303: 6.707 | AH303: =SUM(AB303:AG303) -> 22.077 | AI303: 石見
A304: 0000000190041 | B304: ｸﾞﾘｰﾝｽﾎﾟｯﾄF *ﾚｼﾞ* | C304: 0019 | D304: その他 | E304: =IFERROR(IF(INDEX(INDIRECT("'"&$AI304&"'!$E$2:$E$320"),MATCH($A304,INDIRECT("'"&$AI304&"'!$A$2:$A$320"),0))="","",INDEX(INDIRECT("'"&$AI304&"'!$E$2:$E$320"),MATCH($A304,INDIRECT("'"&$AI304&"'!$A$2:$A$320"),0))),"") | F304: =IF($E304="","",IFERROR(INDEX(担当者マスタ!$B$2:$B$101,MATCH($E304,担当者マスタ!$A$2:$A$101,0)),"※マスタ未登録")) | G304: 0 | H304: 0 | I304: 34.059 | J304: 0 | K304: 0 | L304: 26.039 | M304: =SUM(G304:L304) -> 60.098 | N304: 0 | O304: 0 | P304: 13.342 | Q304: 0 | R304: 0 | S304: 11.412 | T304: =SUM(N304:S304) -> 24.754 | U304: 17.085 | V304: 9.5 | W304: 30.438 | X304: 0 | Y304: 0 | Z304: 4.209 | AA304: =SUM(U304:Z304) -> 61.232 | AB304: 8.666 | AC304: 4.79 | AD304: 12.924 | AE304: 0 | AF304: 0 | AG304: 2.772 | AH304: =SUM(AB304:AG304) -> 29.152 | AI304: 石見
... A317: 0000000703521 | B317: 大田市ごみ袋 | C317: 0020 | D317: 自治体 | E317: =IFERROR(IF(INDEX(INDIRECT("'"&$AI317&"'!$E$2:$E$320"),MATCH($A317,INDIRECT("'"&$AI317&"'!$A$2:$A$320"),0))="","",INDEX(INDIRECT("'"&$AI317&"'!$E$2:$E$320"),MATCH($A317,INDIRECT("'"&$AI317&"'!$A$2:$A$320"),0))),"") | F317: =IF($E317="","",IFERROR(INDEX(担当者マスタ!$B$2:$B$101,MATCH($E317,担当者マスタ!$A$2:$A$101,0)),"※マスタ未登録")) | G317: 0 | H317: 0 | I317: 0 | J317: 0 | K317: 0 | L317: 0 | M317: =SUM(G317:L317) -> 0 | N317: 0 | O317: 0 | P317: 0 | Q317: 0 | R317: 0 | S317: 0 | T317: =SUM(N317:S317) -> 0 | U317: 0 | V317: 11222.8 | W317: 0 | X317: 0 | Y317: 0 | Z317: 0 | AA317: =SUM(U317:Z317) -> 11222.8 | AB317: 0 | AC317: 564.4 | AD317: 0 | AE317: 0 | AF317: 0 | AG317: 0 | AH317: =SUM(AB317:AG317) -> 564.4 | AI317: 石見
A318: 0000000100682 | B318: 深川養鶏田屋 | C318: 0021 | D318: 高橋所長 | E318: =IFERROR(IF(INDEX(INDIRECT("'"&$AI318&"'!$E$2:$E$121"),MATCH($A318,INDIRECT("'"&$AI318&"'!$A$2:$A$121"),0))="","",INDEX(INDIRECT("'"&$AI318&"'!$E$2:$E$121"),MATCH($A318,INDIRECT("'"&$AI318&"'!$A$2:$A$121"),0))),"") | F318: =IF($E318="","",IFERROR(INDEX(担当者マスタ!$B$2:$B$101,MATCH($E318,担当者マスタ!$A$2:$A$101,0)),"※マスタ未登録")) | G318: 627.274 | H318: 586.766 | I318: 636.98 | J318: 439.889 | K318: 558.988 | L318: 479.596 | M318: =SUM(G318:L318) -> 3329.493 | N318: 111.011 | O318: 102.985 | P318: 118.218 | Q318: 88.206 | R318: 105.834 | S318: 80.049 | T318: =SUM(N318:S318) -> 606.303 | U318: 666.94 | V318: 555.38 | W318: 750.908 | X318: 556.719 | Y318: 500.888 | Z318: 588.448 | AA318: =SUM(U318:Z318) -> 3619.283 | AB318: 128.876 | AC318: 107.97 | AD318: 148.097 | AE318: 110.398 | AF318: 91.165 | AG318: 105.138 | AH318: =SUM(AB318:AG318) -> 691.644 | AI318: 下関
...

Sheet 水産部X
A1: 得意先コード | B1: 得意先略称 | C1: 担当者コード | D1: 担当者名 | E1: 新担当者コード | F1: 新担当者 | G1: 2024/10売上 | H1: 2024/11売上 | I1: 2024/12売上 | J1: 2025/01売上 | K1: 2025/02売上 | L1: 2025/03売上 | M1: 前年度売上合計 | N1: 2024/10粗利益 | O1: 2024/11粗利益 | P1: 2024/12粗利益 | Q1: 2025/01粗利益 | R1: 2025/02粗利益 | S1: 2025/03粗利益 | T1: 前年度粗利益合計 | U1: 2025/10売上 | V1: 2025/11売上 | W1: 2025/12売上 | X1: 2026/01売上 | Y1: 2026/02売上 | Z1: 2026/03売上 | AA1: 今年度売上合計 | AB1: 2025/10粗利益 | AC1: 2025/11粗利益 | AD1: 2025/12粗利益 | AE1: 2026/01粗利益 | AF1: 2026/02粗利益 | AG1: 2026/03粗利益 | AH1: 今年度粗利益合計
A2: 0000000000541 | B2: JFしまね冷蔵庫 | C2: 0010 | D2: JF | F2: =IF($E2="","",IFERROR(INDEX(担当者マスタ!$B$2:$B$101,MATCH($E2,担当者マスタ!$A$2:$A$101,0)),"※マスタ未登録")) | G2: 1727.964 | H2: 1845.035 | I2: 1015.906 | J2: 861.896 | K2: 1167.74 | L2: 1096.898 | M2: =SUM(G2:L2) -> 7715.439 | N2: 328.751 | O2: 408.366 | P2: 254.265 | Q2: 212.557 | R2: 257.125 | S2: 195.312 | T2: =SUM(N2:S2) -> 1656.376 | U2: 2143.798 | V2: 2047.515 | W2: 1351.109 | X2: 572.291 | Y2: 606.598 | Z2: 1948.328 | AA2: =SUM(U2:Z2) -> 8669.639 | AB2: 453.995 | AC2: 419.149 | AD2: 269.7 | AE2: 114.237 | AF2: 168.409 | AG2: 474.166 | AH2: =SUM(AB2:AG2) -> 1899.656
A3: 0000000000561 | B3: JFしまねｻｰﾋﾞｽ | C3: 0010 | D3: JF | F3: =IF($E3="","",IFERROR(INDEX(担当者マスタ!$B$2:$B$101,MATCH($E3,担当者マスタ!$A$2:$A$101,0)),"※マスタ未登録")) | G3: 4904.582 | H3: 4227.566 | I3: 5001.807 | J3: 4524.559 | K3: 4927.58 | L3: 3992.029 | M3: =SUM(G3:L3) -> 27578.123 | N3: 663.403 | O3: 582.982 | P3: 684.031 | Q3: 611.08 | R3: 681.929 | S3: 542.967 | T3: =SUM(N3:S3) -> 3766.392 | U3: 4015.689 | V3: 4119.32 | W3: 3764.454 | X3: 3419.529 | Y3: 4470.593 | Z3: 4581.308 | AA3: =SUM(U3:Z3) -> 24370.893 | AB3: 658.181 | AC3: 719.382 | AD3: 647.591 | AE3: 587.202 | AF3: 722.863 | AG3: 793.162 | AH3: =SUM(AB3:AG3) -> 4128.381
A4: 0000000000691 | B4: JFしまね浜田支所総務 | C4: 0010 | D4: JF | F4: =IF($E4="","",IFERROR(INDEX(担当者マスタ!$B$2:$B$101,MATCH($E4,担当者マスタ!$A$2:$A$101,0)),"※マスタ未登録")) | G4: 28.35 | H4: 0 | I4: 0 | J4: 0 | K4: 0 | L4: 0 | M4: =SUM(G4:L4) -> 28.35 | N4: 10.95 | O4: 0 | P4: 0 | Q4: 0 | R4: 0 | S4: 0 | T4: =SUM(N4:S4) -> 10.95 | U4: 0 | V4: 0 | W4: 0 | X4: 0 | Y4: 0 | Z4: 0 | AA4: =SUM(U4:Z4) -> 0 | AB4: 0 | AC4: 0 | AD4: 0 | AE4: 0 | AF4: 0 | AG4: 0 | AH4: =SUM(AB4:AG4) -> 0
A5: 0000000100191 | B5: JF浜田販売部 | C5: 0010 | D5: JF | F5: =IF($E5="","",IFERROR(INDEX(担当者マスタ!$B$2:$B$101,MATCH($E5,担当者マスタ!$A$2:$A$101,0)),"※マスタ未登録")) | G5: 490.36 | H5: 417.535 | I5: 372.735 | J5: 367.135 | K5: 355.935 | L5: 378.334 | M5: =SUM(G5:L5) -> 2382.034 | N5: 371.089 | O5: 295.464 | P5: 253.464 | Q5: 247.864 | R5: 236.664 | S5: 258.34 | T5: =SUM(N5:S5) -> 1662.885 | U5: 371.533 | V5: 354.732 | W5: 168 | X5: 128.8 | Y5: 145.6 | Z5: 140 | AA5: =SUM(U5:Z5) -> 1308.665 | AB5: 361.641 | AC5: 344.84 | AD5: 168 | AE5: 128.8 | AF5: 145.6 | AG5: 140 | AH5: =SUM(AB5:AG5) -> 1288.881
C6: 0010 集計 | D6: JF | G6: =SUBTOTAL(9,G2:G5) -> 7151.256 | H6: =SUBTOTAL(9,H2:H5) -> 6490.136 | I6: =SUBTOTAL(9,I2:I5) -> 6390.448 | J6: =SUBTOTAL(9,J2:J5) -> 5753.59 | K6: =SUBTOTAL(9,K2:K5) -> 6451.255 | L6: =SUBTOTAL(9,L2:L5) -> 5467.261 | M6: =SUBTOTAL(9,M2:M5) -> 37703.946 | N6: =SUBTOTAL(9,N2:N5) -> 1374.193 | ... AH6: =SUBTOTAL(9,AH2:AH5) -> 7316.918
A7: 0000000000341 | B7: 153 新家商店 | C7: 0017 | D7: 鮮魚 | F7: =IF($E7="","",IFERROR(INDEX(担当者マスタ!$B$2:$B$101,MATCH($E7,担当者マスタ!$A$2:$A$101,0)),"※マスタ未登録")) | G7: 39.1 | H7: 14.423 | I7: 11.76 | J7: 17.036 | K7: 11.688 | L7: 8.097 | M7: =SUM(G7:L7) -> 102.104 | N7: 20.201 | O7: 6.885 | P7: 5.061 | Q7: 7.85 | R7: 5.304 | S7: 3.461 | T7: =SUM(N7:S7) -> 48.762 | U7: 26.513 | V7: 14.266 | W7: 18.887 | X7: 5.19 | Y7: 19.191 | Z7: 11.024 | AA7: =SUM(U7:Z7) -> 95.071 | AB7: 12.505 | AC7: 5.797 | AD7: 8.625 | AE7: 2.248 | AF7: 9.099 | AG7: 4.024 | AH7: =SUM(AB7:AG7) -> 42.298
A8: 0000000090221 | B8: 西部農林水産振興ｾﾝﾀｰ | C8: 0017 | D8: 鮮魚 | F8: =IF($E8="","",IFERROR(INDEX(担当者マスタ!$B$2:$B$101,MATCH($E8,担当者マスタ!$A$2:$A$101,0)),"※マスタ未登録")) | G8: 0 | H8: 0 | I8: 0 | J8: 0 | K8: 0 | L8: 0 | M8: =SUM(G8:L8) -> 0 | N8: 0 | O8: 0 | P8: 0 | Q8: 0 | R8: 0 | S8: 0 | T8: =SUM(N8:S8) -> 0 | U8: 7 | V8: 0 | W8: 0 | X8: 0 | Y8: 0 | Z8: 0 | AA8: =SUM(U8:Z8) -> 7 | AB8: 1.72 | AC8: 0 | AD8: 0 | AE8: 0 | AF8: 0 | AG8: 0 | AH8: =SUM(AB8:AG8) -> 1.72
A9: 0000000103121 | B9: (有)浜田運送 | C9: 0017 | D9: 鮮魚 | F9: =IF($E9="","",IFERROR(INDEX(担当者マスタ!$B$2:$B$101,MATCH($E9,担当者マスタ!$A$2:$A$101,0)),"※マスタ未登録")) | G9: 0 | H9: 0 | I9: 0 | J9: 0 | K9: 0 | L9: 0 | M9: =SUM(G9:L9) -> 0 | N9: 0 | O9: 0 | P9: 0 | Q9: 0 | R9: 0 | S9: 0 | T9: =SUM(N9:S9) -> 0 | U9: 0 | V9: 0 | W9: 0 | X9: 0 | Y9: 0 | Z9: 1.164 | AA9: =SUM(U9:Z9) -> 1.164 | AB9: 0 | AC9: 0 | AD9: 0 | AE9: 0 | AF9: 0 | AG9: 0.495 | AH9: =SUM(AB9:AG9) -> 0.495
A10: 0000000202131 | B10: 220 福田水産㈱ | C10: 0017 | D10: 鮮魚 | F10: =IF($E10="","",IFERROR(INDEX(担当者マスタ!$B$2:$B$101,MATCH($E10,担当者マスタ!$A$2:$A$101,0)),"※マスタ未登録")) | G10: 69.5 | H10: 80.845 | I10: 29.36 | J10: 20.562 | K10: 114.97 | L10: 71.34 | M10: =SUM(G10:L10) -> 386.577 | N10: 68.25 | O10: 64.478 | P10: 16.16 | Q10: 20.03 | R10: 114.97 | S10: 71.34 | T10: =SUM(N10:S10) -> 355.228 | U10: 44 | V10: 142.4 | W10: 62.66 | X10: 20 | Y10: 10.6 | Z10: 3 | AA10: =SUM(U10:Z10) -> 282.66 | AB10: 44 | AC10: 141.15 | AD10: 62.243 | AE10: 20 | AF10: 10.6 | AG10: 3 | AH10: =SUM(AB10:AG10) -> 280.993
A11: 0000000202471 | B11: ㈱浜田あけぼの水産 | C11: 0017 | D11: 鮮魚 | F11: =IF($E11="","",IFERROR(INDEX(担当者マスタ!$B$2:$B$101,MATCH($E11,担当者マスタ!$A$2:$A$101,0)),"※マスタ未登録")) | G11: 0 | H11: 0 | I11: 0 | J11: 0 | K11: 0 | L11: 0 | M11: =SUM(G11:L11) -> 0 | N11: 0 | O11: 0 | P11: 0 | Q11: 0 | R11: 0 | S11: 0 | T11: =SUM(N11:S11) -> 0 | U11: 0 | V11: 0 | W11: 0 | X11: 0 | Y11: 473.2 | Z11: 0 | AA11: =SUM(U11:Z11) -> 473.2 | AB11: 0 | AC11: 0 | AD11: 0 | AE11: 0 | AF11: 92.4 | AG11: 0 | AH11: =SUM(AB11:AG11) -> 92.4
A12: 0000000202601 | B12: 103㈲山本一枝(鮮魚) | C12: 0017 | D12: 鮮魚 | F12: =IF($E12="","",IFERROR(INDEX(担当者マスタ!$B$2:$B$101,MATCH($E12,担当者マスタ!$A$2:$A$101,0)),"※マスタ未登録")) | G12: 496.65 | H12: 231.55 | I12: 55.45 | J12: 66.2 | K12: 34.25 | L12: 41.25 | M12: =SUM(G12:L12) -> 925.35 | N12: 449.596 | O12: 213.992 | P12: 55.45 | Q12: 59.177 | R12: 34.25 | S12: 41.25 | T12: =SUM(N12:S12) -> 853.715 | U12: 27.9 | V12: 84.5 | W12: 561.75 | X12: 412.4 | Y12: 546.4 | Z12: 51.7 | AA12: =SUM(U12:Z12) -> 1684.65 | AB12: 27.9 | AC12: 84.5 | AD12: 326.811 | AE12: 365.409 | AF12: 405.898 | AG12: 46.894 | AH12: =SUM(AB12:AG12) -> 1257.412
A13: 0000000202891 | B13: ㈱かもしま資材 | C13: 0017 | D13: 鮮魚 | F13: =IF($E13="","",IFERROR(INDEX(担当者マスタ!$B$2:$B$101,MATCH($E13,担当者マスタ!$A$2:$A$101,0)),"※マスタ未登録")) | G13: 1927.301 | H13: 896.31 | I13: 384.75 | J13: 232.53 | K13: 131.08 | L13: 304.45 | M13: =SUM(G13:L13) -> 3876.421 | N13: 432.615 | O13: 199.95 | P13: 87.61 | Q13: 53.55 | R13: 30.92 | S13: 71.28 | T13: =SUM(N13:S13) -> 875.925 | U13: 1160.935 | V13: 696.99 | W13: 540.014 | X13: 434.97 | Y13: 266.45 | Z13: 417.96 | AA13: =SUM(U13:Z13) -> 3517.319 | AB13: 252.081 | AC13: 151.96 | AD13: 117.586 | AE13: 99.88 | AF13: 60.93 | AG13: 93.45 | AH13: =SUM(AB13:AG13) -> 775.887
A14: 0000000820021 | B14: 116ﾏﾙｾｲ商店 ｽﾁﾛｰﾙ他 | C14: 0017 | D14: 鮮魚 | F14: =IF($E14="","",IFERROR(INDEX(担当者マスタ!$B$2:$B$101,MATCH($E14,担当者マスタ!$A$2:$A$101,0)),"※マスタ未登録")) | G14: 0 | H14: 0 | I14: 0 | J14: 0 | K14: 0 | L14: 0 | M14: =SUM(G14:L14) -> 0 | N14: 0 | O14: 0 | P14: 0 | Q14: 0 | R14: 0 | S14: 0 | T14: =SUM(N14:S14) -> 0 | U14: 5041.8 | V14: 6213.805 | W14: 4525.811 | X14: 4430.911 | Y14: 3797.025 | Z14: 4362.168 | AA14: =SUM(U14:Z14) -> 28371.52 | AB14: 1982.663 | AC14: 2331.152 | AD14: 1754.948 | AE14: 1655.38 | AF14: 1390.295 | AG14: 1680.919 | AH14: =SUM(AB14:AG14) -> 10795.357
C15: 0017 集計 | D15: 鮮魚 | G15: =SUBTOTAL(9,G7:G14) -> 2532.551 | H15: =SUBTOTAL(9,H7:H14) -> 1223.128 | I15: =SUBTOTAL(9,I7:I14) -> 481.32 | J15: =SUBTOTAL(9,J7:J14) -> 336.328 | K15: =SUBTOTAL(9,K7:K14) -> 291.988 | L15: =SUBTOTAL(9,L7:L14) -> 425.137 | M15: =SUBTOTAL(9,M7:M14) -> 5290.452 | N15: =SUBTOTAL(9,N7:N14) -> 970.662 | ... AH15: =SUBTOTAL(9,AH7:AH14) -> 13246.562
A16: 0000000000043 | B16: JFしまね本所総務部 | C16: 0031 | D16: JF境 | F16: =IF($E16="","",IFERROR(INDEX(担当者マスタ!$B$2:$B$101,MATCH($E16,担当者マスタ!$A$2:$A$101,0)),"※マスタ未登録")) | G16: 0 | H16: 0 | I16: 0 | J16: 0 | K16: 0 | L16: 0 | M16: =SUM(G16:L16) -> 0 | N16: 0 | O16: 0 | P16: 0 | Q16: 0 | R16: 0 | S16: 0 | T16: =SUM(N16:S16) -> 0 | U16: 86 | V16: 0 | W16: 0 | X16: 0 | Y16: 0 | Z16: 0 | AA16: =SUM(U16:Z16) -> 86 | AB16: 18.8 | AC16: 0 | AD16: 0 | AE16: 0 | AF16: 0 | AG16: 0 | AH16: =SUM(AB16:AG16) -> 18.8
A17: 0000000101293 | B17: JFしまね購買部購買課 | C17: 0031 | D17: JF境 | F17: =IF($E17="","",IFERROR(INDEX(担当者マスタ!$B$2:$B$101,MATCH($E17,担当者マスタ!$A$2:$A$101,0)),"※マスタ未登録")) | G17: 14712.216 | H17: 11725.807 | I17: 7290.434 | J17: 10119.517 | K17: 7444.632 | L17: 13124.855 | M17: =SUM(G17:L17) -> 64417.461 | N17: 2351.322 | O17: 2302.986 | P17: 1294.6 | Q17: 1794.514 | R17: 1168.471 | S17: 1962.078 | T17: =SUM(N17:S17) -> 10873.971 | U17: 19329.169 | V17: 14724.818 | W17: 11926.7 | X17: 3662.924 | Y17: 8960.96 | Z17: 18624.798 | AA17: =SUM(U17:Z17) -> 77229.369 | AB17: 4171.382 | AC17: 3372.675 | AD17: 2702.494 | AE17: 789.899 | AF17: 1917.207 | AG17: 3597.906 | AH17: =SUM(AB17:AG17) -> 16551.563
C18: 0031 集計 | D18: JF境 | G18: =SUBTOTAL(9,G16:G17) -> 14712.216 | H18: =SUBTOTAL(9,H16:H17) -> 11725.807 | I18: =SUBTOTAL(9,I16:I17) -> 7290.434 | J18: =SUBTOTAL(9,J16:J17) -> 10119.517 | K18: =SUBTOTAL(9,K16:K17) -> 7444.632 | L18: =SUBTOTAL(9,L16:L17) -> 13124.855 | M18: =SUBTOTAL(9,M16:M17) -> 64417.461 | N18: =SUBTOTAL(9,N16:N17) -> 2351.322 | ... AH18: =SUBTOTAL(9,AH16:AH17) -> 16570.363
A19: 0000000000211 | B19: ㈲漁協ｻｰﾋﾞｽ | C19: 0101 | D19: 漁協サービス | F19: =IF($E19="","",IFERROR(INDEX(担当者マスタ!$B$2:$B$101,MATCH($E19,担当者マスタ!$A$2:$A$101,0)),"※マスタ未登録")) | G19: 525.78 | H19: 628.263 | I19: 707.48 | J19: 687.09 | K19: 948.98 | L19: 834.972 | M19: =SUM(G19:L19) -> 4332.565 | N19: 284.751 | O19: 412.73 | P19: 399.469 | Q19: 390.432 | R19: 734.144 | S19: 536.921 | T19: =SUM(N19:S19) -> 2758.447 | U19: 529.547 | V19: 834.739 | W19: 929.941 | X19: 654.036 | Y19: 817.589 | Z19: 607.232 | AA19: =SUM(U19:Z19) -> 4373.084 | AB19: 430.158 | AC19: 660.75 | AD19: 647.324 | AE19: 465.198 | AF19: 580.017 | AG19: 348.719 | AH19: =SUM(AB19:AG19) -> 3132.166
C20: 0101 集計 | D20: 漁協サービス | G20: =SUBTOTAL(9,G19:G19) -> 525.78 | H20: =SUBTOTAL(9,H19:H19) -> 628.263 | I20: =SUBTOTAL(9,I19:I19) -> 707.48 | J20: =SUBTOTAL(9,J19:J19) -> 687.09 | K20: =SUBTOTAL(9,K19:K19) -> 948.98 | L20: =SUBTOTAL(9,L19:L19) -> 834.972 | M20: =SUBTOTAL(9,M19:M19) -> 4332.565 | N20: =SUBTOTAL(9,N19:N19) -> 284.751 | ... AH20: =SUBTOTAL(9,AH19:AH19) -> 3132.166
A21: 0000000000391 | B21: JF大田支所経費 | C21: 0102 | D21: JF大田 | F21: =IF($E21="","",IFERROR(INDEX(担当者マスタ!$B$2:$B$101,MATCH($E21,担当者マスタ!$A$2:$A$101,0)),"※マスタ未登録")) | G21: 0 | H21: 201.8 | I21: 150 | J21: 0 | K21: 165 | L21: 0 | M21: =SUM(G21:L21) -> 516.8 | N21: 0 | O21: 40.52 | P21: 150 | Q21: 0 | R21: 30 | S21: 0 | T21: =SUM(N21:S21) -> 220.52 | U21: 165 | V21: 0 | W21: 0 | X21: 0 | Y21: 6.5 | Z21: 0 | AA21: =SUM(U21:Z21) -> 171.5 | AB21: 30 | AC21: 0 | AD21: 0 | AE21: 0 | AF21: 6.5 | AG21: 0 | AH21: =SUM(AB21:AG21) -> 36.5
A22: 0000000000471 | B22: JFしまね大田支所 | C22: 0102 | D22: JF大田 | F22: =IF($E22="","",IFERROR(INDEX(担当者マスタ!$B$2:$B$101,MATCH($E22,担当者マスタ!$A$2:$A$101,0)),"※マスタ未登録")) | G22: 11181.448 | H22: 9787.562 | I22: 3937.089 | J22: 4402.895 | K22: 5739.73 | L22: 6618.195 | M22: =SUM(G22:L22) -> 41666.919 | N22: 2192.469 | O22: 2024.613 | P22: 799.796 | Q22: 930.288 | R22: 1182.906 | S22: 1412.294 | T22: =SUM(N22:S22) -> 8542.366 | U22: 11002.024 | V22: 12709.28 | W22: 7292.45 | X22: 4099.222 | Y22: 5195.947 | Z22: 10845.253 | AA22: =SUM(U22:Z22) -> 51144.176 | AB22: 2495.362 | AC22: 2948.673 | AD22: 1710.851 | AE22: 945.286 | AF22: 1266.53 | AG22: 2687.809 | AH22: =SUM(AB22:AG22) -> 12054.511
C23: 0102 集計 | D23: JF大田 | G23: =SUBTOTAL(9,G21:G22) -> 11181.448 | H23: =SUBTOTAL(9,H21:H22) -> 9989.362 | I23: =SUBTOTAL(9,I21:I22) -> 4087.089 | J23: =SUBTOTAL(9,J21:J22) -> 4402.895 | K23: =SUBTOTAL(9,K21:K22) -> 5904.73 | L23: =SUBTOTAL(9,L21:L22) -> 6618.195 | M23: =SUBTOTAL(9,M21:M22) -> 42183.719 | N23: =SUBTOTAL(9,N21:N22) -> 2192.469 | ... AH23: =SUBTOTAL(9,AH21:AH22) -> 12091.011
A24: 0000000000201 | B24: JF大田ｼｰﾄ料 | C24: 0104 | D24: 大田荷役 | F24: =IF($E24="","",IFERROR(INDEX(担当者マスタ!$B$2:$B$101,MATCH($E24,担当者マスタ!$A$2:$A$101,0)),"※マスタ未登録")) | G24: 959.76 | H24: 1128.58 | I24: 497.66 | J24: 489.04 | K24: 599.84 | L24: 781.28 | M24: =SUM(G24:L24) -> 4456.16 | N24: 361.574 | O24: 577.482 | P24: 200.481 | Q24: 146.504 | R24: 247.664 | S24: 328.86 | T24: =SUM(N24:S24) -> 1862.565 | U24: 972.52 | V24: 1096.88 | W24: 671.92 | X24: 298.6 | Y24: 542.18 | Z24: 1110.38 | AA24: =SUM(U24:Z24) -> 4692.48 | AB24: 413.851 | AC24: 471.414 | AD24: 265.663 | AE24: 61.76 | AF24: 183.971 | AG24: 453.31 | AH24: =SUM(AB24:AG24) -> 1849.969
A25: 0000000000261 | B25: JF大田製氷工場 | C25: 0104 | D25: 大田荷役 | F25: =IF($E25="","",IFERROR(INDEX(担当者マスタ!$B$2:$B$101,MATCH($E25,担当者マスタ!$A$2:$A$101,0)),"※マスタ未登録")) | G25: 533.52 | H25: 470.34 | I25: 184.86 | J25: 222.3 | K25: 175.5 | L25: 250.2 | M25: =SUM(G25:L25) -> 1836.72 | N25: 533.52 | O25: 470.34 | P25: 184.86 | Q25: 222.3 | R25: 175.5 | S25: 250.2 | T25: =SUM(N25:S25) -> 1836.72 | U25: 487.5 | V25: 474.96 | W25: 253.2 | X25: 154.44 | Y25: 184.86 | Z25: 382.02 | AA25: =SUM(U25:Z25) -> 1936.98 | AB25: 487.5 | AC25: 474.96 | AD25: 253.2 | AE25: 154.44 | AF25: 184.86 | AG25: 382.02 | AH25: =SUM(AB25:AG25) -> 1936.98
A26: 0000000000271 | B26: ※JF大田巻網定置荷役 | C26: 0104 | D26: 大田荷役 | F26: =IF($E26="","",IFERROR(INDEX(担当者マスタ!$B$2:$B$101,MATCH($E26,担当者マスタ!$A$2:$A$101,0)),"※マスタ未登録")) | G26: 15 | H26: 0 | I26: 0 | J26: 0 | K26: 0 | L26: 0 | M26: =SUM(G26:L26) -> 15 | N26: 15 | O26: 0 | P26: 0 | Q26: 0 | R26: 0 | S26: 0 | T26: =SUM(N26:S26) -> 15 | U26: 0 | V26: 0 | W26: 0 | X26: 0 | Y26: 0 | Z26: 7.5 | AA26: =SUM(U26:Z26) -> 7.5 | AB26: 0 | AC26: 0 | AD26: 0 | AE26: 0 | AF26: 0 | AG26: 7.5 | AH26: =SUM(AB26:AG26) -> 7.5
A27: 0000000000281 | B27: JF大田ｺﾝﾍﾞｱｰ洗浄料 | C27: 0104 | D27: 大田荷役 | F27: =IF($E27="","",IFERROR(INDEX(担当者マスタ!$B$2:$B$101,MATCH($E27,担当者マスタ!$A$2:$A$101,0)),"※マスタ未登録")) | G27: 18 | H27: 12 | I27: 0 | J27: 4 | K27: 4 | L27: 6 | M27: =SUM(G27:L27) -> 44 | N27: 18 | O27: 12 | P27: 0 | Q27: 4 | R27: 4 | S27: 6 | T27: =SUM(N27:S27) -> 44 | U27: 16 | V27: 20 | W27: 14 | X27: 4 | Y27: 6 | Z27: 10 | AA27: =SUM(U27:Z27) -> 70 | AB27: 16 | AC27: 20 | AD27: 14 | AE27: 4 | AF27: 6 | AG27: 10 | AH27: =SUM(AB27:AG27) -> 70
A28: 0000000000291 | B28: JF大田小底荷役料 | C28: 0104 | D28: 大田荷役 | F28: =IF($E28="","",IFERROR(INDEX(担当者マスタ!$B$2:$B$101,MATCH($E28,担当者マスタ!$A$2:$A$101,0)),"※マスタ未登録")) | G28: 1654.8 | H28: 1977.93 | I28: 798.6 | J28: 829.805 | K28: 987.265 | L28: 1251.6 | M28: =SUM(G28:L28) -> 7500 | N28: 623.422 | O28: 1012.088 | P28: 321.716 | Q28: 248.59 | R28: 407.628 | S28: 526.832 | T28: =SUM(N28:S28) -> 3140.276 | U28: 1741.14 | V28: 1939.56 | W28: 1147.86 | X28: 539.79 | Y28: 906.63 | Z28: 1817.76 | AA28: =SUM(U28:Z28) -> 8092.74 | AB28: 740.934 | AC28: 833.579 | AD28: 453.841 | AE28: 111.646 | AF28: 307.637 | AG28: 742.098 | AH28: =SUM(AB28:AG28) -> 3189.735
A29: 0000000000301 | B29: JF大田魚集荷料 | C29: 0104 | D29: 大田荷役 | F29: =IF($E29="","",IFERROR(INDEX(担当者マスタ!$B$2:$B$101,MATCH($E29,担当者マスタ!$A$2:$A$101,0)),"※マスタ未登録")) | G29: 324.02 | H29: 342.285 | I29: 126.905 | J29: 169.83 | K29: 194.395 | L29: 235.235 | M29: =SUM(G29:L29) -> 1392.67 | N29: 324.02 | O29: 342.285 | P29: 126.905 | Q29: 169.83 | R29: 194.395 | S29: 235.235 | T29: =SUM(N29:S29) -> 1392.67 | U29: 404.685 | V29: 382.16 | W29: 183.675 | X29: 98.515 | Y29: 161.67 | Z29: 260.95 | AA29: =SUM(U29:Z29) -> 1491.655 | AB29: 404.685 | AC29: 382.16 | AD29: 183.675 | AE29: 98.515 | AF29: 161.67 | AG29: 260.95 | AH29: =SUM(AB29:AG29) -> 1491.655
A30: 0000000000321 | B30: JF大田市場洗浄料 | C30: 0104 | D30: 大田荷役 | F30: =IF($E30="","",IFERROR(INDEX(担当者マスタ!$B$2:$B$101,MATCH($E30,担当者マスタ!$A$2:$A$101,0)),"※マスタ未登録")) | G30: 208 | H30: 104 | I30: 96 | J30: 86 | K30: 72 | L30: 94 | M30: =SUM(G30:L30) -> 660 | N30: 208 | O30: 104 | P30: 96 | Q30: 86 | R30: 72 | S30: 94 | T30: =SUM(N30:S30) -> 660 | U30: 156 | V30: 151 | W30: 128 | X30: 64 | Y30: 99 | Z30: 162 | AA30: =SUM(U30:Z30) -> 760 | AB30: 156 | AC30: 151 | AD30: 128 | AE30: 64 | AF30: 99 | AG30: 162 | AH30: =SUM(AB30:AG30) -> 760
A31: 0000000000381 | B31: JF大田買取荷役料 | C31: 0104 | D31: 大田荷役 | F31: =IF($E31="","",IFERROR(INDEX(担当者マスタ!$B$2:$B$101,MATCH($E31,担当者マスタ!$A$2:$A$101,0)),"※マスタ未登録")) | G31: 299.1 | H31: 282 | I31: 145.5 | J31: 193.5 | K31: 184.2 | L31: 244.2 | M31: =SUM(G31:L31) -> 1348.5 | N31: 299.1 | O31: 282 | P31: 145.5 | Q31: 193.5 | R31: 184.2 | S31: 244.2 | T31: =SUM(N31:S31) -> 1348.5 | U31: 252.6 | V31: 299.4 | W31: 181.8 | X31: 130.5 | Y31: 170.4 | Z31: 323.1 | AA31: =SUM(U31:Z31) -> 1357.8 | AB31: 252.6 | AC31: 299.4 | AD31: 181.8 | AE31: 130.5 | AF31: 170.4 | AG31: 323.1 | AH31: =SUM(AB31:AG31) -> 1357.8
A32: 0000000002011 | B32: 琴代丸 | C32: 0104 | D32: 大田荷役 | F32: =IF($E32="","",IFERROR(INDEX(担当者マスタ!$B$2:$B$101,MATCH($E32,担当者マスタ!$A$2:$A$101,0)),"※マスタ未登録")) | G32: 90.695 | H32: 95.2 | I32: 47.855 | J32: 62.22 | K32: 41.395 | L32: 62.815 | M32: =SUM(G32:L32) -> 400.18 | N32: 90.695 | O32: 95.2 | P32: 47.855 | Q32: 62.22 | R32: 41.395 | S32: 62.815 | T32: =SUM(N32:S32) -> 400.18 | U32: 100.64 | V32: 120.87 | W32: 63.07 | X32: 20.825 | Y32: 33.83 | Z32: 110.245 | AA32: =SUM(U32:Z32) -> 449.48 | AB32: 100.64 | AC32: 120.87 | AD32: 63.07 | AE32: 20.825 | AF32: 33.83 | AG32: 110.245 | AH32: =SUM(AB32:AG32) -> 449.48
A33: 0000000002021 | B33: 玉千代丸 | C33: 0104 | D33: 大田荷役 | F33: =IF($E33="","",IFERROR(INDEX(担当者マスタ!$B$2:$B$101,MATCH($E33,担当者マスタ!$A$2:$A$101,0)),"※マスタ未登録")) | G33: 10.115 | H33: 0 | I33: 0 | J33: 0 | K33: 0.85 | L33: 8.415 | M33: =SUM(G33:L33) -> 19.38 | N33: 10.115 | O33: 0 | P33: 0 | Q33: 0 | R33: 0.85 | S33: 8.415 | T33: =SUM(N33:S33) -> 19.38 | U33: 10.2 | V33: 0 | W33: 0 | X33: 0 | Y33: 0 | Z33: 9.52 | AA33: =SUM(U33:Z33) -> 19.72 | AB33: 10.2 | AC33: 0 | AD33: 0 | AE33: 0 | AF33: 0 | AG33: 9.52 | AH33: =SUM(AB33:AG33) -> 19.72
A34: 0000000002031 | B34: 三和丸 | C34: 0104 | D34: 大田荷役 | F34: =IF($E34="","",IFERROR(INDEX(担当者マスタ!$B$2:$B$101,MATCH($E34,担当者マスタ!$A$2:$A$101,0)),"※マスタ未登録")) | G34: 94.35 | H34: 124.695 | I34: 64.855 | J34: 45.05 | K34: 87.975 | L34: 60.18 | M34: =SUM(G34:L34) -> 477.105 | N34: 94.35 | O34: 124.695 | P34: 64.855 | Q34: 45.05 | R34: 87.975 | S34: 60.18 | T34: =SUM(N34:S34) -> 477.105 | U34: 108.63 | V34: 117.555 | W34: 73.865 | X34: 25.84 | Y34: 73.695 | Z34: 88.655 | AA34: =SUM(U34:Z34) -> 488.24 | AB34: 108.63 | AC34: 117.555 | AD34: 73.865 | AE34: 25.84 | AF34: 73.695 | AG34: 88.655 | AH34: =SUM(AB34:AG34) -> 488.24
A35: 0000000002041 | B35: 漁神丸 | C35: 0104 | D35: 大田荷役 | F35: =IF($E35="","",IFERROR(INDEX(担当者マスタ!$B$2:$B$101,MATCH($E35,担当者マスタ!$A$2:$A$101,0)),"※マスタ未登録")) | G35: 65.875 | H35: 71.4 | I35: 42.755 | J35: 44.71 | K35: 58.65 | L35: 79.39 | M35: =SUM(G35:L35) -> 362.78 | N35: 65.875 | O35: 71.4 | P35: 42.755 | Q35: 44.71 | R35: 58.65 | S35: 79.39 | T35: =SUM(N35:S35) -> 362.78 | U35: 84.32 | V35: 91.375 | W35: 24.565 | X35: 19.04 | Y35: 68.425 | Z35: 107.695 | AA35: =SUM(U35:Z35) -> 395.42 | AB35: 84.32 | AC35: 91.375 | AD35: 24.565 | AE35: 19.04 | AF35: 68.425 | AG35: 107.695 | AH35: =SUM(AB35:AG35) -> 395.42
... A41: 0000000703291 | B41: ㈱ｻﾝﾏﾙｺ-運送委託- | C41: 0104 | D41: 大田荷役 | F41: =IF($E41="","",IFERROR(INDEX(担当者マスタ!$B$2:$B$101,MATCH($E41,担当者マスタ!$A$2:$A$101,0)),"※マスタ未登録")) | G41: 0 | H41: 0 | I41: 0 | J41: 0 | K41: 0 | L41: 0 | M41: =SUM(G41:L41) -> 0 | N41: 0 | O41: 0 | P41: 0 | Q41: 0 | R41: 0 | S41: 0 | T41: =SUM(N41:S41) -> 0 | U41: 200 | V41: 160 | W41: 160 | X41: 160 | Y41: 160 | Z41: 160 | AA41: =SUM(U41:Z41) -> 1000 | AB41: 200 | AC41: 160 | AD41: 160 | AE41: 160 | AF41: 160 | AG41: 160 | AH41: =SUM(AB41:AG41) -> 1000
C42: 0104 集計 | D42: 大田荷役 | G42: =SUBTOTAL(9,G24:G41) -> 4648.265 | H42: =SUBTOTAL(9,H24:H41) -> 5210.065 | I42: =SUBTOTAL(9,I24:I41) -> 2151.435 | J42: =SUBTOTAL(9,J24:J41) -> 2392.025 | K42: =SUBTOTAL(9,K24:K41) -> 2549.38 | L42: =SUBTOTAL(9,L24:L41) -> 3275.315 | M42: =SUBTOTAL(9,M24:M41) -> 20226.485 | N42: =SUBTOTAL(9,N24:N41) -> 3018.701 | ... AH42: =SUBTOTAL(9,AH24:AH41) -> 14913.779
A43: 0000000000461 | B43: JFしまね冷蔵庫経費 | C43: 0106 | D43: 浜田荷役 | F43: =IF($E43="","",IFERROR(INDEX(担当者マスタ!$B$2:$B$101,MATCH($E43,担当者マスタ!$A$2:$A$101,0)),"※マスタ未登録")) | G43: 601.85 | H43: 504.56 | I43: 497.71 | J43: 815.24 | K43: 665.8 | L43: 528.65 | M43: =SUM(G43:L43) -> 3613.81 | N43: 201.35 | O43: 176.077 | P43: 199.912 | Q43: 427.699 | R43: 319.403 | S43: 183.618 | T43: =SUM(N43:S43) -> 1508.059 | U43: 907.04 | V43: 998.405 | W43: 1589.864 | X43: 676.25 | Y43: 518.45 | Z43: 736.25 | AA43: =SUM(U43:Z43) -> 5426.259 | AB43: 547.938 | AC43: 661.597 | AD43: 854.845 | AE43: 376.682 | AF43: 273.077 | AG43: 382.053 | AH43: =SUM(AB43:AG43) -> 3096.192
A44: 0000000003011 | B44: 弘氣丸 | C44: 0106 | D44: 浜田荷役 | F44: =IF($E44="","",IFERROR(INDEX(担当者マスタ!$B$2:$B$101,MATCH($E44,担当者マスタ!$A$2:$A$101,0)),"※マスタ未登録")) | G44: 0 | H44: 0 | I44: 0 | J44: 0.2 | K44: 0 | L44: 0 | M44: =SUM(G44:L44) -> 0.2 | N44: 0 | O44: 0 | P44: 0 | Q44: 0.2 | R44: 0 | S44: 0 | T44: =SUM(N44:S44) -> 0.2 | U44: 0 | V44: 0 | W44: 0 | X44: 0 | Y44: 0 | Z44: 0 | AA44: =SUM(U44:Z44) -> 0 | AB44: 0 | AC44: 0 | AD44: 0 | AE44: 0 | AF44: 0 | AG44: 0 | AH44: =SUM(AB44:AG44) -> 0
A45: 0000000003021 | B45: TT19 1豊生丸 | C45: 0106 | D45: 浜田荷役 | F45: =IF($E45="","",IFERROR(INDEX(担当者マスタ!$B$2:$B$101,MATCH($E45,担当者マスタ!$A$2:$A$101,0)),"※マスタ未登録")) | G45: 0 | H45: 0 | I45: 0 | J45: 0 | K45: 0 | L45: 0 | M45: =SUM(G45:L45) -> 0 | N45: 0 | O45: 0 | P45: 0 | Q45: 0 | R45: 0 | S45: 0 | T45: =SUM(N45:S45) -> 0 | U45: 7.2 | V45: 0 | W45: 0 | X45: 0 | Y45: 0 | Z45: 0 | AA45: =SUM(U45:Z45) -> 7.2 | AB45: 7.2 | AC45: 0 | AD45: 0 | AE45: 0 | AF45: 0 | AG45: 0 | AH45: =SUM(AB45:AG45) -> 7.2
...

Sheet 鳥栖・静岡・東京
A1: 得意先コード | B1: 得意先略称 | C1: 担当者コード | D1: 担当者名 | E1: 新担当者コード | F1: 新担当者 | G1: 2024/10売上 | H1: 2024/11売上 | I1: 2024/12売上 | J1: 2025/01売上 | K1: 2025/02売上 | L1: 2025/03売上 | M1: 前年度売上合計 | N1: 2024/10粗利益 | O1: 2024/11粗利益 | P1: 2024/12粗利益 | Q1: 2025/01粗利益 | R1: 2025/02粗利益 | S1: 2025/03粗利益 | T1: 前年度粗利益合計 | U1: 2025/10売上 | V1: 2025/11売上 | W1: 2025/12売上 | X1: 2026/01売上 | Y1: 2026/02売上 | Z1: 2026/03売上 | AA1: 今年度売上合計 | AB1: 2025/10粗利益 | AC1: 2025/11粗利益 | AD1: 2025/12粗利益 | AE1: 2026/01粗利益 | AF1: 2026/02粗利益 | AG1: 2026/03粗利益 | AH1: 今年度粗利益合計
A2: 0000000001124 | B2: ｶﾈｹﾞﾝ | C2: 0042 | D2: 馬場部長 | F2: =IF($E2="","",IFERROR(INDEX(担当者マスタ!$B$2:$B$101,MATCH($E2,担当者マスタ!$A$2:$A$101,0)),"※マスタ未登録")) | G2: 1530.202 | H2: 1331.485 | I2: 1865.623 | J2: 394.99 | K2: 1245.073 | L2: 1051.65 | M2: =SUM(G2:L2) -> 7419.023 | N2: 176.074 | O2: 155.217 | P2: 216.279 | Q2: 32.626 | R2: 125.93 | S2: 125.627 | T2: =SUM(N2:S2) -> 831.753 | U2: 889.595 | V2: 897.82 | W2: 1410.589 | X2: 691.51 | Y2: 1010.252 | Z2: 981.539 | AA2: =SUM(U2:Z2) -> 5881.305 | AB2: 58.735 | AC2: 65.553 | AD2: 134.763 | AE2: 77.664 | AF2: 84.594 | AG2: 76.589 | AH2: =SUM(AB2:AG2) -> 497.898
A3: 0000000005624 | B3: ㈱ﾘﾝｶﾞｰﾊｯﾄ東京本社 | C3: 0042 | D3: 馬場部長 | F3: =IF($E3="","",IFERROR(INDEX(担当者マスタ!$B$2:$B$101,MATCH($E3,担当者マスタ!$A$2:$A$101,0)),"※マスタ未登録")) | G3: 27357.149 | H3: 29842.14 | I3: 35394.144 | J3: 28095.015 | K3: 29989.885 | L3: 33407.761 | M3: =SUM(G3:L3) -> 184086.09 | N3: 3739.394 | O3: 4189.368 | P3: 5089.205 | Q3: 3916.215 | R3: 4233.37 | S3: 5641.747 | T3: =SUM(N3:S3) -> 26809.299 | U3: 28564.537 | V3: 30135.229 | W3: 37931.299 | X3: 26226.4 | Y3: 27549.329 | Z3: 29111.012 | AA3: =SUM(U3:Z3) -> 179517.81 | AB3: 3889.708 | AC3: 4241.439 | AD3: 5138.571 | AE3: 3462.655 | AF3: 3900.067 | AG3: 5139.252 | AH3: =SUM(AB3:AG3) -> 25771.692
A4: 0000000105624 | B4: ㈱ﾘﾝｶﾞｰﾊｯﾄ東京本社 | C4: 0042 | D4: 馬場部長 | F4: =IF($E4="","",IFERROR(INDEX(担当者マスタ!$B$2:$B$101,MATCH($E4,担当者マスタ!$A$2:$A$101,0)),"※マスタ未登録")) | G4: 0 | H4: 0 | I4: 0 | J4: 0 | K4: 0 | L4: 0 | M4: =SUM(G4:L4) -> 0 | N4: 0 | O4: 0 | P4: 0 | Q4: 0 | R4: 0 | S4: 0 | T4: =SUM(N4:S4) -> 0 | U4: 0 | V4: 3 | W4: 0 | X4: 0 | Y4: 0 | Z4: 0 | AA4: =SUM(U4:Z4) -> 3 | AB4: 0 | AC4: 1.552 | AD4: 0 | AE4: 0 | AF4: 0 | AG4: 0 | AH4: =SUM(AB4:AG4) -> 1.552
C5: 0042 集計 | D5: 馬場部長 | G5: =SUBTOTAL(9,G2:G4) -> 28887.351 | H5: =SUBTOTAL(9,H2:H4) -> 31173.625 | I5: =SUBTOTAL(9,I2:I4) -> 37259.767 | J5: =SUBTOTAL(9,J2:J4) -> 28490.005 | K5: =SUBTOTAL(9,K2:K4) -> 31234.958 | L5: =SUBTOTAL(9,L2:L4) -> 34459.411 | M5: =SUBTOTAL(9,M2:M4) -> 191505.12 | N5: =SUBTOTAL(9,N2:N4) -> 3915.468 | ... AH5: =SUBTOTAL(9,AH2:AH4) -> 26271.142
A6: 0000000000134 | B6: ㈱蔵出しめんたい本舗 | C6: 0046 | D6: 角田 | F6: =IF($E6="","",IFERROR(INDEX(担当者マスタ!$B$2:$B$101,MATCH($E6,担当者マスタ!$A$2:$A$101,0)),"※マスタ未登録")) | G6: 926.207 | H6: 759.301 | I6: 1096.286 | J6: 652.599 | K6: 449.989 | L6: 781.715 | M6: =SUM(G6:L6) -> 4666.097 | N6: 228.524 | O6: 194.533 | P6: 245.062 | Q6: 158.8 | R6: 102.124 | S6: 196.424 | T6: =SUM(N6:S6) -> 1125.467 | U6: 506.412 | V6: 663.9 | W6: 1205.97 | X6: 369.917 | Y6: 513.973 | Z6: 847.946 | AA6: =SUM(U6:Z6) -> 4108.118 | AB6: 108.136 | AC6: 151.327 | AD6: 268.297 | AE6: 70.888 | AF6: 114.738 | AG6: 197.093 | AH6: =SUM(AB6:AG6) -> 910.479
A7: 0000000000144 | B7: ㈲東洋ﾃｸﾆｶﾙﾌｰﾂﾞ | C7: 0046 | D7: 角田 | F7: =IF($E7="","",IFERROR(INDEX(担当者マスタ!$B$2:$B$101,MATCH($E7,担当者マスタ!$A$2:$A$101,0)),"※マスタ未登録")) | G7: 37.375 | H7: 0 | I7: 109.8 | J7: 72 | K7: 97 | L7: 191.696 | M7: =SUM(G7:L7) -> 507.871 | N7: 7.15 | O7: 0 | P7: 19.44 | Q7: 14.4 | R7: 23.4 | S7: 38.61 | T7: =SUM(N7:S7) -> 103 | U7: 204.59 | V7: 37.03 | W7: 0 | X7: 169.3 | Y7: 159.41 | Z7: 123.41 | AA7: =SUM(U7:Z7) -> 693.74 | AB7: 37.688 | AC7: 7.084 | AD7: 0 | AE7: 30.94 | AF7: 31.01 | AG7: 23.81 | AH7: =SUM(AB7:AG7) -> 130.532
A8: 0000000000164 | B8: SUS㈱ | C8: 0046 | D8: 角田 | F8: =IF($E8="","",IFERROR(INDEX(担当者マスタ!$B$2:$B$101,MATCH($E8,担当者マスタ!$A$2:$A$101,0)),"※マスタ未登録")) | G8: 49.09 | H8: 0 | I8: 81.1 | J8: 0 | K8: 44.1 | L8: 37 | M8: =SUM(G8:L8) -> 211.29 | N8: 10.18 | O8: 0 | P8: 7.92 | Q8: 0 | R8: 2.52 | S8: 5.4 | T8: =SUM(N8:S8) -> 26.02 | U8: 80.85 | V8: 0 | W8: 0 | X8: 0 | Y8: 0 | Z8: 0 | AA8: =SUM(U8:Z8) -> 80.85 | AB8: 11.55 | AC8: 0 | AD8: 0 | AE8: 0 | AF8: 0 | AG8: 0 | AH8: =SUM(AB8:AG8) -> 11.55
A9: 0000000000224 | B9: ㈲東龍食品★ | C9: 0046 | D9: 角田 | F9: =IF($E9="","",IFERROR(INDEX(担当者マスタ!$B$2:$B$101,MATCH($E9,担当者マスタ!$A$2:$A$101,0)),"※マスタ未登録")) | G9: 7.725 | H9: 0 | I9: 0 | J9: 0 | K9: 0 | L9: 0 | M9: =SUM(G9:L9) -> 7.725 | N9: 0.99 | O9: 0 | P9: 0 | Q9: 0 | R9: 0 | S9: 0 | T9: =SUM(N9:S9) -> 0.99 | U9: 0 | V9: 0 | W9: 0 | X9: 0 | Y9: 0 | Z9: 0 | AA9: =SUM(U9:Z9) -> 0 | AB9: 0 | AC9: 0 | AD9: 0 | AE9: 0 | AF9: 0 | AG9: 0 | AH9: =SUM(AB9:AG9) -> 0
