Workbook

Sheet 包装資材
C1: 水産部包装資材
C2: 1．2024年
E3: 売上 | L3: 粗利益 | S3: 粗利益率
E4: 45383 | F4: 45413 | G4: 45444 | H4: 45474 | I4: 45505 | J4: 45536 | K4: 合計 | L4: 45383 | M4: 45413 | N4: 45444 | O4: 45474 | P4: 45505 | Q4: 45536 | R4: 合計 | S4: 45383 | T4: 45413 | U4: 45444 | V4: 45474 | W4: 45505 | X4: 45536 | Y4: 合計
C5: 0010 集計 | D5: JF | E5: =全体!E5-機械!E5 | F5: =全体!F5-機械!F5 | G5: =全体!G5-機械!G5 | H5: =全体!H5-機械!H5 | I5: =全体!I5-機械!I5 | J5: =全体!J5-機械!J5 | K5: =SUM(E5:J5) | L5: =全体!L5-機械!L5 | M5: =全体!M5-機械!M5 | N5: =全体!N5-機械!N5 | O5: =全体!O5-機械!O5 | P5: =全体!P5-機械!P5 | Q5: =全体!Q5-機械!Q5 | R5: =SUM(L5:Q5) | S5: =IF(E5=0,"***",L5/E5) | T5: =IF(F5=0,"***",M5/F5) | U5: =IF(G5=0,"***",N5/G5) | V5: =IF(H5=0,"***",O5/H5) | W5: =IF(I5=0,"***",P5/I5) | X5: =IF(J5=0,"***",Q5/J5) | Y5: =IF(K5=0,"***",R5/K5)
C6: 0017 集計 | D6: 鮮魚 | E6: =全体!E6-機械!E6 | F6: =全体!F6-機械!F6 | G6: =全体!G6-機械!G6 | H6: =全体!H6-機械!H6 | I6: =全体!I6-機械!I6 | J6: =全体!J6-機械!J6 | K6: =SUM(E6:J6) | L6: =全体!L6-機械!L6 | M6: =全体!M6-機械!M6 | N6: =全体!N6-機械!N6 | O6: =全体!O6-機械!O6 | P6: =全体!P6-機械!P6 | Q6: =全体!Q6-機械!Q6 | R6: =SUM(L6:Q6) | S6: =IF(E6=0,"***",L6/E6) | T6: =IF(F6=0,"***",M6/F6) | U6: =IF(G6=0,"***",N6/G6) | V6: =IF(H6=0,"***",O6/H6) | W6: =IF(I6=0,"***",P6/I6) | X6: =IF(J6=0,"***",Q6/J6) | Y6: =IF(K6=0,"***",R6/K6)
C7: 0101 集計 | D7: GS | E7: =全体!E7-機械!E7 | F7: =全体!F7-機械!F7 | G7: =全体!G7-機械!G7 | H7: =全体!H7-機械!H7 | I7: =全体!I7-機械!I7 | J7: =全体!J7-機械!J7 | K7: =SUM(E7:J7) | L7: =全体!L7-機械!L7 | M7: =全体!M7-機械!M7 | N7: =全体!N7-機械!N7 | O7: =全体!O7-機械!O7 | P7: =全体!P7-機械!P7 | Q7: =全体!Q7-機械!Q7 | R7: =SUM(L7:Q7) | S7: =IF(E7=0,"***",L7/E7) | T7: =IF(F7=0,"***",M7/F7) | U7: =IF(G7=0,"***",N7/G7) | V7: =IF(H7=0,"***",O7/H7) | W7: =IF(I7=0,"***",P7/I7) | X7: =IF(J7=0,"***",Q7/J7) | Y7: =IF(K7=0,"***",R7/K7)
C8: 0106 集計 | D8: 浜田荷役 | E8: =全体!E8-機械!E8 | F8: =全体!F8-機械!F8 | G8: =全体!G8-機械!G8 | H8: =全体!H8-機械!H8 | I8: =全体!I8-機械!I8 | J8: =全体!J8-機械!J8 | K8: =SUM(E8:J8) | L8: =全体!L8-機械!L8 | M8: =全体!M8-機械!M8 | N8: =全体!N8-機械!N8 | O8: =全体!O8-機械!O8 | P8: =全体!P8-機械!P8 | Q8: =全体!Q8-機械!Q8 | R8: =SUM(L8:Q8) | S8: =IF(E8=0,"***",L8/E8) | T8: =IF(F8=0,"***",M8/F8) | U8: =IF(G8=0,"***",N8/G8) | V8: =IF(H8=0,"***",O8/H8) | W8: =IF(I8=0,"***",P8/I8) | X8: =IF(J8=0,"***",Q8/J8) | Y8: =IF(K8=0,"***",R8/K8)
C9: 浜田水産部合計 | E9: =SUM(E5:E8) | F9: =SUM(F5:F8) | G9: =SUM(G5:G8) | H9: =SUM(H5:H8) | I9: =SUM(I5:I8) | J9: =SUM(J5:J8) | K9: =SUM(K5:K8) | L9: =SUM(L5:L8) | ... R9: =SUM(R5:R8) | S9: =IF(E9=0,"***",L9/E9) | T9: =IF(F9=0,"***",M9/F9) | U9: =IF(G9=0,"***",N9/G9) | V9: =IF(H9=0,"***",O9/H9) | W9: =IF(I9=0,"***",P9/I9) | X9: =IF(J9=0,"***",Q9/J9) | Y9: =IF(K9=0,"***",R9/K9)
C10: 0102 集計 | D10: JF大田 | E10: =全体!E10-機械!E10 | F10: =全体!F10-機械!F10 | G10: =全体!G10-機械!G10 | H10: =全体!H10-機械!H10 | I10: =全体!I10-機械!I10 | J10: =全体!J10-機械!J10 | K10: =SUM(E10:J10) | L10: =全体!L10-機械!L10 | M10: =全体!M10-機械!M10 | N10: =全体!N10-機械!N10 | O10: =全体!O10-機械!O10 | P10: =全体!P10-機械!P10 | Q10: =全体!Q10-機械!Q10 | R10: =SUM(L10:Q10) | S10: =IF(E10=0,"***",L10/E10) | T10: =IF(F10=0,"***",M10/F10) | U10: =IF(G10=0,"***",N10/G10) | V10: =IF(H10=0,"***",O10/H10) | W10: =IF(I10=0,"***",P10/I10) | X10: =IF(J10=0,"***",Q10/J10) | Y10: =IF(K10=0,"***",R10/K10)
C11: 0104 集計 | D11: 大田荷役 | E11: =全体!E11-機械!E11 | F11: =全体!F11-機械!F11 | G11: =全体!G11-機械!G11 | H11: =全体!H11-機械!H11 | I11: =全体!I11-機械!I11 | J11: =全体!J11-機械!J11 | K11: =SUM(E11:J11) | L11: =全体!L11-機械!L11 | M11: =全体!M11-機械!M11 | N11: =全体!N11-機械!N11 | O11: =全体!O11-機械!O11 | P11: =全体!P11-機械!P11 | Q11: =全体!Q11-機械!Q11 | R11: =SUM(L11:Q11) | S11: =IF(E11=0,"***",L11/E11) | T11: =IF(F11=0,"***",M11/F11) | U11: =IF(G11=0,"***",N11/G11) | V11: =IF(H11=0,"***",O11/H11) | W11: =IF(I11=0,"***",P11/I11) | X11: =IF(J11=0,"***",Q11/J11) | Y11: =IF(K11=0,"***",R11/K11)
C12: 大田水産部 | E12: =E10+E11 | F12: =F10+F11 | G12: =G10+G11 | H12: =H10+H11 | I12: =I10+I11 | J12: =J10+J11 | K12: =K10+K11 | L12: =L10+L11 | ... R12: =R10+R11 | S12: =IF(E12=0,"***",L12/E12) | T12: =IF(F12=0,"***",M12/F12) | U12: =IF(G12=0,"***",N12/G12) | V12: =IF(H12=0,"***",O12/H12) | W12: =IF(I12=0,"***",P12/I12) | X12: =IF(J12=0,"***",Q12/J12) | Y12: =IF(K12=0,"***",R12/K12)
C13: 0031 集計 | D13: JF境 | E13: =全体!E13-機械!E13 | F13: =全体!F13-機械!F13 | G13: =全体!G13-機械!G13 | H13: =全体!H13-機械!H13 | I13: =全体!I13-機械!I13 | J13: =全体!J13-機械!J13 | K13: =SUM(E13:J13) | L13: =全体!L13-機械!L13 | M13: =全体!M13-機械!M13 | N13: =全体!N13-機械!N13 | O13: =全体!O13-機械!O13 | P13: =全体!P13-機械!P13 | Q13: =全体!Q13-機械!Q13 | R13: =SUM(L13:Q13) | S13: =IF(E13=0,"***",L13/E13) | T13: =IF(F13=0,"***",M13/F13) | U13: =IF(G13=0,"***",N13/G13) | V13: =IF(H13=0,"***",O13/H13) | W13: =IF(I13=0,"***",P13/I13) | X13: =IF(J13=0,"***",Q13/J13) | Y13: =IF(K13=0,"***",R13/K13)
C14: 0038 集計 | D14: 境その他 | E14: =全体!E14-機械!E14 | F14: =全体!F14-機械!F14 | G14: =全体!G14-機械!G14 | H14: =全体!H14-機械!H14 | I14: =全体!I14-機械!I14 | J14: =全体!J14-機械!J14 | K14: =SUM(E14:J14) | L14: =全体!L14-機械!L14 | M14: =全体!M14-機械!M14 | N14: =全体!N14-機械!N14 | O14: =全体!O14-機械!O14 | P14: =全体!P14-機械!P14 | Q14: =全体!Q14-機械!Q14 | R14: =SUM(L14:Q14) | S14: =IF(E14=0,"***",L14/E14) | T14: =IF(F14=0,"***",M14/F14) | U14: =IF(G14=0,"***",N14/G14) | V14: =IF(H14=0,"***",O14/H14) | W14: =IF(I14=0,"***",P14/I14) | X14: =IF(J14=0,"***",Q14/J14) | Y14: =IF(K14=0,"***",R14/K14)
C15: 境港水産部合計 | E15: =E13+E14 | F15: =F13+F14 | G15: =G13+G14 | H15: =H13+H14 | I15: =I13+I14 | J15: =J13+J14 | K15: =K13+K14 | L15: =L13+L14 | ... R15: =R13+R14 | S15: =IF(E15=0,"***",L15/E15) | T15: =IF(F15=0,"***",M15/F15) | U15: =IF(G15=0,"***",N15/G15) | V15: =IF(H15=0,"***",O15/H15) | W15: =IF(I15=0,"***",P15/I15) | X15: =IF(J15=0,"***",Q15/J15) | Y15: =IF(K15=0,"***",R15/K15)
C16: 合計 | E16: =E9+E12+E15 | F16: =F9+F12+F15 | G16: =G9+G12+G15 | H16: =H9+H12+H15 | I16: =I9+I12+I15 | J16: =J9+J12+J15 | K16: =K9+K12+K15 | L16: =L9+L12+L15 | ... R16: =R9+R12+R15 | S16: =IF(E16=0,"***",L16/E16) | T16: =IF(F16=0,"***",M16/F16) | U16: =IF(G16=0,"***",N16/G16) | V16: =IF(H16=0,"***",O16/H16) | W16: =IF(I16=0,"***",P16/I16) | X16: =IF(J16=0,"***",Q16/J16) | Y16: =IF(K16=0,"***",R16/K16)
C17: 【参考】大海分 | F17: 8671.294 | K17: =SUM(E17:J17) | M17: 3581.357 | R17: =SUM(L17:Q17) | S17: =IF(E17=0,"***",L17/E17) | T17: =IF(F17=0,"***",M17/F17) | U17: =IF(G17=0,"***",N17/G17) | V17: =IF(H17=0,"***",O17/H17) | W17: =IF(I17=0,"***",P17/I17) | X17: =IF(J17=0,"***",Q17/J17) | Y17: =IF(K17=0,"***",R17/K17)
C19: 2．2025年
E20: 売上 | L20: 粗利益 | S20: 粗利益率
E21: 45748 | F21: 45778 | G21: 45809 | H21: 45839 | I21: 45870 | J21: 45901 | K21: 合計 | L21: 45748 | M21: 45778 | N21: 45809 | O21: 45839 | P21: 45870 | Q21: 45901 | R21: 合計 | S21: 45748 | T21: 45778 | U21: 45809 | V21: 45839 | W21: 45870 | X21: 45901 | Y21: 合計
C22: 0010 集計 | D22: JF | E22: =全体!E22-機械!E22 | F22: =全体!F22-機械!F22 | G22: =全体!G22-機械!G22 | H22: =全体!H22-機械!H22 | I22: =全体!I22-機械!I22 | J22: =全体!J22-機械!J22 | K22: =SUM(E22:J22) | L22: =全体!L22-機械!L22 | M22: =全体!M22-機械!M22 | N22: =全体!N22-機械!N22 | O22: =全体!O22-機械!O22 | P22: =全体!P22-機械!P22 | Q22: =全体!Q22-機械!Q22 | R22: =SUM(L22:Q22) | S22: =IF(E22=0,"***",L22/E22) | T22: =IF(F22=0,"***",M22/F22) | U22: =IF(G22=0,"***",N22/G22) | V22: =IF(H22=0,"***",O22/H22) | W22: =IF(I22=0,"***",P22/I22) | X22: =IF(J22=0,"***",Q22/J22) | Y22: =IF(K22=0,"***",R22/K22)
C23: 0017 集計 | D23: 鮮魚 | E23: =全体!E23-機械!E23 | F23: =全体!F23-機械!F23 | G23: =全体!G23-機械!G23 | H23: =全体!H23-機械!H23 | I23: =全体!I23-機械!I23 | J23: =全体!J23-機械!J23 | K23: =SUM(E23:J23) | L23: =全体!L23-機械!L23 | M23: =全体!M23-機械!M23 | N23: =全体!N23-機械!N23 | O23: =全体!O23-機械!O23 | P23: =全体!P23-機械!P23 | Q23: =全体!Q23-機械!Q23 | R23: =SUM(L23:Q23) | S23: =IF(E23=0,"***",L23/E23) | T23: =IF(F23=0,"***",M23/F23) | U23: =IF(G23=0,"***",N23/G23) | V23: =IF(H23=0,"***",O23/H23) | W23: =IF(I23=0,"***",P23/I23) | X23: =IF(J23=0,"***",Q23/J23) | Y23: =IF(K23=0,"***",R23/K23)
C24: 0101 集計 | D24: GS | E24: =全体!E24-機械!E24 | F24: =全体!F24-機械!F24 | G24: =全体!G24-機械!G24 | H24: =全体!H24-機械!H24 | I24: =全体!I24-機械!I24 | J24: =全体!J24-機械!J24 | K24: =SUM(E24:J24) | L24: =全体!L24-機械!L24 | M24: =全体!M24-機械!M24 | N24: =全体!N24-機械!N24 | O24: =全体!O24-機械!O24 | P24: =全体!P24-機械!P24 | Q24: =全体!Q24-機械!Q24 | R24: =SUM(L24:Q24) | S24: =IF(E24=0,"***",L24/E24) | T24: =IF(F24=0,"***",M24/F24) | U24: =IF(G24=0,"***",N24/G24) | V24: =IF(H24=0,"***",O24/H24) | W24: =IF(I24=0,"***",P24/I24) | X24: =IF(J24=0,"***",Q24/J24) | Y24: =IF(K24=0,"***",R24/K24)
C25: 0106 集計 | D25: 浜田荷役 | E25: =全体!E25-機械!E25 | F25: =全体!F25-機械!F25 | G25: =全体!G25-機械!G25 | H25: =全体!H25-機械!H25 | I25: =全体!I25-機械!I25 | J25: =全体!J25-機械!J25 | K25: =SUM(E25:J25) | L25: =全体!L25-機械!L25 | M25: =全体!M25-機械!M25 | N25: =全体!N25-機械!N25 | O25: =全体!O25-機械!O25 | P25: =全体!P25-機械!P25 | Q25: =全体!Q25-機械!Q25 | R25: =SUM(L25:Q25) | S25: =IF(E25=0,"***",L25/E25) | T25: =IF(F25=0,"***",M25/F25) | U25: =IF(G25=0,"***",N25/G25) | V25: =IF(H25=0,"***",O25/H25) | W25: =IF(I25=0,"***",P25/I25) | X25: =IF(J25=0,"***",Q25/J25) | Y25: =IF(K25=0,"***",R25/K25)
C26: 浜田水産部合計 | E26: =SUM(E22:E25) | F26: =SUM(F22:F25) | G26: =SUM(G22:G25) | H26: =SUM(H22:H25) | I26: =SUM(I22:I25) | J26: =SUM(J22:J25) | K26: =SUM(K22:K25) | L26: =SUM(L22:L25) | ... R26: =SUM(R22:R25) | S26: =IF(E26=0,"***",L26/E26) | T26: =IF(F26=0,"***",M26/F26) | U26: =IF(G26=0,"***",N26/G26) | V26: =IF(H26=0,"***",O26/H26) | W26: =IF(I26=0,"***",P26/I26) | X26: =IF(J26=0,"***",Q26/J26) | Y26: =IF(K26=0,"***",R26/K26)
C27: 0102 集計 | D27: JF大田 | E27: =全体!E27-機械!E27 | F27: =全体!F27-機械!F27 | G27: =全体!G27-機械!G27 | H27: =全体!H27-機械!H27 | I27: =全体!I27-機械!I27 | J27: =全体!J27-機械!J27 | K27: =SUM(E27:J27) | L27: =全体!L27-機械!L27 | M27: =全体!M27-機械!M27 | N27: =全体!N27-機械!N27 | O27: =全体!O27-機械!O27 | P27: =全体!P27-機械!P27 | Q27: =全体!Q27-機械!Q27 | R27: =SUM(L27:Q27) | S27: =IF(E27=0,"***",L27/E27) | T27: =IF(F27=0,"***",M27/F27) | U27: =IF(G27=0,"***",N27/G27) | V27: =IF(H27=0,"***",O27/H27) | W27: =IF(I27=0,"***",P27/I27) | X27: =IF(J27=0,"***",Q27/J27) | Y27: =IF(K27=0,"***",R27/K27)
C28: 0104 集計 | D28: 大田荷役 | E28: =全体!E28-機械!E28 | F28: =全体!F28-機械!F28 | G28: =全体!G28-機械!G28 | H28: =全体!H28-機械!H28 | I28: =全体!I28-機械!I28 | J28: =全体!J28-機械!J28 | K28: =SUM(E28:J28) | L28: =全体!L28-機械!L28 | M28: =全体!M28-機械!M28 | N28: =全体!N28-機械!N28 | O28: =全体!O28-機械!O28 | P28: =全体!P28-機械!P28 | Q28: =全体!Q28-機械!Q28 | R28: =SUM(L28:Q28) | S28: =IF(E28=0,"***",L28/E28) | T28: =IF(F28=0,"***",M28/F28) | U28: =IF(G28=0,"***",N28/G28) | V28: =IF(H28=0,"***",O28/H28) | W28: =IF(I28=0,"***",P28/I28) | X28: =IF(J28=0,"***",Q28/J28) | Y28: =IF(K28=0,"***",R28/K28)
C29: 大田水産部 | E29: =E27+E28 | F29: =F27+F28 | G29: =G27+G28 | H29: =H27+H28 | I29: =I27+I28 | J29: =J27+J28 | K29: =K27+K28 | L29: =L27+L28 | ... R29: =R27+R28 | S29: =IF(E29=0,"***",L29/E29) | T29: =IF(F29=0,"***",M29/F29) | U29: =IF(G29=0,"***",N29/G29) | V29: =IF(H29=0,"***",O29/H29) | W29: =IF(I29=0,"***",P29/I29) | X29: =IF(J29=0,"***",Q29/J29) | Y29: =IF(K29=0,"***",R29/K29)
C30: 0031 集計 | D30: JF境 | E30: =全体!E30-機械!E30 | F30: =全体!F30-機械!F30 | G30: =全体!G30-機械!G30 | H30: =全体!H30-機械!H30 | I30: =全体!I30-機械!I30 | J30: =全体!J30-機械!J30 | K30: =SUM(E30:J30) | L30: =全体!L30-機械!L30 | M30: =全体!M30-機械!M30 | N30: =全体!N30-機械!N30 | O30: =全体!O30-機械!O30 | P30: =全体!P30-機械!P30 | Q30: =全体!Q30-機械!Q30 | R30: =SUM(L30:Q30) | S30: =IF(E30=0,"***",L30/E30) | T30: =IF(F30=0,"***",M30/F30) | U30: =IF(G30=0,"***",N30/G30) | V30: =IF(H30=0,"***",O30/H30) | W30: =IF(I30=0,"***",P30/I30) | X30: =IF(J30=0,"***",Q30/J30) | Y30: =IF(K30=0,"***",R30/K30)
C31: 0038 集計 | D31: 境その他 | E31: =全体!E31-機械!E31 | F31: =全体!F31-機械!F31 | G31: =全体!G31-機械!G31 | H31: =全体!H31-機械!H31 | I31: =全体!I31-機械!I31 | J31: =全体!J31-機械!J31 | K31: =SUM(E31:J31) | L31: =全体!L31-機械!L31 | M31: =全体!M31-機械!M31 | N31: =全体!N31-機械!N31 | O31: =全体!O31-機械!O31 | P31: =全体!P31-機械!P31 | Q31: =全体!Q31-機械!Q31 | R31: =SUM(L31:Q31) | S31: =IF(E31=0,"***",L31/E31) | T31: =IF(F31=0,"***",M31/F31) | U31: =IF(G31=0,"***",N31/G31) | V31: =IF(H31=0,"***",O31/H31) | W31: =IF(I31=0,"***",P31/I31) | X31: =IF(J31=0,"***",Q31/J31) | Y31: =IF(K31=0,"***",R31/K31)
C32: 境港水産部合計 | E32: =E30+E31 | F32: =F30+F31 | G32: =G30+G31 | H32: =H30+H31 | I32: =I30+I31 | J32: =J30+J31 | K32: =K30+K31 | L32: =L30+L31 | ... R32: =R30+R31 | S32: =IF(E32=0,"***",L32/E32) | T32: =IF(F32=0,"***",M32/F32) | U32: =IF(G32=0,"***",N32/G32) | V32: =IF(H32=0,"***",O32/H32) | W32: =IF(I32=0,"***",P32/I32) | X32: =IF(J32=0,"***",Q32/J32) | Y32: =IF(K32=0,"***",R32/K32)
C33: 合計 | E33: =E26+E29+E32 | F33: =F26+F29+F32 | G33: =G26+G29+G32 | H33: =H26+H29+H32 | I33: =I26+I29+I32 | J33: =J26+J29+J32 | K33: =K26+K29+K32 | L33: =L26+L29+L32 | ... R33: =R26+R29+R32 | S33: =IF(E33=0,"***",L33/E33) | T33: =IF(F33=0,"***",M33/F33) | U33: =IF(G33=0,"***",N33/G33) | V33: =IF(H33=0,"***",O33/H33) | W33: =IF(I33=0,"***",P33/I33) | X33: =IF(J33=0,"***",Q33/J33) | Y33: =IF(K33=0,"***",R33/K33)
C34: 【参考】大海分 | F34: 8671.294 | K34: =SUM(E34:J34) | M34: 3581.357 | R34: =SUM(L34:Q34) | S34: =IF(E34=0,"***",L34/E34) | T34: =IF(F34=0,"***",M34/F34) | U34: =IF(G34=0,"***",N34/G34) | V34: =IF(H34=0,"***",O34/H34) | W34: =IF(I34=0,"***",P34/I34) | X34: =IF(J34=0,"***",Q34/J34) | Y34: =IF(K34=0,"***",R34/K34)
C36: 3．過年度平均
E37: 売上 | L37: 粗利益 | S37: 粗利益率
E38: 45748 | F38: 45778 | G38: 45809 | H38: 45839 | I38: 45870 | J38: 45901 | K38: 合計 | L38: 45748 | M38: 45778 | N38: 45809 | O38: 45839 | P38: 45870 | Q38: 45901 | R38: 合計 | S38: 45748 | T38: 45778 | U38: 45809 | V38: 45839 | W38: 45870 | X38: 45901 | Y38: 合計
C39: 0010 集計 | D39: JF | E39: =(E22+E5)/2 | F39: =(F22+F5)/2 | G39: =(G22+G5)/2 | H39: =(H22+H5)/2 | I39: =(I22+I5)/2 | J39: =(J22+J5)/2 | K39: =SUM(E39:J39) | L39: =(L22+L5)/2 | M39: =(M22+M5)/2 | N39: =(N22+N5)/2 | O39: =(O22+O5)/2 | P39: =(P22+P5)/2 | Q39: =(Q22+Q5)/2 | R39: =SUM(L39:Q39) | S39: =IF(E39=0,"***",L39/E39) | T39: =IF(F39=0,"***",M39/F39) | U39: =IF(G39=0,"***",N39/G39) | V39: =IF(H39=0,"***",O39/H39) | W39: =IF(I39=0,"***",P39/I39) | X39: =IF(J39=0,"***",Q39/J39) | Y39: =IF(K39=0,"***",R39/K39)
C40: 0017 集計 | D40: 鮮魚 | E40: =(E23+E6)/2 | F40: =(F23+F6)/2 | G40: =(G23+G6)/2 | H40: =(H23+H6)/2 | I40: =(I23+I6)/2 | J40: =(J23+J6)/2 | K40: =SUM(E40:J40) | L40: =(L23+L6)/2 | M40: =(M23+M6)/2 | N40: =(N23+N6)/2 | O40: =(O23+O6)/2 | P40: =(P23+P6)/2 | Q40: =(Q23+Q6)/2 | R40: =SUM(L40:Q40) | S40: =IF(E40=0,"***",L40/E40) | T40: =IF(F40=0,"***",M40/F40) | U40: =IF(G40=0,"***",N40/G40) | V40: =IF(H40=0,"***",O40/H40) | W40: =IF(I40=0,"***",P40/I40) | X40: =IF(J40=0,"***",Q40/J40) | Y40: =IF(K40=0,"***",R40/K40)
C41: 0101 集計 | D41: GS | E41: =(E24+E7)/2 | F41: =(F24+F7)/2 | G41: =(G24+G7)/2 | H41: =(H24+H7)/2 | I41: =(I24+I7)/2 | J41: =(J24+J7)/2 | K41: =SUM(E41:J41) | L41: =(L24+L7)/2 | M41: =(M24+M7)/2 | N41: =(N24+N7)/2 | O41: =(O24+O7)/2 | P41: =(P24+P7)/2 | Q41: =(Q24+Q7)/2 | R41: =SUM(L41:Q41) | S41: =IF(E41=0,"***",L41/E41) | T41: =IF(F41=0,"***",M41/F41) | U41: =IF(G41=0,"***",N41/G41) | V41: =IF(H41=0,"***",O41/H41) | W41: =IF(I41=0,"***",P41/I41) | X41: =IF(J41=0,"***",Q41/J41) | Y41: =IF(K41=0,"***",R41/K41)
C42: 0106 集計 | D42: 浜田荷役 | E42: =(E25+E8)/2 | F42: =(F25+F8)/2 | G42: =(G25+G8)/2 | H42: =(H25+H8)/2 | I42: =(I25+I8)/2 | J42: =(J25+J8)/2 | K42: =SUM(E42:J42) | L42: =(L25+L8)/2 | M42: =(M25+M8)/2 | N42: =(N25+N8)/2 | O42: =(O25+O8)/2 | P42: =(P25+P8)/2 | Q42: =(Q25+Q8)/2 | R42: =SUM(L42:Q42) | S42: =IF(E42=0,"***",L42/E42) | T42: =IF(F42=0,"***",M42/F42) | U42: =IF(G42=0,"***",N42/G42) | V42: =IF(H42=0,"***",O42/H42) | W42: =IF(I42=0,"***",P42/I42) | X42: =IF(J42=0,"***",Q42/J42) | Y42: =IF(K42=0,"***",R42/K42)
...

Sheet 機械
C1: 水産部機械
C2: 1．2024年
E3: 売上 | L3: 粗利益 | S3: 粗利益率
E4: 45383 | F4: 45413 | G4: 45444 | H4: 45474 | I4: 45505 | J4: 45536 | K4: 合計 | L4: 45383 | M4: 45413 | N4: 45444 | O4: 45474 | P4: 45505 | Q4: 45536 | R4: 合計 | S4: 45383 | T4: 45413 | U4: 45444 | V4: 45474 | W4: 45505 | X4: 45536 | Y4: 合計
C5: 0010 集計 | D5: JF | H5: 2131.8 | K5: =SUM(E5:J5) | O5: 428.4 | R5: =SUM(L5:Q5) | S5: =IF(E5=0,"***",L5/E5) | T5: =IF(F5=0,"***",M5/F5) | U5: =IF(G5=0,"***",N5/G5) | V5: =IF(H5=0,"***",O5/H5) | W5: =IF(I5=0,"***",P5/I5) | X5: =IF(J5=0,"***",Q5/J5) | Y5: =IF(K5=0,"***",R5/K5)
C6: 0017 集計 | D6: 鮮魚 | K6: =SUM(E6:J6) | R6: =SUM(L6:Q6) | S6: =IF(E6=0,"***",L6/E6) | T6: =IF(F6=0,"***",M6/F6) | U6: =IF(G6=0,"***",N6/G6) | V6: =IF(H6=0,"***",O6/H6) | W6: =IF(I6=0,"***",P6/I6) | X6: =IF(J6=0,"***",Q6/J6) | Y6: =IF(K6=0,"***",R6/K6)
C7: 0101 集計 | D7: GS | K7: =SUM(E7:J7) | R7: =SUM(L7:Q7) | S7: =IF(E7=0,"***",L7/E7) | T7: =IF(F7=0,"***",M7/F7) | U7: =IF(G7=0,"***",N7/G7) | V7: =IF(H7=0,"***",O7/H7) | W7: =IF(I7=0,"***",P7/I7) | X7: =IF(J7=0,"***",Q7/J7) | Y7: =IF(K7=0,"***",R7/K7)
C8: 0106 集計 | D8: 浜田荷役 | K8: =SUM(E8:J8) | R8: =SUM(L8:Q8) | S8: =IF(E8=0,"***",L8/E8) | T8: =IF(F8=0,"***",M8/F8) | U8: =IF(G8=0,"***",N8/G8) | V8: =IF(H8=0,"***",O8/H8) | W8: =IF(I8=0,"***",P8/I8) | X8: =IF(J8=0,"***",Q8/J8) | Y8: =IF(K8=0,"***",R8/K8)
C9: 浜田水産部合計 | E9: =SUM(E5:E8) | F9: =SUM(F5:F8) | G9: =SUM(G5:G8) | H9: =SUM(H5:H8) | I9: =SUM(I5:I8) | J9: =SUM(J5:J8) | K9: =SUM(K5:K8) | L9: =SUM(L5:L8) | ... R9: =SUM(R5:R8) | S9: =IF(E9=0,"***",L9/E9) | T9: =IF(F9=0,"***",M9/F9) | U9: =IF(G9=0,"***",N9/G9) | V9: =IF(H9=0,"***",O9/H9) | W9: =IF(I9=0,"***",P9/I9) | X9: =IF(J9=0,"***",Q9/J9) | Y9: =IF(K9=0,"***",R9/K9)
C10: 0102 集計 | D10: JF大田 | K10: =SUM(E10:J10) | R10: =SUM(L10:Q10) | S10: =IF(E10=0,"***",L10/E10) | T10: =IF(F10=0,"***",M10/F10) | U10: =IF(G10=0,"***",N10/G10) | V10: =IF(H10=0,"***",O10/H10) | W10: =IF(I10=0,"***",P10/I10) | X10: =IF(J10=0,"***",Q10/J10) | Y10: =IF(K10=0,"***",R10/K10)
C11: 0104 集計 | D11: 大田荷役 | K11: =SUM(E11:J11) | R11: =SUM(L11:Q11) | S11: =IF(E11=0,"***",L11/E11) | T11: =IF(F11=0,"***",M11/F11) | U11: =IF(G11=0,"***",N11/G11) | V11: =IF(H11=0,"***",O11/H11) | W11: =IF(I11=0,"***",P11/I11) | X11: =IF(J11=0,"***",Q11/J11) | Y11: =IF(K11=0,"***",R11/K11)
C12: 大田水産部 | E12: =E10+E11 | F12: =F10+F11 | G12: =G10+G11 | H12: =H10+H11 | I12: =I10+I11 | J12: =J10+J11 | K12: =K10+K11 | L12: =L10+L11 | ... R12: =R10+R11 | S12: =IF(E12=0,"***",L12/E12) | T12: =IF(F12=0,"***",M12/F12) | U12: =IF(G12=0,"***",N12/G12) | V12: =IF(H12=0,"***",O12/H12) | W12: =IF(I12=0,"***",P12/I12) | X12: =IF(J12=0,"***",Q12/J12) | Y12: =IF(K12=0,"***",R12/K12)
C13: 0031 集計 | D13: JF境 | E13: 22 | F13: 28 | G13: 39 | H13: 90.76 | I13: 124.2 | J13: 22 | K13: =SUM(E13:J13) | L13: 2.2 | M13: 2.7 | N13: 3.8 | O13: 12.265 | P13: 17.16 | Q13: 2.2 | R13: =SUM(L13:Q13) | S13: =IF(E13=0,"***",L13/E13) | T13: =IF(F13=0,"***",M13/F13) | U13: =IF(G13=0,"***",N13/G13) | V13: =IF(H13=0,"***",O13/H13) | W13: =IF(I13=0,"***",P13/I13) | X13: =IF(J13=0,"***",Q13/J13) | Y13: =IF(K13=0,"***",R13/K13)
C14: 0038 集計 | D14: 境その他 | K14: =SUM(E14:J14) | R14: =SUM(L14:Q14) | S14: =IF(E14=0,"***",L14/E14) | T14: =IF(F14=0,"***",M14/F14) | U14: =IF(G14=0,"***",N14/G14) | V14: =IF(H14=0,"***",O14/H14) | W14: =IF(I14=0,"***",P14/I14) | X14: =IF(J14=0,"***",Q14/J14) | Y14: =IF(K14=0,"***",R14/K14)
C15: 境港水産部合計 | E15: =E13+E14 | F15: =F13+F14 | G15: =G13+G14 | H15: =H13+H14 | I15: =I13+I14 | J15: =J13+J14 | K15: =K13+K14 | L15: =L13+L14 | ... R15: =R13+R14 | S15: =IF(E15=0,"***",L15/E15) | T15: =IF(F15=0,"***",M15/F15) | U15: =IF(G15=0,"***",N15/G15) | V15: =IF(H15=0,"***",O15/H15) | W15: =IF(I15=0,"***",P15/I15) | X15: =IF(J15=0,"***",Q15/J15) | Y15: =IF(K15=0,"***",R15/K15)
C16: 合計 | E16: =E9+E12+E15 | F16: =F9+F12+F15 | G16: =G9+G12+G15 | H16: =H9+H12+H15 | I16: =I9+I12+I15 | J16: =J9+J12+J15 | K16: =K9+K12+K15 | L16: =L9+L12+L15 | ... R16: =R9+R12+R15 | S16: =IF(E16=0,"***",L16/E16) | T16: =IF(F16=0,"***",M16/F16) | U16: =IF(G16=0,"***",N16/G16) | V16: =IF(H16=0,"***",O16/H16) | W16: =IF(I16=0,"***",P16/I16) | X16: =IF(J16=0,"***",Q16/J16) | Y16: =IF(K16=0,"***",R16/K16)
C17: 【参考】大海分 | K17: =SUM(E17:J17) | R17: =SUM(L17:Q17) | S17: =IF(E17=0,"***",L17/E17) | T17: =IF(F17=0,"***",M17/F17) | U17: =IF(G17=0,"***",N17/G17) | V17: =IF(H17=0,"***",O17/H17) | W17: =IF(I17=0,"***",P17/I17) | X17: =IF(J17=0,"***",Q17/J17) | Y17: =IF(K17=0,"***",R17/K17)
C19: 2．2025年
E20: 売上 | L20: 粗利益 | S20: 粗利益率
E21: 45748 | F21: 45778 | G21: 45809 | H21: 45839 | I21: 45870 | J21: 45901 | K21: 合計 | L21: 45748 | M21: 45778 | N21: 45809 | O21: 45839 | P21: 45870 | Q21: 45901 | R21: 合計 | S21: 45748 | T21: 45778 | U21: 45809 | V21: 45839 | W21: 45870 | X21: 45901 | Y21: 合計
C22: 0010 集計 | D22: JF | H22: 16 | K22: =SUM(E22:J22) | O22: 16 | R22: =SUM(L22:Q22) | S22: =IF(E22=0,"***",L22/E22) | T22: =IF(F22=0,"***",M22/F22) | U22: =IF(G22=0,"***",N22/G22) | V22: =IF(H22=0,"***",O22/H22) | W22: =IF(I22=0,"***",P22/I22) | X22: =IF(J22=0,"***",Q22/J22) | Y22: =IF(K22=0,"***",R22/K22)
C23: 0017 集計 | D23: 鮮魚 | F23: 110 | K23: =SUM(E23:J23) | M23: 27 | R23: =SUM(L23:Q23) | S23: =IF(E23=0,"***",L23/E23) | T23: =IF(F23=0,"***",M23/F23) | U23: =IF(G23=0,"***",N23/G23) | V23: =IF(H23=0,"***",O23/H23) | W23: =IF(I23=0,"***",P23/I23) | X23: =IF(J23=0,"***",Q23/J23) | Y23: =IF(K23=0,"***",R23/K23)
C24: 0101 集計 | D24: GS | K24: =SUM(E24:J24) | R24: =SUM(L24:Q24) | S24: =IF(E24=0,"***",L24/E24) | T24: =IF(F24=0,"***",M24/F24) | U24: =IF(G24=0,"***",N24/G24) | V24: =IF(H24=0,"***",O24/H24) | W24: =IF(I24=0,"***",P24/I24) | X24: =IF(J24=0,"***",Q24/J24) | Y24: =IF(K24=0,"***",R24/K24)
C25: 0106 集計 | D25: 浜田荷役 | K25: =SUM(E25:J25) | R25: =SUM(L25:Q25) | S25: =IF(E25=0,"***",L25/E25) | T25: =IF(F25=0,"***",M25/F25) | U25: =IF(G25=0,"***",N25/G25) | V25: =IF(H25=0,"***",O25/H25) | W25: =IF(I25=0,"***",P25/I25) | X25: =IF(J25=0,"***",Q25/J25) | Y25: =IF(K25=0,"***",R25/K25)
C26: 浜田水産部合計 | E26: =SUM(E22:E25) | F26: =SUM(F22:F25) | G26: =SUM(G22:G25) | H26: =SUM(H22:H25) | I26: =SUM(I22:I25) | J26: =SUM(J22:J25) | K26: =SUM(E26:J26) | L26: =SUM(L22:L25) | M26: =SUM(M22:M25) | N26: =SUM(N22:N25) | O26: =SUM(O22:O25) | P26: =SUM(P22:P25) | Q26: =SUM(Q22:Q25) | R26: =SUM(L26:Q26) | S26: =IF(E26=0,"***",L26/E26) | T26: =IF(F26=0,"***",M26/F26) | U26: =IF(G26=0,"***",N26/G26) | V26: =IF(H26=0,"***",O26/H26) | W26: =IF(I26=0,"***",P26/I26) | X26: =IF(J26=0,"***",Q26/J26) | Y26: =IF(K26=0,"***",R26/K26)
C27: 0102 集計 | D27: JF大田 | K27: =SUM(E27:J27) | R27: =SUM(L27:Q27) | S27: =IF(E27=0,"***",L27/E27) | T27: =IF(F27=0,"***",M27/F27) | U27: =IF(G27=0,"***",N27/G27) | V27: =IF(H27=0,"***",O27/H27) | W27: =IF(I27=0,"***",P27/I27) | X27: =IF(J27=0,"***",Q27/J27) | Y27: =IF(K27=0,"***",R27/K27)
C28: 0104 集計 | D28: 大田荷役 | K28: =SUM(E28:J28) | R28: =SUM(L28:Q28) | S28: =IF(E28=0,"***",L28/E28) | T28: =IF(F28=0,"***",M28/F28) | U28: =IF(G28=0,"***",N28/G28) | V28: =IF(H28=0,"***",O28/H28) | W28: =IF(I28=0,"***",P28/I28) | X28: =IF(J28=0,"***",Q28/J28) | Y28: =IF(K28=0,"***",R28/K28)
C29: 大田水産部 | E29: =SUM(E27:E28) | F29: =SUM(F27:F28) | G29: =SUM(G27:G28) | H29: =SUM(H27:H28) | I29: =SUM(I27:I28) | J29: =SUM(J27:J28) | K29: =SUM(K27:K28) | L29: =SUM(L27:L28) | ... R29: =SUM(R27:R28) | S29: =IF(E29=0,"***",L29/E29) | T29: =IF(F29=0,"***",M29/F29) | U29: =IF(G29=0,"***",N29/G29) | V29: =IF(H29=0,"***",O29/H29) | W29: =IF(I29=0,"***",P29/I29) | X29: =IF(J29=0,"***",Q29/J29) | Y29: =IF(K29=0,"***",R29/K29)
C30: 0031 集計 | D30: JF境 | E30: 296.05 | F30: 78.5 | G30: 49.2 | H30: 60.3 | I30: 90.48 | J30: 206.326 | K30: =SUM(E30:J30) | L30: 44.57 | M30: 18.9 | N30: 6.5 | O30: 8.7 | P30: 5.48 | Q30: 47.345 | R30: =SUM(L30:Q30) | S30: =IF(E30=0,"***",L30/E30) | T30: =IF(F30=0,"***",M30/F30) | U30: =IF(G30=0,"***",N30/G30) | V30: =IF(H30=0,"***",O30/H30) | W30: =IF(I30=0,"***",P30/I30) | X30: =IF(J30=0,"***",Q30/J30) | Y30: =IF(K30=0,"***",R30/K30)
C31: 0038 集計 | D31: 境その他 | K31: =SUM(E31:J31) | R31: =SUM(L31:Q31) | S31: =IF(E31=0,"***",L31/E31) | T31: =IF(F31=0,"***",M31/F31) | U31: =IF(G31=0,"***",N31/G31) | V31: =IF(H31=0,"***",O31/H31) | W31: =IF(I31=0,"***",P31/I31) | X31: =IF(J31=0,"***",Q31/J31) | Y31: =IF(K31=0,"***",R31/K31)
C32: 境港水産部合計 | E32: =E30+E31 | F32: =F30+F31 | G32: =G30+G31 | H32: =H30+H31 | I32: =I30+I31 | J32: =J30+J31 | K32: =SUM(E32:J32) | L32: =L30+L31 | M32: =M30+M31 | N32: =N30+N31 | O32: =O30+O31 | P32: =P30+P31 | Q32: =Q30+Q31 | R32: =SUM(L32:Q32) | S32: =IF(E32=0,"***",L32/E32) | T32: =IF(F32=0,"***",M32/F32) | U32: =IF(G32=0,"***",N32/G32) | V32: =IF(H32=0,"***",O32/H32) | W32: =IF(I32=0,"***",P32/I32) | X32: =IF(J32=0,"***",Q32/J32) | Y32: =IF(K32=0,"***",R32/K32)
C33: 合計 | E33: =E26+E29+E32 | F33: =F26+F29+F32 | G33: =G26+G29+G32 | H33: =H26+H29+H32 | I33: =I26+I29+I32 | J33: =J26+J29+J32 | K33: =K26+K29+K32 | L33: =L26+L29+L32 | ... R33: =R26+R29+R32 | S33: =IF(E33=0,"***",L33/E33) | T33: =IF(F33=0,"***",M33/F33) | U33: =IF(G33=0,"***",N33/G33) | V33: =IF(H33=0,"***",O33/H33) | W33: =IF(I33=0,"***",P33/I33) | X33: =IF(J33=0,"***",Q33/J33) | Y33: =IF(K33=0,"***",R33/K33)
C34: 【参考】大海分 | K34: =SUM(E34:J34) | R34: =SUM(L34:Q34) | S34: =IF(E34=0,"***",L34/E34) | T34: =IF(F34=0,"***",M34/F34) | U34: =IF(G34=0,"***",N34/G34) | V34: =IF(H34=0,"***",O34/H34) | W34: =IF(I34=0,"***",P34/I34) | X34: =IF(J34=0,"***",Q34/J34) | Y34: =IF(K34=0,"***",R34/K34)
C36: 3．過年度平均
E37: 売上 | L37: 粗利益 | S37: 粗利益率
E38: 45748 | F38: 45778 | G38: 45809 | H38: 45839 | I38: 45870 | J38: 45901 | K38: 合計 | L38: 45748 | M38: 45778 | N38: 45809 | O38: 45839 | P38: 45870 | Q38: 45901 | R38: 合計 | S38: 45748 | T38: 45778 | U38: 45809 | V38: 45839 | W38: 45870 | X38: 45901 | Y38: 合計
C39: 0010 集計 | D39: JF | E39: =(E22+E5)/2 | F39: =(F22+F5)/2 | G39: =(G22+G5)/2 | H39: =(H22+H5)/2 | I39: =(I22+I5)/2 | J39: =(J22+J5)/2 | K39: =SUM(E39:J39) | L39: =(L22+L5)/2 | M39: =(M22+M5)/2 | N39: =(N22+N5)/2 | O39: =(O22+O5)/2 | P39: =(P22+P5)/2 | Q39: =(Q22+Q5)/2 | R39: =SUM(L39:Q39) | S39: =IF(E39=0,"***",L39/E39) | T39: =IF(F39=0,"***",M39/F39) | U39: =IF(G39=0,"***",N39/G39) | V39: =IF(H39=0,"***",O39/H39) | W39: =IF(I39=0,"***",P39/I39) | X39: =IF(J39=0,"***",Q39/J39) | Y39: =IF(K39=0,"***",R39/K39)
C40: 0017 集計 | D40: 鮮魚 | E40: =(E23+E6)/2 | F40: =(F23+F6)/2 | G40: =(G23+G6)/2 | H40: =(H23+H6)/2 | I40: =(I23+I6)/2 | J40: =(J23+J6)/2 | K40: =SUM(E40:J40) | L40: =(L23+L6)/2 | M40: =(M23+M6)/2 | N40: =(N23+N6)/2 | O40: =(O23+O6)/2 | P40: =(P23+P6)/2 | Q40: =(Q23+Q6)/2 | R40: =SUM(L40:Q40) | S40: =IF(E40=0,"***",L40/E40) | T40: =IF(F40=0,"***",M40/F40) | U40: =IF(G40=0,"***",N40/G40) | V40: =IF(H40=0,"***",O40/H40) | W40: =IF(I40=0,"***",P40/I40) | X40: =IF(J40=0,"***",Q40/J40) | Y40: =IF(K40=0,"***",R40/K40)
C41: 0101 集計 | D41: GS | E41: =(E24+E7)/2 | F41: =(F24+F7)/2 | G41: =(G24+G7)/2 | H41: =(H24+H7)/2 | I41: =(I24+I7)/2 | J41: =(J24+J7)/2 | K41: =SUM(E41:J41) | L41: =(L24+L7)/2 | M41: =(M24+M7)/2 | N41: =(N24+N7)/2 | O41: =(O24+O7)/2 | P41: =(P24+P7)/2 | Q41: =(Q24+Q7)/2 | R41: =SUM(L41:Q41) | S41: =IF(E41=0,"***",L41/E41) | T41: =IF(F41=0,"***",M41/F41) | U41: =IF(G41=0,"***",N41/G41) | V41: =IF(H41=0,"***",O41/H41) | W41: =IF(I41=0,"***",P41/I41) | X41: =IF(J41=0,"***",Q41/J41) | Y41: =IF(K41=0,"***",R41/K41)
C42: 0106 集計 | D42: 浜田荷役 | E42: =(E25+E8)/2 | F42: =(F25+F8)/2 | G42: =(G25+G8)/2 | H42: =(H25+H8)/2 | I42: =(I25+I8)/2 | J42: =(J25+J8)/2 | K42: =SUM(E42:J42) | L42: =(L25+L8)/2 | M42: =(M25+M8)/2 | N42: =(N25+N8)/2 | O42: =(O25+O8)/2 | P42: =(P25+P8)/2 | Q42: =(Q25+Q8)/2 | R42: =SUM(L42:Q42) | S42: =IF(E42=0,"***",L42/E42) | T42: =IF(F42=0,"***",M42/F42) | U42: =IF(G42=0,"***",N42/G42) | V42: =IF(H42=0,"***",O42/H42) | W42: =IF(I42=0,"***",P42/I42) | X42: =IF(J42=0,"***",Q42/J42) | Y42: =IF(K42=0,"***",R42/K42)
...

Sheet 全体
C1: 水産部全体
C2: 1．2024年
E3: 売上 | L3: 粗利益 | S3: 粗利益率
E4: 45383 | F4: 45413 | G4: 45444 | H4: 45474 | I4: 45505 | J4: 45536 | K4: 合計 | L4: 45383 | M4: 45413 | N4: 45444 | O4: 45474 | P4: 45505 | Q4: 45536 | R4: 合計 | S4: 45383 | T4: 45413 | U4: 45444 | V4: 45474 | W4: 45505 | X4: 45536 | Y4: 合計
C5: 0010 集計 | D5: JF | E5: 7819.702 | F5: 4795.298 | G5: 1764.909 | H5: 3971.482 | I5: 4586.726 | J5: 7121.094 | K5: =SUM(E5:J5) | L5: 1473.163 | M5: 1047.506 | N5: 403.183 | O5: 766.429 | P5: 878.057 | Q5: 1267.57 | R5: =SUM(L5:Q5) | S5: =IF(E5=0,"***",L5/E5) | T5: =IF(F5=0,"***",M5/F5) | U5: =IF(G5=0,"***",N5/G5) | V5: =IF(H5=0,"***",O5/H5) | W5: =IF(I5=0,"***",P5/I5) | X5: =IF(J5=0,"***",Q5/J5) | Y5: =IF(K5=0,"***",R5/K5)
C6: 0017 集計 | D6: 鮮魚 | E6: 1270.335 | F6: 1090.749 | G6: 457.537 | H6: 675.593 | I6: 2326.831 | J6: 2620.375 | K6: =SUM(E6:J6) | L6: 495.785 | M6: 385.803 | N6: 164.416 | O6: 252.919 | P6: 773.717 | Q6: 827.496 | R6: =SUM(L6:Q6) | S6: =IF(E6=0,"***",L6/E6) | T6: =IF(F6=0,"***",M6/F6) | U6: =IF(G6=0,"***",N6/G6) | V6: =IF(H6=0,"***",O6/H6) | W6: =IF(I6=0,"***",P6/I6) | X6: =IF(J6=0,"***",Q6/J6) | Y6: =IF(K6=0,"***",R6/K6)
C7: 0101 集計 | D7: GS | E7: 428.701 | F7: 251.499 | G7: 45.225 | H7: 35.355 | I7: 309.957 | J7: 347.305 | K7: =SUM(E7:J7) | L7: 92.5 | M7: 60.83 | N7: 13.472 | O7: 13.477 | P7: 80.497 | Q7: 185.562 | R7: =SUM(L7:Q7) | S7: =IF(E7=0,"***",L7/E7) | T7: =IF(F7=0,"***",M7/F7) | U7: =IF(G7=0,"***",N7/G7) | V7: =IF(H7=0,"***",O7/H7) | W7: =IF(I7=0,"***",P7/I7) | X7: =IF(J7=0,"***",Q7/J7) | Y7: =IF(K7=0,"***",R7/K7)
C8: 0106 集計 | D8: 浜田荷役 | E8: 3888.393 | F8: 5524.833 | G8: 2439.914 | H8: 3134.156 | I8: 5261.74 | J8: 5914.2 | K8: =SUM(E8:J8) | L8: 2019.778 | M8: 2623.905 | N8: 1163.914 | O8: 1742.196 | P8: 2960.678 | Q8: 3437.035 | R8: =SUM(L8:Q8) | S8: =IF(E8=0,"***",L8/E8) | T8: =IF(F8=0,"***",M8/F8) | U8: =IF(G8=0,"***",N8/G8) | V8: =IF(H8=0,"***",O8/H8) | W8: =IF(I8=0,"***",P8/I8) | X8: =IF(J8=0,"***",Q8/J8) | Y8: =IF(K8=0,"***",R8/K8)
C9: 浜田水産部合計 | E9: =SUM(E5:E8) | F9: =SUM(F5:F8) | G9: =SUM(G5:G8) | H9: =SUM(H5:H8) | I9: =SUM(I5:I8) | J9: =SUM(J5:J8) | K9: =SUM(K5:K8) | L9: =SUM(L5:L8) | ... R9: =SUM(R5:R8) | S9: =IF(E9=0,"***",L9/E9) | T9: =IF(F9=0,"***",M9/F9) | U9: =IF(G9=0,"***",N9/G9) | V9: =IF(H9=0,"***",O9/H9) | W9: =IF(I9=0,"***",P9/I9) | X9: =IF(J9=0,"***",Q9/J9) | Y9: =IF(K9=0,"***",R9/K9)
C10: 0102 集計 | D10: JF大田 | E10: 8598.528 | F10: 5949.793 | G10: 6712.828 | H10: 2910.08 | I10: 4490.196 | J10: 9948.628 | K10: =SUM(E10:J10) | L10: 1815.375 | M10: 1139.616 | N10: 1080.601 | O10: 447.17 | P10: 851.726 | Q10: 1848.082 | R10: =SUM(L10:Q10) | S10: =IF(E10=0,"***",L10/E10) | T10: =IF(F10=0,"***",M10/F10) | U10: =IF(G10=0,"***",N10/G10) | V10: =IF(H10=0,"***",O10/H10) | W10: =IF(I10=0,"***",P10/I10) | X10: =IF(J10=0,"***",Q10/J10) | Y10: =IF(K10=0,"***",R10/K10)
C11: 0104 集計 | D11: 大田荷役 | E11: 4686.11 | F11: 3350.13 | G11: 2005.66 | H11: 1250.16 | I11: 1488.54 | J11: 4361.415 | K11: =SUM(E11:J11) | L11: 2882.91 | M11: 2089.067 | N11: 1471.597 | O11: 940.097 | P11: 1147.04 | Q11: 2488.225 | R11: =SUM(L11:Q11) | S11: =IF(E11=0,"***",L11/E11) | T11: =IF(F11=0,"***",M11/F11) | U11: =IF(G11=0,"***",N11/G11) | V11: =IF(H11=0,"***",O11/H11) | W11: =IF(I11=0,"***",P11/I11) | X11: =IF(J11=0,"***",Q11/J11) | Y11: =IF(K11=0,"***",R11/K11)
C12: 大田水産部 | E12: =E10+E11 | F12: =F10+F11 | G12: =G10+G11 | H12: =H10+H11 | I12: =I10+I11 | J12: =J10+J11 | K12: =K10+K11 | L12: =L10+L11 | ... R12: =R10+R11 | S12: =IF(E12=0,"***",L12/E12) | T12: =IF(F12=0,"***",M12/F12) | U12: =IF(G12=0,"***",N12/G12) | V12: =IF(H12=0,"***",O12/H12) | W12: =IF(I12=0,"***",P12/I12) | X12: =IF(J12=0,"***",Q12/J12) | Y12: =IF(K12=0,"***",R12/K12)
C13: 0031 集計 | D13: JF境 | E13: 17463.391 | F13: 17710.987 | G13: 17263.698 | H13: 12230.208 | I13: 8588.548 | J13: 11851.112 | K13: =SUM(E13:J13) | L13: 2785.482 | M13: 2696.668 | N13: 2637.008 | O13: 1924.18 | P13: 1335.401 | Q13: 1767.93 | R13: =SUM(L13:Q13) | S13: =IF(E13=0,"***",L13/E13) | T13: =IF(F13=0,"***",M13/F13) | U13: =IF(G13=0,"***",N13/G13) | V13: =IF(H13=0,"***",O13/H13) | W13: =IF(I13=0,"***",P13/I13) | X13: =IF(J13=0,"***",Q13/J13) | Y13: =IF(K13=0,"***",R13/K13)
C14: 0038 集計 | D14: 境その他 | E14: 0 | F14: 0 | G14: 0 | H14: 0 | I14: 0 | J14: 0 | K14: =SUM(E14:J14) | L14: 0 | M14: 0 | N14: 0 | O14: 0 | P14: 0 | Q14: 0 | R14: =SUM(L14:Q14) | S14: =IF(E14=0,"***",L14/E14) | T14: =IF(F14=0,"***",M14/F14) | U14: =IF(G14=0,"***",N14/G14) | V14: =IF(H14=0,"***",O14/H14) | W14: =IF(I14=0,"***",P14/I14) | X14: =IF(J14=0,"***",Q14/J14) | Y14: =IF(K14=0,"***",R14/K14)
C15: 境港水産部合計 | E15: =E13+E14 | F15: =F13+F14 | G15: =G13+G14 | H15: =H13+H14 | I15: =I13+I14 | J15: =J13+J14 | K15: =K13+K14 | L15: =L13+L14 | ... R15: =R13+R14 | S15: =IF(E15=0,"***",L15/E15) | T15: =IF(F15=0,"***",M15/F15) | U15: =IF(G15=0,"***",N15/G15) | V15: =IF(H15=0,"***",O15/H15) | W15: =IF(I15=0,"***",P15/I15) | X15: =IF(J15=0,"***",Q15/J15) | Y15: =IF(K15=0,"***",R15/K15)
C16: 合計 | E16: =E9+E12+E15 | F16: =F9+F12+F15 | G16: =G9+G12+G15 | H16: =H9+H12+H15 | I16: =I9+I12+I15 | J16: =J9+J12+J15 | K16: =K9+K12+K15 | L16: =L9+L12+L15 | ... R16: =R9+R12+R15 | S16: =IF(E16=0,"***",L16/E16) | T16: =IF(F16=0,"***",M16/F16) | U16: =IF(G16=0,"***",N16/G16) | V16: =IF(H16=0,"***",O16/H16) | W16: =IF(I16=0,"***",P16/I16) | X16: =IF(J16=0,"***",Q16/J16) | Y16: =IF(K16=0,"***",R16/K16)
C17: 【参考】大海分 | E17: 4919 | F17: 8671.294 | G17: 1764 | H17: 2026 | I17: 5177 | J17: 7426 | K17: =SUM(E17:J17) | L17: 1895 | M17: 3581.357 | N17: 607 | O17: 774 | P17: 1883 | Q17: 2772 | R17: =SUM(L17:Q17) | S17: =IF(E17=0,"***",L17/E17) | T17: =IF(F17=0,"***",M17/F17) | U17: =IF(G17=0,"***",N17/G17) | V17: =IF(H17=0,"***",O17/H17) | W17: =IF(I17=0,"***",P17/I17) | X17: =IF(J17=0,"***",Q17/J17) | Y17: =IF(K17=0,"***",R17/K17)
C19: 2．2025年
E20: 売上 | L20: 粗利益 | S20: 粗利益率
E21: 45748 | F21: 45778 | G21: 45809 | H21: 45839 | I21: 45870 | J21: 45901 | K21: 合計 | L21: 45748 | M21: 45778 | N21: 45809 | O21: 45839 | P21: 45870 | Q21: 45901 | R21: 合計 | S21: 45748 | T21: 45778 | U21: 45809 | V21: 45839 | W21: 45870 | X21: 45901 | Y21: 合計
C22: 0010 集計 | D22: JF | E22: 9147.796 | F22: 4444.472 | G22: 2355.602 | H22: 1557.684 | I22: 3298.471 | J22: 7505.23 | K22: =SUM(E22:J22) | L22: 1807.735 | M22: 979.733 | N22: 613.376 | O22: 497.646 | P22: 716.776 | Q22: 1539.684 | R22: =SUM(L22:Q22) | S22: =IF(E22=0,"***",L22/E22) | T22: =IF(F22=0,"***",M22/F22) | U22: =IF(G22=0,"***",N22/G22) | V22: =IF(H22=0,"***",O22/H22) | W22: =IF(I22=0,"***",P22/I22) | X22: =IF(J22=0,"***",Q22/J22) | Y22: =IF(K22=0,"***",R22/K22)
C23: 0017 集計 | D23: 鮮魚 | E23: 643.412 | F23: 793.478 | G23: 1761.134 | H23: 3657.34 | I23: 2898.805 | J23: 5118.363 | K23: =SUM(E23:J23) | L23: 174.632 | M23: 274.091 | N23: 747.894 | O23: 1286.432 | P23: 848.42 | Q23: 1789.332 | R23: =SUM(L23:Q23) | S23: =IF(E23=0,"***",L23/E23) | T23: =IF(F23=0,"***",M23/F23) | U23: =IF(G23=0,"***",N23/G23) | V23: =IF(H23=0,"***",O23/H23) | W23: =IF(I23=0,"***",P23/I23) | X23: =IF(J23=0,"***",Q23/J23) | Y23: =IF(K23=0,"***",R23/K23)
C24: 0101 集計 | D24: GS | E24: 676.904 | F24: 421.593 | G24: 54.482 | H24: 36.714 | I24: 888.853 | J24: 683.032 | K24: =SUM(E24:J24) | L24: 413.214 | M24: 270.704 | N24: 22.481 | O24: 16.864 | P24: 717.357 | Q24: 517.263 | R24: =SUM(L24:Q24) | S24: =IF(E24=0,"***",L24/E24) | T24: =IF(F24=0,"***",M24/F24) | U24: =IF(G24=0,"***",N24/G24) | V24: =IF(H24=0,"***",O24/H24) | W24: =IF(I24=0,"***",P24/I24) | X24: =IF(J24=0,"***",Q24/J24) | Y24: =IF(K24=0,"***",R24/K24)
C25: 0106 集計 | D25: 浜田荷役 | E25: 3178.58 | F25: 4702.828 | G25: 4402.221 | H25: 3998.11 | I25: 1925.62 | J25: 3546.471 | K25: =SUM(E25:J25) | L25: 1743.381 | M25: 2764.778 | N25: 2329.6 | O25: 2041.687 | P25: 944.998 | Q25: 1949.435 | R25: =SUM(L25:Q25) | S25: =IF(E25=0,"***",L25/E25) | T25: =IF(F25=0,"***",M25/F25) | U25: =IF(G25=0,"***",N25/G25) | V25: =IF(H25=0,"***",O25/H25) | W25: =IF(I25=0,"***",P25/I25) | X25: =IF(J25=0,"***",Q25/J25) | Y25: =IF(K25=0,"***",R25/K25)
C26: 浜田水産部合計 | E26: =SUM(E22:E25) | F26: =SUM(F22:F25) | G26: =SUM(G22:G25) | H26: =SUM(H22:H25) | I26: =SUM(I22:I25) | J26: =SUM(J22:J25) | K26: =SUM(E26:J26) | L26: =SUM(L22:L25) | M26: =SUM(M22:M25) | N26: =SUM(N22:N25) | O26: =SUM(O22:O25) | P26: =SUM(P22:P25) | Q26: =SUM(Q22:Q25) | R26: =SUM(L26:Q26) | S26: =IF(E26=0,"***",L26/E26) | T26: =IF(F26=0,"***",M26/F26) | U26: =IF(G26=0,"***",N26/G26) | V26: =IF(H26=0,"***",O26/H26) | W26: =IF(I26=0,"***",P26/I26) | X26: =IF(J26=0,"***",Q26/J26) | Y26: =IF(K26=0,"***",R26/K26)
C27: 0102 集計 | D27: JF大田 | E27: 5532.763 | F27: 6604.035 | G27: 7174.526 | H27: 5086.631 | I27: 5913.498 | J27: 12536.989 | K27: =SUM(E27:J27) | L27: 1289.446 | M27: 1627.409 | N27: 1407.741 | O27: 950.385 | P27: 1282.931 | Q27: 2609.847 | R27: =SUM(L27:Q27) | S27: =IF(E27=0,"***",L27/E27) | T27: =IF(F27=0,"***",M27/F27) | U27: =IF(G27=0,"***",N27/G27) | V27: =IF(H27=0,"***",O27/H27) | W27: =IF(I27=0,"***",P27/I27) | X27: =IF(J27=0,"***",Q27/J27) | Y27: =IF(K27=0,"***",R27/K27)
C28: 0104 集計 | D28: 大田荷役 | E28: 2776.405 | F28: 3884.685 | G28: 4124.21 | H28: 2676.2 | I28: 1446.795 | J28: 4570.595 | K28: =SUM(E28:J28) | L28: 1708.154 | M28: 2438.683 | N28: 3607.46 | O28: 2209.2 | P28: 1173.045 | Q28: 3099.141 | R28: =SUM(L28:Q28) | S28: =IF(E28=0,"***",L28/E28) | T28: =IF(F28=0,"***",M28/F28) | U28: =IF(G28=0,"***",N28/G28) | V28: =IF(H28=0,"***",O28/H28) | W28: =IF(I28=0,"***",P28/I28) | X28: =IF(J28=0,"***",Q28/J28) | Y28: =IF(K28=0,"***",R28/K28)
C29: 大田水産部 | E29: =SUM(E27:E28) | F29: =SUM(F27:F28) | G29: =SUM(G27:G28) | H29: =SUM(H27:H28) | I29: =SUM(I27:I28) | J29: =SUM(J27:J28) | K29: =SUM(K27:K28) | L29: =SUM(L27:L28) | ... R29: =SUM(R27:R28) | S29: =IF(E29=0,"***",L29/E29) | T29: =IF(F29=0,"***",M29/F29) | U29: =IF(G29=0,"***",N29/G29) | V29: =IF(H29=0,"***",O29/H29) | W29: =IF(I29=0,"***",P29/I29) | X29: =IF(J29=0,"***",Q29/J29) | Y29: =IF(K29=0,"***",R29/K29)
C30: 0031 集計 | D30: JF境 | E30: 13161.188 | F30: 22618.704 | G30: 20298.313 | H30: 13511.618 | I30: 10177.025 | J30: 10696.536 | K30: =SUM(E30:J30) | L30: 3307.326 | M30: 5138.178 | N30: 4393.382 | O30: 2843.846 | P30: 2115.652 | Q30: 2187.245 | R30: =SUM(L30:Q30) | S30: =IF(E30=0,"***",L30/E30) | T30: =IF(F30=0,"***",M30/F30) | U30: =IF(G30=0,"***",N30/G30) | V30: =IF(H30=0,"***",O30/H30) | W30: =IF(I30=0,"***",P30/I30) | X30: =IF(J30=0,"***",Q30/J30) | Y30: =IF(K30=0,"***",R30/K30)
C31: 0038 集計 | D31: 境その他 | E31: 2.95 | F31: 0 | G31: 0 | H31: 16.815 | I31: 17.68 | J31: 14.48 | K31: =SUM(E31:J31) | L31: 0.909 | M31: 0 | N31: 0 | O31: 5.181 | P31: 4.536 | Q31: 1.946 | R31: =SUM(L31:Q31) | S31: =IF(E31=0,"***",L31/E31) | T31: =IF(F31=0,"***",M31/F31) | U31: =IF(G31=0,"***",N31/G31) | V31: =IF(H31=0,"***",O31/H31) | W31: =IF(I31=0,"***",P31/I31) | X31: =IF(J31=0,"***",Q31/J31) | Y31: =IF(K31=0,"***",R31/K31)
C32: 境港水産部合計 | E32: =E30+E31 | F32: =F30+F31 | G32: =G30+G31 | H32: =H30+H31 | I32: =I30+I31 | J32: =J30+J31 | K32: =SUM(E32:J32) | L32: =L30+L31 | M32: =M30+M31 | N32: =N30+N31 | O32: =O30+O31 | P32: =P30+P31 | Q32: =Q30+Q31 | R32: =SUM(L32:Q32) | S32: =IF(E32=0,"***",L32/E32) | T32: =IF(F32=0,"***",M32/F32) | U32: =IF(G32=0,"***",N32/G32) | V32: =IF(H32=0,"***",O32/H32) | W32: =IF(I32=0,"***",P32/I32) | X32: =IF(J32=0,"***",Q32/J32) | Y32: =IF(K32=0,"***",R32/K32)
C33: 合計 | E33: =E26+E29+E32 | F33: =F26+F29+F32 | G33: =G26+G29+G32 | H33: =H26+H29+H32 | I33: =I26+I29+I32 | J33: =J26+J29+J32 | K33: =K26+K29+K32 | L33: =L26+L29+L32 | ... R33: =R26+R29+R32 | S33: =IF(E33=0,"***",L33/E33) | T33: =IF(F33=0,"***",M33/F33) | U33: =IF(G33=0,"***",N33/G33) | V33: =IF(H33=0,"***",O33/H33) | W33: =IF(I33=0,"***",P33/I33) | X33: =IF(J33=0,"***",Q33/J33) | Y33: =IF(K33=0,"***",R33/K33)
C34: 【参考】大海分 | E34: 2808 | F34: 8671.294 | G34: 3956 | K34: =SUM(E34:J34) | L34: 1068 | M34: 3581.357 | N34: 1431 | R34: =SUM(L34:Q34) | S34: =IF(E34=0,"***",L34/E34) | T34: =IF(F34=0,"***",M34/F34) | U34: =IF(G34=0,"***",N34/G34) | V34: =IF(H34=0,"***",O34/H34) | W34: =IF(I34=0,"***",P34/I34) | X34: =IF(J34=0,"***",Q34/J34) | Y34: =IF(K34=0,"***",R34/K34)
C36: 3．過年度平均
E37: 売上 | L37: 粗利益 | S37: 粗利益率
E38: 45748 | F38: 45778 | G38: 45809 | H38: 45839 | I38: 45870 | J38: 45901 | K38: 合計 | L38: 45748 | M38: 45778 | N38: 45809 | O38: 45839 | P38: 45870 | Q38: 45901 | R38: 合計 | S38: 45748 | T38: 45778 | U38: 45809 | V38: 45839 | W38: 45870 | X38: 45901 | Y38: 合計
C39: 0010 集計 | D39: JF | E39: =(E22+E5)/2 | F39: =(F22+F5)/2 | G39: =(G22+G5)/2 | H39: =(H22+H5)/2 | I39: =(I22+I5)/2 | J39: =(J22+J5)/2 | K39: =SUM(E39:J39) | L39: =(L22+L5)/2 | M39: =(M22+M5)/2 | N39: =(N22+N5)/2 | O39: =(O22+O5)/2 | P39: =(P22+P5)/2 | Q39: =(Q22+Q5)/2 | R39: =SUM(L39:Q39) | S39: =IF(E39=0,"***",L39/E39) | T39: =IF(F39=0,"***",M39/F39) | U39: =IF(G39=0,"***",N39/G39) | V39: =IF(H39=0,"***",O39/H39) | W39: =IF(I39=0,"***",P39/I39) | X39: =IF(J39=0,"***",Q39/J39) | Y39: =IF(K39=0,"***",R39/K39)
C40: 0017 集計 | D40: 鮮魚 | E40: =(E23+E6)/2 | F40: =(F23+F6)/2 | G40: =(G23+G6)/2 | H40: =(H23+H6)/2 | I40: =(I23+I6)/2 | J40: =(J23+J6)/2 | K40: =SUM(E40:J40) | L40: =(L23+L6)/2 | M40: =(M23+M6)/2 | N40: =(N23+N6)/2 | O40: =(O23+O6)/2 | P40: =(P23+P6)/2 | Q40: =(Q23+Q6)/2 | R40: =SUM(L40:Q40) | S40: =IF(E40=0,"***",L40/E40) | T40: =IF(F40=0,"***",M40/F40) | U40: =IF(G40=0,"***",N40/G40) | V40: =IF(H40=0,"***",O40/H40) | W40: =IF(I40=0,"***",P40/I40) | X40: =IF(J40=0,"***",Q40/J40) | Y40: =IF(K40=0,"***",R40/K40)
C41: 0101 集計 | D41: GS | E41: =(E24+E7)/2 | F41: =(F24+F7)/2 | G41: =(G24+G7)/2 | H41: =(H24+H7)/2 | I41: =(I24+I7)/2 | J41: =(J24+J7)/2 | K41: =SUM(E41:J41) | L41: =(L24+L7)/2 | M41: =(M24+M7)/2 | N41: =(N24+N7)/2 | O41: =(O24+O7)/2 | P41: =(P24+P7)/2 | Q41: =(Q24+Q7)/2 | R41: =SUM(L41:Q41) | S41: =IF(E41=0,"***",L41/E41) | T41: =IF(F41=0,"***",M41/F41) | U41: =IF(G41=0,"***",N41/G41) | V41: =IF(H41=0,"***",O41/H41) | W41: =IF(I41=0,"***",P41/I41) | X41: =IF(J41=0,"***",Q41/J41) | Y41: =IF(K41=0,"***",R41/K41)
C42: 0106 集計 | D42: 浜田荷役 | E42: =(E25+E8)/2 | F42: =(F25+F8)/2 | G42: =(G25+G8)/2 | H42: =(H25+H8)/2 | I42: =(I25+I8)/2 | J42: =(J25+J8)/2 | K42: =SUM(E42:J42) | L42: =(L25+L8)/2 | M42: =(M25+M8)/2 | N42: =(N25+N8)/2 | O42: =(O25+O8)/2 | P42: =(P25+P8)/2 | Q42: =(Q25+Q8)/2 | R42: =SUM(L42:Q42) | S42: =IF(E42=0,"***",L42/E42) | T42: =IF(F42=0,"***",M42/F42) | U42: =IF(G42=0,"***",N42/G42) | V42: =IF(H42=0,"***",O42/H42) | W42: =IF(I42=0,"***",P42/I42) | X42: =IF(J42=0,"***",Q42/J42) | Y42: =IF(K42=0,"***",R42/K42)
...

Sheet 総括
D1: 水産部第50期下期予算について
G7: 2024年4～9月 | J7: 2025年4～9月 | M7: 過年度平均 | P7: 計画 | U7: 根拠
G8: 売上 | H8: 粗利益 | I8: 粗利益率 | J8: 売上 | K8: 粗利益 | L8: 粗利益率 | M8: 売上 | N8: 粗利益 | O8: 粗利益率 | P8: 売上 | Q8: 粗利益 | R8: 粗利益率 | S8: 年率 | T8: 粗利益年率
D9: 水産部 | G9: =G13+G17+G21 | H9: =H13+H17+H21 | I9: =H9/G9 | J9: =J13+J17+J21 | K9: =K13+K17+K21 | L9: =K9/J9 | M9: =(G9+J9)/2 | N9: =(H9+K9)/2 | O9: =N9/M9 | P9: =P13+P17+P21 | Q9: =Q13+Q17+Q21 | R9: =Q9/P9 | S9: =P9/J9-1 | T9: =Q9/K9-1
F10: 包装資材 | G10: =G9-G11-G12 | H10: =H9-H11-H12 | I10: =H10/G10 | J10: =J9-J11-J12 | K10: =K9-K11-K12 | L10: =K10/J10 | M10: =(G10+J10)/2 | N10: =(H10+K10)/2 | O10: =N10/M10 | P10: =P9-P12-P11 | Q10: =Q9-Q12-Q11 | R10: =Q10/P10 | S10: =P10/J10-1 | T10: =Q10/K10-1
F11: 荷役 | G11: =G15+G19 | H11: =H15+H19 | I11: =H11/G11 | J11: =J15+J19 | K11: =K15+K19 | L11: =K11/J11 | M11: =(G11+J11)/2 | N11: =(H11+K11)/2 | O11: =N11/M11 | P11: =P15+P19 | Q11: =Q15+Q19 | R11: =Q11/P11 | S11: =P11/J11-1 | T11: =Q11/K11-1
F12: 機械 | G12: =G16+G20+G23 | H12: =H16+H20+H23 | I12: =H12/G12 | J12: =J16+J20+J23 | K12: =K16+K20+K23 | L12: =K12/J12 | M12: =(G12+J12)/2 | N12: =(H12+K12)/2 | O12: =N12/M12 | P12: =P16+P20+P23 | Q12: =Q16+Q20+Q23 | R12: =Q12/P12 | S12: =P12/J12-1 | T12: =Q12/K12-1
E13: 浜田 | G13: 66081.909 | H13: 23129.888 | I13: =H13/G13 | J13: 67697.195 | K13: 25007.513 | L13: =K13/J13 | M13: =(G13+J13)/2 | N13: =(H13+K13)/2 | O13: =N13/M13 | P13: =P14+P16+P15 | Q13: =Q14+Q16+Q15 | R13: =Q13/P13 | S13: =P13/J13-1 | T13: =Q13/K13-1
F14: 包装資材 | G14: =G13-G15-G16 | H14: =H13-H15-H16 | I14: =H14/G14 | J14: =J13-J15-J16 | K14: =K13-K15-K16 | L14: =K14/J14 | M14: =(G14+J14)/2 | N14: =(H14+K14)/2 | O14: =N14/M14 | P14: 57140 | Q14: 16130 | R14: =Q14/P14 | S14: =P14/J14-1 | T14: =Q14/K14-1 | U14: 生産者向け売価15％増で売上8％増加、粗利益率2％改善、福宝▲800/月
F15: 荷役 | G15: 26163.236 | H15: 13947.506 | I15: =H15/G15 | J15: 21753.83 | K15: 11773.879 | L15: =K15/J15 | M15: =(G15+J15)/2 | N15: =(H15+K15)/2 | O15: =N15/M15 | P15: 23290 | Q15: 11480 | R15: =Q15/P15 | S15: =P15/J15-1 | T15: =Q15/K15-1
F16: 機械 | G16: 2131.8 | H16: 428.4 | I16: =H16/G16 | J16: 126 | K16: 43 | L16: =K16/J16 | M16: =(G16+J16)/2 | N16: =(H16+K16)/2 | O16: =N16/M16 | P16: 300 | Q16: 60 | R16: =Q16/P16 | S16: =P16/J16-1 | T16: =Q16/K16-1 | U16: ベルトコンベヤーのメンテナンス料と部品代
E17: 大田 | G17: 55752.068 | H17: 18201.506 | I17: =H17/G17 | J17: 62327.332 | K17: 23403.442 | L17: =K17/J17 | M17: =(G17+J17)/2 | N17: =(H17+K17)/2 | O17: =N17/M17 | P17: =P18+P19+P20 | Q17: =Q18+Q19+Q20 | R17: =Q17/P17 | S17: =P17/J17-1 | T17: =Q17/K17-1
F18: 包装資材 | G18: =G17-G19-G20 | H18: =H17-H19-H20 | I18: =H18/G18 | J18: =J17-J19-J20 | K18: =K17-K19-K20 | L18: =K18/J18 | M18: =(G18+J18)/2 | N18: =(H18+K18)/2 | O18: =N18/M18 | P18: 41600 | Q18: 8160 | R18: =Q18/P18 | S18: =P18/J18-1 | T18: =Q18/K18-1 | U18: 生産者向け売価15％増で売上8％増加、粗利益率2％改善
F19: 荷役 | G19: 17142.015 | H19: 11018.936 | I19: =H19/G19 | J19: 19478.89 | K19: 14235.683 | L19: =K19/J19 | M19: =(G19+J19)/2 | N19: =(H19+K19)/2 | O19: =N19/M19 | P19: 23650 | Q19: 15870 | R19: =Q19/P19 | S19: =P19/J19-1 | T19: =Q19/K19-1
F20: 機械 | G20: 0 | H20: 0 | I20: =H20/G20 | J20: 0 | K20: 0 | L20: =K20/J20 | M20: =(G20+J20)/2 | N20: =(H20+K20)/2 | O20: =N20/M20 | P20: 0 | Q20: 0 | R20: =Q20/P20 | S20: =P20/J20-1 | T20: =Q20/K20-1
E21: 境港 | G21: 85107.944 | H21: 13146.669 | I21: =H21/G21 | J21: 90515.309 | K21: 19998.201 | L21: =K21/J21 | M21: =(G21+J21)/2 | N21: =(H21+K21)/2 | O21: =N21/M21 | P21: =P22+P23 | Q21: =Q22+Q23 | R21: =Q21/P21 | S21: =P21/J21-1 | T21: =Q21/K21-1
F22: 包装資材 | G22: =G21-G23 | H22: =H21-H23 | I22: =H22/G22 | J22: =J21-J23 | K22: =K21-K23 | L22: =K22/J22 | M22: =(G22+J22)/2 | N22: =(H22+K22)/2 | O22: =N22/M22 | P22: 93070 | Q22: 20270 | R22: =Q22/P22 | S22: =P22/J22-1 | T22: =Q22/K22-1
F23: 機械 | G23: 325.96 | H23: 40.325 | I23: =H23/G23 | J23: 780.856 | K23: 131 | L23: =K23/J23 | M23: =(G23+J23)/2 | N23: =(H23+K23)/2 | O23: =N23/M23 | P23: 0 | Q23: 0 | R23: =Q23/P23 | S23: =P23/J23-1 | T23: =Q23/K23-1
