Workbook

Sheet 包装資材
C1: 下関営業所包装資材
C2: 1．2024年
E3: 売上 | L3: 粗利益 | S3: 粗利益率
E4: 45383 | F4: 45413 | G4: 45444 | H4: 45474 | I4: 45505 | J4: 45536 | K4: 合計 | L4: 45383 | M4: 45413 | N4: 45444 | O4: 45474 | P4: 45505 | Q4: 45536 | R4: 合計 | S4: 45017 | T4: 45047 | U4: 45078 | V4: 45108 | W4: 45139 | X4: 45170 | Y4: 合計
C5: 0021 集計 | D5: 高橋所長 | E5: =全体!E5-機械!E5 | F5: =全体!F5-機械!F5 | G5: =全体!G5-機械!G5 | H5: =全体!H5-機械!H5 | I5: =全体!I5-機械!I5 | J5: =全体!J5-機械!J5 | K5: =SUM(E5:J5) | L5: =全体!L5-機械!L5 | M5: =全体!M5-機械!M5 | N5: =全体!N5-機械!N5 | O5: =全体!O5-機械!O5 | P5: =全体!P5-機械!P5 | Q5: =全体!Q5-機械!Q5 | R5: =SUM(L5:Q5) | S5: =IF(E5=0,"***",L5/E5) | T5: =IF(F5=0,"***",M5/F5) | U5: =IF(G5=0,"***",N5/G5) | V5: =IF(H5=0,"***",O5/H5) | W5: =IF(I5=0,"***",P5/I5) | X5: =IF(J5=0,"***",Q5/J5) | Y5: =IF(K5=0,"***",R5/K5)
C6: 0024 集計 | D6: 東野 | E6: =全体!E6-機械!E6 | F6: =全体!F6-機械!F6 | G6: =全体!G6-機械!G6 | H6: =全体!H6-機械!H6 | I6: =全体!I6-機械!I6 | J6: =全体!J6-機械!J6 | K6: =SUM(E6:J6) | L6: =全体!L6-機械!L6 | M6: =全体!M6-機械!M6 | N6: =全体!N6-機械!N6 | O6: =全体!O6-機械!O6 | P6: =全体!P6-機械!P6 | Q6: =全体!Q6-機械!Q6 | R6: =SUM(L6:Q6) | S6: =IF(E6=0,"***",L6/E6) | T6: =IF(F6=0,"***",M6/F6) | U6: =IF(G6=0,"***",N6/G6) | V6: =IF(H6=0,"***",O6/H6) | W6: =IF(I6=0,"***",P6/I6) | X6: =IF(J6=0,"***",Q6/J6) | Y6: =IF(K6=0,"***",R6/K6)
C7: 0025 集計 | D7: 橋本課長 | E7: =全体!E7-機械!E7 | F7: =全体!F7-機械!F7 | G7: =全体!G7-機械!G7 | H7: =全体!H7-機械!H7 | I7: =全体!I7-機械!I7 | J7: =全体!J7-機械!J7 | K7: =SUM(E7:J7) | L7: =全体!L7-機械!L7 | M7: =全体!M7-機械!M7 | N7: =全体!N7-機械!N7 | O7: =全体!O7-機械!O7 | P7: =全体!P7-機械!P7 | Q7: =全体!Q7-機械!Q7 | R7: =SUM(L7:Q7) | S7: =IF(E7=0,"***",L7/E7) | T7: =IF(F7=0,"***",M7/F7) | U7: =IF(G7=0,"***",N7/G7) | V7: =IF(H7=0,"***",O7/H7) | W7: =IF(I7=0,"***",P7/I7) | X7: =IF(J7=0,"***",Q7/J7) | Y7: =IF(K7=0,"***",R7/K7)
C8: 0026 集計 | D8: 井上課長 | E8: =全体!E8-機械!E8 | F8: =全体!F8-機械!F8 | G8: =全体!G8-機械!G8 | H8: =全体!H8-機械!H8 | I8: =全体!I8-機械!I8 | J8: =全体!J8-機械!J8 | K8: =SUM(E8:J8) | L8: =全体!L8-機械!L8 | M8: =全体!M8-機械!M8 | N8: =全体!N8-機械!N8 | O8: =全体!O8-機械!O8 | P8: =全体!P8-機械!P8 | Q8: =全体!Q8-機械!Q8 | R8: =SUM(L8:Q8) | S8: =IF(E8=0,"***",L8/E8) | T8: =IF(F8=0,"***",M8/F8) | U8: =IF(G8=0,"***",N8/G8) | V8: =IF(H8=0,"***",O8/H8) | W8: =IF(I8=0,"***",P8/I8) | X8: =IF(J8=0,"***",Q8/J8) | Y8: =IF(K8=0,"***",R8/K8)
C9: 0027 集計 | D9: 中国 | E9: =全体!E9-機械!E9 | F9: =全体!F9-機械!F9 | G9: =全体!G9-機械!G9 | H9: =全体!H9-機械!H9 | I9: =全体!I9-機械!I9 | J9: =全体!J9-機械!J9 | K9: =SUM(E9:J9) | L9: =全体!L9-機械!L9 | M9: =全体!M9-機械!M9 | N9: =全体!N9-機械!N9 | O9: =全体!O9-機械!O9 | P9: =全体!P9-機械!P9 | Q9: =全体!Q9-機械!Q9 | R9: =SUM(L9:Q9) | S9: =IF(E9=0,"***",L9/E9) | T9: =IF(F9=0,"***",M9/F9) | U9: =IF(G9=0,"***",N9/G9) | V9: =IF(H9=0,"***",O9/H9) | W9: =IF(I9=0,"***",P9/I9) | X9: =IF(J9=0,"***",Q9/J9) | Y9: =IF(K9=0,"***",R9/K9)
C10: 0028 集計 | D10: 自治体
C11: 0029 集計 | D11: その他 | E11: =全体!E11-機械!E11 | F11: =全体!F11-機械!F11 | G11: =全体!G11-機械!G11 | H11: =全体!H11-機械!H11 | I11: =全体!I11-機械!I11 | J11: =全体!J11-機械!J11 | K11: =SUM(E11:J11) | L11: =全体!L11-機械!L11 | M11: =全体!M11-機械!M11 | N11: =全体!N11-機械!N11 | O11: =全体!O11-機械!O11 | P11: =全体!P11-機械!P11 | Q11: =全体!Q11-機械!Q11 | R11: =SUM(L11:Q11) | S11: =IF(E11=0,"***",L11/E11) | T11: =IF(F11=0,"***",M11/F11) | U11: =IF(G11=0,"***",N11/G11) | V11: =IF(H11=0,"***",O11/H11) | W11: =IF(I11=0,"***",P11/I11) | X11: =IF(J11=0,"***",Q11/J11) | Y11: =IF(K11=0,"***",R11/K11)
C12: 合計 | E12: =SUM(E5:E11) | F12: =SUM(F5:F11) | G12: =SUM(G5:G11) | H12: =SUM(H5:H11) | I12: =SUM(I5:I11) | J12: =SUM(J5:J11) | K12: =SUM(E12:J12) | L12: =SUM(L5:L11) | M12: =SUM(M5:M11) | N12: =SUM(N5:N11) | O12: =SUM(O5:O11) | P12: =SUM(P5:P11) | Q12: =SUM(Q5:Q11) | R12: =SUM(L12:Q12) | S12: =IF(E12=0,"***",L12/E12) | T12: =IF(F12=0,"***",M12/F12) | U12: =IF(G12=0,"***",N12/G12) | V12: =IF(H12=0,"***",O12/H12) | W12: =IF(I12=0,"***",P12/I12) | X12: =IF(J12=0,"***",Q12/J12) | Y12: =IF(K12=0,"***",R12/K12)
C14: 2．2025年
E15: 売上 | L15: 粗利益 | S15: 粗利益率
E16: 45748 | F16: 45778 | G16: 45809 | H16: 45839 | I16: 45870 | J16: 45901 | K16: 合計 | L16: 45748 | M16: 45778 | N16: 45809 | O16: 45839 | P16: 45870 | Q16: 45901 | R16: 合計 | S16: 45748 | T16: 45778 | U16: 45809 | V16: 45839 | W16: 45870 | X16: 45901 | Y16: 合計
C17: 0021 集計 | D17: 高橋所長 | E17: =全体!E17-機械!E17 | F17: =全体!F17-機械!F17 | G17: =全体!G17-機械!G17 | H17: =全体!H17-機械!H17 | I17: =全体!I17-機械!I17 | J17: =全体!J17-機械!J17 | K17: =SUM(E17:J17) | L17: =全体!L17-機械!L17 | M17: =全体!M17-機械!M17 | N17: =全体!N17-機械!N17 | O17: =全体!O17-機械!O17 | P17: =全体!P17-機械!P17 | Q17: =全体!Q17-機械!Q17 | R17: =SUM(L17:Q17) | S17: =IF(E17=0,"***",L17/E17) | T17: =IF(F17=0,"***",M17/F17) | U17: =IF(G17=0,"***",N17/G17) | V17: =IF(H17=0,"***",O17/H17) | W17: =IF(I17=0,"***",P17/I17) | X17: =IF(J17=0,"***",Q17/J17) | Y17: =IF(K17=0,"***",R17/K17)
C18: 0024 集計 | D18: 東野 | E18: =全体!E18-機械!E18 | F18: =全体!F18-機械!F18 | G18: =全体!G18-機械!G18 | H18: =全体!H18-機械!H18 | I18: =全体!I18-機械!I18 | J18: =全体!J18-機械!J18 | K18: =SUM(E18:J18) | L18: =全体!L18-機械!L18 | M18: =全体!M18-機械!M18 | N18: =全体!N18-機械!N18 | O18: =全体!O18-機械!O18 | P18: =全体!P18-機械!P18 | Q18: =全体!Q18-機械!Q18 | R18: =SUM(L18:Q18) | S18: =IF(E18=0,"***",L18/E18) | T18: =IF(F18=0,"***",M18/F18) | U18: =IF(G18=0,"***",N18/G18) | V18: =IF(H18=0,"***",O18/H18) | W18: =IF(I18=0,"***",P18/I18) | X18: =IF(J18=0,"***",Q18/J18) | Y18: =IF(K18=0,"***",R18/K18)
C19: 0025 集計 | D19: 橋本課長 | E19: =全体!E19-機械!E19 | F19: =全体!F19-機械!F19 | G19: =全体!G19-機械!G19 | H19: =全体!H19-機械!H19 | I19: =全体!I19-機械!I19 | J19: =全体!J19-機械!J19 | K19: =SUM(E19:J19) | L19: =全体!L19-機械!L19 | M19: =全体!M19-機械!M19 | N19: =全体!N19-機械!N19 | O19: =全体!O19-機械!O19 | P19: =全体!P19-機械!P19 | Q19: =全体!Q19-機械!Q19 | R19: =SUM(L19:Q19) | S19: =IF(E19=0,"***",L19/E19) | T19: =IF(F19=0,"***",M19/F19) | U19: =IF(G19=0,"***",N19/G19) | V19: =IF(H19=0,"***",O19/H19) | W19: =IF(I19=0,"***",P19/I19) | X19: =IF(J19=0,"***",Q19/J19) | Y19: =IF(K19=0,"***",R19/K19)
C20: 0026 集計 | D20: 井上課長 | E20: =全体!E20-機械!E20 | F20: =全体!F20-機械!F20 | G20: =全体!G20-機械!G20 | H20: =全体!H20-機械!H20 | I20: =全体!I20-機械!I20 | J20: =全体!J20-機械!J20 | K20: =SUM(E20:J20) | L20: =全体!L20-機械!L20 | M20: =全体!M20-機械!M20 | N20: =全体!N20-機械!N20 | O20: =全体!O20-機械!O20 | P20: =全体!P20-機械!P20 | Q20: =全体!Q20-機械!Q20 | R20: =SUM(L20:Q20) | S20: =IF(E20=0,"***",L20/E20) | T20: =IF(F20=0,"***",M20/F20) | U20: =IF(G20=0,"***",N20/G20) | V20: =IF(H20=0,"***",O20/H20) | W20: =IF(I20=0,"***",P20/I20) | X20: =IF(J20=0,"***",Q20/J20) | Y20: =IF(K20=0,"***",R20/K20)
C21: 0027 集計 | D21: 中国 | E21: =全体!E21-機械!E21 | F21: =全体!F21-機械!F21 | G21: =全体!G21-機械!G21 | H21: =全体!H21-機械!H21 | I21: =全体!I21-機械!I21 | J21: =全体!J21-機械!J21 | K21: =SUM(E21:J21) | L21: =全体!L21-機械!L21 | M21: =全体!M21-機械!M21 | N21: =全体!N21-機械!N21 | O21: =全体!O21-機械!O21 | P21: =全体!P21-機械!P21 | Q21: =全体!Q21-機械!Q21 | R21: =SUM(L21:Q21) | S21: =IF(E21=0,"***",L21/E21) | T21: =IF(F21=0,"***",M21/F21) | U21: =IF(G21=0,"***",N21/G21) | V21: =IF(H21=0,"***",O21/H21) | W21: =IF(I21=0,"***",P21/I21) | X21: =IF(J21=0,"***",Q21/J21) | Y21: =IF(K21=0,"***",R21/K21)
C22: 0028 集計 | D22: 自治体
C23: 0029 集計 | D23: その他 | E23: =全体!E23-機械!E23 | F23: =全体!F23-機械!F23 | G23: =全体!G23-機械!G23 | H23: =全体!H23-機械!H23 | I23: =全体!I23-機械!I23 | J23: =全体!J23-機械!J23 | K23: =SUM(E23:J23) | L23: =全体!L23-機械!L23 | M23: =全体!M23-機械!M23 | N23: =全体!N23-機械!N23 | O23: =全体!O23-機械!O23 | P23: =全体!P23-機械!P23 | Q23: =全体!Q23-機械!Q23 | R23: =SUM(L23:Q23) | S23: =IF(E23=0,"***",L23/E23) | T23: =IF(F23=0,"***",M23/F23) | U23: =IF(G23=0,"***",N23/G23) | V23: =IF(H23=0,"***",O23/H23) | W23: =IF(I23=0,"***",P23/I23) | X23: =IF(J23=0,"***",Q23/J23) | Y23: =IF(K23=0,"***",R23/K23)
C24: 合計 | E24: =SUM(E17:E23) | F24: =SUM(F17:F23) | G24: =SUM(G17:G23) | H24: =SUM(H17:H23) | I24: =SUM(I17:I23) | J24: =SUM(J17:J23) | K24: =SUM(E24:J24) | L24: =SUM(L17:L23) | M24: =SUM(M17:M23) | N24: =SUM(N17:N23) | O24: =SUM(O17:O23) | P24: =SUM(P17:P23) | Q24: =SUM(Q17:Q23) | R24: =SUM(L24:Q24) | S24: =IF(E24=0,"***",L24/E24) | T24: =IF(F24=0,"***",M24/F24) | U24: =IF(G24=0,"***",N24/G24) | V24: =IF(H24=0,"***",O24/H24) | W24: =IF(I24=0,"***",P24/I24) | X24: =IF(J24=0,"***",Q24/J24) | Y24: =IF(K24=0,"***",R24/K24)
C26: 3．過年度平均
E27: 売上 | L27: 粗利益 | S27: 粗利益率
E28: 45748 | F28: 45778 | G28: 45809 | H28: 45839 | I28: 45870 | J28: 45901 | K28: 合計 | L28: 45748 | M28: 45778 | N28: 45809 | O28: 45839 | P28: 45870 | Q28: 45901 | R28: 合計 | S28: 45748 | T28: 45778 | U28: 45809 | V28: 45839 | W28: 45870 | X28: 45901 | Y28: 合計
C29: 0021 集計 | D29: 高橋所長 | E29: =(E17+E5)/2 | F29: =(F17+F5)/2 | G29: =(G17+G5)/2 | H29: =(H17+H5)/2 | I29: =(I17+I5)/2 | J29: =(J17+J5)/2 | K29: =SUM(E29:J29) | L29: =(L17+L5)/2 | M29: =(M17+M5)/2 | N29: =(N17+N5)/2 | O29: =(O17+O5)/2 | P29: =(P17+P5)/2 | Q29: =(Q17+Q5)/2 | R29: =SUM(L29:Q29) | S29: =IF(E29=0,"***",L29/E29) | T29: =IF(F29=0,"***",M29/F29) | U29: =IF(G29=0,"***",N29/G29) | V29: =IF(H29=0,"***",O29/H29) | W29: =IF(I29=0,"***",P29/I29) | X29: =IF(J29=0,"***",Q29/J29) | Y29: =IF(K29=0,"***",R29/K29)
C30: 0024 集計 | D30: 東野 | E30: =(E18+E6)/2 | F30: =(F18+F6)/2 | G30: =(G18+G6)/2 | H30: =(H18+H6)/2 | I30: =(I18+I6)/2 | J30: =(J18+J6)/2 | K30: =SUM(E30:J30) | L30: =(L18+L6)/2 | M30: =(M18+M6)/2 | N30: =(N18+N6)/2 | O30: =(O18+O6)/2 | P30: =(P18+P6)/2 | Q30: =(Q18+Q6)/2 | R30: =SUM(L30:Q30) | S30: =IF(E30=0,"***",L30/E30) | T30: =IF(F30=0,"***",M30/F30) | U30: =IF(G30=0,"***",N30/G30) | V30: =IF(H30=0,"***",O30/H30) | W30: =IF(I30=0,"***",P30/I30) | X30: =IF(J30=0,"***",Q30/J30) | Y30: =IF(K30=0,"***",R30/K30)
C31: 0025 集計 | D31: 橋本課長 | E31: =(E19+E7)/2 | F31: =(F19+F7)/2 | G31: =(G19+G7)/2 | H31: =(H19+H7)/2 | I31: =(I19+I7)/2 | J31: =(J19+J7)/2 | K31: =SUM(E31:J31) | L31: =(L19+L7)/2 | M31: =(M19+M7)/2 | N31: =(N19+N7)/2 | O31: =(O19+O7)/2 | P31: =(P19+P7)/2 | Q31: =(Q19+Q7)/2 | R31: =SUM(L31:Q31) | S31: =IF(E31=0,"***",L31/E31) | T31: =IF(F31=0,"***",M31/F31) | U31: =IF(G31=0,"***",N31/G31) | V31: =IF(H31=0,"***",O31/H31) | W31: =IF(I31=0,"***",P31/I31) | X31: =IF(J31=0,"***",Q31/J31) | Y31: =IF(K31=0,"***",R31/K31)
C32: 0026 集計 | D32: 井上課長 | E32: =(E20+E8)/2 | F32: =(F20+F8)/2 | G32: =(G20+G8)/2 | H32: =(H20+H8)/2 | I32: =(I20+I8)/2 | J32: =(J20+J8)/2 | K32: =SUM(E32:J32) | L32: =(L20+L8)/2 | M32: =(M20+M8)/2 | N32: =(N20+N8)/2 | O32: =(O20+O8)/2 | P32: =(P20+P8)/2 | Q32: =(Q20+Q8)/2 | R32: =SUM(L32:Q32) | S32: =IF(E32=0,"***",L32/E32) | T32: =IF(F32=0,"***",M32/F32) | U32: =IF(G32=0,"***",N32/G32) | V32: =IF(H32=0,"***",O32/H32) | W32: =IF(I32=0,"***",P32/I32) | X32: =IF(J32=0,"***",Q32/J32) | Y32: =IF(K32=0,"***",R32/K32)
C33: 0027 集計 | D33: 中国 | E33: =(E21+E9)/2 | F33: =(F21+F9)/2 | G33: =(G21+G9)/2 | H33: =(H21+H9)/2 | I33: =(I21+I9)/2 | J33: =(J21+J9)/2 | K33: =SUM(E33:J33) | L33: =(L21+L9)/2 | M33: =(M21+M9)/2 | N33: =(N21+N9)/2 | O33: =(O21+O9)/2 | P33: =(P21+P9)/2 | Q33: =(Q21+Q9)/2 | R33: =SUM(L33:Q33) | S33: =IF(E33=0,"***",L33/E33) | T33: =IF(F33=0,"***",M33/F33) | U33: =IF(G33=0,"***",N33/G33) | V33: =IF(H33=0,"***",O33/H33) | W33: =IF(I33=0,"***",P33/I33) | X33: =IF(J33=0,"***",Q33/J33) | Y33: =IF(K33=0,"***",R33/K33)
C34: 0028 集計 | D34: 自治体
C35: 0029 集計 | D35: その他 | E35: =(E23+E11)/2 | F35: =(F23+F11)/2 | G35: =(G23+G11)/2 | H35: =(H23+H11)/2 | I35: =(I23+I11)/2 | J35: =(J23+J11)/2 | K35: =SUM(E35:J35) | L35: =(L23+L11)/2 | M35: =(M23+M11)/2 | N35: =(N23+N11)/2 | O35: =(O23+O11)/2 | P35: =(P23+P11)/2 | Q35: =(Q23+Q11)/2 | R35: =SUM(L35:Q35) | S35: =IF(E35=0,"***",L35/E35) | T35: =IF(F35=0,"***",M35/F35) | U35: =IF(G35=0,"***",N35/G35) | V35: =IF(H35=0,"***",O35/H35) | W35: =IF(I35=0,"***",P35/I35) | X35: =IF(J35=0,"***",Q35/J35) | Y35: =IF(K35=0,"***",R35/K35)
C36: 合計 | E36: =SUM(E29:E35) | F36: =SUM(F29:F35) | G36: =SUM(G29:G35) | H36: =SUM(H29:H35) | I36: =SUM(I29:I35) | J36: =SUM(J29:J35) | K36: =SUM(E36:J36) | L36: =SUM(L29:L35) | M36: =SUM(M29:M35) | N36: =SUM(N29:N35) | O36: =SUM(O29:O35) | P36: =SUM(P29:P35) | Q36: =SUM(Q29:Q35) | R36: =SUM(L36:Q36) | S36: =IF(E36=0,"***",L36/E36) | T36: =IF(F36=0,"***",M36/F36) | U36: =IF(G36=0,"***",N36/G36) | V36: =IF(H36=0,"***",O36/H36) | W36: =IF(I36=0,"***",P36/I36) | X36: =IF(J36=0,"***",Q36/J36) | Y36: =IF(K36=0,"***",R36/K36)
C38: 4．計画
E39: 売上 | L39: 粗利益 | S39: 粗利益率
E40: 46113 | F40: 46143 | G40: 46174 | H40: 46204 | I40: 46235 | J40: 46266 | K40: 合計 | L40: 46113 | M40: 46143 | N40: 46174 | O40: 46204 | P40: 46235 | Q40: 46266 | R40: 合計 | S40: 46113 | T40: 46143 | U40: 46174 | V40: 46204 | W40: 46235 | X40: 46266 | Y40: 合計
C41: 0021 集計 | D41: 高橋所長 | E41: =全体!E41-機械!E41 | F41: =全体!F41-機械!F41 | G41: =全体!G41-機械!G41 | H41: =全体!H41-機械!H41 | I41: =全体!I41-機械!I41 | J41: =全体!J41-機械!J41 | K41: =SUM(E41:J41) | L41: =全体!L41-機械!L41 | M41: =全体!M41-機械!M41 | N41: =全体!N41-機械!N41 | O41: =全体!O41-機械!O41 | P41: =全体!P41-機械!P41 | Q41: =全体!Q41-機械!Q41 | R41: =SUM(L41:Q41) | S41: =IF(E41=0,"***",L41/E41) | T41: =IF(F41=0,"***",M41/F41) | U41: =IF(G41=0,"***",N41/G41) | V41: =IF(H41=0,"***",O41/H41) | W41: =IF(I41=0,"***",P41/I41) | X41: =IF(J41=0,"***",Q41/J41) | Y41: =IF(K41=0,"***",R41/K41)
C42: 0024 集計 | D42: 東野 | E42: =全体!E42-機械!E42 | F42: =全体!F42-機械!F42 | G42: =全体!G42-機械!G42 | H42: =全体!H42-機械!H42 | I42: =全体!I42-機械!I42 | J42: =全体!J42-機械!J42 | K42: =SUM(E42:J42) | L42: =全体!L42-機械!L42 | M42: =全体!M42-機械!M42 | N42: =全体!N42-機械!N42 | O42: =全体!O42-機械!O42 | P42: =全体!P42-機械!P42 | Q42: =全体!Q42-機械!Q42 | R42: =SUM(L42:Q42) | S42: =IF(E42=0,"***",L42/E42) | T42: =IF(F42=0,"***",M42/F42) | U42: =IF(G42=0,"***",N42/G42) | V42: =IF(H42=0,"***",O42/H42) | W42: =IF(I42=0,"***",P42/I42) | X42: =IF(J42=0,"***",Q42/J42) | Y42: =IF(K42=0,"***",R42/K42)
C43: 0025 集計 | D43: 橋本課長 | E43: =全体!E43-機械!E43 | F43: =全体!F43-機械!F43 | G43: =全体!G43-機械!G43 | H43: =全体!H43-機械!H43 | I43: =全体!I43-機械!I43 | J43: =全体!J43-機械!J43 | K43: =SUM(E43:J43) | L43: =全体!L43-機械!L43 | M43: =全体!M43-機械!M43 | N43: =全体!N43-機械!N43 | O43: =全体!O43-機械!O43 | P43: =全体!P43-機械!P43 | Q43: =全体!Q43-機械!Q43 | R43: =SUM(L43:Q43) | S43: =IF(E43=0,"***",L43/E43) | T43: =IF(F43=0,"***",M43/F43) | U43: =IF(G43=0,"***",N43/G43) | V43: =IF(H43=0,"***",O43/H43) | W43: =IF(I43=0,"***",P43/I43) | X43: =IF(J43=0,"***",Q43/J43) | Y43: =IF(K43=0,"***",R43/K43)
...

Sheet 機械
C1: 下関営業所機械
C2: 1．2024年
E3: 売上 | L3: 粗利益 | S3: 粗利益率
E4: 45383 | F4: 45413 | G4: 45444 | H4: 45474 | I4: 45505 | J4: 45536 | K4: 合計 | L4: 45383 | M4: 45413 | N4: 45444 | O4: 45474 | P4: 45505 | Q4: 45536 | R4: 合計 | S4: 45017 | T4: 45047 | U4: 45078 | V4: 45108 | W4: 45139 | X4: 45170 | Y4: 合計
C5: 0021 集計 | D5: 高橋所長 | E5: 114 | F5: 827 | G5: 107 | H5: 107 | I5: 93 | J5: 44 | K5: =SUM(E5:J5) | L5: 17 | M5: 195 | N5: 15 | O5: 15 | P5: 17 | Q5: 22 | R5: =SUM(L5:Q5) | S5: =IF(E5=0,"***",L5/E5) | T5: =IF(F5=0,"***",M5/F5) | U5: =IF(G5=0,"***",N5/G5) | V5: =IF(H5=0,"***",O5/H5) | W5: =IF(I5=0,"***",P5/I5) | X5: =IF(J5=0,"***",Q5/J5) | Y5: =IF(K5=0,"***",R5/K5)
C6: 0024 集計 | D6: 東野 | E6: 225 | F6: 66 | G6: 68 | H6: 94 | I6: 0 | J6: 60 | K6: =SUM(E6:J6) | L6: 42 | M6: 10 | N6: -56 | O6: 6 | P6: 0 | Q6: 12 | R6: =SUM(L6:Q6) | S6: =IF(E6=0,"***",L6/E6) | T6: =IF(F6=0,"***",M6/F6) | U6: =IF(G6=0,"***",N6/G6) | V6: =IF(H6=0,"***",O6/H6) | W6: =IF(I6=0,"***",P6/I6) | X6: =IF(J6=0,"***",Q6/J6) | Y6: =IF(K6=0,"***",R6/K6)
C7: 0025 集計 | D7: 橋本課長 | E7: 60 | F7: 844 | G7: 0 | H7: 0 | I7: 38 | J7: 4 | K7: =SUM(E7:J7) | L7: 12 | M7: 113 | N7: 0 | O7: 0 | P7: 5 | Q7: 1 | R7: =SUM(L7:Q7) | S7: =IF(E7=0,"***",L7/E7) | T7: =IF(F7=0,"***",M7/F7) | U7: =IF(G7=0,"***",N7/G7) | V7: =IF(H7=0,"***",O7/H7) | W7: =IF(I7=0,"***",P7/I7) | X7: =IF(J7=0,"***",Q7/J7) | Y7: =IF(K7=0,"***",R7/K7)
C8: 0026 集計 | D8: 井上課長 | E8: 66 | F8: 67 | G8: 50 | H8: 241 | I8: 42 | J8: 259 | K8: =SUM(E8:J8) | L8: 10 | M8: 16 | N8: 8 | O8: 51 | P8: 6 | Q8: 38 | R8: =SUM(L8:Q8) | S8: =IF(E8=0,"***",L8/E8) | T8: =IF(F8=0,"***",M8/F8) | U8: =IF(G8=0,"***",N8/G8) | V8: =IF(H8=0,"***",O8/H8) | W8: =IF(I8=0,"***",P8/I8) | X8: =IF(J8=0,"***",Q8/J8) | Y8: =IF(K8=0,"***",R8/K8)
C9: 0027 集計 | D9: 中国 | K9: =SUM(E9:J9) | R9: =SUM(L9:Q9) | S9: =IF(E9=0,"***",L9/E9) | T9: =IF(F9=0,"***",M9/F9) | U9: =IF(G9=0,"***",N9/G9) | V9: =IF(H9=0,"***",O9/H9) | W9: =IF(I9=0,"***",P9/I9) | X9: =IF(J9=0,"***",Q9/J9) | Y9: =IF(K9=0,"***",R9/K9)
C10: 0028 集計 | D10: 自治体
C11: 0029 集計 | D11: その他 | K11: =SUM(E11:J11) | R11: =SUM(L11:Q11) | S11: =IF(E11=0,"***",L11/E11) | T11: =IF(F11=0,"***",M11/F11) | U11: =IF(G11=0,"***",N11/G11) | V11: =IF(H11=0,"***",O11/H11) | W11: =IF(I11=0,"***",P11/I11) | X11: =IF(J11=0,"***",Q11/J11) | Y11: =IF(K11=0,"***",R11/K11)
C12: 合計 | E12: =SUM(E5:E11) | F12: =SUM(F5:F11) | G12: =SUM(G5:G11) | H12: =SUM(H5:H11) | I12: =SUM(I5:I11) | J12: =SUM(J5:J11) | K12: =SUM(E12:J12) | L12: =SUM(L5:L11) | M12: =SUM(M5:M11) | N12: =SUM(N5:N11) | O12: =SUM(O5:O11) | P12: =SUM(P5:P11) | Q12: =SUM(Q5:Q11) | R12: =SUM(L12:Q12) | S12: =IF(E12=0,"***",L12/E12) | T12: =IF(F12=0,"***",M12/F12) | U12: =IF(G12=0,"***",N12/G12) | V12: =IF(H12=0,"***",O12/H12) | W12: =IF(I12=0,"***",P12/I12) | X12: =IF(J12=0,"***",Q12/J12) | Y12: =IF(K12=0,"***",R12/K12)
C14: 2．2025年
E15: 売上 | L15: 粗利益 | S15: 粗利益率
E16: 45748 | F16: 45778 | G16: 45809 | H16: 45839 | I16: 45870 | J16: 45901 | K16: 合計 | L16: 45748 | M16: 45778 | N16: 45809 | O16: 45839 | P16: 45870 | Q16: 45901 | R16: 合計 | S16: 45748 | T16: 45778 | U16: 45809 | V16: 45839 | W16: 45870 | X16: 45901 | Y16: 合計
C17: 0021 集計 | D17: 高橋所長 | E17: 88 | F17: 12 | G17: 12 | H17: 284 | I17: 12 | J17: 0 | K17: =SUM(E17:J17) | L17: 16 | M17: 1 | N17: 1 | O17: 49 | P17: 1 | Q17: 0 | R17: =SUM(L17:Q17) | S17: =IF(E17=0,"***",L17/E17) | T17: =IF(F17=0,"***",M17/F17) | U17: =IF(G17=0,"***",N17/G17) | V17: =IF(H17=0,"***",O17/H17) | W17: =IF(I17=0,"***",P17/I17) | X17: =IF(J17=0,"***",Q17/J17) | Y17: =IF(K17=0,"***",R17/K17)
C18: 0024 集計 | D18: 東野 | E18: 103 | F18: 182 | G18: 53 | H18: 119 | I18: 78 | J18: 36 | K18: =SUM(E18:J18) | L18: 23 | M18: 37 | N18: 7 | O18: 108 | P18: 17 | Q18: 4 | R18: =SUM(L18:Q18) | S18: =IF(E18=0,"***",L18/E18) | T18: =IF(F18=0,"***",M18/F18) | U18: =IF(G18=0,"***",N18/G18) | V18: =IF(H18=0,"***",O18/H18) | W18: =IF(I18=0,"***",P18/I18) | X18: =IF(J18=0,"***",Q18/J18) | Y18: =IF(K18=0,"***",R18/K18)
C19: 0025 集計 | D19: 橋本課長 | E19: 1916 | F19: 18 | G19: 54 | H19: 0 | I19: 0 | J19: 108 | K19: =SUM(E19:J19) | L19: 196 | M19: 3 | N19: 5 | O19: 0 | P19: 0 | Q19: 22 | R19: =SUM(L19:Q19) | S19: =IF(E19=0,"***",L19/E19) | T19: =IF(F19=0,"***",M19/F19) | U19: =IF(G19=0,"***",N19/G19) | V19: =IF(H19=0,"***",O19/H19) | W19: =IF(I19=0,"***",P19/I19) | X19: =IF(J19=0,"***",Q19/J19) | Y19: =IF(K19=0,"***",R19/K19)
C20: 0026 集計 | D20: 井上課長 | E20: 538 | F20: 86 | G20: 147 | H20: 116 | I20: 94 | J20: 311 | K20: =SUM(E20:J20) | L20: 55 | M20: 10 | N20: 27 | O20: 15 | P20: 9 | Q20: 17 | R20: =SUM(L20:Q20) | S20: =IF(E20=0,"***",L20/E20) | T20: =IF(F20=0,"***",M20/F20) | U20: =IF(G20=0,"***",N20/G20) | V20: =IF(H20=0,"***",O20/H20) | W20: =IF(I20=0,"***",P20/I20) | X20: =IF(J20=0,"***",Q20/J20) | Y20: =IF(K20=0,"***",R20/K20)
C21: 0027 集計 | D21: 中国 | K21: =SUM(E21:J21) | R21: =SUM(L21:Q21) | S21: =IF(E21=0,"***",L21/E21) | T21: =IF(F21=0,"***",M21/F21) | U21: =IF(G21=0,"***",N21/G21) | V21: =IF(H21=0,"***",O21/H21) | W21: =IF(I21=0,"***",P21/I21) | X21: =IF(J21=0,"***",Q21/J21) | Y21: =IF(K21=0,"***",R21/K21)
C22: 0028 集計 | D22: 自治体 | K22: =SUM(E22:J22) | R22: =SUM(L22:Q22)
C23: 0029 集計 | D23: その他 | K23: =SUM(E23:J23) | R23: =SUM(L23:Q23) | S23: =IF(E23=0,"***",L23/E23) | T23: =IF(F23=0,"***",M23/F23) | U23: =IF(G23=0,"***",N23/G23) | V23: =IF(H23=0,"***",O23/H23) | W23: =IF(I23=0,"***",P23/I23) | X23: =IF(J23=0,"***",Q23/J23) | Y23: =IF(K23=0,"***",R23/K23)
C24: 合計 | E24: =SUM(E17:E23) | F24: =SUM(F17:F23) | G24: =SUM(G17:G23) | H24: =SUM(H17:H23) | I24: =SUM(I17:I23) | J24: =SUM(J17:J23) | K24: =SUM(E24:J24) | L24: =SUM(L17:L23) | M24: =SUM(M17:M23) | N24: =SUM(N17:N23) | O24: =SUM(O17:O23) | P24: =SUM(P17:P23) | Q24: =SUM(Q17:Q23) | R24: =SUM(L24:Q24) | S24: =IF(E24=0,"***",L24/E24) | T24: =IF(F24=0,"***",M24/F24) | U24: =IF(G24=0,"***",N24/G24) | V24: =IF(H24=0,"***",O24/H24) | W24: =IF(I24=0,"***",P24/I24) | X24: =IF(J24=0,"***",Q24/J24) | Y24: =IF(K24=0,"***",R24/K24)
C26: 3．過年度平均
E27: 売上 | L27: 粗利益 | S27: 粗利益率
E28: 45748 | F28: 45778 | G28: 45809 | H28: 45839 | I28: 45870 | J28: 45901 | K28: 合計 | L28: 45748 | M28: 45778 | N28: 45809 | O28: 45839 | P28: 45870 | Q28: 45901 | R28: 合計 | S28: 45748 | T28: 45778 | U28: 45809 | V28: 45839 | W28: 45870 | X28: 45901 | Y28: 合計
C29: 0021 集計 | D29: 高橋所長 | E29: =(E17+E5)/2 | F29: =(F17+F5)/2 | G29: =(G17+G5)/2 | H29: =(H17+H5)/2 | I29: =(I17+I5)/2 | J29: =(J17+J5)/2 | K29: =SUM(E29:J29) | L29: =(L17+L5)/2 | M29: =(M17+M5)/2 | N29: =(N17+N5)/2 | O29: =(O17+O5)/2 | P29: =(P17+P5)/2 | Q29: =(Q17+Q5)/2 | R29: =SUM(L29:Q29) | S29: =IF(E29=0,"***",L29/E29) | T29: =IF(F29=0,"***",M29/F29) | U29: =IF(G29=0,"***",N29/G29) | V29: =IF(H29=0,"***",O29/H29) | W29: =IF(I29=0,"***",P29/I29) | X29: =IF(J29=0,"***",Q29/J29) | Y29: =IF(K29=0,"***",R29/K29)
C30: 0024 集計 | D30: 東野 | E30: =(E18+E6)/2 | F30: =(F18+F6)/2 | G30: =(G18+G6)/2 | H30: =(H18+H6)/2 | I30: =(I18+I6)/2 | J30: =(J18+J6)/2 | K30: =SUM(E30:J30) | L30: =(L18+L6)/2 | M30: =(M18+M6)/2 | N30: =(N18+N6)/2 | O30: =(O18+O6)/2 | P30: =(P18+P6)/2 | Q30: =(Q18+Q6)/2 | R30: =SUM(L30:Q30) | S30: =IF(E30=0,"***",L30/E30) | T30: =IF(F30=0,"***",M30/F30) | U30: =IF(G30=0,"***",N30/G30) | V30: =IF(H30=0,"***",O30/H30) | W30: =IF(I30=0,"***",P30/I30) | X30: =IF(J30=0,"***",Q30/J30) | Y30: =IF(K30=0,"***",R30/K30)
C31: 0025 集計 | D31: 橋本課長 | E31: =(E19+E7)/2 | F31: =(F19+F7)/2 | G31: =(G19+G7)/2 | H31: =(H19+H7)/2 | I31: =(I19+I7)/2 | J31: =(J19+J7)/2 | K31: =SUM(E31:J31) | L31: =(L19+L7)/2 | M31: =(M19+M7)/2 | N31: =(N19+N7)/2 | O31: =(O19+O7)/2 | P31: =(P19+P7)/2 | Q31: =(Q19+Q7)/2 | R31: =SUM(L31:Q31) | S31: =IF(E31=0,"***",L31/E31) | T31: =IF(F31=0,"***",M31/F31) | U31: =IF(G31=0,"***",N31/G31) | V31: =IF(H31=0,"***",O31/H31) | W31: =IF(I31=0,"***",P31/I31) | X31: =IF(J31=0,"***",Q31/J31) | Y31: =IF(K31=0,"***",R31/K31)
C32: 0026 集計 | D32: 井上課長 | E32: =(E20+E8)/2 | F32: =(F20+F8)/2 | G32: =(G20+G8)/2 | H32: =(H20+H8)/2 | I32: =(I20+I8)/2 | J32: =(J20+J8)/2 | K32: =SUM(E32:J32) | L32: =(L20+L8)/2 | M32: =(M20+M8)/2 | N32: =(N20+N8)/2 | O32: =(O20+O8)/2 | P32: =(P20+P8)/2 | Q32: =(Q20+Q8)/2 | R32: =SUM(L32:Q32) | S32: =IF(E32=0,"***",L32/E32) | T32: =IF(F32=0,"***",M32/F32) | U32: =IF(G32=0,"***",N32/G32) | V32: =IF(H32=0,"***",O32/H32) | W32: =IF(I32=0,"***",P32/I32) | X32: =IF(J32=0,"***",Q32/J32) | Y32: =IF(K32=0,"***",R32/K32)
C33: 0027 集計 | D33: 中国 | E33: =(E21+E9)/2 | F33: =(F21+F9)/2 | G33: =(G21+G9)/2 | H33: =(H21+H9)/2 | I33: =(I21+I9)/2 | J33: =(J21+J9)/2 | K33: =SUM(E33:J33) | L33: =(L21+L9)/2 | M33: =(M21+M9)/2 | N33: =(N21+N9)/2 | O33: =(O21+O9)/2 | P33: =(P21+P9)/2 | Q33: =(Q21+Q9)/2 | R33: =SUM(L33:Q33) | S33: =IF(E33=0,"***",L33/E33) | T33: =IF(F33=0,"***",M33/F33) | U33: =IF(G33=0,"***",N33/G33) | V33: =IF(H33=0,"***",O33/H33) | W33: =IF(I33=0,"***",P33/I33) | X33: =IF(J33=0,"***",Q33/J33) | Y33: =IF(K33=0,"***",R33/K33)
C34: 0028 集計 | D34: 自治体
C35: 0029 集計 | D35: その他 | E35: =(E23+E11)/2 | F35: =(F23+F11)/2 | G35: =(G23+G11)/2 | H35: =(H23+H11)/2 | I35: =(I23+I11)/2 | J35: =(J23+J11)/2 | K35: =SUM(E35:J35) | L35: =(L23+L11)/2 | M35: =(M23+M11)/2 | N35: =(N23+N11)/2 | O35: =(O23+O11)/2 | P35: =(P23+P11)/2 | Q35: =(Q23+Q11)/2 | R35: =SUM(L35:Q35) | S35: =IF(E35=0,"***",L35/E35) | T35: =IF(F35=0,"***",M35/F35) | U35: =IF(G35=0,"***",N35/G35) | V35: =IF(H35=0,"***",O35/H35) | W35: =IF(I35=0,"***",P35/I35) | X35: =IF(J35=0,"***",Q35/J35) | Y35: =IF(K35=0,"***",R35/K35)
C36: 合計 | E36: =SUM(E29:E35) | F36: =SUM(F29:F35) | G36: =SUM(G29:G35) | H36: =SUM(H29:H35) | I36: =SUM(I29:I35) | J36: =SUM(J29:J35) | K36: =SUM(E36:J36) | L36: =SUM(L29:L35) | M36: =SUM(M29:M35) | N36: =SUM(N29:N35) | O36: =SUM(O29:O35) | P36: =SUM(P29:P35) | Q36: =SUM(Q29:Q35) | R36: =SUM(L36:Q36) | S36: =IF(E36=0,"***",L36/E36) | T36: =IF(F36=0,"***",M36/F36) | U36: =IF(G36=0,"***",N36/G36) | V36: =IF(H36=0,"***",O36/H36) | W36: =IF(I36=0,"***",P36/I36) | X36: =IF(J36=0,"***",Q36/J36) | Y36: =IF(K36=0,"***",R36/K36)
C38: 4．計画
E39: 売上 | L39: 粗利益 | S39: 粗利益率
E40: 46113 | F40: 46143 | G40: 46174 | H40: 46204 | I40: 46235 | J40: 46266 | K40: 合計 | L40: 46113 | M40: 46143 | N40: 46174 | O40: 46204 | P40: 46235 | Q40: 46266 | R40: 合計 | S40: 46113 | T40: 46143 | U40: 46174 | V40: 46204 | W40: 46235 | X40: 46266 | Y40: 合計
C41: 0021 集計 | D41: 高橋所長 | E41: 150 | F41: 150 | G41: 150 | H41: 150 | I41: 150 | J41: 150 | K41: =SUM(E41:J41) | L41: 25 | M41: 25 | N41: 25 | O41: 25 | P41: 25 | Q41: 25 | R41: =SUM(L41:Q41) | S41: =IF(E41=0,"***",L41/E41) | T41: =IF(F41=0,"***",M41/F41) | U41: =IF(G41=0,"***",N41/G41) | V41: =IF(H41=0,"***",O41/H41) | W41: =IF(I41=0,"***",P41/I41) | X41: =IF(J41=0,"***",Q41/J41) | Y41: =IF(K41=0,"***",R41/K41)
C42: 0024 集計 | D42: 東野 | E42: 3240 | K42: =SUM(E42:J42) | L42: 430 | R42: =SUM(L42:Q42) | S42: =IF(E42=0,"***",L42/E42) | T42: =IF(F42=0,"***",M42/F42) | U42: =IF(G42=0,"***",N42/G42) | V42: =IF(H42=0,"***",O42/H42) | W42: =IF(I42=0,"***",P42/I42) | X42: =IF(J42=0,"***",Q42/J42) | Y42: =IF(K42=0,"***",R42/K42)
C43: 0025 集計 | D43: 橋本課長 | E43: 150 | F43: 150 | G43: 150 | H43: 150 | I43: 150 | J43: 150 | K43: =SUM(E43:J43) | L43: 25 | M43: 25 | N43: 25 | O43: 25 | P43: 25 | Q43: 25 | R43: =SUM(L43:Q43) | S43: =IF(E43=0,"***",L43/E43) | T43: =IF(F43=0,"***",M43/F43) | U43: =IF(G43=0,"***",N43/G43) | V43: =IF(H43=0,"***",O43/H43) | W43: =IF(I43=0,"***",P43/I43) | X43: =IF(J43=0,"***",Q43/J43) | Y43: =IF(K43=0,"***",R43/K43)
...

Sheet 全体
C1: 下関営業所全体
C2: 1．2024年
E3: 売上 | L3: 粗利益 | S3: 粗利益率
E4: 45383 | F4: 45413 | G4: 45444 | H4: 45474 | I4: 45505 | J4: 45536 | K4: 合計 | L4: 45383 | M4: 45413 | N4: 45444 | O4: 45474 | P4: 45505 | Q4: 45536 | R4: 合計 | S4: 45017 | T4: 45047 | U4: 45078 | V4: 45108 | W4: 45139 | X4: 45170 | Y4: 合計
C5: 0021 集計 | D5: 高橋所長 | E5: 11753.171 | F5: 10563.879 | G5: 9223.07 | H5: 10595.855 | I5: 10776.385 | J5: 8638.656 | K5: =SUM(E5:J5) | L5: 2624.741 | M5: 2364.821 | N5: 2014.608 | O5: 2326.429 | P5: 2387.037 | Q5: 2072.398 | R5: =SUM(L5:Q5) | S5: =IF(E5=0,"***",L5/E5) | T5: =IF(F5=0,"***",M5/F5) | U5: =IF(G5=0,"***",N5/G5) | V5: =IF(H5=0,"***",O5/H5) | W5: =IF(I5=0,"***",P5/I5) | X5: =IF(J5=0,"***",Q5/J5) | Y5: =IF(K5=0,"***",R5/K5)
C6: 0024 集計 | D6: 東野 | E6: 13328.239 | F6: 10428.931 | G6: 11991.208 | H6: 13843.186 | I6: 11383.003 | J6: 14024.166 | K6: =SUM(E6:J6) | L6: 2832.923 | M6: 2155.516 | N6: 2459.638 | O6: 2954.298 | P6: 2296.569 | Q6: 2908.856 | R6: =SUM(L6:Q6) | S6: =IF(E6=0,"***",L6/E6) | T6: =IF(F6=0,"***",M6/F6) | U6: =IF(G6=0,"***",N6/G6) | V6: =IF(H6=0,"***",O6/H6) | W6: =IF(I6=0,"***",P6/I6) | X6: =IF(J6=0,"***",Q6/J6) | Y6: =IF(K6=0,"***",R6/K6)
C7: 0025 集計 | D7: 橋本課長 | E7: 9755.118 | F7: 8922.02 | G7: 7512.023 | H7: 8068.27 | I7: 8839.392 | J7: 9951.129 | K7: =SUM(E7:J7) | L7: 1820.776 | M7: 1584.587 | N7: 1260.419 | O7: 1425.398 | P7: 1569.458 | Q7: 1621.124 | R7: =SUM(L7:Q7) | S7: =IF(E7=0,"***",L7/E7) | T7: =IF(F7=0,"***",M7/F7) | U7: =IF(G7=0,"***",N7/G7) | V7: =IF(H7=0,"***",O7/H7) | W7: =IF(I7=0,"***",P7/I7) | X7: =IF(J7=0,"***",Q7/J7) | Y7: =IF(K7=0,"***",R7/K7)
C8: 0026 集計 | D8: 井上課長 | E8: 13260.614 | F8: 11607.928 | G8: 11655.598 | H8: 12809.026 | I8: 11252.949 | J8: 11636.983 | K8: =SUM(E8:J8) | L8: 2517.61 | M8: 2235.196 | N8: 2179.799 | O8: 2431.708 | P8: 2204.012 | Q8: 2268.755 | R8: =SUM(L8:Q8) | S8: =IF(E8=0,"***",L8/E8) | T8: =IF(F8=0,"***",M8/F8) | U8: =IF(G8=0,"***",N8/G8) | V8: =IF(H8=0,"***",O8/H8) | W8: =IF(I8=0,"***",P8/I8) | X8: =IF(J8=0,"***",Q8/J8) | Y8: =IF(K8=0,"***",R8/K8)
C9: 0027 集計 | D9: 中国 | E9: 3244.418 | F9: 0 | G9: 0 | H9: 0 | I9: 0 | J9: 2238.475 | K9: =SUM(E9:J9) | L9: 177.043 | M9: 0 | N9: 0 | O9: 0 | P9: 0 | Q9: 136.78 | R9: =SUM(L9:Q9) | S9: =IF(E9=0,"***",L9/E9) | T9: =IF(F9=0,"***",M9/F9) | U9: =IF(G9=0,"***",N9/G9) | V9: =IF(H9=0,"***",O9/H9) | W9: =IF(I9=0,"***",P9/I9) | X9: =IF(J9=0,"***",Q9/J9) | Y9: =IF(K9=0,"***",R9/K9)
C10: 0028 集計 | D10: 自治体
C11: 0029 集計 | D11: その他 | E11: 75.2 | F11: 1.8 | G11: 0 | H11: 0 | I11: 0 | J11: 0 | K11: =SUM(E11:J11) | L11: 16.72 | M11: 0.525 | N11: 0 | O11: 0 | P11: 0 | Q11: 0 | R11: =SUM(L11:Q11) | S11: =IF(E11=0,"***",L11/E11) | T11: =IF(F11=0,"***",M11/F11) | U11: =IF(G11=0,"***",N11/G11) | V11: =IF(H11=0,"***",O11/H11) | W11: =IF(I11=0,"***",P11/I11) | X11: =IF(J11=0,"***",Q11/J11) | Y11: =IF(K11=0,"***",R11/K11)
C12: 合計 | E12: =SUM(E5:E11) | F12: =SUM(F5:F11) | G12: =SUM(G5:G11) | H12: =SUM(H5:H11) | I12: =SUM(I5:I11) | J12: =SUM(J5:J11) | K12: =SUM(E12:J12) | L12: =SUM(L5:L11) | M12: =SUM(M5:M11) | N12: =SUM(N5:N11) | O12: =SUM(O5:O11) | P12: =SUM(P5:P11) | Q12: =SUM(Q5:Q11) | R12: =SUM(L12:Q12) | S12: =IF(E12=0,"***",L12/E12) | T12: =IF(F12=0,"***",M12/F12) | U12: =IF(G12=0,"***",N12/G12) | V12: =IF(H12=0,"***",O12/H12) | W12: =IF(I12=0,"***",P12/I12) | X12: =IF(J12=0,"***",Q12/J12) | Y12: =IF(K12=0,"***",R12/K12)
C14: 2．2025年
E15: 売上 | L15: 粗利益 | S15: 粗利益率
E16: 45748 | F16: 45778 | G16: 45809 | H16: 45839 | I16: 45870 | J16: 45901 | K16: 合計 | L16: 45748 | M16: 45778 | N16: 45809 | O16: 45839 | P16: 45870 | Q16: 45901 | R16: 合計 | S16: 45748 | T16: 45778 | U16: 45809 | V16: 45839 | W16: 45870 | X16: 45901 | Y16: 合計
C17: 0021 集計 | D17: 高橋所長 | E17: 12613.22 | F17: 8701.224 | G17: 8907.097 | H17: 11991.28 | I17: 8473.623 | J17: 10873.978 | K17: =SUM(E17:J17) | L17: 3055.373 | M17: 1995.807 | N17: 2147.106 | O17: 2808.03 | P17: 1948.398 | Q17: 2467.586 | R17: =SUM(L17:Q17) | S17: =IF(E17=0,"***",L17/E17) | T17: =IF(F17=0,"***",M17/F17) | U17: =IF(G17=0,"***",N17/G17) | V17: =IF(H17=0,"***",O17/H17) | W17: =IF(I17=0,"***",P17/I17) | X17: =IF(J17=0,"***",Q17/J17) | Y17: =IF(K17=0,"***",R17/K17)
C18: 0024 集計 | D18: 東野 | E18: 14217.865 | F18: 12444.771 | G18: 11689.779 | H18: 14073.076 | I18: 11761.85 | J18: 12710.688 | K18: =SUM(E18:J18) | L18: 2955.326 | M18: 2676.657 | N18: 2394.003 | O18: 2966.272 | P18: 2500.065 | Q18: 2549.72 | R18: =SUM(L18:Q18) | S18: =IF(E18=0,"***",L18/E18) | T18: =IF(F18=0,"***",M18/F18) | U18: =IF(G18=0,"***",N18/G18) | V18: =IF(H18=0,"***",O18/H18) | W18: =IF(I18=0,"***",P18/I18) | X18: =IF(J18=0,"***",Q18/J18) | Y18: =IF(K18=0,"***",R18/K18)
C19: 0025 集計 | D19: 橋本課長 | E19: 9524.192 | F19: 7397.389 | G19: 6553.115 | H19: 7484.947 | I19: 7106.066 | J19: 9966.925 | K19: =SUM(E19:J19) | L19: 1605.049 | M19: 1501.787 | N19: 1231.215 | O19: 1371.167 | P19: 1453.381 | Q19: 1870.951 | R19: =SUM(L19:Q19) | S19: =IF(E19=0,"***",L19/E19) | T19: =IF(F19=0,"***",M19/F19) | U19: =IF(G19=0,"***",N19/G19) | V19: =IF(H19=0,"***",O19/H19) | W19: =IF(I19=0,"***",P19/I19) | X19: =IF(J19=0,"***",Q19/J19) | Y19: =IF(K19=0,"***",R19/K19)
C20: 0026 集計 | D20: 井上課長 | E20: 14053.099 | F20: 12472.69 | G20: 11107.365 | H20: 12987.361 | I20: 11939.249 | J20: 11811.983 | K20: =SUM(E20:J20) | L20: 2683.704 | M20: 2345.139 | N20: 2120.899 | O20: 2561.005 | P20: 2364.696 | Q20: 2326.408 | R20: =SUM(L20:Q20) | S20: =IF(E20=0,"***",L20/E20) | T20: =IF(F20=0,"***",M20/F20) | U20: =IF(G20=0,"***",N20/G20) | V20: =IF(H20=0,"***",O20/H20) | W20: =IF(I20=0,"***",P20/I20) | X20: =IF(J20=0,"***",Q20/J20) | Y20: =IF(K20=0,"***",R20/K20)
C21: 0027 集計 | D21: 中国 | E21: 0 | F21: 0 | G21: 0 | H21: 0 | I21: 0 | J21: 0 | K21: =SUM(E21:J21) | L21: 0 | M21: 0 | N21: 0 | O21: 0 | P21: 0 | Q21: 0 | R21: =SUM(L21:Q21) | S21: =IF(E21=0,"***",L21/E21) | T21: =IF(F21=0,"***",M21/F21) | U21: =IF(G21=0,"***",N21/G21) | V21: =IF(H21=0,"***",O21/H21) | W21: =IF(I21=0,"***",P21/I21) | X21: =IF(J21=0,"***",Q21/J21) | Y21: =IF(K21=0,"***",R21/K21)
C22: 0028 集計 | D22: 自治体 | E22: 0 | F22: 0 | G22: 0 | H22: 107.5 | I22: 0 | J22: 0 | K22: =SUM(E22:J22) | L22: 0 | M22: 0 | N22: 0 | O22: 3.6 | P22: 0 | Q22: 0 | R22: =SUM(L22:Q22) | S22: =IF(E22=0,"***",L22/E22) | T22: =IF(F22=0,"***",M22/F22) | U22: =IF(G22=0,"***",N22/G22) | V22: =IF(H22=0,"***",O22/H22) | W22: =IF(I22=0,"***",P22/I22) | X22: =IF(J22=0,"***",Q22/J22) | Y22: =IF(K22=0,"***",R22/K22)
C23: 0029 集計 | D23: その他 | E23: 0 | F23: 0 | G23: 125 | H23: 0 | I23: 4.8 | J23: 0 | K23: =SUM(E23:J23) | L23: 0 | M23: 0 | N23: 20.2 | O23: 0 | P23: 1.38 | Q23: 0 | R23: =SUM(L23:Q23) | S23: =IF(E23=0,"***",L23/E23) | T23: =IF(F23=0,"***",M23/F23) | U23: =IF(G23=0,"***",N23/G23) | V23: =IF(H23=0,"***",O23/H23) | W23: =IF(I23=0,"***",P23/I23) | X23: =IF(J23=0,"***",Q23/J23) | Y23: =IF(K23=0,"***",R23/K23)
C24: 合計 | E24: =SUM(E17:E23) | F24: =SUM(F17:F23) | G24: =SUM(G17:G23) | H24: =SUM(H17:H23) | I24: =SUM(I17:I23) | J24: =SUM(J17:J23) | K24: =SUM(E24:J24) | L24: =SUM(L17:L23) | M24: =SUM(M17:M23) | N24: =SUM(N17:N23) | O24: =SUM(O17:O23) | P24: =SUM(P17:P23) | Q24: =SUM(Q17:Q23) | R24: =SUM(L24:Q24) | S24: =IF(E24=0,"***",L24/E24) | T24: =IF(F24=0,"***",M24/F24) | U24: =IF(G24=0,"***",N24/G24) | V24: =IF(H24=0,"***",O24/H24) | W24: =IF(I24=0,"***",P24/I24) | X24: =IF(J24=0,"***",Q24/J24) | Y24: =IF(K24=0,"***",R24/K24)
C26: 3．過年度平均
E27: 売上 | L27: 粗利益 | S27: 粗利益率
E28: 45748 | F28: 45778 | G28: 45809 | H28: 45839 | I28: 45870 | J28: 45901 | K28: 合計 | L28: 45748 | M28: 45778 | N28: 45809 | O28: 45839 | P28: 45870 | Q28: 45901 | R28: 合計 | S28: 45748 | T28: 45778 | U28: 45809 | V28: 45839 | W28: 45870 | X28: 45901 | Y28: 合計
C29: 0021 集計 | D29: 高橋所長 | E29: =(E17+E5)/2 | F29: =(F17+F5)/2 | G29: =(G17+G5)/2 | H29: =(H17+H5)/2 | I29: =(I17+I5)/2 | J29: =(J17+J5)/2 | K29: =SUM(E29:J29) | L29: =(L17+L5)/2 | M29: =(M17+M5)/2 | N29: =(N17+N5)/2 | O29: =(O17+O5)/2 | P29: =(P17+P5)/2 | Q29: =(Q17+Q5)/2 | R29: =SUM(L29:Q29) | S29: =IF(E29=0,"***",L29/E29) | T29: =IF(F29=0,"***",M29/F29) | U29: =IF(G29=0,"***",N29/G29) | V29: =IF(H29=0,"***",O29/H29) | W29: =IF(I29=0,"***",P29/I29) | X29: =IF(J29=0,"***",Q29/J29) | Y29: =IF(K29=0,"***",R29/K29)
C30: 0024 集計 | D30: 東野 | E30: =(E18+E6)/2 | F30: =(F18+F6)/2 | G30: =(G18+G6)/2 | H30: =(H18+H6)/2 | I30: =(I18+I6)/2 | J30: =(J18+J6)/2 | K30: =SUM(E30:J30) | L30: =(L18+L6)/2 | M30: =(M18+M6)/2 | N30: =(N18+N6)/2 | O30: =(O18+O6)/2 | P30: =(P18+P6)/2 | Q30: =(Q18+Q6)/2 | R30: =SUM(L30:Q30) | S30: =IF(E30=0,"***",L30/E30) | T30: =IF(F30=0,"***",M30/F30) | U30: =IF(G30=0,"***",N30/G30) | V30: =IF(H30=0,"***",O30/H30) | W30: =IF(I30=0,"***",P30/I30) | X30: =IF(J30=0,"***",Q30/J30) | Y30: =IF(K30=0,"***",R30/K30)
C31: 0025 集計 | D31: 橋本課長 | E31: =(E19+E7)/2 | F31: =(F19+F7)/2 | G31: =(G19+G7)/2 | H31: =(H19+H7)/2 | I31: =(I19+I7)/2 | J31: =(J19+J7)/2 | K31: =SUM(E31:J31) | L31: =(L19+L7)/2 | M31: =(M19+M7)/2 | N31: =(N19+N7)/2 | O31: =(O19+O7)/2 | P31: =(P19+P7)/2 | Q31: =(Q19+Q7)/2 | R31: =SUM(L31:Q31) | S31: =IF(E31=0,"***",L31/E31) | T31: =IF(F31=0,"***",M31/F31) | U31: =IF(G31=0,"***",N31/G31) | V31: =IF(H31=0,"***",O31/H31) | W31: =IF(I31=0,"***",P31/I31) | X31: =IF(J31=0,"***",Q31/J31) | Y31: =IF(K31=0,"***",R31/K31)
C32: 0026 集計 | D32: 井上課長 | E32: =(E20+E8)/2 | F32: =(F20+F8)/2 | G32: =(G20+G8)/2 | H32: =(H20+H8)/2 | I32: =(I20+I8)/2 | J32: =(J20+J8)/2 | K32: =SUM(E32:J32) | L32: =(L20+L8)/2 | M32: =(M20+M8)/2 | N32: =(N20+N8)/2 | O32: =(O20+O8)/2 | P32: =(P20+P8)/2 | Q32: =(Q20+Q8)/2 | R32: =SUM(L32:Q32) | S32: =IF(E32=0,"***",L32/E32) | T32: =IF(F32=0,"***",M32/F32) | U32: =IF(G32=0,"***",N32/G32) | V32: =IF(H32=0,"***",O32/H32) | W32: =IF(I32=0,"***",P32/I32) | X32: =IF(J32=0,"***",Q32/J32) | Y32: =IF(K32=0,"***",R32/K32)
C33: 0027 集計 | D33: 中国 | E33: =(E21+E9)/2 | F33: =(F21+F9)/2 | G33: =(G21+G9)/2 | H33: =(H21+H9)/2 | I33: =(I21+I9)/2 | J33: =(J21+J9)/2 | K33: =SUM(E33:J33) | L33: =(L21+L9)/2 | M33: =(M21+M9)/2 | N33: =(N21+N9)/2 | O33: =(O21+O9)/2 | P33: =(P21+P9)/2 | Q33: =(Q21+Q9)/2 | R33: =SUM(L33:Q33) | S33: =IF(E33=0,"***",L33/E33) | T33: =IF(F33=0,"***",M33/F33) | U33: =IF(G33=0,"***",N33/G33) | V33: =IF(H33=0,"***",O33/H33) | W33: =IF(I33=0,"***",P33/I33) | X33: =IF(J33=0,"***",Q33/J33) | Y33: =IF(K33=0,"***",R33/K33)
C34: 0028 集計 | D34: 自治体 | E34: =(E22+E10)/2 | F34: =(F22+F10)/2 | G34: =(G22+G10)/2 | H34: =(H22+H10)/2 | I34: =(I22+I10)/2 | J34: =(J22+J10)/2 | K34: =SUM(E34:J34) | L34: =(L22+L10)/2 | M34: =(M22+M10)/2 | N34: =(N22+N10)/2 | O34: =(O22+O10)/2 | P34: =(P22+P10)/2 | Q34: =(Q22+Q10)/2 | R34: =SUM(L34:Q34) | S34: =IF(E34=0,"***",L34/E34) | T34: =IF(F34=0,"***",M34/F34) | U34: =IF(G34=0,"***",N34/G34) | V34: =IF(H34=0,"***",O34/H34) | W34: =IF(I34=0,"***",P34/I34) | X34: =IF(J34=0,"***",Q34/J34) | Y34: =IF(K34=0,"***",R34/K34)
C35: 0029 集計 | D35: その他 | E35: =(E23+E11)/2 | F35: =(F23+F11)/2 | G35: =(G23+G11)/2 | H35: =(H23+H11)/2 | I35: =(I23+I11)/2 | J35: =(J23+J11)/2 | K35: =SUM(E35:J35) | L35: =(L23+L11)/2 | M35: =(M23+M11)/2 | N35: =(N23+N11)/2 | O35: =(O23+O11)/2 | P35: =(P23+P11)/2 | Q35: =(Q23+Q11)/2 | R35: =SUM(L35:Q35) | S35: =IF(E35=0,"***",L35/E35) | T35: =IF(F35=0,"***",M35/F35) | U35: =IF(G35=0,"***",N35/G35) | V35: =IF(H35=0,"***",O35/H35) | W35: =IF(I35=0,"***",P35/I35) | X35: =IF(J35=0,"***",Q35/J35) | Y35: =IF(K35=0,"***",R35/K35)
C36: 合計 | E36: =SUM(E29:E35) | F36: =SUM(F29:F35) | G36: =SUM(G29:G35) | H36: =SUM(H29:H35) | I36: =SUM(I29:I35) | J36: =SUM(J29:J35) | K36: =SUM(E36:J36) | L36: =SUM(L29:L35) | M36: =SUM(M29:M35) | N36: =SUM(N29:N35) | O36: =SUM(O29:O35) | P36: =SUM(P29:P35) | Q36: =SUM(Q29:Q35) | R36: =SUM(L36:Q36) | S36: =IF(E36=0,"***",L36/E36) | T36: =IF(F36=0,"***",M36/F36) | U36: =IF(G36=0,"***",N36/G36) | V36: =IF(H36=0,"***",O36/H36) | W36: =IF(I36=0,"***",P36/I36) | X36: =IF(J36=0,"***",Q36/J36) | Y36: =IF(K36=0,"***",R36/K36)
C38: 4．計画
E39: 売上 | L39: 粗利益 | S39: 粗利益率
E40: 46113 | F40: 46143 | G40: 46174 | H40: 46204 | I40: 46235 | J40: 46266 | K40: 合計 | L40: 46113 | M40: 46143 | N40: 46174 | O40: 46204 | P40: 46235 | Q40: 46266 | R40: 合計 | S40: 46113 | T40: 46143 | U40: 46174 | V40: 46204 | W40: 46235 | X40: 46266 | Y40: 合計
C41: 0021 集計 | D41: 高橋所長 | E41: 12500 | F41: 9500 | G41: 9500 | H41: 11000 | I41: 11000 | J41: 11800 | K41: =SUM(E41:J41) | L41: 2900 | M41: 2200 | N41: 2200 | O41: 2550 | P41: 2550 | Q41: 2750 | R41: =SUM(L41:Q41) | S41: =IF(E41=0,"***",L41/E41) | T41: =IF(F41=0,"***",M41/F41) | U41: =IF(G41=0,"***",N41/G41) | V41: =IF(H41=0,"***",O41/H41) | W41: =IF(I41=0,"***",P41/I41) | X41: =IF(J41=0,"***",Q41/J41) | Y41: =IF(K41=0,"***",R41/K41)
C42: 0024 集計 | D42: 東野 | E42: 17000 | F42: 13000 | G42: 12200 | H42: 14500 | I42: 12200 | J42: 13200 | K42: =SUM(E42:J42) | L42: 3400 | M42: 2700 | N42: 2500 | O42: 3000 | P42: 2550 | Q42: 2750 | R42: =SUM(L42:Q42) | S42: =IF(E42=0,"***",L42/E42) | T42: =IF(F42=0,"***",M42/F42) | U42: =IF(G42=0,"***",N42/G42) | V42: =IF(H42=0,"***",O42/H42) | W42: =IF(I42=0,"***",P42/I42) | X42: =IF(J42=0,"***",Q42/J42) | Y42: =IF(K42=0,"***",R42/K42)
C43: 0025 集計 | D43: 橋本課長 | E43: 10000 | F43: 7800 | G43: 7100 | H43: 8000 | I43: 8000 | J43: 10500 | K43: =SUM(E43:J43) | L43: 1850 | M43: 1450 | N43: 1350 | O43: 1550 | P43: 1550 | Q43: 2000 | R43: =SUM(L43:Q43) | S43: =IF(E43=0,"***",L43/E43) | T43: =IF(F43=0,"***",M43/F43) | U43: =IF(G43=0,"***",N43/G43) | V43: =IF(H43=0,"***",O43/H43) | W43: =IF(I43=0,"***",P43/I43) | X43: =IF(J43=0,"***",Q43/J43) | Y43: =IF(K43=0,"***",R43/K43)
...

Sheet 総括
D1: 下関営業所第51期下期予算について
D3: 管理職の業務は数字責任と人材育成です。なので営業所全体の目標達成に取り組みます。
D4: 所長は予算の過年度平均増加分の人員からは外した上で、営業所全体で計画を作成ます。その営業所全体の予算から所長含めて営業担当に配分するようにお願いします。
G7: 2024年4～9月 | J7: 2025年4～9月 | M7: 過年度平均 | P7: 計画 | U7: 根拠
G8: 売上 | H8: 粗利益 | I8: 粗利益率 | J8: 売上 | K8: 粗利益 | L8: 粗利益率 | M8: 売上 | N8: 粗利益 | O8: 粗利益率 | P8: 売上 | Q8: 粗利益 | R8: 粗利益率 | S8: 売上年率 | T8: 粗利益年率
D9: 下関営業所 | G9: 267380.69 | H9: 52847.744 | I9: =H9/G9 | J9: 261100.13 | K9: 53924.924 | L9: =K9/J9 | M9: =(G9+J9)/2 | N9: =(H9+K9)/2 | O9: =N9/M9 | P9: =P10+P14+P13 | Q9: =Q10+Q14+Q13 | R9: =Q9/P9 | S9: =P9/J9-1 | T9: =Q9/K9-1
E10: 営業 | G10: =G9-G14-G13 | H10: =H9-H14-H13 | I10: =H10/G10 | J10: =J9-J14-J13 | K10: =K9-K14-K13 | L10: =K10/J10 | M10: =(G10+J10)/2 | N10: =(H10+K10)/2 | O10: =N10/M10 | P10: =P11+P12 | Q10: =Q11+Q12 | R10: =Q10/P10 | S10: =P10/J10-1 | T10: =Q10/K10-1
F11: 包装資材 | G11: =G10-G12 | H11: =H10-H12 | I11: =H11/G11 | J11: =J10-J12 | K11: =K10-K12 | L11: =K11/J11 | M11: =(G11+J11)/2 | N11: =(H11+K11)/2 | O11: =N11/M11 | P11: =包装資材!K48-全体!K46 | Q11: =包装資材!R48-全体!R46 | R11: =Q11/P11 | S11: =P11/J11-1 | T11: =Q11/K11-1
F12: 機械 | G12: 3476 | H12: 555 | I12: =H12/G12 | J12: 4367 | K12: 4367 | L12: =K12/J12 | M12: =(G12+J12)/2 | N12: =(H12+K12)/2 | O12: =N12/M12 | P12: =機械!K48 | Q12: =機械!R48 | R12: =Q12/P12 | S12: =P12/J12-1 | T12: =Q12/K12-1
E13: 自治体 | G13: 0 | H13: 0 | I13: =H13/G13 | J13: 107.5 | K13: 3.6 | L13: =K13/J13 | M13: 53.75 | N13: 1.8 | O13: =N13/M13 | P13: 200 | Q13: 20 | R13: =Q13/P13 | S13: =P13/J13-1 | T13: =Q13/K13-1
E14: 中国事業 | G14: 5482.893 | H14: 313.823 | I14: =H14/G14 | J14: 0 | K14: 0 | L14: =K14/J14 | M14: =(G14+J14)/2 | N14: =(H14+K14)/2 | O14: =N14/M14 | P14: 0 | Q14: 0 | R14: =Q14/P14 | S14: =P14/J14-1 | T14: =Q14/K14-1
