Workbook

Sheet 包装資材
C1: 境港営業所包装資材
C2: 1．2024年
E3: 売上 | L3: 粗利益 | S3: 粗利益率
E4: 45383 | F4: 45413 | G4: 45444 | H4: 45474 | I4: 45505 | J4: 45536 | K4: 合計 | L4: 45383 | M4: 45413 | N4: 45444 | O4: 45474 | P4: 45505 | Q4: 45536 | R4: 合計 | S4: 45383 | T4: 45413 | U4: 45444 | V4: 45474 | W4: 45505 | X4: 45536 | Y4: 合計
C5: 0903 集計 | D5: 西岡 | E5: =全体!E5-機械!E5 | F5: =全体!F5-機械!F5 | G5: =全体!G5-機械!G5 | H5: =全体!H5-機械!H5 | I5: =全体!I5-機械!I5 | J5: =全体!J5-機械!J5 | K5: =SUM(E5:J5) | L5: =全体!L5-機械!L5 | M5: =全体!M5-機械!M5 | N5: =全体!N5-機械!N5 | O5: =全体!O5-機械!O5 | P5: =全体!P5-機械!P5 | Q5: =全体!Q5-機械!Q5 | R5: =SUM(L5:Q5) | S5: =IF(E5=0,"***",L5/E5) | T5: =IF(F5=0,"***",M5/F5) | U5: =IF(G5=0,"***",N5/G5) | V5: =IF(H5=0,"***",O5/H5) | W5: =IF(I5=0,"***",P5/I5) | X5: =IF(J5=0,"***",Q5/J5) | Y5: =IF(K5=0,"***",R5/K5)
C6: 0904 集計 | D6: 足立次長 | E6: =全体!E6-機械!E6 | F6: =全体!F6-機械!F6 | G6: =全体!G6-機械!G6 | H6: =全体!H6-機械!H6 | I6: =全体!I6-機械!I6 | J6: =全体!J6-機械!J6 | K6: =SUM(E6:J6) | L6: =全体!L6-機械!L6 | M6: =全体!M6-機械!M6 | N6: =全体!N6-機械!N6 | O6: =全体!O6-機械!O6 | P6: =全体!P6-機械!P6 | Q6: =全体!Q6-機械!Q6 | R6: =SUM(L6:Q6) | S6: =IF(E6=0,"***",L6/E6) | T6: =IF(F6=0,"***",M6/F6) | U6: =IF(G6=0,"***",N6/G6) | V6: =IF(H6=0,"***",O6/H6) | W6: =IF(I6=0,"***",P6/I6) | X6: =IF(J6=0,"***",Q6/J6) | Y6: =IF(K6=0,"***",R6/K6)
C7: 0909 集計 | D7: 藤波課長 | E7: =全体!E7-機械!E7 | F7: =全体!F7-機械!F7 | G7: =全体!G7-機械!G7 | H7: =全体!H7-機械!H7 | I7: =全体!I7-機械!I7 | J7: =全体!J7-機械!J7 | K7: =SUM(E7:J7) | L7: =全体!L7-機械!L7 | M7: =全体!M7-機械!M7 | N7: =全体!N7-機械!N7 | O7: =全体!O7-機械!O7 | P7: =全体!P7-機械!P7 | Q7: =全体!Q7-機械!Q7 | R7: =SUM(L7:Q7) | S7: =IF(E7=0,"***",L7/E7) | T7: =IF(F7=0,"***",M7/F7) | U7: =IF(G7=0,"***",N7/G7) | V7: =IF(H7=0,"***",O7/H7) | W7: =IF(I7=0,"***",P7/I7) | X7: =IF(J7=0,"***",Q7/J7) | Y7: =IF(K7=0,"***",R7/K7)
C8: 0910 集計 | D8: 足立課長 | E8: =全体!E8-機械!E8 | F8: =全体!F8-機械!F8 | G8: =全体!G8-機械!G8 | H8: =全体!H8-機械!H8 | I8: =全体!I8-機械!I8 | J8: =全体!J8-機械!J8 | K8: =SUM(E8:J8) | L8: =全体!L8-機械!L8 | M8: =全体!M8-機械!M8 | N8: =全体!N8-機械!N8 | O8: =全体!O8-機械!O8 | P8: =全体!P8-機械!P8 | Q8: =全体!Q8-機械!Q8 | R8: =SUM(L8:Q8) | S8: =IF(E8=0,"***",L8/E8) | T8: =IF(F8=0,"***",M8/F8) | U8: =IF(G8=0,"***",N8/G8) | V8: =IF(H8=0,"***",O8/H8) | W8: =IF(I8=0,"***",P8/I8) | X8: =IF(J8=0,"***",Q8/J8) | Y8: =IF(K8=0,"***",R8/K8)
C9: 0911 集計 | D9: 川邊主任 | E9: =全体!E9-機械!E9 | F9: =全体!F9-機械!F9 | G9: =全体!G9-機械!G9 | H9: =全体!H9-機械!H9 | I9: =全体!I9-機械!I9 | J9: =全体!J9-機械!J9 | K9: =SUM(E9:J9) | L9: =全体!L9-機械!L9 | M9: =全体!M9-機械!M9 | N9: =全体!N9-機械!N9 | O9: =全体!O9-機械!O9 | P9: =全体!P9-機械!P9 | Q9: =全体!Q9-機械!Q9 | R9: =SUM(L9:Q9) | S9: =IF(E9=0,"***",L9/E9) | T9: =IF(F9=0,"***",M9/F9) | U9: =IF(G9=0,"***",N9/G9) | V9: =IF(H9=0,"***",O9/H9) | W9: =IF(I9=0,"***",P9/I9) | X9: =IF(J9=0,"***",Q9/J9) | Y9: =IF(K9=0,"***",R9/K9)
C10: 0914 集計 | D10: 白根主任 | E10: =全体!E10-機械!E10 | F10: =全体!F10-機械!F10 | G10: =全体!G10-機械!G10 | H10: =全体!H10-機械!H10 | I10: =全体!I10-機械!I10 | J10: =全体!J10-機械!J10 | K10: =SUM(E10:J10) | L10: =全体!L10-機械!L10 | M10: =全体!M10-機械!M10 | N10: =全体!N10-機械!N10 | O10: =全体!O10-機械!O10 | P10: =全体!P10-機械!P10 | Q10: =全体!Q10-機械!Q10 | R10: =SUM(L10:Q10) | S10: =IF(E10=0,"***",L10/E10) | T10: =IF(F10=0,"***",M10/F10) | U10: =IF(G10=0,"***",N10/G10) | V10: =IF(H10=0,"***",O10/H10) | W10: =IF(I10=0,"***",P10/I10) | X10: =IF(J10=0,"***",Q10/J10) | Y10: =IF(K10=0,"***",R10/K10)
C11: 0918 集計 | D11: 海外 | E11: =全体!E11-機械!E11 | F11: =全体!F11-機械!F11 | G11: =全体!G11-機械!G11 | H11: =全体!H11-機械!H11 | I11: =全体!I11-機械!I11 | J11: =全体!J11-機械!J11 | K11: =SUM(E11:J11) | L11: =全体!L11-機械!L11 | M11: =全体!M11-機械!M11 | N11: =全体!N11-機械!N11 | O11: =全体!O11-機械!O11 | P11: =全体!P11-機械!P11 | Q11: =全体!Q11-機械!Q11 | R11: =SUM(L11:Q11) | S11: =IF(E11=0,"***",L11/E11) | T11: =IF(F11=0,"***",M11/F11) | U11: =IF(G11=0,"***",N11/G11) | V11: =IF(H11=0,"***",O11/H11) | W11: =IF(I11=0,"***",P11/I11) | X11: =IF(J11=0,"***",Q11/J11) | Y11: =IF(K11=0,"***",R11/K11)
C12: 0919 集計 | D12: その他 | E12: =全体!E12-機械!E12 | F12: =全体!F12-機械!F12 | G12: =全体!G12-機械!G12 | H12: =全体!H12-機械!H12 | I12: =全体!I12-機械!I12 | J12: =全体!J12-機械!J12 | K12: =SUM(E12:J12) | L12: =全体!L12-機械!L12 | M12: =全体!M12-機械!M12 | N12: =全体!N12-機械!N12 | O12: =全体!O12-機械!O12 | P12: =全体!P12-機械!P12 | Q12: =全体!Q12-機械!Q12 | R12: =SUM(L12:Q12) | S12: =IF(E12=0,"***",L12/E12) | T12: =IF(F12=0,"***",M12/F12) | U12: =IF(G12=0,"***",N12/G12) | V12: =IF(H12=0,"***",O12/H12) | W12: =IF(I12=0,"***",P12/I12) | X12: =IF(J12=0,"***",Q12/J12) | Y12: =IF(K12=0,"***",R12/K12)
C13: 0930 集計 | D13: 自治体 | E13: =全体!E13-機械!E13 | F13: =全体!F13-機械!F13 | G13: =全体!G13-機械!G13 | H13: =全体!H13-機械!H13 | I13: =全体!I13-機械!I13 | J13: =全体!J13-機械!J13 | K13: =SUM(E13:J13) | L13: =全体!L13-機械!L13 | M13: =全体!M13-機械!M13 | N13: =全体!N13-機械!N13 | O13: =全体!O13-機械!O13 | P13: =全体!P13-機械!P13 | Q13: =全体!Q13-機械!Q13 | R13: =SUM(L13:Q13) | S13: =IF(E13=0,"***",L13/E13) | T13: =IF(F13=0,"***",M13/F13) | U13: =IF(G13=0,"***",N13/G13) | V13: =IF(H13=0,"***",O13/H13) | W13: =IF(I13=0,"***",P13/I13) | X13: =IF(J13=0,"***",Q13/J13) | Y13: =IF(K13=0,"***",R13/K13)
C14: 合計 | E14: =SUM(E5:E13) | F14: =SUM(F5:F13) | G14: =SUM(G5:G13) | H14: =SUM(H5:H13) | I14: =SUM(I5:I13) | J14: =SUM(J5:J13) | K14: =SUM(K5:K13) | L14: =SUM(L5:L13) | ... R14: =SUM(R5:R13) | S14: =IF(E14=0,"***",L14/E14) | T14: =IF(F14=0,"***",M14/F14) | U14: =IF(G14=0,"***",N14/G14) | V14: =IF(H14=0,"***",O14/H14) | W14: =IF(I14=0,"***",P14/I14) | X14: =IF(J14=0,"***",Q14/J14) | Y14: =IF(K14=0,"***",R14/K14)
C16: 2．2025年
E17: 売上 | L17: 粗利益 | S17: 粗利益率
E18: 45748 | F18: 45778 | G18: 45809 | H18: 45839 | I18: 45870 | J18: 45901 | K18: 合計 | L18: 45748 | M18: 45778 | N18: 45809 | O18: 45839 | P18: 45870 | Q18: 45901 | R18: 合計 | S18: 45748 | T18: 45778 | U18: 45809 | V18: 45839 | W18: 45870 | X18: 45901 | Y18: 合計
C19: 0903 集計 | D19: 西岡 | E19: =全体!E19-機械!E19 | F19: =全体!F19-機械!F19 | G19: =全体!G19-機械!G19 | H19: =全体!H19-機械!H19 | I19: =全体!I19-機械!I19 | J19: =全体!J19-機械!J19 | K19: =SUM(E19:J19) | L19: =全体!L19-機械!L19 | M19: =全体!M19-機械!M19 | N19: =全体!N19-機械!N19 | O19: =全体!O19-機械!O19 | P19: =全体!P19-機械!P19 | Q19: =全体!Q19-機械!Q19 | R19: =SUM(L19:Q19) | S19: =IF(E19=0,"***",L19/E19) | T19: =IF(F19=0,"***",M19/F19) | U19: =IF(G19=0,"***",N19/G19) | V19: =IF(H19=0,"***",O19/H19) | W19: =IF(I19=0,"***",P19/I19) | X19: =IF(J19=0,"***",Q19/J19) | Y19: =IF(K19=0,"***",R19/K19)
C20: 0904 集計 | D20: 足立次長 | E20: =全体!E20-機械!E20 | F20: =全体!F20-機械!F20 | G20: =全体!G20-機械!G20 | H20: =全体!H20-機械!H20 | I20: =全体!I20-機械!I20 | J20: =全体!J20-機械!J20 | K20: =SUM(E20:J20) | L20: =全体!L20-機械!L20 | M20: =全体!M20-機械!M20 | N20: =全体!N20-機械!N20 | O20: =全体!O20-機械!O20 | P20: =全体!P20-機械!P20 | Q20: =全体!Q20-機械!Q20 | R20: =SUM(L20:Q20) | S20: =IF(E20=0,"***",L20/E20) | T20: =IF(F20=0,"***",M20/F20) | U20: =IF(G20=0,"***",N20/G20) | V20: =IF(H20=0,"***",O20/H20) | W20: =IF(I20=0,"***",P20/I20) | X20: =IF(J20=0,"***",Q20/J20) | Y20: =IF(K20=0,"***",R20/K20)
C21: 0909 集計 | D21: 藤波課長 | E21: =全体!E21-機械!E21 | F21: =全体!F21-機械!F21 | G21: =全体!G21-機械!G21 | H21: =全体!H21-機械!H21 | I21: =全体!I21-機械!I21 | J21: =全体!J21-機械!J21 | K21: =SUM(E21:J21) | L21: =全体!L21-機械!L21 | M21: =全体!M21-機械!M21 | N21: =全体!N21-機械!N21 | O21: =全体!O21-機械!O21 | P21: =全体!P21-機械!P21 | Q21: =全体!Q21-機械!Q21 | R21: =SUM(L21:Q21) | S21: =IF(E21=0,"***",L21/E21) | T21: =IF(F21=0,"***",M21/F21) | U21: =IF(G21=0,"***",N21/G21) | V21: =IF(H21=0,"***",O21/H21) | W21: =IF(I21=0,"***",P21/I21) | X21: =IF(J21=0,"***",Q21/J21) | Y21: =IF(K21=0,"***",R21/K21)
C22: 0910 集計 | D22: 足立課長 | E22: =全体!E22-機械!E22 | F22: =全体!F22-機械!F22 | G22: =全体!G22-機械!G22 | H22: =全体!H22-機械!H22 | I22: =全体!I22-機械!I22 | J22: =全体!J22-機械!J22 | K22: =SUM(E22:J22) | L22: =全体!L22-機械!L22 | M22: =全体!M22-機械!M22 | N22: =全体!N22-機械!N22 | O22: =全体!O22-機械!O22 | P22: =全体!P22-機械!P22 | Q22: =全体!Q22-機械!Q22 | R22: =SUM(L22:Q22) | S22: =IF(E22=0,"***",L22/E22) | T22: =IF(F22=0,"***",M22/F22) | U22: =IF(G22=0,"***",N22/G22) | V22: =IF(H22=0,"***",O22/H22) | W22: =IF(I22=0,"***",P22/I22) | X22: =IF(J22=0,"***",Q22/J22) | Y22: =IF(K22=0,"***",R22/K22)
C23: 0911 集計 | D23: 川邊主任 | E23: =全体!E23-機械!E23 | F23: =全体!F23-機械!F23 | G23: =全体!G23-機械!G23 | H23: =全体!H23-機械!H23 | I23: =全体!I23-機械!I23 | J23: =全体!J23-機械!J23 | K23: =SUM(E23:J23) | L23: =全体!L23-機械!L23 | M23: =全体!M23-機械!M23 | N23: =全体!N23-機械!N23 | O23: =全体!O23-機械!O23 | P23: =全体!P23-機械!P23 | Q23: =全体!Q23-機械!Q23 | R23: =SUM(L23:Q23) | S23: =IF(E23=0,"***",L23/E23) | T23: =IF(F23=0,"***",M23/F23) | U23: =IF(G23=0,"***",N23/G23) | V23: =IF(H23=0,"***",O23/H23) | W23: =IF(I23=0,"***",P23/I23) | X23: =IF(J23=0,"***",Q23/J23) | Y23: =IF(K23=0,"***",R23/K23)
C24: 0914 集計 | D24: 白根主任 | E24: =全体!E24-機械!E24 | F24: =全体!F24-機械!F24 | G24: =全体!G24-機械!G24 | H24: =全体!H24-機械!H24 | I24: =全体!I24-機械!I24 | J24: =全体!J24-機械!J24 | K24: =SUM(E24:J24) | L24: =全体!L24-機械!L24 | M24: =全体!M24-機械!M24 | N24: =全体!N24-機械!N24 | O24: =全体!O24-機械!O24 | P24: =全体!P24-機械!P24 | Q24: =全体!Q24-機械!Q24 | R24: =SUM(L24:Q24) | S24: =IF(E24=0,"***",L24/E24) | T24: =IF(F24=0,"***",M24/F24) | U24: =IF(G24=0,"***",N24/G24) | V24: =IF(H24=0,"***",O24/H24) | W24: =IF(I24=0,"***",P24/I24) | X24: =IF(J24=0,"***",Q24/J24) | Y24: =IF(K24=0,"***",R24/K24)
C25: 0918 集計 | D25: 海外 | E25: =全体!E25-機械!E25 | F25: =全体!F25-機械!F25 | G25: =全体!G25-機械!G25 | H25: =全体!H25-機械!H25 | I25: =全体!I25-機械!I25 | J25: =全体!J25-機械!J25 | K25: =SUM(E25:J25) | L25: =全体!L25-機械!L25 | M25: =全体!M25-機械!M25 | N25: =全体!N25-機械!N25 | O25: =全体!O25-機械!O25 | P25: =全体!P25-機械!P25 | Q25: =全体!Q25-機械!Q25 | R25: =SUM(L25:Q25) | S25: =IF(E25=0,"***",L25/E25) | T25: =IF(F25=0,"***",M25/F25) | U25: =IF(G25=0,"***",N25/G25) | V25: =IF(H25=0,"***",O25/H25) | W25: =IF(I25=0,"***",P25/I25) | X25: =IF(J25=0,"***",Q25/J25) | Y25: =IF(K25=0,"***",R25/K25)
C26: 0919 集計 | D26: その他 | E26: =全体!E26-機械!E26 | F26: =全体!F26-機械!F26 | G26: =全体!G26-機械!G26 | H26: =全体!H26-機械!H26 | I26: =全体!I26-機械!I26 | J26: =全体!J26-機械!J26 | K26: =SUM(E26:J26) | L26: =全体!L26-機械!L26 | M26: =全体!M26-機械!M26 | N26: =全体!N26-機械!N26 | O26: =全体!O26-機械!O26 | P26: =全体!P26-機械!P26 | Q26: =全体!Q26-機械!Q26 | R26: =SUM(L26:Q26) | S26: =IF(E26=0,"***",L26/E26) | T26: =IF(F26=0,"***",M26/F26) | U26: =IF(G26=0,"***",N26/G26) | V26: =IF(H26=0,"***",O26/H26) | W26: =IF(I26=0,"***",P26/I26) | X26: =IF(J26=0,"***",Q26/J26) | Y26: =IF(K26=0,"***",R26/K26)
C27: 0930 集計 | D27: 自治体 | E27: =全体!E27-機械!E27 | F27: =全体!F27-機械!F27 | G27: =全体!G27-機械!G27 | H27: =全体!H27-機械!H27 | I27: =全体!I27-機械!I27 | J27: =全体!J27-機械!J27 | K27: =SUM(E27:J27) | L27: =全体!L27-機械!L27 | M27: =全体!M27-機械!M27 | N27: =全体!N27-機械!N27 | O27: =全体!O27-機械!O27 | P27: =全体!P27-機械!P27 | Q27: =全体!Q27-機械!Q27 | R27: =SUM(L27:Q27) | S27: =IF(E27=0,"***",L27/E27) | T27: =IF(F27=0,"***",M27/F27) | U27: =IF(G27=0,"***",N27/G27) | V27: =IF(H27=0,"***",O27/H27) | W27: =IF(I27=0,"***",P27/I27) | X27: =IF(J27=0,"***",Q27/J27) | Y27: =IF(K27=0,"***",R27/K27)
C28: 合計 | E28: =SUM(E19:E27) | F28: =SUM(F19:F27) | G28: =SUM(G19:G27) | H28: =SUM(H19:H27) | I28: =SUM(I19:I27) | J28: =SUM(J19:J27) | K28: =SUM(K19:K27) | L28: =SUM(L19:L27) | ... R28: =SUM(R19:R27) | S28: =IF(E28=0,"***",L28/E28) | T28: =IF(F28=0,"***",M28/F28) | U28: =IF(G28=0,"***",N28/G28) | V28: =IF(H28=0,"***",O28/H28) | W28: =IF(I28=0,"***",P28/I28) | X28: =IF(J28=0,"***",Q28/J28) | Y28: =IF(K28=0,"***",R28/K28)
C30: 3．過年度平均
E31: 売上 | L31: 粗利益 | S31: 粗利益率
E32: 45748 | F32: 45778 | G32: 45809 | H32: 45839 | I32: 45870 | J32: 45901 | K32: 合計 | L32: 45748 | M32: 45778 | N32: 45809 | O32: 45839 | P32: 45870 | Q32: 45901 | R32: 合計 | S32: 45748 | T32: 45778 | U32: 45809 | V32: 45839 | W32: 45870 | X32: 45901 | Y32: 合計
C33: 0903 集計 | D33: 西岡 | E33: =(E19+E5)/2 | F33: =(F19+F5)/2 | G33: =(G19+G5)/2 | H33: =(H19+H5)/2 | I33: =(I19+I5)/2 | J33: =(J19+J5)/2 | K33: =SUM(E33:J33) | L33: =(L19+L5)/2 | M33: =(M19+M5)/2 | N33: =(N19+N5)/2 | O33: =(O19+O5)/2 | P33: =(P19+P5)/2 | Q33: =(Q19+Q5)/2 | R33: =SUM(L33:Q33) | S33: =IF(E33=0,"***",L33/E33) | T33: =IF(F33=0,"***",M33/F33) | U33: =IF(G33=0,"***",N33/G33) | V33: =IF(H33=0,"***",O33/H33) | W33: =IF(I33=0,"***",P33/I33) | X33: =IF(J33=0,"***",Q33/J33) | Y33: =IF(K33=0,"***",R33/K33)
C34: 0904 集計 | D34: 足立次長 | E34: =(E20+E6)/2 | F34: =(F20+F6)/2 | G34: =(G20+G6)/2 | H34: =(H20+H6)/2 | I34: =(I20+I6)/2 | J34: =(J20+J6)/2 | K34: =SUM(E34:J34) | L34: =(L20+L6)/2 | M34: =(M20+M6)/2 | N34: =(N20+N6)/2 | O34: =(O20+O6)/2 | P34: =(P20+P6)/2 | Q34: =(Q20+Q6)/2 | R34: =SUM(L34:Q34) | S34: =IF(E34=0,"***",L34/E34) | T34: =IF(F34=0,"***",M34/F34) | U34: =IF(G34=0,"***",N34/G34) | V34: =IF(H34=0,"***",O34/H34) | W34: =IF(I34=0,"***",P34/I34) | X34: =IF(J34=0,"***",Q34/J34) | Y34: =IF(K34=0,"***",R34/K34)
C35: 0909 集計 | D35: 藤波課長 | E35: =(E21+E7)/2 | F35: =(F21+F7)/2 | G35: =(G21+G7)/2 | H35: =(H21+H7)/2 | I35: =(I21+I7)/2 | J35: =(J21+J7)/2 | K35: =SUM(E35:J35) | L35: =(L21+L7)/2 | M35: =(M21+M7)/2 | N35: =(N21+N7)/2 | O35: =(O21+O7)/2 | P35: =(P21+P7)/2 | Q35: =(Q21+Q7)/2 | R35: =SUM(L35:Q35) | S35: =IF(E35=0,"***",L35/E35) | T35: =IF(F35=0,"***",M35/F35) | U35: =IF(G35=0,"***",N35/G35) | V35: =IF(H35=0,"***",O35/H35) | W35: =IF(I35=0,"***",P35/I35) | X35: =IF(J35=0,"***",Q35/J35) | Y35: =IF(K35=0,"***",R35/K35)
C36: 0910 集計 | D36: 足立課長 | E36: =(E22+E8)/2 | F36: =(F22+F8)/2 | G36: =(G22+G8)/2 | H36: =(H22+H8)/2 | I36: =(I22+I8)/2 | J36: =(J22+J8)/2 | K36: =SUM(E36:J36) | L36: =(L22+L8)/2 | M36: =(M22+M8)/2 | N36: =(N22+N8)/2 | O36: =(O22+O8)/2 | P36: =(P22+P8)/2 | Q36: =(Q22+Q8)/2 | R36: =SUM(L36:Q36) | S36: =IF(E36=0,"***",L36/E36) | T36: =IF(F36=0,"***",M36/F36) | U36: =IF(G36=0,"***",N36/G36) | V36: =IF(H36=0,"***",O36/H36) | W36: =IF(I36=0,"***",P36/I36) | X36: =IF(J36=0,"***",Q36/J36) | Y36: =IF(K36=0,"***",R36/K36)
C37: 0911 集計 | D37: 川邊主任 | E37: =(E23+E9)/2 | F37: =(F23+F9)/2 | G37: =(G23+G9)/2 | H37: =(H23+H9)/2 | I37: =(I23+I9)/2 | J37: =(J23+J9)/2 | K37: =SUM(E37:J37) | L37: =(L23+L9)/2 | M37: =(M23+M9)/2 | N37: =(N23+N9)/2 | O37: =(O23+O9)/2 | P37: =(P23+P9)/2 | Q37: =(Q23+Q9)/2 | R37: =SUM(L37:Q37) | S37: =IF(E37=0,"***",L37/E37) | T37: =IF(F37=0,"***",M37/F37) | U37: =IF(G37=0,"***",N37/G37) | V37: =IF(H37=0,"***",O37/H37) | W37: =IF(I37=0,"***",P37/I37) | X37: =IF(J37=0,"***",Q37/J37) | Y37: =IF(K37=0,"***",R37/K37)
C38: 0914 集計 | D38: 白根主任 | E38: =(E24+E10)/2 | F38: =(F24+F10)/2 | G38: =(G24+G10)/2 | H38: =(H24+H10)/2 | I38: =(I24+I10)/2 | J38: =(J24+J10)/2 | K38: =SUM(E38:J38) | L38: =(L24+L10)/2 | M38: =(M24+M10)/2 | N38: =(N24+N10)/2 | O38: =(O24+O10)/2 | P38: =(P24+P10)/2 | Q38: =(Q24+Q10)/2 | R38: =SUM(L38:Q38) | S38: =IF(E38=0,"***",L38/E38) | T38: =IF(F38=0,"***",M38/F38) | U38: =IF(G38=0,"***",N38/G38) | V38: =IF(H38=0,"***",O38/H38) | W38: =IF(I38=0,"***",P38/I38) | X38: =IF(J38=0,"***",Q38/J38) | Y38: =IF(K38=0,"***",R38/K38)
C39: 0918 集計 | D39: 海外 | E39: =(E25+E11)/2 | F39: =(F25+F11)/2 | G39: =(G25+G11)/2 | H39: =(H25+H11)/2 | I39: =(I25+I11)/2 | J39: =(J25+J11)/2 | K39: =SUM(E39:J39) | L39: =(L25+L11)/2 | M39: =(M25+M11)/2 | N39: =(N25+N11)/2 | O39: =(O25+O11)/2 | P39: =(P25+P11)/2 | Q39: =(Q25+Q11)/2 | R39: =SUM(L39:Q39) | S39: =IF(E39=0,"***",L39/E39) | T39: =IF(F39=0,"***",M39/F39) | U39: =IF(G39=0,"***",N39/G39) | V39: =IF(H39=0,"***",O39/H39) | W39: =IF(I39=0,"***",P39/I39) | X39: =IF(J39=0,"***",Q39/J39) | Y39: =IF(K39=0,"***",R39/K39)
C40: 0919 集計 | D40: その他 | E40: =(E26+E12)/2 | F40: =(F26+F12)/2 | G40: =(G26+G12)/2 | H40: =(H26+H12)/2 | I40: =(I26+I12)/2 | J40: =(J26+J12)/2 | K40: =SUM(E40:J40) | L40: =(L26+L12)/2 | M40: =(M26+M12)/2 | N40: =(N26+N12)/2 | O40: =(O26+O12)/2 | P40: =(P26+P12)/2 | Q40: =(Q26+Q12)/2 | R40: =SUM(L40:Q40) | S40: =IF(E40=0,"***",L40/E40) | T40: =IF(F40=0,"***",M40/F40) | U40: =IF(G40=0,"***",N40/G40) | V40: =IF(H40=0,"***",O40/H40) | W40: =IF(I40=0,"***",P40/I40) | X40: =IF(J40=0,"***",Q40/J40) | Y40: =IF(K40=0,"***",R40/K40)
C41: 0930 集計 | D41: 自治体 | E41: =(E27+E13)/2 | F41: =(F27+F13)/2 | G41: =(G27+G13)/2 | H41: =(H27+H13)/2 | I41: =(I27+I13)/2 | J41: =(J27+J13)/2 | K41: =SUM(E41:J41) | L41: =(L27+L13)/2 | M41: =(M27+M13)/2 | N41: =(N27+N13)/2 | O41: =(O27+O13)/2 | P41: =(P27+P13)/2 | Q41: =(Q27+Q13)/2 | R41: =SUM(L41:Q41) | S41: =IF(E41=0,"***",L41/E41) | T41: =IF(F41=0,"***",M41/F41) | U41: =IF(G41=0,"***",N41/G41) | V41: =IF(H41=0,"***",O41/H41) | W41: =IF(I41=0,"***",P41/I41) | X41: =IF(J41=0,"***",Q41/J41) | Y41: =IF(K41=0,"***",R41/K41)
C42: 合計 | E42: =SUM(E33:E41) | F42: =SUM(F33:F41) | G42: =SUM(G33:G41) | H42: =SUM(H33:H41) | I42: =SUM(I33:I41) | J42: =SUM(J33:J41) | K42: =SUM(K33:K41) | L42: =SUM(L33:L41) | ... R42: =SUM(R33:R41) | S42: =IF(E42=0,"***",L42/E42) | T42: =IF(F42=0,"***",M42/F42) | U42: =IF(G42=0,"***",N42/G42) | V42: =IF(H42=0,"***",O42/H42) | W42: =IF(I42=0,"***",P42/I42) | X42: =IF(J42=0,"***",Q42/J42) | Y42: =IF(K42=0,"***",R42/K42)
...

Sheet 機械
C1: 境港営業所機械
C2: 1．2024年
E3: 売上 | L3: 粗利益 | S3: 粗利益率
E4: 45383 | F4: 45413 | G4: 45444 | H4: 45474 | I4: 45505 | J4: 45536 | K4: 合計 | L4: 45383 | M4: 45413 | N4: 45444 | O4: 45474 | P4: 45505 | Q4: 45536 | R4: 合計 | S4: 45383 | T4: 45413 | U4: 45444 | V4: 45474 | W4: 45505 | X4: 45536 | Y4: 合計
C5: 0903 集計 | D5: 西岡 | E5: 1 | F5: 72 | G5: 56 | H5: =168+76 | I5: =217+11 | J5: 268 | K5: =SUM(E5:J5) | L5: 0 | M5: 13 | N5: 14 | O5: =56+24 | P5: =62+3 | Q5: 98 | R5: =SUM(L5:Q5) | S5: =IF(E5=0,"***",L5/E5) | T5: =IF(F5=0,"***",M5/F5) | U5: =IF(G5=0,"***",N5/G5) | V5: =IF(H5=0,"***",O5/H5) | W5: =IF(I5=0,"***",P5/I5) | X5: =IF(J5=0,"***",Q5/J5) | Y5: =IF(K5=0,"***",R5/K5)
C6: 0904 集計 | D6: 足立次長 | E6: 643 | F6: 26318 | G6: 397 | H6: 472 | I6: 265 | J6: 444 | K6: =SUM(E6:J6) | L6: 105 | M6: 5374 | N6: 81 | O6: 124 | P6: 47 | Q6: 71 | R6: =SUM(L6:Q6) | S6: =IF(E6=0,"***",L6/E6) | T6: =IF(F6=0,"***",M6/F6) | U6: =IF(G6=0,"***",N6/G6) | V6: =IF(H6=0,"***",O6/H6) | W6: =IF(I6=0,"***",P6/I6) | X6: =IF(J6=0,"***",Q6/J6) | Y6: =IF(K6=0,"***",R6/K6)
C7: 0909 集計 | D7: 藤波課長 | E7: 575 | F7: 675 | G7: 193 | H7: =414+70 | I7: =169+58 | J7: 814 | K7: =SUM(E7:J7) | L7: 209 | M7: 193 | N7: 89 | O7: =201+23 | P7: =91+18 | Q7: 223 | R7: =SUM(L7:Q7) | S7: =IF(E7=0,"***",L7/E7) | T7: =IF(F7=0,"***",M7/F7) | U7: =IF(G7=0,"***",N7/G7) | V7: =IF(H7=0,"***",O7/H7) | W7: =IF(I7=0,"***",P7/I7) | X7: =IF(J7=0,"***",Q7/J7) | Y7: =IF(K7=0,"***",R7/K7)
C8: 0910 集計 | D8: 足立課長 | E8: 6691 | F8: 59 | G8: 60 | K8: =SUM(E8:J8) | L8: 1276 | M8: 14 | N8: 16 | R8: =SUM(L8:Q8) | S8: =IF(E8=0,"***",L8/E8) | T8: =IF(F8=0,"***",M8/F8) | U8: =IF(G8=0,"***",N8/G8) | V8: =IF(H8=0,"***",O8/H8) | W8: =IF(I8=0,"***",P8/I8) | X8: =IF(J8=0,"***",Q8/J8) | Y8: =IF(K8=0,"***",R8/K8)
C9: 0911 集計 | D9: 川邊主任 | E9: 393 | F9: 1326 | G9: 753 | H9: 511 | I9: 237 | J9: 389 | K9: =SUM(E9:J9) | L9: 101 | M9: 298 | N9: 166 | O9: 124 | P9: 52 | Q9: 87 | R9: =SUM(L9:Q9) | S9: =IF(E9=0,"***",L9/E9) | T9: =IF(F9=0,"***",M9/F9) | U9: =IF(G9=0,"***",N9/G9) | V9: =IF(H9=0,"***",O9/H9) | W9: =IF(I9=0,"***",P9/I9) | X9: =IF(J9=0,"***",Q9/J9) | Y9: =IF(K9=0,"***",R9/K9)
C10: 0914 集計 | D10: 白根主任 | E10: 978 | F10: 3707 | G10: 2099 | H10: 711 | I10: 326 | J10: 956 | K10: =SUM(E10:J10) | L10: 278 | M10: 384 | N10: 539 | O10: 197 | P10: 89 | Q10: 260 | R10: =SUM(L10:Q10) | S10: =IF(E10=0,"***",L10/E10) | T10: =IF(F10=0,"***",M10/F10) | U10: =IF(G10=0,"***",N10/G10) | V10: =IF(H10=0,"***",O10/H10) | W10: =IF(I10=0,"***",P10/I10) | X10: =IF(J10=0,"***",Q10/J10) | Y10: =IF(K10=0,"***",R10/K10)
C11: 0918 集計 | D11: 海外 | E11: 199 | F11: 2039 | G11: 379 | H11: 108 | I11: 35 | J11: 0 | K11: =SUM(E11:J11) | L11: 56 | M11: 381 | N11: 90 | O11: 27 | P11: 29 | Q11: 0 | R11: =SUM(L11:Q11) | S11: =IF(E11=0,"***",L11/E11) | T11: =IF(F11=0,"***",M11/F11) | U11: =IF(G11=0,"***",N11/G11) | V11: =IF(H11=0,"***",O11/H11) | W11: =IF(I11=0,"***",P11/I11) | X11: =IF(J11=0,"***",Q11/J11) | Y11: =IF(K11=0,"***",R11/K11)
C12: 0919 集計 | D12: その他 | E12: 0 | F12: 0 | G12: 0 | H12: 0 | I12: 0 | J12: 4 | K12: =SUM(E12:J12) | L12: 0 | M12: 0 | N12: 0 | O12: 0 | P12: 0 | Q12: 1 | R12: =SUM(L12:Q12) | S12: =IF(E12=0,"***",L12/E12) | T12: =IF(F12=0,"***",M12/F12) | U12: =IF(G12=0,"***",N12/G12) | V12: =IF(H12=0,"***",O12/H12) | W12: =IF(I12=0,"***",P12/I12) | X12: =IF(J12=0,"***",Q12/J12) | Y12: =IF(K12=0,"***",R12/K12)
C13: 0930 集計 | D13: 自治体 | K13: =SUM(E13:J13) | R13: =SUM(L13:Q13) | S13: =IF(E13=0,"***",L13/E13) | T13: =IF(F13=0,"***",M13/F13) | U13: =IF(G13=0,"***",N13/G13) | V13: =IF(H13=0,"***",O13/H13) | W13: =IF(I13=0,"***",P13/I13) | X13: =IF(J13=0,"***",Q13/J13) | Y13: =IF(K13=0,"***",R13/K13)
C14: 合計 | E14: =SUM(E5:E13) | F14: =SUM(F5:F13) | G14: =SUM(G5:G13) | H14: =SUM(H5:H13) | I14: =SUM(I5:I13) | J14: =SUM(J5:J13) | K14: =SUM(K5:K13) | L14: =SUM(L5:L13) | ... R14: =SUM(R5:R13) | S14: =IF(E14=0,"***",L14/E14) | T14: =IF(F14=0,"***",M14/F14) | U14: =IF(G14=0,"***",N14/G14) | V14: =IF(H14=0,"***",O14/H14) | W14: =IF(I14=0,"***",P14/I14) | X14: =IF(J14=0,"***",Q14/J14) | Y14: =IF(K14=0,"***",R14/K14)
C16: 2．2025年
E17: 売上 | L17: 粗利益 | S17: 粗利益率
E18: 45748 | F18: 45778 | G18: 45809 | H18: 45839 | I18: 45870 | J18: 45901 | K18: 合計 | L18: 45748 | M18: 45778 | N18: 45809 | O18: 45839 | P18: 45870 | Q18: 45901 | R18: 合計 | S18: 45748 | T18: 45778 | U18: 45809 | V18: 45839 | W18: 45870 | X18: 45901 | Y18: 合計
C19: 0903 集計 | D19: 西岡 | E19: 145 | F19: 22 | G19: 250 | H19: =57+130 | I19: =60+8 | J19: =130+5 | K19: =SUM(E19:J19) | L19: 35 | M19: 3 | N19: 127 | O19: =23+27 | P19: =14+0 | Q19: =32+1 | R19: =SUM(L19:Q19) | S19: =IF(E19=0,"***",L19/E19) | T19: =IF(F19=0,"***",M19/F19) | U19: =IF(G19=0,"***",N19/G19) | V19: =IF(H19=0,"***",O19/H19) | W19: =IF(I19=0,"***",P19/I19) | X19: =IF(J19=0,"***",Q19/J19) | Y19: =IF(K19=0,"***",R19/K19)
C20: 0904 集計 | D20: 足立次長 | E20: 625 | F20: 200 | G20: 207 | H20: 1557 | I20: 82542 | J20: 30771 | K20: =SUM(E20:J20) | L20: 106 | M20: 40 | N20: 37 | O20: 296 | P20: 13969 | Q20: 7512 | R20: =SUM(L20:Q20) | S20: =IF(E20=0,"***",L20/E20) | T20: =IF(F20=0,"***",M20/F20) | U20: =IF(G20=0,"***",N20/G20) | V20: =IF(H20=0,"***",O20/H20) | W20: =IF(I20=0,"***",P20/I20) | X20: =IF(J20=0,"***",Q20/J20) | Y20: =IF(K20=0,"***",R20/K20)
C21: 0909 集計 | D21: 藤波課長 | E21: 419 | F21: 740 | G21: 708 | H21: =3107+1124-130 | I21: =434+1804 | J21: =244+132-5 | K21: =SUM(E21:J21) | L21: 172 | M21: 261 | N21: 302 | O21: =945+376-27 | P21: =190+491-0 | Q21: =141+33-1 | R21: =SUM(L21:Q21) | S21: =IF(E21=0,"***",L21/E21) | T21: =IF(F21=0,"***",M21/F21) | U21: =IF(G21=0,"***",N21/G21) | V21: =IF(H21=0,"***",O21/H21) | W21: =IF(I21=0,"***",P21/I21) | X21: =IF(J21=0,"***",Q21/J21) | Y21: =IF(K21=0,"***",R21/K21)
C22: 0910 集計 | D22: 足立課長 | E22: 114 | F22: 87 | G22: 124 | K22: =SUM(E22:J22) | L22: 31 | M22: 31 | N22: 34 | R22: =SUM(L22:Q22) | S22: =IF(E22=0,"***",L22/E22) | T22: =IF(F22=0,"***",M22/F22) | U22: =IF(G22=0,"***",N22/G22) | V22: =IF(H22=0,"***",O22/H22) | W22: =IF(I22=0,"***",P22/I22) | X22: =IF(J22=0,"***",Q22/J22) | Y22: =IF(K22=0,"***",R22/K22)
C23: 0911 集計 | D23: 川邊主任 | E23: 319 | F23: 1653 | G23: 400 | H23: 906 | I23: 402 | J23: 243 | K23: =SUM(E23:J23) | L23: 101 | M23: 284 | N23: 90 | O23: 184 | P23: 77 | Q23: 39 | R23: =SUM(L23:Q23) | S23: =IF(E23=0,"***",L23/E23) | T23: =IF(F23=0,"***",M23/F23) | U23: =IF(G23=0,"***",N23/G23) | V23: =IF(H23=0,"***",O23/H23) | W23: =IF(I23=0,"***",P23/I23) | X23: =IF(J23=0,"***",Q23/J23) | Y23: =IF(K23=0,"***",R23/K23)
C24: 0914 集計 | D24: 白根主任 | E24: 1021 | F24: 176 | G24: 6504 | H24: 738 | I24: 427 | J24: 394 | K24: =SUM(E24:J24) | L24: 346 | M24: 55 | N24: 1639 | O24: 217 | P24: 158 | Q24: 101 | R24: =SUM(L24:Q24) | S24: =IF(E24=0,"***",L24/E24) | T24: =IF(F24=0,"***",M24/F24) | U24: =IF(G24=0,"***",N24/G24) | V24: =IF(H24=0,"***",O24/H24) | W24: =IF(I24=0,"***",P24/I24) | X24: =IF(J24=0,"***",Q24/J24) | Y24: =IF(K24=0,"***",R24/K24)
C25: 0918 集計 | D25: 海外 | E25: 643 | F25: 95 | G25: 576 | H25: 219 | I25: 2 | J25: 176 | K25: =SUM(E25:J25) | L25: 130 | M25: 19 | N25: 130 | O25: 47 | P25: 0 | Q25: 48 | R25: =SUM(L25:Q25) | S25: =IF(E25=0,"***",L25/E25) | T25: =IF(F25=0,"***",M25/F25) | U25: =IF(G25=0,"***",N25/G25) | V25: =IF(H25=0,"***",O25/H25) | W25: =IF(I25=0,"***",P25/I25) | X25: =IF(J25=0,"***",Q25/J25) | Y25: =IF(K25=0,"***",R25/K25)
C26: 0919 集計 | D26: その他 | E26: 0 | F26: 0 | G26: 0 | H26: 0 | I26: 0 | J26: 0 | K26: =SUM(E26:J26) | L26: 0 | M26: 0 | N26: 0 | O26: 0 | P26: 0 | Q26: 0 | R26: =SUM(L26:Q26) | S26: =IF(E26=0,"***",L26/E26) | T26: =IF(F26=0,"***",M26/F26) | U26: =IF(G26=0,"***",N26/G26) | V26: =IF(H26=0,"***",O26/H26) | W26: =IF(I26=0,"***",P26/I26) | X26: =IF(J26=0,"***",Q26/J26) | Y26: =IF(K26=0,"***",R26/K26)
C27: 0930 集計 | D27: 自治体
C28: 合計 | E28: =SUM(E19:E27) | F28: =SUM(F19:F27) | G28: =SUM(G19:G27) | H28: =SUM(H19:H27) | I28: =SUM(I19:I27) | J28: =SUM(J19:J27) | K28: =SUM(K19:K27) | L28: =SUM(L19:L27) | ... R28: =SUM(R19:R27) | S28: =IF(E28=0,"***",L28/E28) | T28: =IF(F28=0,"***",M28/F28) | U28: =IF(G28=0,"***",N28/G28) | V28: =IF(H28=0,"***",O28/H28) | W28: =IF(I28=0,"***",P28/I28) | X28: =IF(J28=0,"***",Q28/J28) | Y28: =IF(K28=0,"***",R28/K28)
C30: 3．過年度平均
E31: 売上 | L31: 粗利益 | S31: 粗利益率
E32: 45748 | F32: 45778 | G32: 45809 | H32: 45839 | I32: 45870 | J32: 45901 | K32: 合計 | L32: 45748 | M32: 45778 | N32: 45809 | O32: 45839 | P32: 45870 | Q32: 45901 | R32: 合計 | S32: 45748 | T32: 45778 | U32: 45809 | V32: 45839 | W32: 45870 | X32: 45901 | Y32: 合計
C33: 0903 集計 | D33: 西岡 | E33: =(E19+E5)/2 | F33: =(F19+F5)/2 | G33: =(G19+G5)/2 | H33: =(H19+H5)/2 | I33: =(I19+I5)/2 | J33: =(J19+J5)/2 | K33: =SUM(E33:J33) | L33: =(L19+L5)/2 | M33: =(M19+M5)/2 | N33: =(N19+N5)/2 | O33: =(O19+O5)/2 | P33: =(P19+P5)/2 | Q33: =(Q19+Q5)/2 | R33: =SUM(L33:Q33) | S33: =IF(E33=0,"***",L33/E33) | T33: =IF(F33=0,"***",M33/F33) | U33: =IF(G33=0,"***",N33/G33) | V33: =IF(H33=0,"***",O33/H33) | W33: =IF(I33=0,"***",P33/I33) | X33: =IF(J33=0,"***",Q33/J33) | Y33: =IF(K33=0,"***",R33/K33)
C34: 0904 集計 | D34: 足立次長 | E34: =(E20+E6)/2 | F34: =(F20+F6)/2 | G34: =(G20+G6)/2 | H34: =(H20+H6)/2 | I34: =(I20+I6)/2 | J34: =(J20+J6)/2 | K34: =SUM(E34:J34) | L34: =(L20+L6)/2 | M34: =(M20+M6)/2 | N34: =(N20+N6)/2 | O34: =(O20+O6)/2 | P34: =(P20+P6)/2 | Q34: =(Q20+Q6)/2 | R34: =SUM(L34:Q34) | S34: =IF(E34=0,"***",L34/E34) | T34: =IF(F34=0,"***",M34/F34) | U34: =IF(G34=0,"***",N34/G34) | V34: =IF(H34=0,"***",O34/H34) | W34: =IF(I34=0,"***",P34/I34) | X34: =IF(J34=0,"***",Q34/J34) | Y34: =IF(K34=0,"***",R34/K34)
C35: 0909 集計 | D35: 藤波課長 | E35: =(E21+E7)/2 | F35: =(F21+F7)/2 | G35: =(G21+G7)/2 | H35: =(H21+H7)/2 | I35: =(I21+I7)/2 | J35: =(J21+J7)/2 | K35: =SUM(E35:J35) | L35: =(L21+L7)/2 | M35: =(M21+M7)/2 | N35: =(N21+N7)/2 | O35: =(O21+O7)/2 | P35: =(P21+P7)/2 | Q35: =(Q21+Q7)/2 | R35: =SUM(L35:Q35) | S35: =IF(E35=0,"***",L35/E35) | T35: =IF(F35=0,"***",M35/F35) | U35: =IF(G35=0,"***",N35/G35) | V35: =IF(H35=0,"***",O35/H35) | W35: =IF(I35=0,"***",P35/I35) | X35: =IF(J35=0,"***",Q35/J35) | Y35: =IF(K35=0,"***",R35/K35)
C36: 0910 集計 | D36: 足立課長 | E36: =(E22+E8)/2 | F36: =(F22+F8)/2 | G36: =(G22+G8)/2 | H36: =(H22+H8)/2 | I36: =(I22+I8)/2 | J36: =(J22+J8)/2 | K36: =SUM(E36:J36) | L36: =(L22+L8)/2 | M36: =(M22+M8)/2 | N36: =(N22+N8)/2 | O36: =(O22+O8)/2 | P36: =(P22+P8)/2 | Q36: =(Q22+Q8)/2 | R36: =SUM(L36:Q36) | S36: =IF(E36=0,"***",L36/E36) | T36: =IF(F36=0,"***",M36/F36) | U36: =IF(G36=0,"***",N36/G36) | V36: =IF(H36=0,"***",O36/H36) | W36: =IF(I36=0,"***",P36/I36) | X36: =IF(J36=0,"***",Q36/J36) | Y36: =IF(K36=0,"***",R36/K36)
C37: 0911 集計 | D37: 川邊主任 | E37: =(E23+E9)/2 | F37: =(F23+F9)/2 | G37: =(G23+G9)/2 | H37: =(H23+H9)/2 | I37: =(I23+I9)/2 | J37: =(J23+J9)/2 | K37: =SUM(E37:J37) | L37: =(L23+L9)/2 | M37: =(M23+M9)/2 | N37: =(N23+N9)/2 | O37: =(O23+O9)/2 | P37: =(P23+P9)/2 | Q37: =(Q23+Q9)/2 | R37: =SUM(L37:Q37) | S37: =IF(E37=0,"***",L37/E37) | T37: =IF(F37=0,"***",M37/F37) | U37: =IF(G37=0,"***",N37/G37) | V37: =IF(H37=0,"***",O37/H37) | W37: =IF(I37=0,"***",P37/I37) | X37: =IF(J37=0,"***",Q37/J37) | Y37: =IF(K37=0,"***",R37/K37)
C38: 0914 集計 | D38: 白根主任 | E38: =(E24+E10)/2 | F38: =(F24+F10)/2 | G38: =(G24+G10)/2 | H38: =(H24+H10)/2 | I38: =(I24+I10)/2 | J38: =(J24+J10)/2 | K38: =SUM(E38:J38) | L38: =(L24+L10)/2 | M38: =(M24+M10)/2 | N38: =(N24+N10)/2 | O38: =(O24+O10)/2 | P38: =(P24+P10)/2 | Q38: =(Q24+Q10)/2 | R38: =SUM(L38:Q38) | S38: =IF(E38=0,"***",L38/E38) | T38: =IF(F38=0,"***",M38/F38) | U38: =IF(G38=0,"***",N38/G38) | V38: =IF(H38=0,"***",O38/H38) | W38: =IF(I38=0,"***",P38/I38) | X38: =IF(J38=0,"***",Q38/J38) | Y38: =IF(K38=0,"***",R38/K38)
C39: 0918 集計 | D39: 海外 | E39: =(E25+E11)/2 | F39: =(F25+F11)/2 | G39: =(G25+G11)/2 | H39: =(H25+H11)/2 | I39: =(I25+I11)/2 | J39: =(J25+J11)/2 | K39: =SUM(E39:J39) | L39: =(L25+L11)/2 | M39: =(M25+M11)/2 | N39: =(N25+N11)/2 | O39: =(O25+O11)/2 | P39: =(P25+P11)/2 | Q39: =(Q25+Q11)/2 | R39: =SUM(L39:Q39) | S39: =IF(E39=0,"***",L39/E39) | T39: =IF(F39=0,"***",M39/F39) | U39: =IF(G39=0,"***",N39/G39) | V39: =IF(H39=0,"***",O39/H39) | W39: =IF(I39=0,"***",P39/I39) | X39: =IF(J39=0,"***",Q39/J39) | Y39: =IF(K39=0,"***",R39/K39)
C40: 0919 集計 | D40: その他 | E40: =(E26+E12)/2 | F40: =(F26+F12)/2 | G40: =(G26+G12)/2 | H40: =(H26+H12)/2 | I40: =(I26+I12)/2 | J40: =(J26+J12)/2 | K40: =SUM(E40:J40) | L40: =(L26+L12)/2 | M40: =(M26+M12)/2 | N40: =(N26+N12)/2 | O40: =(O26+O12)/2 | P40: =(P26+P12)/2 | Q40: =(Q26+Q12)/2 | R40: =SUM(L40:Q40) | S40: =IF(E40=0,"***",L40/E40) | T40: =IF(F40=0,"***",M40/F40) | U40: =IF(G40=0,"***",N40/G40) | V40: =IF(H40=0,"***",O40/H40) | W40: =IF(I40=0,"***",P40/I40) | X40: =IF(J40=0,"***",Q40/J40) | Y40: =IF(K40=0,"***",R40/K40)
C41: 0930 集計 | D41: 自治体 | E41: =(E27+E13)/2 | F41: =(F27+F13)/2 | G41: =(G27+G13)/2 | H41: =(H27+H13)/2 | I41: =(I27+I13)/2 | J41: =(J27+J13)/2 | K41: =SUM(E41:J41) | L41: =(L27+L13)/2 | M41: =(M27+M13)/2 | N41: =(N27+N13)/2 | O41: =(O27+O13)/2 | P41: =(P27+P13)/2 | Q41: =(Q27+Q13)/2 | R41: =SUM(L41:Q41) | S41: =IF(E41=0,"***",L41/E41) | T41: =IF(F41=0,"***",M41/F41) | U41: =IF(G41=0,"***",N41/G41) | V41: =IF(H41=0,"***",O41/H41) | W41: =IF(I41=0,"***",P41/I41) | X41: =IF(J41=0,"***",Q41/J41) | Y41: =IF(K41=0,"***",R41/K41)
C42: 合計 | E42: =SUM(E33:E41) | F42: =SUM(F33:F41) | G42: =SUM(G33:G41) | H42: =SUM(H33:H41) | I42: =SUM(I33:I41) | J42: =SUM(J33:J41) | K42: =SUM(K33:K41) | L42: =SUM(L33:L41) | ... R42: =SUM(R33:R41) | S42: =IF(E42=0,"***",L42/E42) | T42: =IF(F42=0,"***",M42/F42) | U42: =IF(G42=0,"***",N42/G42) | V42: =IF(H42=0,"***",O42/H42) | W42: =IF(I42=0,"***",P42/I42) | X42: =IF(J42=0,"***",Q42/J42) | Y42: =IF(K42=0,"***",R42/K42)
...

Sheet 全体
C1: 境港営業所全体
C2: 1．2024年
E3: 売上 | L3: 粗利益 | S3: 粗利益率
E4: 45383 | F4: 45413 | G4: 45444 | H4: 45474 | I4: 45505 | J4: 45536 | K4: 合計 | L4: 45383 | M4: 45413 | N4: 45444 | O4: 45474 | P4: 45505 | Q4: 45536 | R4: 合計 | S4: 45383 | T4: 45413 | U4: 45444 | V4: 45474 | W4: 45505 | X4: 45536 | Y4: 合計
C5: 0903 集計 | D5: 西岡 | E5: 2992.321 | F5: 1870.416 | G5: 2624.67 | H5: 2506.235 | I5: 2707.683 | J5: 4067.607 | K5: =SUM(E5:J5) | L5: 548.984 | M5: 363.353 | N5: 510.638 | O5: 513.458 | P5: 563.279 | Q5: 811.5544 | R5: =SUM(L5:Q5) | S5: =IF(E5=0,"***",L5/E5) | T5: =IF(F5=0,"***",M5/F5) | U5: =IF(G5=0,"***",N5/G5) | V5: =IF(H5=0,"***",O5/H5) | W5: =IF(I5=0,"***",P5/I5) | X5: =IF(J5=0,"***",Q5/J5) | Y5: =IF(K5=0,"***",R5/K5)
C6: 0904 集計 | D6: 足立次長 | E6: 9457.609 | F6: 33342.444 | G6: 9536.075 | H6: 12322.971 | I6: 8433.195 | J6: 12377.608 | K6: =SUM(E6:J6) | L6: 2013.302 | M6: 6923.814 | N6: 1850.747 | O6: 2403.043 | P6: 1946.27 | Q6: 2430.328 | R6: =SUM(L6:Q6) | S6: =IF(E6=0,"***",L6/E6) | T6: =IF(F6=0,"***",M6/F6) | U6: =IF(G6=0,"***",N6/G6) | V6: =IF(H6=0,"***",O6/H6) | W6: =IF(I6=0,"***",P6/I6) | X6: =IF(J6=0,"***",Q6/J6) | Y6: =IF(K6=0,"***",R6/K6)
C7: 0909 集計 | D7: 藤波課長 | E7: 7831.518 | F7: 7149.748 | G7: 5762.823 | H7: 8011.724 | I7: 6436.908 | J7: 8821.121 | K7: =SUM(E7:J7) | L7: 1249.792 | M7: 1193.97 | N7: 1008.843 | O7: 1465.948 | P7: 1134.483 | Q7: 1613.746 | R7: =SUM(L7:Q7) | S7: =IF(E7=0,"***",L7/E7) | T7: =IF(F7=0,"***",M7/F7) | U7: =IF(G7=0,"***",N7/G7) | V7: =IF(H7=0,"***",O7/H7) | W7: =IF(I7=0,"***",P7/I7) | X7: =IF(J7=0,"***",Q7/J7) | Y7: =IF(K7=0,"***",R7/K7)
C8: 0910 集計 | D8: 足立課長 | E8: 8439.824 | F8: 1787.369 | G8: 1386.514 | K8: =SUM(E8:J8) | L8: 1598.596 | M8: 276.611 | N8: 246.168 | R8: =SUM(L8:Q8) | S8: =IF(E8=0,"***",L8/E8) | T8: =IF(F8=0,"***",M8/F8) | U8: =IF(G8=0,"***",N8/G8) | V8: =IF(H8=0,"***",O8/H8) | W8: =IF(I8=0,"***",P8/I8) | X8: =IF(J8=0,"***",Q8/J8) | Y8: =IF(K8=0,"***",R8/K8)
C9: 0911 集計 | D9: 川邊主任 | E9: 9628.221 | F9: 8898.137 | G9: 8938.893 | H9: 8453.326 | I9: 8467.791 | J9: 9049.48 | K9: =SUM(E9:J9) | L9: 1562.079 | M9: 1570.745 | N9: 1489.311 | O9: 1463.971 | P9: 1504.084 | Q9: 1448.511 | R9: =SUM(L9:Q9) | S9: =IF(E9=0,"***",L9/E9) | T9: =IF(F9=0,"***",M9/F9) | U9: =IF(G9=0,"***",N9/G9) | V9: =IF(H9=0,"***",O9/H9) | W9: =IF(I9=0,"***",P9/I9) | X9: =IF(J9=0,"***",Q9/J9) | Y9: =IF(K9=0,"***",R9/K9)
C10: 0914 集計 | D10: 白根主任 | E10: 8795.503 | F10: 11637.292 | G10: 9494.164 | H10: 10083.54 | I10: 18835.421 | J10: 25101.073 | K10: =SUM(E10:J10) | L10: 1505.568 | M10: 1605.192 | N10: 1706.263 | O10: 1787.849 | P10: 4384.14 | Q10: 5731.302 | R10: =SUM(L10:Q10) | S10: =IF(E10=0,"***",L10/E10) | T10: =IF(F10=0,"***",M10/F10) | U10: =IF(G10=0,"***",N10/G10) | V10: =IF(H10=0,"***",O10/H10) | W10: =IF(I10=0,"***",P10/I10) | X10: =IF(J10=0,"***",Q10/J10) | Y10: =IF(K10=0,"***",R10/K10)
C11: 0918 集計 | D11: 海外 | E11: 462.725 | F11: 2599.656 | G11: 378.6 | H11: 1452.4 | I11: 232.15 | J11: 3240.614 | K11: =SUM(E11:J11) | L11: 127.104 | M11: 474.93 | N11: 89.88 | O11: 218.502 | P11: 73.45 | Q11: 653.405 | R11: =SUM(L11:Q11) | S11: =IF(E11=0,"***",L11/E11) | T11: =IF(F11=0,"***",M11/F11) | U11: =IF(G11=0,"***",N11/G11) | V11: =IF(H11=0,"***",O11/H11) | W11: =IF(I11=0,"***",P11/I11) | X11: =IF(J11=0,"***",Q11/J11) | Y11: =IF(K11=0,"***",R11/K11)
C12: 0919 集計 | D12: その他 | E12: 25.21 | F12: 37.986 | G12: 27.305 | H12: 17.22 | I12: 39.025 | J12: 44.165 | K12: =SUM(E12:J12) | L12: 5.949 | M12: 8.269 | N12: 6.925 | O12: 2.97 | P12: 6.325 | Q12: 12.399 | R12: =SUM(L12:Q12) | S12: =IF(E12=0,"***",L12/E12) | T12: =IF(F12=0,"***",M12/F12) | U12: =IF(G12=0,"***",N12/G12) | V12: =IF(H12=0,"***",O12/H12) | W12: =IF(I12=0,"***",P12/I12) | X12: =IF(J12=0,"***",Q12/J12) | Y12: =IF(K12=0,"***",R12/K12)
C13: 0930 集計 | D13: 自治体 | E13: 0 | F13: 0 | G13: 56.54 | H13: 0 | I13: 0 | J13: 0 | K13: =SUM(E13:J13) | L13: 0 | M13: 0 | N13: 1.751 | O13: 0 | P13: 0 | Q13: 0 | R13: =SUM(L13:Q13) | S13: =IF(E13=0,"***",L13/E13) | T13: =IF(F13=0,"***",M13/F13) | U13: =IF(G13=0,"***",N13/G13) | V13: =IF(H13=0,"***",O13/H13) | W13: =IF(I13=0,"***",P13/I13) | X13: =IF(J13=0,"***",Q13/J13) | Y13: =IF(K13=0,"***",R13/K13)
C14: 合計 | E14: =SUM(E5:E13) | F14: =SUM(F5:F13) | G14: =SUM(G5:G13) | H14: =SUM(H5:H13) | I14: =SUM(I5:I13) | J14: =SUM(J5:J13) | K14: =SUM(K5:K13) | L14: =SUM(L5:L13) | ... R14: =SUM(R5:R13) | S14: =IF(E14=0,"***",L14/E14) | T14: =IF(F14=0,"***",M14/F14) | U14: =IF(G14=0,"***",N14/G14) | V14: =IF(H14=0,"***",O14/H14) | W14: =IF(I14=0,"***",P14/I14) | X14: =IF(J14=0,"***",Q14/J14) | Y14: =IF(K14=0,"***",R14/K14)
C16: 2．2025年
E17: 売上 | L17: 粗利益 | S17: 粗利益率
E18: 45748 | F18: 45778 | G18: 45809 | H18: 45839 | I18: 45870 | J18: 45901 | K18: 合計 | L18: 45748 | M18: 45778 | N18: 45809 | O18: 45839 | P18: 45870 | Q18: 45901 | R18: 合計 | S18: 45748 | T18: 45778 | U18: 45809 | V18: 45839 | W18: 45870 | X18: 45901 | Y18: 合計
C19: 0903 集計 | D19: 西岡 | E19: 2842.845 | F19: 1782.782 | G19: 2650.612 | H19: 2128.284 | I19: 1678.593 | J19: 3222.317 | K19: =SUM(E19:J19) | L19: 549.261 | M19: 400.415 | N19: 592.779 | O19: 470.908 | P19: 329.85 | Q19: 643.129 | R19: =SUM(L19:Q19) | S19: =IF(E19=0,"***",L19/E19) | T19: =IF(F19=0,"***",M19/F19) | U19: =IF(G19=0,"***",N19/G19) | V19: =IF(H19=0,"***",O19/H19) | W19: =IF(I19=0,"***",P19/I19) | X19: =IF(J19=0,"***",Q19/J19) | Y19: =IF(K19=0,"***",R19/K19)
C20: 0904 集計 | D20: 足立次長 | E20: 11862.965 | F20: 11689.497 | G20: 7550.568 | H20: 13687.464 | I20: 94774.135 | J20: 40900.174 | K20: =SUM(E20:J20) | L20: 2574.856 | M20: 2531.644 | N20: 1747.441 | O20: 2580.203 | P20: 16143.789 | Q20: 9365.84 | R20: =SUM(L20:Q20) | S20: =IF(E20=0,"***",L20/E20) | T20: =IF(F20=0,"***",M20/F20) | U20: =IF(G20=0,"***",N20/G20) | V20: =IF(H20=0,"***",O20/H20) | W20: =IF(I20=0,"***",P20/I20) | X20: =IF(J20=0,"***",Q20/J20) | Y20: =IF(K20=0,"***",R20/K20)
C21: 0909 集計 | D21: 藤波課長 | E21: 7842.768 | F21: 5683.808 | G21: 6360.448 | H21: 12802.674 | I21: 10570.955 | J21: 12015.35 | K21: =SUM(E21:J21) | L21: 1363.778 | M21: 1061.963 | N21: 1284.442 | O21: 2847.084 | P21: 2207.566 | Q21: 2274.845 | R21: =SUM(L21:Q21) | S21: =IF(E21=0,"***",L21/E21) | T21: =IF(F21=0,"***",M21/F21) | U21: =IF(G21=0,"***",N21/G21) | V21: =IF(H21=0,"***",O21/H21) | W21: =IF(I21=0,"***",P21/I21) | X21: =IF(J21=0,"***",Q21/J21) | Y21: =IF(K21=0,"***",R21/K21)
C22: 0910 集計 | D22: 足立課長 | E22: 2264.573 | F22: 1770.147 | G22: 1664.316 | K22: =SUM(E22:J22) | L22: 450.801 | M22: 345.224 | N22: 314.771 | R22: =SUM(L22:Q22) | S22: =IF(E22=0,"***",L22/E22) | T22: =IF(F22=0,"***",M22/F22) | U22: =IF(G22=0,"***",N22/G22) | V22: =IF(H22=0,"***",O22/H22) | W22: =IF(I22=0,"***",P22/I22) | X22: =IF(J22=0,"***",Q22/J22) | Y22: =IF(K22=0,"***",R22/K22)
C23: 0911 集計 | D23: 川邊主任 | E23: 10963.509 | F23: 10807.006 | G23: 7331.919 | H23: 10739.124 | I23: 6927.711 | J23: 9685.745 | K23: =SUM(E23:J23) | L23: 1855.471 | M23: 1855.43 | N23: 1341.294 | O23: 1734.601 | P23: 1138.342 | Q23: 1483.015 | R23: =SUM(L23:Q23) | S23: =IF(E23=0,"***",L23/E23) | T23: =IF(F23=0,"***",M23/F23) | U23: =IF(G23=0,"***",N23/G23) | V23: =IF(H23=0,"***",O23/H23) | W23: =IF(I23=0,"***",P23/I23) | X23: =IF(J23=0,"***",Q23/J23) | Y23: =IF(K23=0,"***",R23/K23)
C24: 0914 集計 | D24: 白根主任 | E24: 8829.619 | F24: 8702.497 | G24: 13277.306 | H24: 11551.865 | I24: 8043.705 | J24: 22830.648 | K24: =SUM(E24:J24) | L24: 1721.514 | M24: 1717.424 | N24: 2915.928 | O24: 2832.065 | P24: 1698.655 | Q24: 5392.991 | R24: =SUM(L24:Q24) | S24: =IF(E24=0,"***",L24/E24) | T24: =IF(F24=0,"***",M24/F24) | U24: =IF(G24=0,"***",N24/G24) | V24: =IF(H24=0,"***",O24/H24) | W24: =IF(I24=0,"***",P24/I24) | X24: =IF(J24=0,"***",Q24/J24) | Y24: =IF(K24=0,"***",R24/K24)
C25: 0918 集計 | D25: 海外 | E25: 1833.894 | F25: 2423.2 | G25: 1376.87 | H25: 604.22 | I25: 21.15 | J25: 693.45 | K25: =SUM(E25:J25) | L25: 326.979 | M25: 339.583 | N25: 289.41 | O25: 117.704 | P25: 5.8 | Q25: 204.995 | R25: =SUM(L25:Q25) | S25: =IF(E25=0,"***",L25/E25) | T25: =IF(F25=0,"***",M25/F25) | U25: =IF(G25=0,"***",N25/G25) | V25: =IF(H25=0,"***",O25/H25) | W25: =IF(I25=0,"***",P25/I25) | X25: =IF(J25=0,"***",Q25/J25) | Y25: =IF(K25=0,"***",R25/K25)
C26: 0919 集計 | D26: その他 | E26: 33.365 | F26: 30.73 | G26: 37.726 | H26: 17.86 | I26: 32.296 | J26: 30.7 | K26: =SUM(E26:J26) | L26: 6.939 | M26: 6.67 | N26: 7.436 | O26: 3 | P26: 8.956 | Q26: 6.12 | R26: =SUM(L26:Q26) | S26: =IF(E26=0,"***",L26/E26) | T26: =IF(F26=0,"***",M26/F26) | U26: =IF(G26=0,"***",N26/G26) | V26: =IF(H26=0,"***",O26/H26) | W26: =IF(I26=0,"***",P26/I26) | X26: =IF(J26=0,"***",Q26/J26) | Y26: =IF(K26=0,"***",R26/K26)
C27: 0930 集計 | D27: 自治体 | E27: 0 | F27: 87.14 | G27: 0 | H27: 0 | I27: 0 | J27: 0 | K27: =SUM(E27:J27) | L27: 0 | M27: 4.893 | N27: 0 | O27: 0 | P27: 0 | Q27: 0 | R27: =SUM(L27:Q27) | S27: =IF(E27=0,"***",L27/E27) | T27: =IF(F27=0,"***",M27/F27) | U27: =IF(G27=0,"***",N27/G27) | V27: =IF(H27=0,"***",O27/H27) | W27: =IF(I27=0,"***",P27/I27) | X27: =IF(J27=0,"***",Q27/J27) | Y27: =IF(K27=0,"***",R27/K27)
C28: 合計 | E28: =SUM(E19:E27) | F28: =SUM(F19:F27) | G28: =SUM(G19:G27) | H28: =SUM(H19:H27) | I28: =SUM(I19:I27) | J28: =SUM(J19:J27) | K28: =SUM(K19:K27) | L28: =SUM(L19:L27) | ... R28: =SUM(R19:R27) | S28: =IF(E28=0,"***",L28/E28) | T28: =IF(F28=0,"***",M28/F28) | U28: =IF(G28=0,"***",N28/G28) | V28: =IF(H28=0,"***",O28/H28) | W28: =IF(I28=0,"***",P28/I28) | X28: =IF(J28=0,"***",Q28/J28) | Y28: =IF(K28=0,"***",R28/K28)
C30: 3．過年度平均
E31: 売上 | L31: 粗利益 | S31: 粗利益率
E32: 45748 | F32: 45778 | G32: 45809 | H32: 45839 | I32: 45870 | J32: 45901 | K32: 合計 | L32: 45748 | M32: 45778 | N32: 45809 | O32: 45839 | P32: 45870 | Q32: 45901 | R32: 合計 | S32: 45748 | T32: 45778 | U32: 45809 | V32: 45839 | W32: 45870 | X32: 45901 | Y32: 合計
C33: 0903 集計 | D33: 西岡 | E33: =(E19+E5)/2 | F33: =(F19+F5)/2 | G33: =(G19+G5)/2 | H33: =(H19+H5)/2 | I33: =(I19+I5)/2 | J33: =(J19+J5)/2 | K33: =SUM(E33:J33) | L33: =(L19+L5)/2 | M33: =(M19+M5)/2 | N33: =(N19+N5)/2 | O33: =(O19+O5)/2 | P33: =(P19+P5)/2 | Q33: =(Q19+Q5)/2 | R33: =SUM(L33:Q33) | S33: =IF(E33=0,"***",L33/E33) | T33: =IF(F33=0,"***",M33/F33) | U33: =IF(G33=0,"***",N33/G33) | V33: =IF(H33=0,"***",O33/H33) | W33: =IF(I33=0,"***",P33/I33) | X33: =IF(J33=0,"***",Q33/J33) | Y33: =IF(K33=0,"***",R33/K33)
C34: 0904 集計 | D34: 足立次長 | E34: =(E20+E6)/2 | F34: =(F20+F6)/2 | G34: =(G20+G6)/2 | H34: =(H20+H6)/2 | I34: =(I20+I6)/2 | J34: =(J20+J6)/2 | K34: =SUM(E34:J34) | L34: =(L20+L6)/2 | M34: =(M20+M6)/2 | N34: =(N20+N6)/2 | O34: =(O20+O6)/2 | P34: =(P20+P6)/2 | Q34: =(Q20+Q6)/2 | R34: =SUM(L34:Q34) | S34: =IF(E34=0,"***",L34/E34) | T34: =IF(F34=0,"***",M34/F34) | U34: =IF(G34=0,"***",N34/G34) | V34: =IF(H34=0,"***",O34/H34) | W34: =IF(I34=0,"***",P34/I34) | X34: =IF(J34=0,"***",Q34/J34) | Y34: =IF(K34=0,"***",R34/K34)
C35: 0909 集計 | D35: 藤波課長 | E35: =(E21+E7)/2 | F35: =(F21+F7)/2 | G35: =(G21+G7)/2 | H35: =(H21+H7)/2 | I35: =(I21+I7)/2 | J35: =(J21+J7)/2 | K35: =SUM(E35:J35) | L35: =(L21+L7)/2 | M35: =(M21+M7)/2 | N35: =(N21+N7)/2 | O35: =(O21+O7)/2 | P35: =(P21+P7)/2 | Q35: =(Q21+Q7)/2 | R35: =SUM(L35:Q35) | S35: =IF(E35=0,"***",L35/E35) | T35: =IF(F35=0,"***",M35/F35) | U35: =IF(G35=0,"***",N35/G35) | V35: =IF(H35=0,"***",O35/H35) | W35: =IF(I35=0,"***",P35/I35) | X35: =IF(J35=0,"***",Q35/J35) | Y35: =IF(K35=0,"***",R35/K35)
C36: 0910 集計 | D36: 足立課長 | E36: =(E22+E8)/2 | F36: =(F22+F8)/2 | G36: =(G22+G8)/2 | H36: =(H22+H8)/2 | I36: =(I22+I8)/2 | J36: =(J22+J8)/2 | K36: =SUM(E36:J36) | L36: =(L22+L8)/2 | M36: =(M22+M8)/2 | N36: =(N22+N8)/2 | O36: =(O22+O8)/2 | P36: =(P22+P8)/2 | Q36: =(Q22+Q8)/2 | R36: =SUM(L36:Q36) | S36: =IF(E36=0,"***",L36/E36) | T36: =IF(F36=0,"***",M36/F36) | U36: =IF(G36=0,"***",N36/G36) | V36: =IF(H36=0,"***",O36/H36) | W36: =IF(I36=0,"***",P36/I36) | X36: =IF(J36=0,"***",Q36/J36) | Y36: =IF(K36=0,"***",R36/K36)
C37: 0911 集計 | D37: 川邊主任 | E37: =(E23+E9)/2 | F37: =(F23+F9)/2 | G37: =(G23+G9)/2 | H37: =(H23+H9)/2 | I37: =(I23+I9)/2 | J37: =(J23+J9)/2 | K37: =SUM(E37:J37) | L37: =(L23+L9)/2 | M37: =(M23+M9)/2 | N37: =(N23+N9)/2 | O37: =(O23+O9)/2 | P37: =(P23+P9)/2 | Q37: =(Q23+Q9)/2 | R37: =SUM(L37:Q37) | S37: =IF(E37=0,"***",L37/E37) | T37: =IF(F37=0,"***",M37/F37) | U37: =IF(G37=0,"***",N37/G37) | V37: =IF(H37=0,"***",O37/H37) | W37: =IF(I37=0,"***",P37/I37) | X37: =IF(J37=0,"***",Q37/J37) | Y37: =IF(K37=0,"***",R37/K37)
C38: 0914 集計 | D38: 白根主任 | E38: =(E24+E10)/2 | F38: =(F24+F10)/2 | G38: =(G24+G10)/2 | H38: =(H24+H10)/2 | I38: =(I24+I10)/2 | J38: =(J24+J10)/2 | K38: =SUM(E38:J38) | L38: =(L24+L10)/2 | M38: =(M24+M10)/2 | N38: =(N24+N10)/2 | O38: =(O24+O10)/2 | P38: =(P24+P10)/2 | Q38: =(Q24+Q10)/2 | R38: =SUM(L38:Q38) | S38: =IF(E38=0,"***",L38/E38) | T38: =IF(F38=0,"***",M38/F38) | U38: =IF(G38=0,"***",N38/G38) | V38: =IF(H38=0,"***",O38/H38) | W38: =IF(I38=0,"***",P38/I38) | X38: =IF(J38=0,"***",Q38/J38) | Y38: =IF(K38=0,"***",R38/K38)
C39: 0918 集計 | D39: 海外 | E39: =(E25+E11)/2 | F39: =(F25+F11)/2 | G39: =(G25+G11)/2 | H39: =(H25+H11)/2 | I39: =(I25+I11)/2 | J39: =(J25+J11)/2 | K39: =SUM(E39:J39) | L39: =(L25+L11)/2 | M39: =(M25+M11)/2 | N39: =(N25+N11)/2 | O39: =(O25+O11)/2 | P39: =(P25+P11)/2 | Q39: =(Q25+Q11)/2 | R39: =SUM(L39:Q39) | S39: =IF(E39=0,"***",L39/E39) | T39: =IF(F39=0,"***",M39/F39) | U39: =IF(G39=0,"***",N39/G39) | V39: =IF(H39=0,"***",O39/H39) | W39: =IF(I39=0,"***",P39/I39) | X39: =IF(J39=0,"***",Q39/J39) | Y39: =IF(K39=0,"***",R39/K39)
C40: 0919 集計 | D40: その他 | E40: =(E26+E12)/2 | F40: =(F26+F12)/2 | G40: =(G26+G12)/2 | H40: =(H26+H12)/2 | I40: =(I26+I12)/2 | J40: =(J26+J12)/2 | K40: =SUM(E40:J40) | L40: =(L26+L12)/2 | M40: =(M26+M12)/2 | N40: =(N26+N12)/2 | O40: =(O26+O12)/2 | P40: =(P26+P12)/2 | Q40: =(Q26+Q12)/2 | R40: =SUM(L40:Q40) | S40: =IF(E40=0,"***",L40/E40) | T40: =IF(F40=0,"***",M40/F40) | U40: =IF(G40=0,"***",N40/G40) | V40: =IF(H40=0,"***",O40/H40) | W40: =IF(I40=0,"***",P40/I40) | X40: =IF(J40=0,"***",Q40/J40) | Y40: =IF(K40=0,"***",R40/K40)
C41: 0930 集計 | D41: 自治体 | E41: =(E27+E13)/2 | F41: =(F27+F13)/2 | G41: =(G27+G13)/2 | H41: =(H27+H13)/2 | I41: =(I27+I13)/2 | J41: =(J27+J13)/2 | K41: =SUM(E41:J41) | L41: =(L27+L13)/2 | M41: =(M27+M13)/2 | N41: =(N27+N13)/2 | O41: =(O27+O13)/2 | P41: =(P27+P13)/2 | Q41: =(Q27+Q13)/2 | R41: =SUM(L41:Q41) | S41: =IF(E41=0,"***",L41/E41) | T41: =IF(F41=0,"***",M41/F41) | U41: =IF(G41=0,"***",N41/G41) | V41: =IF(H41=0,"***",O41/H41) | W41: =IF(I41=0,"***",P41/I41) | X41: =IF(J41=0,"***",Q41/J41) | Y41: =IF(K41=0,"***",R41/K41)
C42: 合計 | E42: =SUM(E33:E41) | F42: =SUM(F33:F41) | G42: =SUM(G33:G41) | H42: =SUM(H33:H41) | I42: =SUM(I33:I41) | J42: =SUM(J33:J41) | K42: =SUM(K33:K41) | L42: =SUM(L33:L41) | ... R42: =SUM(R33:R41) | S42: =IF(E42=0,"***",L42/E42) | T42: =IF(F42=0,"***",M42/F42) | U42: =IF(G42=0,"***",N42/G42) | V42: =IF(H42=0,"***",O42/H42) | W42: =IF(I42=0,"***",P42/I42) | X42: =IF(J42=0,"***",Q42/J42) | Y42: =IF(K42=0,"***",R42/K42)
...

Sheet 総括
D1: 境港営業所第51期下期予算について
G7: 2024年4～9月 | J7: 2025年4～9月 | M7: 過年度平均 | P7: 計画 | U7: 根拠
G8: 売上 | H8: 粗利益 | I8: 粗利益率 | J8: 売上 | K8: 粗利益 | L8: 粗利益率 | M8: 売上 | N8: 粗利益 | O8: 粗利益率 | P8: 売上 | Q8: 粗利益 | R8: 粗利益率 | S8: 売上年率 | T8: 粗利益年率
D9: 境港営業所 | G9: 303863 | H9: 58108 | I9: =H9/G9 | J9: 392659 | K9: 77096 | L9: =K9/J9 | M9: =(G9+J9)/2 | N9: =(H9+K9)/2 | O9: =N9/M9 | P9: =P10+P13+P14 | Q9: =Q10+Q13+Q14 | R9: =Q9/P9 | S9: =P9/J9-1 | T9: =Q9/K9-1
E10: 営業 | G10: =G9-G14-G13 | H10: =H9-H14-H13 | I10: =H10/G10 | J10: =J9-J14-J13 | K10: =K9-K14-K13 | L10: =K10/J10 | M10: =(G10+J10)/2 | N10: =(H10+K10)/2 | O10: =N10/M10 | P10: =P11+P12 | Q10: =Q11+Q12 | R10: =Q10/P10 | S10: =P10/J10-1 | T10: =Q10/K10-1
F11: 包装資材 | G11: =G10-G12 | H11: =H10-H12 | I11: =H11/G11 | J11: =J10-J12 | K11: =K10-K12 | L11: =K11/J11 | M11: =(G11+J11)/2 | N11: =(H11+K11)/2 | O11: =N11/M11 | P11: 279390 | Q11: 54430 | R11: =Q11/P11 | S11: =P11/J11-1 | T11: =Q11/K11-1
F12: 機械 | G12: 51572 | H12: 11000 | I12: =H12/G12 | J12: 138794 | K12: 28492 | L12: =K12/J12 | M12: =(G12+J12)/2 | N12: =(H12+K12)/2 | O12: =N12/M12 | P12: =H26 | Q12: 19730 | R12: =Q12/P12 | S12: =P12/J12-1 | T12: =Q12/K12-1
E13: 自治体 | G13: 57 | H13: 2 | I13: =H13/G13 | J13: 87 | K13: 5 | L13: =K13/J13 | M13: =(G13+J13)/2 | N13: =(H13+K13)/2 | O13: =N13/M13 | P13: 0 | Q13: 0 | R13: =Q13/P13 | S13: =P13/J13-1 | T13: =Q13/K13-1
E14: 海外 | G14: 8366 | H14: 1637 | I14: =H14/G14 | J14: 6953 | K14: 1284 | L14: =K14/J14 | M14: =(G14+J14)/2 | N14: =(H14+K14)/2 | O14: =N14/M14 | P14: 8610 | Q14: 1640 | R14: =Q14/P14 | S14: =P14/J14-1 | T14: =Q14/K14-1
F17: 包材：期初計画 年率11.5％ 粗利率：段ボールも含め値上げで苦戦するので約1％程度改善で計画。
F18: 上期2月末実績では前年比+3,800（年率1.6％）で特定の顧客の増加があり売上が増えているので難しいが＋5％で計画。
F19: 機械：受注案件金額と個人別過年度平均にて個別に計画策定
G20: 秋田さん | H20: 1200 | I20: 過年度平均は723千円/6か月 200千円/月で1,200千円/6ヶ月で計画。浅井SAと一緒に大新、環境プラントの機械案件に取り組む
G21: 足立次長 | H21: 30000 | I21: 昨年実績は特殊（弓ヶ浜、岡野農場）だったので前々年実績（28,600千円）を参照し約5％UPの30,000千円で計画
G22: 藤波課長 | H22: 22200 | I22: 過年度平均4,200千円にモリイ食品の包装機18,000千円（6月）を足して22,200千円で計画
G23: 足立課長 | H23: 6000 | I23: 過年度平均が5,000千円で、大型機械案件がないので過年度平均並みで計画。澤井珈琲の資材と食品輸出にウェイトを増やす。
G24: 川邊主任 | H24: 4200 | I24: 期内にて大きな機械案件がないので過年度平均に約5％UPで計画。粗利は有償メンテを推進して2％前後改善する。
G25: 白根主任 | H25: 28000 | I25: 過年度＋白雪食品の包装機が19,000千円（4月納品）で計画
G26: 合計 | H26: =SUM(H20:H25) | I26: 前々期（2024年4月～9月）と比較すると約40,000千円の増加にて計画。粗利は機械メンテ有償化推進にて2％UPを計画
F27: 海外：過年度平均に食品輸出を約15％盛り込み計画。機械については案件がないので400千円/月で計算。
