Workbook

Sheet 8月
D1: 1．単月
I3: 2024年8月売上実績 | J3: 2025年8月売上実績 | K3: 2026年8月売上計画 | L3: 2026年8月売上実績 | P3: 2024年8月粗利益実績 | Q3: 2025年8月粗利益実績 | R3: 2026年8月粗利益計画 | S3: 2026年8月粗利益実績 | W3: 2024年8月粗利益率実績 | X3: 2025年8月粗利益率実績 | Y3: 2026年8月粗利益率計画 | Z3: 2026年8月粗利益率実績 | AC3: 作成根拠
M4: 計画比 | N4: 前期比 | O4: 年率 | T4: 計画比 | U4: 前期比 | V4: 年率 | AA4: 計画比 | AB4: 前期比
F5: 石見営業所 | I5: 72108.628 | J5: 66987.523 | K5: 73080 | L5: 64244.212 | M5: =L5-K5 | N5: =L5-J5 | O5: =IF(J5=0,"***",N5/J5) | P5: 18018.943 | Q5: 18750.251 | R5: 19360 | S5: 19039.774 | T5: =S5-R5 | U5: =S5-Q5 | V5: =IF(Q5=0,"***",U5/Q5) | W5: =IF(I5=0,"***",P5/I5) | X5: =IF(J5=0,"***",Q5/J5) | Y5: =IF(K5=0,"***",R5/K5) | Z5: =IF(L5=0,"***",S5/L5) | AA5: =IF(Y5="***","***",Z5-X5) | AB5: =IF(Z5="***","***",Z5-X5)
G6: 営業 | I6: =I5-I9 | J6: =J5-J9 | K6: =K5-K9 | L6: =L5-L9 | M6: =L6-K6 | N6: =L6-J6 | O6: =IF(J6=0,"***",N6/J6) | P6: =P5-P9 | Q6: =Q5-Q9 | R6: =R5-R9 | S6: =S5-S9 | T6: =S6-R6 | U6: =S6-Q6 | V6: =IF(Q6=0,"***",U6/Q6) | W6: =IF(I6=0,"***",P6/I6) | X6: =IF(J6=0,"***",Q6/J6) | Y6: =IF(K6=0,"***",R6/K6) | Z6: =IF(L6=0,"***",S6/L6) | AA6: =IF(Y6="***","***",Z6-X6) | AB6: =IF(Z6="***","***",Z6-X6)
H7: 包装資材 | I7: =I6-I8 | J7: =J6-J8 | K7: =K6-K8 | L7: =L6-L8 | M7: =L7-K7 | N7: =L7-J7 | O7: =IF(J7=0,"***",N7/J7) | P7: =P6-P8 | Q7: =Q6-Q8 | R7: =R6-R8 | S7: =S6-S8 | T7: =S7-R7 | U7: =S7-Q7 | V7: =IF(Q7=0,"***",U7/Q7) | W7: =IF(I7=0,"***",P7/I7) | X7: =IF(J7=0,"***",Q7/J7) | Y7: =IF(K7=0,"***",R7/K7) | Z7: =IF(L7=0,"***",S7/L7) | AA7: =IF(Y7="***","***",Z7-X7) | AB7: =IF(Z7="***","***",Z7-X7)
H8: 機械 | I8: 7509.518 | J8: 1265.522 | K8: 4000 | L8: 975.121 | M8: =L8-K8 | N8: =L8-J8 | O8: =IF(J8=0,"***",N8/J8) | P8: 1071.83 | Q8: 327.011 | R8: 640 | S8: 236.88 | T8: =S8-R8 | U8: =S8-Q8 | V8: =IF(Q8=0,"***",U8/Q8) | W8: =IF(I8=0,"***",P8/I8) | X8: =IF(J8=0,"***",Q8/J8) | Y8: =IF(K8=0,"***",R8/K8) | Z8: =IF(L8=0,"***",S8/L8) | AA8: =IF(Y8="***","***",Z8-X8) | AB8: =IF(Z8="***","***",Z8-X8)
G9: 自治体 | I9: 4126.3 | J9: 0 | K9: 1340 | L9: 698 | M9: =L9-K9 | N9: =L9-J9 | O9: =IF(J9=0,"***",N9/J9) | P9: 267.6 | Q9: 0 | R9: 210 | S9: 77.7 | T9: =S9-R9 | U9: =S9-Q9 | V9: =IF(Q9=0,"***",U9/Q9) | W9: =IF(I9=0,"***",P9/I9) | X9: =IF(J9=0,"***",Q9/J9) | Y9: =IF(K9=0,"***",R9/K9) | Z9: =IF(L9=0,"***",S9/L9) | AA9: =IF(Y9="***","***",Z9-X9) | AB9: =IF(Z9="***","***",Z9-X9)
F10: 下関営業所 | I10: 42251.729 | J10: 39285.588 | K10: 43700 | L10: 44275.119 | M10: =L10-K10 | N10: =L10-J10 | O10: =IF(J10=0,"***",N10/J10) | P10: 8457.076 | Q10: 8267.92 | R10: 9100 | S10: 9189.129 | T10: =S10-R10 | U10: =S10-Q10 | V10: =IF(Q10=0,"***",U10/Q10) | W10: =IF(I10=0,"***",P10/I10) | X10: =IF(J10=0,"***",Q10/J10) | Y10: =IF(K10=0,"***",R10/K10) | Z10: =IF(L10=0,"***",S10/L10) | AA10: =IF(Y10="***","***",Z10-X10) | AB10: =IF(Z10="***","***",Z10-X10)
G11: 営業 | I11: =I10-I15-I14 | J11: =J10-J15-J14 | K11: =K10-K15-K14 | L11: =L10-L15-L14 | M11: =L11-K11 | N11: =L11-J11 | O11: =IF(J11=0,"***",N11/J11) | P11: =P10-P15-P14 | Q11: =Q10-Q15-Q14 | R11: =R10-R15-R14 | S11: =S10-S15-S14 | T11: =S11-R11 | U11: =S11-Q11 | V11: =IF(Q11=0,"***",U11/Q11) | W11: =IF(I11=0,"***",P11/I11) | X11: =IF(J11=0,"***",Q11/J11) | Y11: =IF(K11=0,"***",R11/K11) | Z11: =IF(L11=0,"***",S11/L11) | AA11: =IF(Y11="***","***",Z11-X11) | AB11: =IF(Z11="***","***",Z11-X11)
H12: 包装資材 | I12: =I11-I13 | J12: =J11-J13 | K12: =K11-K13 | L12: =L11-L13 | M12: =L12-K12 | N12: =L12-J12 | O12: =IF(J12=0,"***",N12/J12) | P12: =P11-P13 | Q12: =Q11-Q13 | R12: =R11-R13 | S12: =S11-S13 | T12: =S12-R12 | U12: =S12-Q12 | V12: =IF(Q12=0,"***",U12/Q12) | W12: =IF(I12=0,"***",P12/I12) | X12: =IF(J12=0,"***",Q12/J12) | Y12: =IF(K12=0,"***",R12/K12) | Z12: =IF(L12=0,"***",S12/L12) | AA12: =IF(Y12="***","***",Z12-X12) | AB12: =IF(Z12="***","***",Z12-X12)
H13: 機械 | I13: 173 | J13: 184 | K13: 300 | L13: 602.41 | M13: =L13-K13 | N13: =L13-J13 | O13: =IF(J13=0,"***",N13/J13) | P13: 28 | Q13: 27 | R13: 50 | S13: 110.4 | T13: =S13-R13 | U13: =S13-Q13 | V13: =IF(Q13=0,"***",U13/Q13) | W13: =IF(I13=0,"***",P13/I13) | X13: =IF(J13=0,"***",Q13/J13) | Y13: =IF(K13=0,"***",R13/K13) | Z13: =IF(L13=0,"***",S13/L13) | AA13: =IF(Y13="***","***",Z13-X13) | AB13: =IF(Z13="***","***",Z13-X13)
G14: 自治体 | I14: 0 | J14: 0 | K14: 0 | L14: 69.1 | M14: =L14-K14 | N14: =L14-J14 | O14: =IF(J14=0,"***",N14/J14) | P14: 0 | Q14: 0 | R14: 0 | S14: 2.2 | T14: =S14-R14 | U14: =S14-Q14 | V14: =IF(Q14=0,"***",U14/Q14) | W14: =IF(I14=0,"***",P14/I14) | X14: =IF(J14=0,"***",Q14/J14) | Y14: =IF(K14=0,"***",R14/K14) | Z14: =IF(L14=0,"***",S14/L14)
G15: 海外 | I15: 0 | J15: 0 | K15: 0 | L15: 0 | M15: =L15-K15 | N15: =L15-J15 | O15: =IF(J15=0,"***",N15/J15) | P15: 0 | Q15: 0 | R15: 0 | S15: 0 | T15: =S15-R15 | U15: =S15-Q15 | V15: =IF(Q15=0,"***",U15/Q15) | W15: =IF(I15=0,"***",P15/I15) | X15: =IF(J15=0,"***",Q15/J15) | Y15: =IF(K15=0,"***",R15/K15) | Z15: =IF(L15=0,"***",S15/L15) | AA15: =IF(Y15="***","***",Z15-X15) | AB15: =IF(Z15="***","***",Z15-X15)
F16: 松江営業所 | I16: 29878.207 | J16: 32089.888 | K16: 30970 | L16: 33113.79 | M16: =L16-K16 | N16: =L16-J16 | O16: =IF(J16=0,"***",N16/J16) | P16: 7280.478 | Q16: 7302.819 | R16: 8030 | S16: 9530.098 | T16: =S16-R16 | U16: =S16-Q16 | V16: =IF(Q16=0,"***",U16/Q16) | W16: =IF(I16=0,"***",P16/I16) | X16: =IF(J16=0,"***",Q16/J16) | Y16: =IF(K16=0,"***",R16/K16) | Z16: =IF(L16=0,"***",S16/L16) | AA16: =IF(Y16="***","***",Z16-X16) | AB16: =IF(Z16="***","***",Z16-X16)
G17: 営業 | I17: =I16-I20 | J17: =J16-J20 | K17: =K16-K20 | L17: =L16-L20 | M17: =L17-K17 | N17: =L17-J17 | O17: =IF(J17=0,"***",N17/J17) | P17: =P16-P20 | Q17: =Q16-Q20 | R17: =R16-R20 | S17: =S16-S20 | T17: =S17-R17 | U17: =S17-Q17 | V17: =IF(Q17=0,"***",U17/Q17) | W17: =IF(I17=0,"***",P17/I17) | X17: =IF(J17=0,"***",Q17/J17) | Y17: =IF(K17=0,"***",R17/K17) | Z17: =IF(L17=0,"***",S17/L17) | AA17: =IF(Y17="***","***",Z17-X17) | AB17: =IF(Z17="***","***",Z17-X17)
H18: 包装資材 | I18: =I17-I19 | J18: =J17-J19 | K18: =K17-K19 | L18: =L17-L19 | M18: =L18-K18 | N18: =L18-J18 | O18: =IF(J18=0,"***",N18/J18) | P18: =P17-P19 | Q18: =Q17-Q19 | R18: =R17-R19 | S18: =S17-S19 | T18: =S18-R18 | U18: =S18-Q18 | V18: =IF(Q18=0,"***",U18/Q18) | W18: =IF(I18=0,"***",P18/I18) | X18: =IF(J18=0,"***",Q18/J18) | Y18: =IF(K18=0,"***",R18/K18) | Z18: =IF(L18=0,"***",S18/L18) | AA18: =IF(Y18="***","***",Z18-X18) | AB18: =IF(Z18="***","***",Z18-X18)
H19: 機械 | I19: 300 | J19: 219 | K19: 500 | L19: 1451.84 | M19: =L19-K19 | N19: =L19-J19 | O19: =IF(J19=0,"***",N19/J19) | P19: 60 | Q19: 77 | R19: 120 | S19: 299.935 | T19: =S19-R19 | U19: =S19-Q19 | V19: =IF(Q19=0,"***",U19/Q19) | W19: =IF(I19=0,"***",P19/I19) | X19: =IF(J19=0,"***",Q19/J19) | Y19: =IF(K19=0,"***",R19/K19) | Z19: =IF(L19=0,"***",S19/L19) | AA19: =IF(Y19="***","***",Z19-X19) | AB19: =IF(Z19="***","***",Z19-X19)
G20: 自治体 | I20: 0 | J20: 6139.904 | K20: 0 | L20: 0 | M20: =L20-K20 | N20: =L20-J20 | O20: =IF(J20=0,"***",N20/J20) | P20: 0 | Q20: 115.904 | R20: 0 | S20: 0 | T20: =S20-R20 | U20: =S20-Q20 | V20: =IF(Q20=0,"***",U20/Q20) | W20: =IF(I20=0,"***",P20/I20) | X20: =IF(J20=0,"***",Q20/J20) | Y20: =IF(K20=0,"***",R20/K20) | Z20: =IF(L20=0,"***",S20/L20) | AA20: =IF(Y20="***","***",Z20-X20) | AB20: =IF(Z20="***","***",Z20-X20)
F21: 広域営業部 | I21: 38098.848 | J21: 40343.715 | K21: 44990 | L21: 49723.074 | M21: =L21-K21 | N21: =L21-J21 | O21: =IF(J21=0,"***",N21/J21) | P21: 5188.215 | Q21: 6090.348 | R21: 6810 | S21: 9152.9145 | T21: =S21-R21 | U21: =S21-Q21 | V21: =IF(Q21=0,"***",U21/Q21) | W21: =IF(I21=0,"***",P21/I21) | X21: =IF(J21=0,"***",Q21/J21) | Y21: =IF(K21=0,"***",R21/K21) | Z21: =IF(L21=0,"***",S21/L21) | AA21: =IF(Y21="***","***",Z21-X21) | AB21: =IF(Z21="***","***",Z21-X21)
H22: 包装資材 | I22: =I21-I23 | J22: =J21-J23 | K22: =K21-K23 | L22: =L21-L23 | M22: =L22-K22 | N22: =L22-J22 | O22: =IF(J22=0,"***",N22/J22) | P22: =P21-P23 | Q22: =Q21-Q23 | R22: =R21-R23 | S22: =S21-S23 | T22: =S22-R22 | U22: =S22-Q22 | V22: =IF(Q22=0,"***",U22/Q22) | W22: =IF(I22=0,"***",P22/I22) | X22: =IF(J22=0,"***",Q22/J22) | Y22: =IF(K22=0,"***",R22/K22) | Z22: =IF(L22=0,"***",S22/L22) | AA22: =IF(Y22="***","***",Z22-X22) | AB22: =IF(Z22="***","***",Z22-X22)
H23: 機械 | I23: 207 | J23: 70 | K23: 1000 | L23: 363.055 | M23: =L23-K23 | N23: =L23-J23 | O23: =IF(J23=0,"***",N23/J23) | P23: 22 | Q23: 6 | R23: 110 | S23: 40.345 | T23: =S23-R23 | U23: =S23-Q23 | V23: =IF(Q23=0,"***",U23/Q23) | W23: =IF(I23=0,"***",P23/I23) | X23: =IF(J23=0,"***",Q23/J23) | Y23: =IF(K23=0,"***",R23/K23) | Z23: =IF(L23=0,"***",S23/L23) | AA23: =IF(Y23="***","***",Z23-X23) | AB23: =IF(Z23="***","***",Z23-X23)
G24: リンガーハット | I24: 28967.532 | J24: 29499.674 | K24: 29366.639 | L24: 37090.624 | M24: =L24-K24 | N24: =L24-J24 | O24: =IF(J24=0,"***",N24/J24) | P24: 3790.54 | Q24: 4379.268 | R24: 4232.086 | S24: 7289.537 | T24: =S24-R24 | U24: =S24-Q24 | V24: =IF(Q24=0,"***",U24/Q24) | W24: =IF(I24=0,"***",P24/I24) | X24: =IF(J24=0,"***",Q24/J24) | Y24: =IF(K24=0,"***",R24/K24) | Z24: =IF(L24=0,"***",S24/L24) | AA24: =IF(Y24="***","***",Z24-X24) | AB24: =IF(Z24="***","***",Z24-X24)
H25: 包装資材 | I25: =I24-I26 | J25: =J24-J26 | K25: =K24-K26 | L25: =L24-L26 | M25: =L25-K25 | N25: =L25-J25 | O25: =IF(J25=0,"***",N25/J25) | P25: =P24-P26 | Q25: =Q24-Q26 | R25: =R24-R26 | S25: =S24-S26 | T25: =S25-R25 | U25: =S25-Q25 | V25: =IF(Q25=0,"***",U25/Q25) | W25: =IF(I25=0,"***",P25/I25) | X25: =IF(J25=0,"***",Q25/J25) | Y25: =IF(K25=0,"***",R25/K25) | Z25: =IF(L25=0,"***",S25/L25) | AA25: =IF(Y25="***","***",Z25-X25) | AB25: =IF(Z25="***","***",Z25-X25)
H26: 機械 | I26: 83 | J26: 23 | K26: 38 | L26: 286.455 | M26: =L26-K26 | N26: =L26-J26 | O26: =IF(J26=0,"***",N26/J26) | P26: 1 | Q26: 0 | R26: 0.25 | S26: 25.625 | T26: =S26-R26 | U26: =S26-Q26 | V26: =IF(Q26=0,"***",U26/Q26) | W26: =IF(I26=0,"***",P26/I26) | X26: =IF(J26=0,"***",Q26/J26) | Y26: =IF(K26=0,"***",R26/K26) | Z26: =IF(L26=0,"***",S26/L26) | AA26: =IF(Y26="***","***",Z26-X26) | AB26: =IF(Z26="***","***",Z26-X26)
G27: リンガーハット以外 | I27: =I21-I24 | J27: =J21-J24 | K27: =K21-K24 | L27: =L21-L24 | M27: =L27-K27 | N27: =L27-J27 | O27: =IF(J27=0,"***",N27/J27) | P27: =P21-P24 | Q27: =Q21-Q24 | R27: =R21-R24 | S27: =S21-S24 | T27: =S27-R27 | U27: =S27-Q27 | V27: =IF(Q27=0,"***",U27/Q27) | W27: =IF(I27=0,"***",P27/I27) | X27: =IF(J27=0,"***",Q27/J27) | Y27: =IF(K27=0,"***",R27/K27) | Z27: =IF(L27=0,"***",S27/L27) | AA27: =IF(Y27="***","***",Z27-X27) | AB27: =IF(Z27="***","***",Z27-X27)
H28: 包装資材 | I28: =I27-I29 | J28: =J27-J29 | K28: =K27-K29 | L28: =L27-L29 | M28: =L28-K28 | N28: =L28-J28 | O28: =IF(J28=0,"***",N28/J28) | P28: =P27-P29 | Q28: =Q27-Q29 | R28: =R27-R29 | S28: =S27-S29 | T28: =S28-R28 | U28: =S28-Q28 | V28: =IF(Q28=0,"***",U28/Q28) | W28: =IF(I28=0,"***",P28/I28) | X28: =IF(J28=0,"***",Q28/J28) | Y28: =IF(K28=0,"***",R28/K28) | Z28: =IF(L28=0,"***",S28/L28) | AA28: =IF(Y28="***","***",Z28-X28) | AB28: =IF(Z28="***","***",Z28-X28)
H29: 機械 | I29: =I23-I26 | J29: =J23-J26 | K29: =K23-K26 | L29: =L23-L26 | M29: =L29-K29 | N29: =L29-J29 | O29: =IF(J29=0,"***",N29/J29) | P29: =P23-P26 | Q29: =Q23-Q26 | R29: =R23-R26 | S29: =S23-S26 | T29: =S29-R29 | U29: =S29-Q29 | V29: =IF(Q29=0,"***",U29/Q29) | W29: =IF(I29=0,"***",P29/I29) | X29: =IF(J29=0,"***",Q29/J29) | Y29: =IF(K29=0,"***",R29/K29) | Z29: =IF(L29=0,"***",S29/L29) | AA29: =IF(Y29="***","***",Z29-X29) | AB29: =IF(Z29="***","***",Z29-X29)
F30: 境港営業所 | I30: 45152.173 | J30: 122048.54 | K30: 47810 | L30: 41885.331 | M30: =L30-K30 | N30: =L30-J30 | O30: =IF(J30=0,"***",N30/J30) | P30: 9612.031 | Q30: 21532.958 | R30: 9410 | S30: 8386.044 | T30: =S30-R30 | U30: =S30-Q30 | V30: =IF(Q30=0,"***",U30/Q30) | W30: =IF(I30=0,"***",P30/I30) | X30: =IF(J30=0,"***",Q30/J30) | Y30: =IF(K30=0,"***",R30/K30) | Z30: =IF(L30=0,"***",S30/L30) | AA30: =IF(Y30="***","***",Z30-X30) | AB30: =IF(Z30="***","***",Z30-X30)
G31: 営業 | I31: =I30-I35-I34 | J31: =J30-J35-J34 | K31: =K30-K35-K34 | L31: =L30-L35-L34 | M31: =L31-K31 | N31: =L31-J31 | O31: =IF(J31=0,"***",N31/J31) | P31: =P30-P35-P34 | Q31: =Q30-Q35-Q34 | R31: =R30-R35-R34 | S31: =S30-S35-S34 | T31: =S31-R31 | U31: =S31-Q31 | V31: =IF(Q31=0,"***",U31/Q31) | W31: =IF(I31=0,"***",P31/I31) | X31: =IF(J31=0,"***",Q31/J31) | Y31: =IF(K31=0,"***",R31/K31) | Z31: =IF(L31=0,"***",S31/L31) | AA31: =IF(Y31="***","***",Z31-X31) | AB31: =IF(Z31="***","***",Z31-X31)
H32: 包装資材 | I32: =I31-I33 | J32: =J31-J33 | K32: =K31-K33 | L32: =L31-L33 | M32: =L32-K32 | N32: =L32-J32 | O32: =IF(J32=0,"***",N32/J32) | P32: =P31-P33 | Q32: =Q31-Q33 | R32: =R31-R33 | S32: =S31-S33 | T32: =S32-R32 | U32: =S32-Q32 | V32: =IF(Q32=0,"***",U32/Q32) | W32: =IF(I32=0,"***",P32/I32) | X32: =IF(J32=0,"***",Q32/J32) | Y32: =IF(K32=0,"***",R32/K32) | Z32: =IF(L32=0,"***",S32/L32) | AA32: =IF(Y32="***","***",Z32-X32) | AB32: =IF(Z32="***","***",Z32-X32)
H33: 機械 | I33: 1318 | J33: 85679 | K33: 8500 | L33: 4649.01 | M33: =L33-K33 | N33: =L33-J33 | O33: =IF(J33=0,"***",N33/J33) | P33: 391 | Q33: 14899 | R33: 1880 | S33: 1001.375 | T33: =S33-R33 | U33: =S33-Q33 | V33: =IF(Q33=0,"***",U33/Q33) | W33: =IF(I33=0,"***",P33/I33) | X33: =IF(J33=0,"***",Q33/J33) | Y33: =IF(K33=0,"***",R33/K33) | Z33: =IF(L33=0,"***",S33/L33) | AA33: =IF(Y33="***","***",Z33-X33) | AB33: =IF(Z33="***","***",Z33-X33)
G34: 自治体 | I34: 0 | J34: 0 | K34: 0 | L34: 156 | M34: =L34-K34 | N34: =L34-J34 | O34: =IF(J34=0,"***",N34/J34) | P34: 0 | Q34: 0 | R34: 0 | S34: 4.8 | T34: =S34-R34 | U34: =S34-Q34 | V34: =IF(Q34=0,"***",U34/Q34) | W34: =IF(I34=0,"***",P34/I34) | X34: =IF(J34=0,"***",Q34/J34) | Y34: =IF(K34=0,"***",R34/K34) | Z34: =IF(L34=0,"***",S34/L34) | AA34: =IF(Y34="***","***",Z34-X34) | AB34: =IF(Z34="***","***",Z34-X34)
G35: 海外 | I35: 232.15 | J35: 21.15 | K35: 530 | L35: 314.45 | M35: =L35-K35 | N35: =L35-J35 | O35: =IF(J35=0,"***",N35/J35) | P35: 73.45 | Q35: 5.8 | R35: 100 | S35: 59.63 | T35: =S35-R35 | U35: =S35-Q35 | V35: =IF(Q35=0,"***",U35/Q35) | W35: =IF(I35=0,"***",P35/I35) | X35: =IF(J35=0,"***",Q35/J35) | Y35: =IF(K35=0,"***",R35/K35) | Z35: =IF(L35=0,"***",S35/L35) | AA35: =IF(Y35="***","***",Z35-X35) | AB35: =IF(Z35="***","***",Z35-X35)
E36: 営業部門合計 | I36: =I30+I21+I16+I10+I5 | J36: =J30+J21+J16+J10+J5 | K36: =K30+K21+K16+K10+K5 | L36: =L30+L21+L16+L10+L5 | M36: =L36-K36 | N36: =L36-J36 | O36: =IF(J36=0,"***",N36/J36) | P36: =P30+P21+P16+P10+P5 | Q36: =Q30+Q21+Q16+Q10+Q5 | R36: =R30+R21+R16+R10+R5 | S36: =S30+S21+S16+S10+S5 | T36: =S36-R36 | U36: =S36-Q36 | V36: =IF(Q36=0,"***",U36/Q36) | W36: =IF(I36=0,"***",P36/I36) | X36: =IF(J36=0,"***",Q36/J36) | Y36: =IF(K36=0,"***",R36/K36) | Z36: =IF(L36=0,"***",S36/L36) | AA36: =IF(Y36="***","***",Z36-X36) | AB36: =IF(Z36="***","***",Z36-X36)
H37: 機械以外 | I37: =I36-I38-I39-I40 | J37: =J36-J38-J39-J40 | K37: =K36-K38-K39-K40 | L37: =L36-L38-L39-L40 | M37: =L37-K37 | N37: =L37-J37 | O37: =IF(J37=0,"***",N37/J37) | P37: =P36-P38-P39-P40 | Q37: =Q36-Q38-Q39-Q40 | R37: =R36-R38-R39-R40 | S37: =S36-S38-S39-S40 | T37: =S37-R37 | U37: =S37-Q37 | V37: =IF(Q37=0,"***",U37/Q37) | W37: =IF(I37=0,"***",P37/I37) | X37: =IF(J37=0,"***",Q37/J37) | Y37: =IF(K37=0,"***",R37/K37) | Z37: =IF(L37=0,"***",S37/L37) | AA37: =IF(Y37="***","***",Z37-X37) | AB37: =IF(Z37="***","***",Z37-X37)
H38: 機械 | I38: =I33+I23+I19+I13+I8 | J38: =J33+J23+J19+J13+J8 | K38: =K33+K23+K19+K13+K8 | L38: =L33+L23+L19+L13+L8 | M38: =L38-K38 | N38: =L38-J38 | O38: =IF(J38=0,"***",N38/J38) | P38: =P33+P23+P19+P13+P8 | Q38: =Q33+Q23+Q19+Q13+Q8 | R38: =R33+R23+R19+R13+R8 | S38: =S33+S23+S19+S13+S8 | T38: =S38-R38 | U38: =S38-Q38 | V38: =IF(Q38=0,"***",U38/Q38) | W38: =IF(I38=0,"***",P38/I38) | X38: =IF(J38=0,"***",Q38/J38) | Y38: =IF(K38=0,"***",R38/K38) | Z38: =IF(L38=0,"***",S38/L38) | AA38: =IF(Y38="***","***",Z38-X38) | AB38: =IF(Z38="***","***",Z38-X38)
H39: 自治体 | I39: =I34+I20+I14+I9 | J39: =J34+J20+J14+J9 | K39: =K34+K20+K14+K9 | L39: =L34+L20+L14+L9 | M39: =L39-K39 | N39: =L39-J39 | O39: =IF(J39=0,"***",N39/J39) | P39: =P34+P20+P14+P9 | Q39: =Q34+Q20+Q14+Q9 | R39: =R34+R20+R14+R9 | S39: =S34+S20+S14+S9 | T39: =S39-R39 | U39: =S39-Q39 | V39: =IF(Q39=0,"***",U39/Q39) | W39: =IF(I39=0,"***",P39/I39) | X39: =IF(J39=0,"***",Q39/J39) | Y39: =IF(K39=0,"***",R39/K39) | Z39: =IF(L39=0,"***",S39/L39) | AA39: =IF(Y39="***","***",Z39-X39) | AB39: =IF(Z39="***","***",Z39-X39)
H40: 海外 | I40: =I35+I15 | J40: =J35+J15 | K40: =K35+K15 | L40: =L35+L15 | M40: =L40-K40 | N40: =L40-J40 | O40: =IF(J40=0,"***",N40/J40) | P40: =P35+P15 | Q40: =Q35+Q15 | R40: =R35+R15 | S40: =S35+S15 | T40: =S40-R40 | U40: =S40-Q40 | V40: =IF(Q40=0,"***",U40/Q40) | W40: =IF(I40=0,"***",P40/I40) | X40: =IF(J40=0,"***",Q40/J40) | Y40: =IF(K40=0,"***",R40/K40) | Z40: =IF(L40=0,"***",S40/L40) | AA40: =IF(Y40="***","***",Z40-X40) | AB40: =IF(Z40="***","***",Z40-X40)
E41: 水産部 | I41: 27052.538 | J41: 26566.747 | K41: 28670 | L41: 32703.688 | M41: =L41-K41 | N41: =L41-J41 | O41: =IF(J41=0,"***",N41/J41) | P41: 8027.116 | Q41: 7803.715 | R41: 8170 | S41: 8776.157 | T41: =S41-R41 | U41: =S41-Q41 | V41: =IF(Q41=0,"***",U41/Q41) | W41: =IF(I41=0,"***",P41/I41) | X41: =IF(J41=0,"***",Q41/J41) | Y41: =IF(K41=0,"***",R41/K41) | Z41: =IF(L41=0,"***",S41/L41) | AA41: =IF(Y41="***","***",Z41-X41) | AB41: =IF(Z41="***","***",Z41-X41)
...

Sheet 下期
D1: 2．下期
I3: 第49期下期売上実績 | J3: 第50期下期売上実績 | K3: 第51期下期売上計画 | L3: 第51期下期売上実績 | P3: 第49期下期粗利益実績 | Q3: 第50期下期粗利益実績 | R3: 第51期下期粗利益計画 | S3: 第51期下期粗利益実績 | W3: 第49期下期粗利益率実績 | X3: 第50期下期粗利益率実績 | Y3: 第51期下期粗利益率計画 | Z3: 第51期下期粗利益率実績 | AC3: 作成根拠
M4: 計画比 | N4: 前期比 | O4: 年率 | T4: 計画比 | U4: 前期比 | V4: 年率 | AA4: 計画比 | AB4: 前期比
F5: 石見営業所 | I5: ='8月'!I5+BACKDATA7月!I5+BACKDATA6月!I5+BACKDATA5月!I5+BACKDATA4月!I5 | J5: ='8月'!J5+BACKDATA7月!J5+BACKDATA6月!J5+BACKDATA5月!J5+BACKDATA4月!J5 | K5: ='8月'!K5+BACKDATA7月!K5+BACKDATA6月!K5+BACKDATA5月!K5+BACKDATA4月!K5 | L5: ='8月'!L5+BACKDATA7月!L5+BACKDATA6月!L5+BACKDATA5月!L5+BACKDATA4月!L5 | M5: =L5-K5 | N5: =L5-J5 | O5: =IF(J5=0,"***",N5/J5) | P5: ='8月'!P5+BACKDATA7月!P5+BACKDATA6月!P5+BACKDATA5月!P5+BACKDATA4月!P5 | Q5: ='8月'!Q5+BACKDATA7月!Q5+BACKDATA6月!Q5+BACKDATA5月!Q5+BACKDATA4月!Q5 | R5: ='8月'!R5+BACKDATA7月!R5+BACKDATA6月!R5+BACKDATA5月!R5+BACKDATA4月!R5 | S5: ='8月'!S5+BACKDATA7月!S5+BACKDATA6月!S5+BACKDATA5月!S5+BACKDATA4月!S5 | T5: =S5-R5 | U5: =S5-Q5 | V5: =IF(Q5=0,"***",U5/Q5) | W5: =IF(I5=0,"***",P5/I5) | X5: =IF(J5=0,"***",Q5/J5) | Y5: =IF(K5=0,"***",R5/K5) | Z5: =IF(L5=0,"***",S5/L5) | AA5: =IF(Y5="***","***",Z5-X5) | AB5: =IF(Z5="***","***",Z5-X5)
G6: 営業 | I6: =I5-I9 | J6: =J5-J9 | K6: =K5-K9 | L6: =L5-L9 | M6: =L6-K6 | N6: =L6-J6 | O6: =IF(J6=0,"***",N6/J6) | P6: =P5-P9 | Q6: =Q5-Q9 | R6: =R5-R9 | S6: =S5-S9 | T6: =S6-R6 | U6: =S6-Q6 | V6: =IF(Q6=0,"***",U6/Q6) | W6: =IF(I6=0,"***",P6/I6) | X6: =IF(J6=0,"***",Q6/J6) | Y6: =IF(K6=0,"***",R6/K6) | Z6: =IF(L6=0,"***",S6/L6) | AA6: =IF(Y6="***","***",Z6-X6) | AB6: =IF(Z6="***","***",Z6-X6)
H7: 包装資材 | I7: =I6-I8 | J7: =J6-J8 | K7: =K6-K8 | L7: =L6-L8 | M7: =L7-K7 | N7: =L7-J7 | O7: =IF(J7=0,"***",N7/J7) | P7: =P6-P8 | Q7: =Q6-Q8 | R7: =R6-R8 | S7: =S6-S8 | T7: =S7-R7 | U7: =S7-Q7 | V7: =IF(Q7=0,"***",U7/Q7) | W7: =IF(I7=0,"***",P7/I7) | X7: =IF(J7=0,"***",Q7/J7) | Y7: =IF(K7=0,"***",R7/K7) | Z7: =IF(L7=0,"***",S7/L7) | AA7: =IF(Y7="***","***",Z7-X7) | AB7: =IF(Z7="***","***",Z7-X7)
H8: 機械 | I8: ='8月'!I8+BACKDATA7月!I8+BACKDATA6月!I8+BACKDATA5月!I8+BACKDATA4月!I8 | J8: ='8月'!J8+BACKDATA7月!J8+BACKDATA6月!J8+BACKDATA5月!J8+BACKDATA4月!J8 | K8: ='8月'!K8+BACKDATA7月!K8+BACKDATA6月!K8+BACKDATA5月!K8+BACKDATA4月!K8 | L8: ='8月'!L8+BACKDATA7月!L8+BACKDATA6月!L8+BACKDATA5月!L8+BACKDATA4月!L8 | M8: =L8-K8 | N8: =L8-J8 | O8: =IF(J8=0,"***",N8/J8) | P8: ='8月'!P8+BACKDATA7月!P8+BACKDATA6月!P8+BACKDATA5月!P8+BACKDATA4月!P8 | Q8: ='8月'!Q8+BACKDATA7月!Q8+BACKDATA6月!Q8+BACKDATA5月!Q8+BACKDATA4月!Q8 | R8: ='8月'!R8+BACKDATA7月!R8+BACKDATA6月!R8+BACKDATA5月!R8+BACKDATA4月!R8 | S8: ='8月'!S8+BACKDATA7月!S8+BACKDATA6月!S8+BACKDATA5月!S8+BACKDATA4月!S8 | T8: =S8-R8 | U8: =S8-Q8 | V8: =IF(Q8=0,"***",U8/Q8) | W8: =IF(I8=0,"***",P8/I8) | X8: =IF(J8=0,"***",Q8/J8) | Y8: =IF(K8=0,"***",R8/K8) | Z8: =IF(L8=0,"***",S8/L8) | AA8: =IF(Y8="***","***",Z8-X8) | AB8: =IF(Z8="***","***",Z8-X8)
G9: 自治体 | I9: ='8月'!I9+BACKDATA7月!I9+BACKDATA6月!I9+BACKDATA5月!I9+BACKDATA4月!I9 | J9: ='8月'!J9+BACKDATA7月!J9+BACKDATA6月!J9+BACKDATA5月!J9+BACKDATA4月!J9 | K9: ='8月'!K9+BACKDATA7月!K9+BACKDATA6月!K9+BACKDATA5月!K9+BACKDATA4月!K9 | L9: ='8月'!L9+BACKDATA7月!L9+BACKDATA6月!L9+BACKDATA5月!L9+BACKDATA4月!L9 | M9: =L9-K9 | N9: =L9-J9 | O9: =IF(J9=0,"***",N9/J9) | P9: ='8月'!P9+BACKDATA7月!P9+BACKDATA6月!P9+BACKDATA5月!P9+BACKDATA4月!P9 | Q9: ='8月'!Q9+BACKDATA7月!Q9+BACKDATA6月!Q9+BACKDATA5月!Q9+BACKDATA4月!Q9 | R9: ='8月'!R9+BACKDATA7月!R9+BACKDATA6月!R9+BACKDATA5月!R9+BACKDATA4月!R9 | S9: ='8月'!S9+BACKDATA7月!S9+BACKDATA6月!S9+BACKDATA5月!S9+BACKDATA4月!S9 | T9: =S9-R9 | U9: =S9-Q9 | V9: =IF(Q9=0,"***",U9/Q9) | W9: =IF(I9=0,"***",P9/I9) | X9: =IF(J9=0,"***",Q9/J9) | Y9: =IF(K9=0,"***",R9/K9) | Z9: =IF(L9=0,"***",S9/L9) | AA9: =IF(Y9="***","***",Z9-X9) | AB9: =IF(Z9="***","***",Z9-X9)
F10: 下関営業所 | I10: ='8月'!I10+BACKDATA7月!I10+BACKDATA6月!I10+BACKDATA5月!I10+BACKDATA4月!I10 | J10: ='8月'!J10+BACKDATA7月!J10+BACKDATA6月!J10+BACKDATA5月!J10+BACKDATA4月!J10 | K10: ='8月'!K10+BACKDATA7月!K10+BACKDATA6月!K10+BACKDATA5月!K10+BACKDATA4月!K10 | L10: ='8月'!L10+BACKDATA7月!L10+BACKDATA6月!L10+BACKDATA5月!L10+BACKDATA4月!L10 | M10: =L10-K10 | N10: =L10-J10 | O10: =IF(J10=0,"***",N10/J10) | P10: ='8月'!P10+BACKDATA7月!P10+BACKDATA6月!P10+BACKDATA5月!P10+BACKDATA4月!P10 | Q10: ='8月'!Q10+BACKDATA7月!Q10+BACKDATA6月!Q10+BACKDATA5月!Q10+BACKDATA4月!Q10 | R10: ='8月'!R10+BACKDATA7月!R10+BACKDATA6月!R10+BACKDATA5月!R10+BACKDATA4月!R10 | S10: ='8月'!S10+BACKDATA7月!S10+BACKDATA6月!S10+BACKDATA5月!S10+BACKDATA4月!S10 | T10: =S10-R10 | U10: =S10-Q10 | V10: =IF(Q10=0,"***",U10/Q10) | W10: =IF(I10=0,"***",P10/I10) | X10: =IF(J10=0,"***",Q10/J10) | Y10: =IF(K10=0,"***",R10/K10) | Z10: =IF(L10=0,"***",S10/L10) | AA10: =IF(Y10="***","***",Z10-X10) | AB10: =IF(Z10="***","***",Z10-X10)
G11: 営業 | I11: =I10-I15-I14 | J11: =J10-J15-J14 | K11: =K10-K15-K14 | L11: =L10-L15-L14 | M11: =L11-K11 | N11: =L11-J11 | O11: =IF(J11=0,"***",N11/J11) | P11: =P10-P15-P14 | Q11: =Q10-Q15-Q14 | R11: =R10-R15-R14 | S11: =S10-S15-S14 | T11: =S11-R11 | U11: =S11-Q11 | V11: =IF(Q11=0,"***",U11/Q11) | W11: =IF(I11=0,"***",P11/I11) | X11: =IF(J11=0,"***",Q11/J11) | Y11: =IF(K11=0,"***",R11/K11) | Z11: =IF(L11=0,"***",S11/L11) | AA11: =IF(Y11="***","***",Z11-X11) | AB11: =IF(Z11="***","***",Z11-X11)
H12: 包装資材 | I12: =I11-I13 | J12: =J11-J13 | K12: =K11-K13 | L12: =L11-L13 | M12: =L12-K12 | N12: =L12-J12 | O12: =IF(J12=0,"***",N12/J12) | P12: =P11-P13 | Q12: =Q11-Q13 | R12: =R11-R13 | S12: =S11-S13 | T12: =S12-R12 | U12: =S12-Q12 | V12: =IF(Q12=0,"***",U12/Q12) | W12: =IF(I12=0,"***",P12/I12) | X12: =IF(J12=0,"***",Q12/J12) | Y12: =IF(K12=0,"***",R12/K12) | Z12: =IF(L12=0,"***",S12/L12) | AA12: =IF(Y12="***","***",Z12-X12) | AB12: =IF(Z12="***","***",Z12-X12)
H13: 機械 | I13: ='8月'!I13+BACKDATA7月!I13+BACKDATA6月!I13+BACKDATA5月!I13+BACKDATA4月!I13 | J13: ='8月'!J13+BACKDATA7月!J13+BACKDATA6月!J13+BACKDATA5月!J13+BACKDATA4月!J13 | K13: ='8月'!K13+BACKDATA7月!K13+BACKDATA6月!K13+BACKDATA5月!K13+BACKDATA4月!K13 | L13: ='8月'!L13+BACKDATA7月!L13+BACKDATA6月!L13+BACKDATA5月!L13+BACKDATA4月!L13 | M13: =L13-K13 | N13: =L13-J13 | O13: =IF(J13=0,"***",N13/J13) | P13: ='8月'!P13+BACKDATA7月!P13+BACKDATA6月!P13+BACKDATA5月!P13+BACKDATA4月!P13 | Q13: ='8月'!Q13+BACKDATA7月!Q13+BACKDATA6月!Q13+BACKDATA5月!Q13+BACKDATA4月!Q13 | R13: ='8月'!R13+BACKDATA7月!R13+BACKDATA6月!R13+BACKDATA5月!R13+BACKDATA4月!R13 | S13: ='8月'!S13+BACKDATA7月!S13+BACKDATA6月!S13+BACKDATA5月!S13+BACKDATA4月!S13 | T13: =S13-R13 | U13: =S13-Q13 | V13: =IF(Q13=0,"***",U13/Q13) | W13: =IF(I13=0,"***",P13/I13) | X13: =IF(J13=0,"***",Q13/J13) | Y13: =IF(K13=0,"***",R13/K13) | Z13: =IF(L13=0,"***",S13/L13) | AA13: =IF(Y13="***","***",Z13-X13) | AB13: =IF(Z13="***","***",Z13-X13)
G14: 自治体 | I14: ='8月'!I14+BACKDATA7月!I14+BACKDATA6月!I14+BACKDATA5月!I14+BACKDATA4月!I14 | J14: ='8月'!J14+BACKDATA7月!J14+BACKDATA6月!J14+BACKDATA5月!J14+BACKDATA4月!J14 | K14: ='8月'!K14+BACKDATA7月!K14+BACKDATA6月!K14+BACKDATA5月!K14+BACKDATA4月!K14 | L14: ='8月'!L14+BACKDATA7月!L14+BACKDATA6月!L14+BACKDATA5月!L14+BACKDATA4月!L14 | M14: =L14-K14 | N14: =L14-J14 | O14: =IF(J14=0,"***",N14/J14) | P14: ='8月'!P14+BACKDATA7月!P14+BACKDATA6月!P14+BACKDATA5月!P14+BACKDATA4月!P14 | Q14: ='8月'!Q14+BACKDATA7月!Q14+BACKDATA6月!Q14+BACKDATA5月!Q14+BACKDATA4月!Q14 | R14: ='8月'!R14+BACKDATA7月!R14+BACKDATA6月!R14+BACKDATA5月!R14+BACKDATA4月!R14 | S14: ='8月'!S14+BACKDATA7月!S14+BACKDATA6月!S14+BACKDATA5月!S14+BACKDATA4月!S14 | T14: =S14-R14 | U14: =S14-Q14 | V14: =IF(Q14=0,"***",U14/Q14) | W14: =IF(I14=0,"***",P14/I14) | X14: =IF(J14=0,"***",Q14/J14) | Y14: =IF(K14=0,"***",R14/K14) | Z14: =IF(L14=0,"***",S14/L14)
G15: 海外 | I15: ='8月'!I15+BACKDATA7月!I15+BACKDATA6月!I15+BACKDATA5月!I15+BACKDATA4月!I15 | J15: ='8月'!J15+BACKDATA7月!J15+BACKDATA6月!J15+BACKDATA5月!J15+BACKDATA4月!J15 | K15: ='8月'!K15+BACKDATA7月!K15+BACKDATA6月!K15+BACKDATA5月!K15+BACKDATA4月!K15 | L15: ='8月'!L15+BACKDATA7月!L15+BACKDATA6月!L15+BACKDATA5月!L15+BACKDATA4月!L15 | M15: =L15-K15 | N15: =L15-J15 | O15: =IF(J15=0,"***",N15/J15) | P15: ='8月'!P15+BACKDATA7月!P15+BACKDATA6月!P15+BACKDATA5月!P15+BACKDATA4月!P15 | Q15: ='8月'!Q15+BACKDATA7月!Q15+BACKDATA6月!Q15+BACKDATA5月!Q15+BACKDATA4月!Q15 | R15: ='8月'!R15+BACKDATA7月!R15+BACKDATA6月!R15+BACKDATA5月!R15+BACKDATA4月!R15 | S15: ='8月'!S15+BACKDATA7月!S15+BACKDATA6月!S15+BACKDATA5月!S15+BACKDATA4月!S15 | T15: =S15-R15 | U15: =S15-Q15 | V15: =IF(Q15=0,"***",U15/Q15) | W15: =IF(I15=0,"***",P15/I15) | X15: =IF(J15=0,"***",Q15/J15) | Y15: =IF(K15=0,"***",R15/K15) | Z15: =IF(L15=0,"***",S15/L15) | AA15: =IF(Y15="***","***",Z15-X15) | AB15: =IF(Z15="***","***",Z15-X15)
F16: 松江営業所 | I16: ='8月'!I16+BACKDATA7月!I16+BACKDATA6月!I16+BACKDATA5月!I16+BACKDATA4月!I16 | J16: ='8月'!J16+BACKDATA7月!J16+BACKDATA6月!J16+BACKDATA5月!J16+BACKDATA4月!J16 | K16: ='8月'!K16+BACKDATA7月!K16+BACKDATA6月!K16+BACKDATA5月!K16+BACKDATA4月!K16 | L16: ='8月'!L16+BACKDATA7月!L16+BACKDATA6月!L16+BACKDATA5月!L16+BACKDATA4月!L16 | M16: =L16-K16 | N16: =L16-J16 | O16: =IF(J16=0,"***",N16/J16) | P16: ='8月'!P16+BACKDATA7月!P16+BACKDATA6月!P16+BACKDATA5月!P16+BACKDATA4月!P16 | Q16: ='8月'!Q16+BACKDATA7月!Q16+BACKDATA6月!Q16+BACKDATA5月!Q16+BACKDATA4月!Q16 | R16: ='8月'!R16+BACKDATA7月!R16+BACKDATA6月!R16+BACKDATA5月!R16+BACKDATA4月!R16 | S16: ='8月'!S16+BACKDATA7月!S16+BACKDATA6月!S16+BACKDATA5月!S16+BACKDATA4月!S16 | T16: =S16-R16 | U16: =S16-Q16 | V16: =IF(Q16=0,"***",U16/Q16) | W16: =IF(I16=0,"***",P16/I16) | X16: =IF(J16=0,"***",Q16/J16) | Y16: =IF(K16=0,"***",R16/K16) | Z16: =IF(L16=0,"***",S16/L16) | AA16: =IF(Y16="***","***",Z16-X16) | AB16: =IF(Z16="***","***",Z16-X16)
G17: 営業 | I17: =I16-I20 | J17: =J16-J20 | K17: =K16-K20 | L17: =L16-L20 | M17: =L17-K17 | N17: =L17-J17 | O17: =IF(J17=0,"***",N17/J17) | P17: =P16-P20 | Q17: =Q16-Q20 | R17: =R16-R20 | S17: =S16-S20 | T17: =S17-R17 | U17: =S17-Q17 | V17: =IF(Q17=0,"***",U17/Q17) | W17: =IF(I17=0,"***",P17/I17) | X17: =IF(J17=0,"***",Q17/J17) | Y17: =IF(K17=0,"***",R17/K17) | Z17: =IF(L17=0,"***",S17/L17) | AA17: =IF(Y17="***","***",Z17-X17) | AB17: =IF(Z17="***","***",Z17-X17)
H18: 包装資材 | I18: =I17-I19 | J18: =J17-J19 | K18: =K17-K19 | L18: =L17-L19 | M18: =L18-K18 | N18: =L18-J18 | O18: =IF(J18=0,"***",N18/J18) | P18: =P17-P19 | Q18: =Q17-Q19 | R18: =R17-R19 | S18: =S17-S19 | T18: =S18-R18 | U18: =S18-Q18 | V18: =IF(Q18=0,"***",U18/Q18) | W18: =IF(I18=0,"***",P18/I18) | X18: =IF(J18=0,"***",Q18/J18) | Y18: =IF(K18=0,"***",R18/K18) | Z18: =IF(L18=0,"***",S18/L18) | AA18: =IF(Y18="***","***",Z18-X18) | AB18: =IF(Z18="***","***",Z18-X18)
H19: 機械 | I19: ='8月'!I19+BACKDATA7月!I19+BACKDATA6月!I19+BACKDATA5月!I19+BACKDATA4月!I19 | J19: ='8月'!J19+BACKDATA7月!J19+BACKDATA6月!J19+BACKDATA5月!J19+BACKDATA4月!J19 | K19: ='8月'!K19+BACKDATA7月!K19+BACKDATA6月!K19+BACKDATA5月!K19+BACKDATA4月!K19 | L19: ='8月'!L19+BACKDATA7月!L19+BACKDATA6月!L19+BACKDATA5月!L19+BACKDATA4月!L19 | M19: =L19-K19 | N19: =L19-J19 | O19: =IF(J19=0,"***",N19/J19) | P19: ='8月'!P19+BACKDATA7月!P19+BACKDATA6月!P19+BACKDATA5月!P19+BACKDATA4月!P19 | Q19: ='8月'!Q19+BACKDATA7月!Q19+BACKDATA6月!Q19+BACKDATA5月!Q19+BACKDATA4月!Q19 | R19: ='8月'!R19+BACKDATA7月!R19+BACKDATA6月!R19+BACKDATA5月!R19+BACKDATA4月!R19 | S19: ='8月'!S19+BACKDATA7月!S19+BACKDATA6月!S19+BACKDATA5月!S19+BACKDATA4月!S19 | T19: =S19-R19 | U19: =S19-Q19 | V19: =IF(Q19=0,"***",U19/Q19) | W19: =IF(I19=0,"***",P19/I19) | X19: =IF(J19=0,"***",Q19/J19) | Y19: =IF(K19=0,"***",R19/K19) | Z19: =IF(L19=0,"***",S19/L19) | AA19: =IF(Y19="***","***",Z19-X19) | AB19: =IF(Z19="***","***",Z19-X19)
G20: 自治体 | I20: ='8月'!I20+BACKDATA7月!I20+BACKDATA6月!I20+BACKDATA5月!I20+BACKDATA4月!I20 | J20: ='8月'!J20+BACKDATA7月!J20+BACKDATA6月!J20+BACKDATA5月!J20+BACKDATA4月!J20 | K20: ='8月'!K20+BACKDATA7月!K20+BACKDATA6月!K20+BACKDATA5月!K20+BACKDATA4月!K20 | L20: ='8月'!L20+BACKDATA7月!L20+BACKDATA6月!L20+BACKDATA5月!L20+BACKDATA4月!L20 | M20: =L20-K20 | N20: =L20-J20 | O20: =IF(J20=0,"***",N20/J20) | P20: ='8月'!P20+BACKDATA7月!P20+BACKDATA6月!P20+BACKDATA5月!P20+BACKDATA4月!P20 | Q20: ='8月'!Q20+BACKDATA7月!Q20+BACKDATA6月!Q20+BACKDATA5月!Q20+BACKDATA4月!Q20 | R20: ='8月'!R20+BACKDATA7月!R20+BACKDATA6月!R20+BACKDATA5月!R20+BACKDATA4月!R20 | S20: ='8月'!S20+BACKDATA7月!S20+BACKDATA6月!S20+BACKDATA5月!S20+BACKDATA4月!S20 | T20: =S20-R20 | U20: =S20-Q20 | V20: =IF(Q20=0,"***",U20/Q20) | W20: =IF(I20=0,"***",P20/I20) | X20: =IF(J20=0,"***",Q20/J20) | Y20: =IF(K20=0,"***",R20/K20) | Z20: =IF(L20=0,"***",S20/L20) | AA20: =IF(Y20="***","***",Z20-X20) | AB20: =IF(Z20="***","***",Z20-X20)
F21: 広域営業部 | I21: ='8月'!I21+BACKDATA7月!I21+BACKDATA6月!I21+BACKDATA5月!I21+BACKDATA4月!I21 | J21: ='8月'!J21+BACKDATA7月!J21+BACKDATA6月!J21+BACKDATA5月!J21+BACKDATA4月!J21 | K21: ='8月'!K21+BACKDATA7月!K21+BACKDATA6月!K21+BACKDATA5月!K21+BACKDATA4月!K21 | L21: ='8月'!L21+BACKDATA7月!L21+BACKDATA6月!L21+BACKDATA5月!L21+BACKDATA4月!L21 | M21: =L21-K21 | N21: =L21-J21 | O21: =IF(J21=0,"***",N21/J21) | P21: ='8月'!P21+BACKDATA7月!P21+BACKDATA6月!P21+BACKDATA5月!P21+BACKDATA4月!P21 | Q21: ='8月'!Q21+BACKDATA7月!Q21+BACKDATA6月!Q21+BACKDATA5月!Q21+BACKDATA4月!Q21 | R21: ='8月'!R21+BACKDATA7月!R21+BACKDATA6月!R21+BACKDATA5月!R21+BACKDATA4月!R21 | S21: ='8月'!S21+BACKDATA7月!S21+BACKDATA6月!S21+BACKDATA5月!S21+BACKDATA4月!S21 | T21: =S21-R21 | U21: =S21-Q21 | V21: =IF(Q21=0,"***",U21/Q21) | W21: =IF(I21=0,"***",P21/I21) | X21: =IF(J21=0,"***",Q21/J21) | Y21: =IF(K21=0,"***",R21/K21) | Z21: =IF(L21=0,"***",S21/L21) | AA21: =IF(Y21="***","***",Z21-X21) | AB21: =IF(Z21="***","***",Z21-X21)
H22: 包装資材 | I22: =I21-I23 | J22: =J21-J23 | K22: =K21-K23 | L22: =L21-L23 | M22: =L22-K22 | N22: =L22-J22 | O22: =IF(J22=0,"***",N22/J22) | P22: =P21-P23 | Q22: =Q21-Q23 | R22: =R21-R23 | S22: =S21-S23 | T22: =S22-R22 | U22: =S22-Q22 | V22: =IF(Q22=0,"***",U22/Q22) | W22: =IF(I22=0,"***",P22/I22) | X22: =IF(J22=0,"***",Q22/J22) | Y22: =IF(K22=0,"***",R22/K22) | Z22: =IF(L22=0,"***",S22/L22) | AA22: =IF(Y22="***","***",Z22-X22) | AB22: =IF(Z22="***","***",Z22-X22)
H23: 機械 | I23: ='8月'!I23+BACKDATA7月!I23+BACKDATA6月!I23+BACKDATA5月!I23+BACKDATA4月!I23 | J23: ='8月'!J23+BACKDATA7月!J23+BACKDATA6月!J23+BACKDATA5月!J23+BACKDATA4月!J23 | K23: ='8月'!K23+BACKDATA7月!K23+BACKDATA6月!K23+BACKDATA5月!K23+BACKDATA4月!K23 | L23: ='8月'!L23+BACKDATA7月!L23+BACKDATA6月!L23+BACKDATA5月!L23+BACKDATA4月!L23 | M23: =L23-K23 | N23: =L23-J23 | O23: =IF(J23=0,"***",N23/J23) | P23: ='8月'!P23+BACKDATA7月!P23+BACKDATA6月!P23+BACKDATA5月!P23+BACKDATA4月!P23 | Q23: ='8月'!Q23+BACKDATA7月!Q23+BACKDATA6月!Q23+BACKDATA5月!Q23+BACKDATA4月!Q23 | R23: ='8月'!R23+BACKDATA7月!R23+BACKDATA6月!R23+BACKDATA5月!R23+BACKDATA4月!R23 | S23: ='8月'!S23+BACKDATA7月!S23+BACKDATA6月!S23+BACKDATA5月!S23+BACKDATA4月!S23 | T23: =S23-R23 | U23: =S23-Q23 | V23: =IF(Q23=0,"***",U23/Q23) | W23: =IF(I23=0,"***",P23/I23) | X23: =IF(J23=0,"***",Q23/J23) | Y23: =IF(K23=0,"***",R23/K23) | Z23: =IF(L23=0,"***",S23/L23) | AA23: =IF(Y23="***","***",Z23-X23) | AB23: =IF(Z23="***","***",Z23-X23)
G24: リンガーハット | I24: ='8月'!I24+BACKDATA7月!I24+BACKDATA6月!I24+BACKDATA5月!I24+BACKDATA4月!I24 | J24: ='8月'!J24+BACKDATA7月!J24+BACKDATA6月!J24+BACKDATA5月!J24+BACKDATA4月!J24 | K24: ='8月'!K24+BACKDATA7月!K24+BACKDATA6月!K24+BACKDATA5月!K24+BACKDATA4月!K24 | L24: ='8月'!L24+BACKDATA7月!L24+BACKDATA6月!L24+BACKDATA5月!L24+BACKDATA4月!L24 | M24: =L24-K24 | N24: =L24-J24 | O24: =IF(J24=0,"***",N24/J24) | P24: ='8月'!P24+BACKDATA7月!P24+BACKDATA6月!P24+BACKDATA5月!P24+BACKDATA4月!P24 | Q24: ='8月'!Q24+BACKDATA7月!Q24+BACKDATA6月!Q24+BACKDATA5月!Q24+BACKDATA4月!Q24 | R24: ='8月'!R24+BACKDATA7月!R24+BACKDATA6月!R24+BACKDATA5月!R24+BACKDATA4月!R24 | S24: ='8月'!S24+BACKDATA7月!S24+BACKDATA6月!S24+BACKDATA5月!S24+BACKDATA4月!S24 | T24: =S24-R24 | U24: =S24-Q24 | V24: =IF(Q24=0,"***",U24/Q24) | W24: =IF(I24=0,"***",P24/I24) | X24: =IF(J24=0,"***",Q24/J24) | Y24: =IF(K24=0,"***",R24/K24) | Z24: =IF(L24=0,"***",S24/L24) | AA24: =IF(Y24="***","***",Z24-X24) | AB24: =IF(Z24="***","***",Z24-X24)
H25: 包装資材 | I25: =I24-I26 | J25: =J24-J26 | K25: =K24-K26 | L25: =L24-L26 | M25: =L25-K25 | N25: =L25-J25 | O25: =IF(J25=0,"***",N25/J25) | P25: =P24-P26 | Q25: =Q24-Q26 | R25: =R24-R26 | S25: =S24-S26 | T25: =S25-R25 | U25: =S25-Q25 | V25: =IF(Q25=0,"***",U25/Q25) | W25: =IF(I25=0,"***",P25/I25) | X25: =IF(J25=0,"***",Q25/J25) | Y25: =IF(K25=0,"***",R25/K25) | Z25: =IF(L25=0,"***",S25/L25) | AA25: =IF(Y25="***","***",Z25-X25) | AB25: =IF(Z25="***","***",Z25-X25)
H26: 機械 | I26: ='8月'!I26+BACKDATA7月!I26+BACKDATA6月!I26+BACKDATA5月!I26+BACKDATA4月!I26 | J26: ='8月'!J26+BACKDATA7月!J26+BACKDATA6月!J26+BACKDATA5月!J26+BACKDATA4月!J26 | K26: ='8月'!K26+BACKDATA7月!K26+BACKDATA6月!K26+BACKDATA5月!K26+BACKDATA4月!K26 | L26: ='8月'!L26+BACKDATA7月!L26+BACKDATA6月!L26+BACKDATA5月!L26+BACKDATA4月!L26 | M26: =L26-K26 | N26: =L26-J26 | O26: =IF(J26=0,"***",N26/J26) | P26: ='8月'!P26+BACKDATA7月!P26+BACKDATA6月!P26+BACKDATA5月!P26+BACKDATA4月!P26 | Q26: ='8月'!Q26+BACKDATA7月!Q26+BACKDATA6月!Q26+BACKDATA5月!Q26+BACKDATA4月!Q26 | R26: ='8月'!R26+BACKDATA7月!R26+BACKDATA6月!R26+BACKDATA5月!R26+BACKDATA4月!R26 | S26: ='8月'!S26+BACKDATA7月!S26+BACKDATA6月!S26+BACKDATA5月!S26+BACKDATA4月!S26 | T26: =S26-R26 | U26: =S26-Q26 | V26: =IF(Q26=0,"***",U26/Q26) | W26: =IF(I26=0,"***",P26/I26) | X26: =IF(J26=0,"***",Q26/J26) | Y26: =IF(K26=0,"***",R26/K26) | Z26: =IF(L26=0,"***",S26/L26) | AA26: =IF(Y26="***","***",Z26-X26) | AB26: =IF(Z26="***","***",Z26-X26)
G27: リンガーハット以外 | I27: =I21-I24 | J27: =J21-J24 | K27: =K21-K24 | L27: =L21-L24 | M27: =L27-K27 | N27: =L27-J27 | O27: =IF(J27=0,"***",N27/J27) | P27: =P21-P24 | Q27: =Q21-Q24 | R27: =R21-R24 | S27: =S21-S24 | T27: =S27-R27 | U27: =S27-Q27 | V27: =IF(Q27=0,"***",U27/Q27) | W27: =IF(I27=0,"***",P27/I27) | X27: =IF(J27=0,"***",Q27/J27) | Y27: =IF(K27=0,"***",R27/K27) | Z27: =IF(L27=0,"***",S27/L27) | AA27: =IF(Y27="***","***",Z27-X27) | AB27: =IF(Z27="***","***",Z27-X27)
H28: 包装資材 | I28: =I27-I29 | J28: =J27-J29 | K28: =K27-K29 | L28: =L27-L29 | M28: =L28-K28 | N28: =L28-J28 | O28: =IF(J28=0,"***",N28/J28) | P28: =P27-P29 | Q28: =Q27-Q29 | R28: =R27-R29 | S28: =S27-S29 | T28: =S28-R28 | U28: =S28-Q28 | V28: =IF(Q28=0,"***",U28/Q28) | W28: =IF(I28=0,"***",P28/I28) | X28: =IF(J28=0,"***",Q28/J28) | Y28: =IF(K28=0,"***",R28/K28) | Z28: =IF(L28=0,"***",S28/L28) | AA28: =IF(Y28="***","***",Z28-X28) | AB28: =IF(Z28="***","***",Z28-X28)
H29: 機械 | I29: =I23-I26 | J29: =J23-J26 | K29: =K23-K26 | L29: =L23-L26 | M29: =L29-K29 | N29: =L29-J29 | O29: =IF(J29=0,"***",N29/J29) | P29: =P23-P26 | Q29: =Q23-Q26 | R29: =R23-R26 | S29: =S23-S26 | T29: =S29-R29 | U29: =S29-Q29 | V29: =IF(Q29=0,"***",U29/Q29) | W29: =IF(I29=0,"***",P29/I29) | X29: =IF(J29=0,"***",Q29/J29) | Y29: =IF(K29=0,"***",R29/K29) | Z29: =IF(L29=0,"***",S29/L29) | AA29: =IF(Y29="***","***",Z29-X29) | AB29: =IF(Z29="***","***",Z29-X29)
F30: 境港営業所 | I30: ='8月'!I30+BACKDATA7月!I30+BACKDATA6月!I30+BACKDATA5月!I30+BACKDATA4月!I30 | J30: ='8月'!J30+BACKDATA7月!J30+BACKDATA6月!J30+BACKDATA5月!J30+BACKDATA4月!J30 | K30: ='8月'!K30+BACKDATA7月!K30+BACKDATA6月!K30+BACKDATA5月!K30+BACKDATA4月!K30 | L30: ='8月'!L30+BACKDATA7月!L30+BACKDATA6月!L30+BACKDATA5月!L30+BACKDATA4月!L30 | M30: =L30-K30 | N30: =L30-J30 | O30: =IF(J30=0,"***",N30/J30) | P30: ='8月'!P30+BACKDATA7月!P30+BACKDATA6月!P30+BACKDATA5月!P30+BACKDATA4月!P30 | Q30: ='8月'!Q30+BACKDATA7月!Q30+BACKDATA6月!Q30+BACKDATA5月!Q30+BACKDATA4月!Q30 | R30: ='8月'!R30+BACKDATA7月!R30+BACKDATA6月!R30+BACKDATA5月!R30+BACKDATA4月!R30 | S30: ='8月'!S30+BACKDATA7月!S30+BACKDATA6月!S30+BACKDATA5月!S30+BACKDATA4月!S30 | T30: =S30-R30 | U30: =S30-Q30 | V30: =IF(Q30=0,"***",U30/Q30) | W30: =IF(I30=0,"***",P30/I30) | X30: =IF(J30=0,"***",Q30/J30) | Y30: =IF(K30=0,"***",R30/K30) | Z30: =IF(L30=0,"***",S30/L30) | AA30: =IF(Y30="***","***",Z30-X30) | AB30: =IF(Z30="***","***",Z30-X30)
G31: 営業 | I31: =I30-I35-I34 | J31: =J30-J35-J34 | K31: =K30-K35-K34 | L31: =L30-L35-L34 | M31: =L31-K31 | N31: =L31-J31 | O31: =IF(J31=0,"***",N31/J31) | P31: =P30-P35-P34 | Q31: =Q30-Q35-Q34 | R31: =R30-R35-R34 | S31: =S30-S35-S34 | T31: =S31-R31 | U31: =S31-Q31 | V31: =IF(Q31=0,"***",U31/Q31) | W31: =IF(I31=0,"***",P31/I31) | X31: =IF(J31=0,"***",Q31/J31) | Y31: =IF(K31=0,"***",R31/K31) | Z31: =IF(L31=0,"***",S31/L31) | AA31: =IF(Y31="***","***",Z31-X31) | AB31: =IF(Z31="***","***",Z31-X31)
H32: 包装資材 | I32: =I31-I33 | J32: =J31-J33 | K32: =K31-K33 | L32: =L31-L33 | M32: =L32-K32 | N32: =L32-J32 | O32: =IF(J32=0,"***",N32/J32) | P32: =P31-P33 | Q32: =Q31-Q33 | R32: =R31-R33 | S32: =S31-S33 | T32: =S32-R32 | U32: =S32-Q32 | V32: =IF(Q32=0,"***",U32/Q32) | W32: =IF(I32=0,"***",P32/I32) | X32: =IF(J32=0,"***",Q32/J32) | Y32: =IF(K32=0,"***",R32/K32) | Z32: =IF(L32=0,"***",S32/L32) | AA32: =IF(Y32="***","***",Z32-X32) | AB32: =IF(Z32="***","***",Z32-X32)
H33: 機械 | I33: ='8月'!I33+BACKDATA7月!I33+BACKDATA6月!I33+BACKDATA5月!I33+BACKDATA4月!I33 | J33: ='8月'!J33+BACKDATA7月!J33+BACKDATA6月!J33+BACKDATA5月!J33+BACKDATA4月!J33 | K33: ='8月'!K33+BACKDATA7月!K33+BACKDATA6月!K33+BACKDATA5月!K33+BACKDATA4月!K33 | L33: ='8月'!L33+BACKDATA7月!L33+BACKDATA6月!L33+BACKDATA5月!L33+BACKDATA4月!L33 | M33: =L33-K33 | N33: =L33-J33 | O33: =IF(J33=0,"***",N33/J33) | P33: ='8月'!P33+BACKDATA7月!P33+BACKDATA6月!P33+BACKDATA5月!P33+BACKDATA4月!P33 | Q33: ='8月'!Q33+BACKDATA7月!Q33+BACKDATA6月!Q33+BACKDATA5月!Q33+BACKDATA4月!Q33 | R33: ='8月'!R33+BACKDATA7月!R33+BACKDATA6月!R33+BACKDATA5月!R33+BACKDATA4月!R33 | S33: ='8月'!S33+BACKDATA7月!S33+BACKDATA6月!S33+BACKDATA5月!S33+BACKDATA4月!S33 | T33: =S33-R33 | U33: =S33-Q33 | V33: =IF(Q33=0,"***",U33/Q33) | W33: =IF(I33=0,"***",P33/I33) | X33: =IF(J33=0,"***",Q33/J33) | Y33: =IF(K33=0,"***",R33/K33) | Z33: =IF(L33=0,"***",S33/L33) | AA33: =IF(Y33="***","***",Z33-X33) | AB33: =IF(Z33="***","***",Z33-X33)
G34: 自治体 | I34: ='8月'!I34+BACKDATA7月!I34+BACKDATA6月!I34+BACKDATA5月!I34+BACKDATA4月!I34 | J34: ='8月'!J34+BACKDATA7月!J34+BACKDATA6月!J34+BACKDATA5月!J34+BACKDATA4月!J34 | K34: ='8月'!K34+BACKDATA7月!K34+BACKDATA6月!K34+BACKDATA5月!K34+BACKDATA4月!K34 | L34: ='8月'!L34+BACKDATA7月!L34+BACKDATA6月!L34+BACKDATA5月!L34+BACKDATA4月!L34 | M34: =L34-K34 | N34: =L34-J34 | O34: =IF(J34=0,"***",N34/J34) | P34: ='8月'!P34+BACKDATA7月!P34+BACKDATA6月!P34+BACKDATA5月!P34+BACKDATA4月!P34 | Q34: ='8月'!Q34+BACKDATA7月!Q34+BACKDATA6月!Q34+BACKDATA5月!Q34+BACKDATA4月!Q34 | R34: ='8月'!R34+BACKDATA7月!R34+BACKDATA6月!R34+BACKDATA5月!R34+BACKDATA4月!R34 | S34: ='8月'!S34+BACKDATA7月!S34+BACKDATA6月!S34+BACKDATA5月!S34+BACKDATA4月!S34 | T34: =S34-R34 | U34: =S34-Q34 | V34: =IF(Q34=0,"***",U34/Q34) | W34: =IF(I34=0,"***",P34/I34) | X34: =IF(J34=0,"***",Q34/J34) | Y34: =IF(K34=0,"***",R34/K34) | Z34: =IF(L34=0,"***",S34/L34) | AA34: =IF(Y34="***","***",Z34-X34) | AB34: =IF(Z34="***","***",Z34-X34)
G35: 海外 | I35: ='8月'!I35+BACKDATA7月!I35+BACKDATA6月!I35+BACKDATA5月!I35+BACKDATA4月!I35 | J35: ='8月'!J35+BACKDATA7月!J35+BACKDATA6月!J35+BACKDATA5月!J35+BACKDATA4月!J35 | K35: ='8月'!K35+BACKDATA7月!K35+BACKDATA6月!K35+BACKDATA5月!K35+BACKDATA4月!K35 | L35: ='8月'!L35+BACKDATA7月!L35+BACKDATA6月!L35+BACKDATA5月!L35+BACKDATA4月!L35 | M35: =L35-K35 | N35: =L35-J35 | O35: =IF(J35=0,"***",N35/J35) | P35: ='8月'!P35+BACKDATA7月!P35+BACKDATA6月!P35+BACKDATA5月!P35+BACKDATA4月!P35 | Q35: ='8月'!Q35+BACKDATA7月!Q35+BACKDATA6月!Q35+BACKDATA5月!Q35+BACKDATA4月!Q35 | R35: ='8月'!R35+BACKDATA7月!R35+BACKDATA6月!R35+BACKDATA5月!R35+BACKDATA4月!R35 | S35: ='8月'!S35+BACKDATA7月!S35+BACKDATA6月!S35+BACKDATA5月!S35+BACKDATA4月!S35 | T35: =S35-R35 | U35: =S35-Q35 | V35: =IF(Q35=0,"***",U35/Q35) | W35: =IF(I35=0,"***",P35/I35) | X35: =IF(J35=0,"***",Q35/J35) | Y35: =IF(K35=0,"***",R35/K35) | Z35: =IF(L35=0,"***",S35/L35) | AA35: =IF(Y35="***","***",Z35-X35) | AB35: =IF(Z35="***","***",Z35-X35)
E36: 営業部門合計 | I36: =I30+I21+I16+I10+I5 | J36: =J30+J21+J16+J10+J5 | K36: =K30+K21+K16+K10+K5 | L36: =L30+L21+L16+L10+L5 | M36: =L36-K36 | N36: =L36-J36 | O36: =IF(J36=0,"***",N36/J36) | P36: =P30+P21+P16+P10+P5 | Q36: =Q30+Q21+Q16+Q10+Q5 | R36: =R30+R21+R16+R10+R5 | S36: =S30+S21+S16+S10+S5 | T36: =S36-R36 | U36: =S36-Q36 | V36: =IF(Q36=0,"***",U36/Q36) | W36: =IF(I36=0,"***",P36/I36) | X36: =IF(J36=0,"***",Q36/J36) | Y36: =IF(K36=0,"***",R36/K36) | Z36: =IF(L36=0,"***",S36/L36) | AA36: =IF(Y36="***","***",Z36-X36) | AB36: =IF(Z36="***","***",Z36-X36)
H37: 機械以外 | I37: =I36-I38-I39-I40 | J37: =J36-J38-J39-J40 | K37: =K36-K38-K39-K40 | L37: =L36-L38-L39-L40 | M37: =L37-K37 | N37: =L37-J37 | O37: =IF(J37=0,"***",N37/J37) | P37: =P36-P38-P39-P40 | Q37: =Q36-Q38-Q39-Q40 | R37: =R36-R38-R39-R40 | S37: =S36-S38-S39-S40 | T37: =S37-R37 | U37: =S37-Q37 | V37: =IF(Q37=0,"***",U37/Q37) | W37: =IF(I37=0,"***",P37/I37) | X37: =IF(J37=0,"***",Q37/J37) | Y37: =IF(K37=0,"***",R37/K37) | Z37: =IF(L37=0,"***",S37/L37) | AA37: =IF(Y37="***","***",Z37-X37) | AB37: =IF(Z37="***","***",Z37-X37)
H38: 機械 | I38: =I33+I23+I19+I13+I8 | J38: =J33+J23+J19+J13+J8 | K38: =K33+K23+K19+K13+K8 | L38: =L33+L23+L19+L13+L8 | M38: =L38-K38 | N38: =L38-J38 | O38: =IF(J38=0,"***",N38/J38) | P38: =P33+P23+P19+P13+P8 | Q38: =Q33+Q23+Q19+Q13+Q8 | R38: =R33+R23+R19+R13+R8 | S38: =S33+S23+S19+S13+S8 | T38: =S38-R38 | U38: =S38-Q38 | V38: =IF(Q38=0,"***",U38/Q38) | W38: =IF(I38=0,"***",P38/I38) | X38: =IF(J38=0,"***",Q38/J38) | Y38: =IF(K38=0,"***",R38/K38) | Z38: =IF(L38=0,"***",S38/L38) | AA38: =IF(Y38="***","***",Z38-X38) | AB38: =IF(Z38="***","***",Z38-X38)
H39: 自治体 | I39: =I34+I20+I14+I9 | J39: =J34+J20+J14+J9 | K39: =K34+K20+K14+K9 | L39: =L34+L20+L14+L9 | M39: =L39-K39 | N39: =L39-J39 | O39: =IF(J39=0,"***",N39/J39) | P39: =P34+P20+P14+P9 | Q39: =Q34+Q20+Q14+Q9 | R39: =R34+R20+R14+R9 | S39: =S34+S20+S14+S9 | T39: =S39-R39 | U39: =S39-Q39 | V39: =IF(Q39=0,"***",U39/Q39) | W39: =IF(I39=0,"***",P39/I39) | X39: =IF(J39=0,"***",Q39/J39) | Y39: =IF(K39=0,"***",R39/K39) | Z39: =IF(L39=0,"***",S39/L39) | AA39: =IF(Y39="***","***",Z39-X39) | AB39: =IF(Z39="***","***",Z39-X39)
H40: 海外 | I40: =I35+I15 | J40: =J35+J15 | K40: =K35+K15 | L40: =L35+L15 | M40: =L40-K40 | N40: =L40-J40 | O40: =IF(J40=0,"***",N40/J40) | P40: =P35+P15 | Q40: =Q35+Q15 | R40: =R35+R15 | S40: =S35+S15 | T40: =S40-R40 | U40: =S40-Q40 | V40: =IF(Q40=0,"***",U40/Q40) | W40: =IF(I40=0,"***",P40/I40) | X40: =IF(J40=0,"***",Q40/J40) | Y40: =IF(K40=0,"***",R40/K40) | Z40: =IF(L40=0,"***",S40/L40) | AA40: =IF(Y40="***","***",Z40-X40) | AB40: =IF(Z40="***","***",Z40-X40)
E41: 水産部 | I41: ='8月'!I41+BACKDATA7月!I41+BACKDATA6月!I41+BACKDATA5月!I41+BACKDATA4月!I41 | J41: ='8月'!J41+BACKDATA7月!J41+BACKDATA6月!J41+BACKDATA5月!J41+BACKDATA4月!J41 | K41: ='8月'!K41+BACKDATA7月!K41+BACKDATA6月!K41+BACKDATA5月!K41+BACKDATA4月!K41 | L41: ='8月'!L41+BACKDATA7月!L41+BACKDATA6月!L41+BACKDATA5月!L41+BACKDATA4月!L41 | M41: =L41-K41 | N41: =L41-J41 | O41: =IF(J41=0,"***",N41/J41) | P41: ='8月'!P41+BACKDATA7月!P41+BACKDATA6月!P41+BACKDATA5月!P41+BACKDATA4月!P41 | Q41: ='8月'!Q41+BACKDATA7月!Q41+BACKDATA6月!Q41+BACKDATA5月!Q41+BACKDATA4月!Q41 | R41: ='8月'!R41+BACKDATA7月!R41+BACKDATA6月!R41+BACKDATA5月!R41+BACKDATA4月!R41 | S41: ='8月'!S41+BACKDATA7月!S41+BACKDATA6月!S41+BACKDATA5月!S41+BACKDATA4月!S41 | T41: =S41-R41 | U41: =S41-Q41 | V41: =IF(Q41=0,"***",U41/Q41) | W41: =IF(I41=0,"***",P41/I41) | X41: =IF(J41=0,"***",Q41/J41) | Y41: =IF(K41=0,"***",R41/K41) | Z41: =IF(L41=0,"***",S41/L41) | AA41: =IF(Y41="***","***",Z41-X41) | AB41: =IF(Z41="***","***",Z41-X41)
...

Sheet 期初来累計
D1: 3．期初来累計（上期＋下期）
I3: 前々期売上実績 | J3: 前期売上実績 | K3: 今期期初来計画 | L3: 今期期初来実績 | P3: 前々期粗利益実績 | Q3: 前期粗利益実績 | R3: 今期期初来粗利計画 | S3: 今期期初来粗利実績 | W3: 前々期初来粗利益率実績 | X3: 前期期初来粗利益率実績 | Y3: 今期期初来粗利益率計画 | Z3: 今期期初来粗利益率実績 | AC3: 作成根拠
M4: 計画比 | N4: 前期比 | O4: 年率 | T4: 計画比 | U4: 前期比 | V4: 年率 | AA4: 計画比 | AB4: 前期比
F5: 石見営業所 | I5: =BACKDATA上期!CO5+下期!I5 | J5: =BACKDATA上期!CP5+下期!J5 | K5: =BACKDATA上期!CQ5+下期!K5 | L5: =BACKDATA上期!CR5+下期!L5 | M5: =L5-K5 | N5: =L5-J5 | O5: =IF(J5=0,"***",N5/J5) | P5: =BACKDATA上期!CV5+下期!P5 | Q5: =BACKDATA上期!CW5+下期!Q5 | R5: =BACKDATA上期!CX5+下期!R5 | S5: =BACKDATA上期!CY5+下期!S5 | T5: =S5-R5 | U5: =S5-Q5 | V5: =IF(Q5=0,"***",U5/Q5) | W5: =IF(I5=0,"***",P5/I5) | X5: =IF(J5=0,"***",Q5/J5) | Y5: =IF(K5=0,"***",R5/K5) | Z5: =IF(L5=0,"***",S5/L5) | AA5: =IF(Y5="***","***",Z5-X5) | AB5: =IF(Z5="***","***",Z5-X5)
G6: 営業 | I6: =I5-I9 | J6: =J5-J9 | K6: =K5-K9 | L6: =L5-L9 | M6: =L6-K6 | N6: =L6-J6 | O6: =IF(J6=0,"***",N6/J6) | P6: =P5-P9 | Q6: =Q5-Q9 | R6: =R5-R9 | S6: =S5-S9 | T6: =S6-R6 | U6: =S6-Q6 | V6: =IF(Q6=0,"***",U6/Q6) | W6: =IF(I6=0,"***",P6/I6) | X6: =IF(J6=0,"***",Q6/J6) | Y6: =IF(K6=0,"***",R6/K6) | Z6: =IF(L6=0,"***",S6/L6) | AA6: =IF(Y6="***","***",Z6-X6) | AB6: =IF(Z6="***","***",Z6-X6)
H7: 包装資材 | I7: =I6-I8 | J7: =J6-J8 | K7: =K6-K8 | L7: =L6-L8 | M7: =L7-K7 | N7: =L7-J7 | O7: =IF(J7=0,"***",N7/J7) | P7: =P6-P8 | Q7: =Q6-Q8 | R7: =R6-R8 | S7: =S6-S8 | T7: =S7-R7 | U7: =S7-Q7 | V7: =IF(Q7=0,"***",U7/Q7) | W7: =IF(I7=0,"***",P7/I7) | X7: =IF(J7=0,"***",Q7/J7) | Y7: =IF(K7=0,"***",R7/K7) | Z7: =IF(L7=0,"***",S7/L7) | AA7: =IF(Y7="***","***",Z7-X7) | AB7: =IF(Z7="***","***",Z7-X7)
H8: 機械 | I8: =BACKDATA上期!CO8+下期!I8 | J8: =BACKDATA上期!CP8+下期!J8 | K8: =BACKDATA上期!CQ8+下期!K8 | L8: =BACKDATA上期!CR8+下期!L8 | M8: =L8-K8 | N8: =L8-J8 | O8: =IF(J8=0,"***",N8/J8) | P8: =BACKDATA上期!CV8+下期!P8 | Q8: =BACKDATA上期!CW8+下期!Q8 | R8: =BACKDATA上期!CX8+下期!R8 | S8: =BACKDATA上期!CY8+下期!S8 | T8: =S8-R8 | U8: =S8-Q8 | V8: =IF(Q8=0,"***",U8/Q8) | W8: =IF(I8=0,"***",P8/I8) | X8: =IF(J8=0,"***",Q8/J8) | Y8: =IF(K8=0,"***",R8/K8) | Z8: =IF(L8=0,"***",S8/L8) | AA8: =IF(Y8="***","***",Z8-X8) | AB8: =IF(Z8="***","***",Z8-X8)
G9: 自治体 | I9: =BACKDATA上期!CO9+下期!I9 | J9: =BACKDATA上期!CP9+下期!J9 | K9: =BACKDATA上期!CQ9+下期!K9 | L9: =BACKDATA上期!CR9+下期!L9 | M9: =L9-K9 | N9: =L9-J9 | O9: =IF(J9=0,"***",N9/J9) | P9: =BACKDATA上期!CV9+下期!P9 | Q9: =BACKDATA上期!CW9+下期!Q9 | R9: =BACKDATA上期!CX9+下期!R9 | S9: =BACKDATA上期!CY9+下期!S9 | T9: =S9-R9 | U9: =S9-Q9 | V9: =IF(Q9=0,"***",U9/Q9) | W9: =IF(I9=0,"***",P9/I9) | X9: =IF(J9=0,"***",Q9/J9) | Y9: =IF(K9=0,"***",R9/K9) | Z9: =IF(L9=0,"***",S9/L9) | AA9: =IF(Y9="***","***",Z9-X9) | AB9: =IF(Z9="***","***",Z9-X9)
F10: 下関営業所 | I10: =BACKDATA上期!CO10+下期!I10 | J10: =BACKDATA上期!CP10+下期!J10 | K10: =BACKDATA上期!CQ10+下期!K10 | L10: =BACKDATA上期!CR10+下期!L10 | M10: =L10-K10 | N10: =L10-J10 | O10: =IF(J10=0,"***",N10/J10) | P10: =BACKDATA上期!CV10+下期!P10 | Q10: =BACKDATA上期!CW10+下期!Q10 | R10: =BACKDATA上期!CX10+下期!R10 | S10: =BACKDATA上期!CY10+下期!S10 | T10: =S10-R10 | U10: =S10-Q10 | V10: =IF(Q10=0,"***",U10/Q10) | W10: =IF(I10=0,"***",P10/I10) | X10: =IF(J10=0,"***",Q10/J10) | Y10: =IF(K10=0,"***",R10/K10) | Z10: =IF(L10=0,"***",S10/L10) | AA10: =IF(Y10="***","***",Z10-X10) | AB10: =IF(Z10="***","***",Z10-X10)
G11: 営業 | I11: =I10-I15-I14 | J11: =J10-J15-J14 | K11: =K10-K15-K14 | L11: =L10-L15-L14 | M11: =L11-K11 | N11: =L11-J11 | O11: =IF(J11=0,"***",N11/J11) | P11: =P10-P15-P14 | Q11: =Q10-Q15-Q14 | R11: =R10-R15-R14 | S11: =S10-S15-S14 | T11: =S11-R11 | U11: =S11-Q11 | V11: =IF(Q11=0,"***",U11/Q11) | W11: =IF(I11=0,"***",P11/I11) | X11: =IF(J11=0,"***",Q11/J11) | Y11: =IF(K11=0,"***",R11/K11) | Z11: =IF(L11=0,"***",S11/L11) | AA11: =IF(Y11="***","***",Z11-X11) | AB11: =IF(Z11="***","***",Z11-X11)
H12: 包装資材 | I12: =I11-I13 | J12: =J11-J13 | K12: =K11-K13 | L12: =L11-L13 | M12: =L12-K12 | N12: =L12-J12 | O12: =IF(J12=0,"***",N12/J12) | P12: =P11-P13 | Q12: =Q11-Q13 | R12: =R11-R13 | S12: =S11-S13 | T12: =S12-R12 | U12: =S12-Q12 | V12: =IF(Q12=0,"***",U12/Q12) | W12: =IF(I12=0,"***",P12/I12) | X12: =IF(J12=0,"***",Q12/J12) | Y12: =IF(K12=0,"***",R12/K12) | Z12: =IF(L12=0,"***",S12/L12) | AA12: =IF(Y12="***","***",Z12-X12) | AB12: =IF(Z12="***","***",Z12-X12)
H13: 機械 | I13: =BACKDATA上期!CO13+下期!I13 | J13: =BACKDATA上期!CP13+下期!J13 | K13: =BACKDATA上期!CQ13+下期!K13 | L13: =BACKDATA上期!CR13+下期!L13 | M13: =L13-K13 | N13: =L13-J13 | O13: =IF(J13=0,"***",N13/J13) | P13: =BACKDATA上期!CV13+下期!P13 | Q13: =BACKDATA上期!CW13+下期!Q13 | R13: =BACKDATA上期!CX13+下期!R13 | S13: =BACKDATA上期!CY13+下期!S13 | T13: =S13-R13 | U13: =S13-Q13 | V13: =IF(Q13=0,"***",U13/Q13) | W13: =IF(I13=0,"***",P13/I13) | X13: =IF(J13=0,"***",Q13/J13) | Y13: =IF(K13=0,"***",R13/K13) | Z13: =IF(L13=0,"***",S13/L13) | AA13: =IF(Y13="***","***",Z13-X13) | AB13: =IF(Z13="***","***",Z13-X13)
G14: 自治体 | I14: =BACKDATA上期!CO14+下期!I14 | J14: =BACKDATA上期!CP14+下期!J14 | K14: =BACKDATA上期!CQ14+下期!K14 | L14: =BACKDATA上期!CR14+下期!L14 | M14: =L14-K14 | N14: =L14-J14 | O14: =IF(J14=0,"***",N14/J14) | P14: =BACKDATA上期!CV14+下期!P14 | Q14: =BACKDATA上期!CW14+下期!Q14 | R14: =BACKDATA上期!CX14+下期!R14 | S14: =BACKDATA上期!CY14+下期!S14 | T14: =S14-R14 | U14: =S14-Q14 | V14: =IF(Q14=0,"***",U14/Q14) | W14: =IF(I14=0,"***",P14/I14) | X14: =IF(J14=0,"***",Q14/J14) | Y14: =IF(K14=0,"***",R14/K14) | Z14: =IF(L14=0,"***",S14/L14) | AA14: =IF(Y14="***","***",Z14-X14) | AB14: =IF(Z14="***","***",Z14-X14)
G15: 海外 | I15: =BACKDATA上期!CO15+下期!I15 | J15: =BACKDATA上期!CP15+下期!J15 | K15: =BACKDATA上期!CQ15+下期!K15 | L15: =BACKDATA上期!CR15+下期!L15 | M15: =L15-K15 | N15: =L15-J15 | O15: =IF(J15=0,"***",N15/J15) | P15: =BACKDATA上期!CV15+下期!P15 | Q15: =BACKDATA上期!CW15+下期!Q15 | R15: =BACKDATA上期!CX15+下期!R15 | S15: =BACKDATA上期!CY15+下期!S15 | T15: =S15-R15 | U15: =S15-Q15 | V15: =IF(Q15=0,"***",U15/Q15) | W15: =IF(I15=0,"***",P15/I15) | X15: =IF(J15=0,"***",Q15/J15) | Y15: =IF(K15=0,"***",R15/K15) | Z15: =IF(L15=0,"***",S15/L15) | AA15: =IF(Y15="***","***",Z15-X15) | AB15: =IF(Z15="***","***",Z15-X15)
F16: 松江営業所 | I16: =BACKDATA上期!CO16+下期!I16 | J16: =BACKDATA上期!CP16+下期!J16 | K16: =BACKDATA上期!CQ16+下期!K16 | L16: =BACKDATA上期!CR16+下期!L16 | M16: =L16-K16 | N16: =L16-J16 | O16: =IF(J16=0,"***",N16/J16) | P16: =BACKDATA上期!CV16+下期!P16 | Q16: =BACKDATA上期!CW16+下期!Q16 | R16: =BACKDATA上期!CX16+下期!R16 | S16: =BACKDATA上期!CY16+下期!S16 | T16: =S16-R16 | U16: =S16-Q16 | V16: =IF(Q16=0,"***",U16/Q16) | W16: =IF(I16=0,"***",P16/I16) | X16: =IF(J16=0,"***",Q16/J16) | Y16: =IF(K16=0,"***",R16/K16) | Z16: =IF(L16=0,"***",S16/L16) | AA16: =IF(Y16="***","***",Z16-X16) | AB16: =IF(Z16="***","***",Z16-X16)
G17: 営業 | I17: =I16-I20 | J17: =J16-J20 | K17: =K16-K20 | L17: =L16-L20 | M17: =L17-K17 | N17: =L17-J17 | O17: =IF(J17=0,"***",N17/J17) | P17: =P16-P20 | Q17: =Q16-Q20 | R17: =R16-R20 | S17: =S16-S20 | T17: =S17-R17 | U17: =S17-Q17 | V17: =IF(Q17=0,"***",U17/Q17) | W17: =IF(I17=0,"***",P17/I17) | X17: =IF(J17=0,"***",Q17/J17) | Y17: =IF(K17=0,"***",R17/K17) | Z17: =IF(L17=0,"***",S17/L17) | AA17: =IF(Y17="***","***",Z17-X17) | AB17: =IF(Z17="***","***",Z17-X17)
H18: 包装資材 | I18: =I17-I19 | J18: =J17-J19 | K18: =K17-K19 | L18: =L17-L19 | M18: =L18-K18 | N18: =L18-J18 | O18: =IF(J18=0,"***",N18/J18) | P18: =P17-P19 | Q18: =Q17-Q19 | R18: =R17-R19 | S18: =S17-S19 | T18: =S18-R18 | U18: =S18-Q18 | V18: =IF(Q18=0,"***",U18/Q18) | W18: =IF(I18=0,"***",P18/I18) | X18: =IF(J18=0,"***",Q18/J18) | Y18: =IF(K18=0,"***",R18/K18) | Z18: =IF(L18=0,"***",S18/L18) | AA18: =IF(Y18="***","***",Z18-X18) | AB18: =IF(Z18="***","***",Z18-X18)
H19: 機械 | I19: =BACKDATA上期!CO19+下期!I19 | J19: =BACKDATA上期!CP19+下期!J19 | K19: =BACKDATA上期!CQ19+下期!K19 | L19: =BACKDATA上期!CR19+下期!L19 | M19: =L19-K19 | N19: =L19-J19 | O19: =IF(J19=0,"***",N19/J19) | P19: =BACKDATA上期!CV19+下期!P19 | Q19: =BACKDATA上期!CW19+下期!Q19 | R19: =BACKDATA上期!CX19+下期!R19 | S19: =BACKDATA上期!CY19+下期!S19 | T19: =S19-R19 | U19: =S19-Q19 | V19: =IF(Q19=0,"***",U19/Q19) | W19: =IF(I19=0,"***",P19/I19) | X19: =IF(J19=0,"***",Q19/J19) | Y19: =IF(K19=0,"***",R19/K19) | Z19: =IF(L19=0,"***",S19/L19) | AA19: =IF(Y19="***","***",Z19-X19) | AB19: =IF(Z19="***","***",Z19-X19)
G20: 自治体 | I20: =BACKDATA上期!CO20+下期!I20 | J20: =BACKDATA上期!CP20+下期!J20 | K20: =BACKDATA上期!CQ20+下期!K20 | L20: =BACKDATA上期!CR20+下期!L20 | M20: =L20-K20 | N20: =L20-J20 | O20: =IF(J20=0,"***",N20/J20) | P20: =BACKDATA上期!CV20+下期!P20 | Q20: =BACKDATA上期!CW20+下期!Q20 | R20: =BACKDATA上期!CX20+下期!R20 | S20: =BACKDATA上期!CY20+下期!S20 | T20: =S20-R20 | U20: =S20-Q20 | V20: =IF(Q20=0,"***",U20/Q20) | W20: =IF(I20=0,"***",P20/I20) | X20: =IF(J20=0,"***",Q20/J20) | Y20: =IF(K20=0,"***",R20/K20) | Z20: =IF(L20=0,"***",S20/L20) | AA20: =IF(Y20="***","***",Z20-X20) | AB20: =IF(Z20="***","***",Z20-X20)
F21: 広域営業部 | I21: =BACKDATA上期!CO21+下期!I21 | J21: =BACKDATA上期!CP21+下期!J21 | K21: =BACKDATA上期!CQ21+下期!K21 | L21: =BACKDATA上期!CR21+下期!L21 | M21: =L21-K21 | N21: =L21-J21 | O21: =IF(J21=0,"***",N21/J21) | P21: =BACKDATA上期!CV21+下期!P21 | Q21: =BACKDATA上期!CW21+下期!Q21 | R21: =BACKDATA上期!CX21+下期!R21 | S21: =BACKDATA上期!CY21+下期!S21 | T21: =S21-R21 | U21: =S21-Q21 | V21: =IF(Q21=0,"***",U21/Q21) | W21: =IF(I21=0,"***",P21/I21) | X21: =IF(J21=0,"***",Q21/J21) | Y21: =IF(K21=0,"***",R21/K21) | Z21: =IF(L21=0,"***",S21/L21) | AA21: =IF(Y21="***","***",Z21-X21) | AB21: =IF(Z21="***","***",Z21-X21)
H22: 包装資材 | I22: =I21-I23 | J22: =J21-J23 | K22: =K21-K23 | L22: =L21-L23 | M22: =L22-K22 | N22: =L22-J22 | O22: =IF(J22=0,"***",N22/J22) | P22: =P21-P23 | Q22: =Q21-Q23 | R22: =R21-R23 | S22: =S21-S23 | T22: =S22-R22 | U22: =S22-Q22 | V22: =IF(Q22=0,"***",U22/Q22) | W22: =IF(I22=0,"***",P22/I22) | X22: =IF(J22=0,"***",Q22/J22) | Y22: =IF(K22=0,"***",R22/K22) | Z22: =IF(L22=0,"***",S22/L22) | AA22: =IF(Y22="***","***",Z22-X22) | AB22: =IF(Z22="***","***",Z22-X22)
H23: 機械 | I23: =BACKDATA上期!CO23+下期!I23 | J23: =BACKDATA上期!CP23+下期!J23 | K23: =BACKDATA上期!CQ23+下期!K23 | L23: =BACKDATA上期!CR23+下期!L23 | M23: =L23-K23 | N23: =L23-J23 | O23: =IF(J23=0,"***",N23/J23) | P23: =BACKDATA上期!CV23+下期!P23 | Q23: =BACKDATA上期!CW23+下期!Q23 | R23: =BACKDATA上期!CX23+下期!R23 | S23: =BACKDATA上期!CY23+下期!S23 | T23: =S23-R23 | U23: =S23-Q23 | V23: =IF(Q23=0,"***",U23/Q23) | W23: =IF(I23=0,"***",P23/I23) | X23: =IF(J23=0,"***",Q23/J23) | Y23: =IF(K23=0,"***",R23/K23) | Z23: =IF(L23=0,"***",S23/L23) | AA23: =IF(Y23="***","***",Z23-X23) | AB23: =IF(Z23="***","***",Z23-X23)
G24: リンガーハット | I24: =BACKDATA上期!CO24+下期!I24 | J24: =BACKDATA上期!CP24+下期!J24 | K24: =BACKDATA上期!CQ24+下期!K24 | L24: =BACKDATA上期!CR24+下期!L24 | M24: =L24-K24 | N24: =L24-J24 | O24: =IF(J24=0,"***",N24/J24) | P24: =BACKDATA上期!CV24+下期!P24 | Q24: =BACKDATA上期!CW24+下期!Q24 | R24: =BACKDATA上期!CX24+下期!R24 | S24: =BACKDATA上期!CY24+下期!S24 | T24: =S24-R24 | U24: =S24-Q24 | V24: =IF(Q24=0,"***",U24/Q24) | W24: =IF(I24=0,"***",P24/I24) | X24: =IF(J24=0,"***",Q24/J24) | Y24: =IF(K24=0,"***",R24/K24) | Z24: =IF(L24=0,"***",S24/L24) | AA24: =IF(Y24="***","***",Z24-X24) | AB24: =IF(Z24="***","***",Z24-X24)
H25: 包装資材 | I25: =I24-I26 | J25: =J24-J26 | K25: =K24-K26 | L25: =L24-L26 | M25: =L25-K25 | N25: =L25-J25 | O25: =IF(J25=0,"***",N25/J25) | P25: =P24-P26 | Q25: =Q24-Q26 | R25: =R24-R26 | S25: =S24-S26 | T25: =S25-R25 | U25: =S25-Q25 | V25: =IF(Q25=0,"***",U25/Q25) | W25: =IF(I25=0,"***",P25/I25) | X25: =IF(J25=0,"***",Q25/J25) | Y25: =IF(K25=0,"***",R25/K25) | Z25: =IF(L25=0,"***",S25/L25) | AA25: =IF(Y25="***","***",Z25-X25) | AB25: =IF(Z25="***","***",Z25-X25)
H26: 機械 | I26: =BACKDATA上期!CO26+下期!I26 | J26: =BACKDATA上期!CP26+下期!J26 | K26: =BACKDATA上期!CQ26+下期!K26 | L26: =BACKDATA上期!CR26+下期!L26 | M26: =L26-K26 | N26: =L26-J26 | O26: =IF(J26=0,"***",N26/J26) | P26: =BACKDATA上期!CV26+下期!P26 | Q26: =BACKDATA上期!CW26+下期!Q26 | R26: =BACKDATA上期!CX26+下期!R26 | S26: =BACKDATA上期!CY26+下期!S26 | T26: =S26-R26 | U26: =S26-Q26 | V26: =IF(Q26=0,"***",U26/Q26) | W26: =IF(I26=0,"***",P26/I26) | X26: =IF(J26=0,"***",Q26/J26) | Y26: =IF(K26=0,"***",R26/K26) | Z26: =IF(L26=0,"***",S26/L26) | AA26: =IF(Y26="***","***",Z26-X26) | AB26: =IF(Z26="***","***",Z26-X26)
G27: リンガーハット以外 | I27: =I21-I24 | J27: =J21-J24 | K27: =K21-K24 | L27: =L21-L24 | M27: =L27-K27 | N27: =L27-J27 | O27: =IF(J27=0,"***",N27/J27) | P27: =P21-P24 | Q27: =Q21-Q24 | R27: =R21-R24 | S27: =S21-S24 | T27: =S27-R27 | U27: =S27-Q27 | V27: =IF(Q27=0,"***",U27/Q27) | W27: =IF(I27=0,"***",P27/I27) | X27: =IF(J27=0,"***",Q27/J27) | Y27: =IF(K27=0,"***",R27/K27) | Z27: =IF(L27=0,"***",S27/L27) | AA27: =IF(Y27="***","***",Z27-X27) | AB27: =IF(Z27="***","***",Z27-X27)
H28: 包装資材 | I28: =I27-I29 | J28: =J27-J29 | K28: =K27-K29 | L28: =L27-L29 | M28: =L28-K28 | N28: =L28-J28 | O28: =IF(J28=0,"***",N28/J28) | P28: =P27-P29 | Q28: =Q27-Q29 | R28: =R27-R29 | S28: =S27-S29 | T28: =S28-R28 | U28: =S28-Q28 | V28: =IF(Q28=0,"***",U28/Q28) | W28: =IF(I28=0,"***",P28/I28) | X28: =IF(J28=0,"***",Q28/J28) | Y28: =IF(K28=0,"***",R28/K28) | Z28: =IF(L28=0,"***",S28/L28) | AA28: =IF(Y28="***","***",Z28-X28) | AB28: =IF(Z28="***","***",Z28-X28)
H29: 機械 | I29: =I23-I26 | J29: =J23-J26 | K29: =K23-K26 | L29: =L23-L26 | M29: =L29-K29 | N29: =L29-J29 | O29: =IF(J29=0,"***",N29/J29) | P29: =P23-P26 | Q29: =Q23-Q26 | R29: =R23-R26 | S29: =S23-S26 | T29: =S29-R29 | U29: =S29-Q29 | V29: =IF(Q29=0,"***",U29/Q29) | W29: =IF(I29=0,"***",P29/I29) | X29: =IF(J29=0,"***",Q29/J29) | Y29: =IF(K29=0,"***",R29/K29) | Z29: =IF(L29=0,"***",S29/L29) | AA29: =IF(Y29="***","***",Z29-X29) | AB29: =IF(Z29="***","***",Z29-X29)
F30: 境港営業所 | I30: =BACKDATA上期!CO30+下期!I30 | J30: =BACKDATA上期!CP30+下期!J30 | K30: =BACKDATA上期!CQ30+下期!K30 | L30: =BACKDATA上期!CR30+下期!L30 | M30: =L30-K30 | N30: =L30-J30 | O30: =IF(J30=0,"***",N30/J30) | P30: =BACKDATA上期!CV30+下期!P30 | Q30: =BACKDATA上期!CW30+下期!Q30 | R30: =BACKDATA上期!CX30+下期!R30 | S30: =BACKDATA上期!CY30+下期!S30 | T30: =S30-R30 | U30: =S30-Q30 | V30: =IF(Q30=0,"***",U30/Q30) | W30: =IF(I30=0,"***",P30/I30) | X30: =IF(J30=0,"***",Q30/J30) | Y30: =IF(K30=0,"***",R30/K30) | Z30: =IF(L30=0,"***",S30/L30) | AA30: =IF(Y30="***","***",Z30-X30) | AB30: =IF(Z30="***","***",Z30-X30)
G31: 営業 | I31: =I30-I35-I34 | J31: =J30-J35-J34 | K31: =K30-K35-K34 | L31: =L30-L35-L34 | M31: =L31-K31 | N31: =L31-J31 | O31: =IF(J31=0,"***",N31/J31) | P31: =P30-P35-P34 | Q31: =Q30-Q35-Q34 | R31: =R30-R35-R34 | S31: =S30-S35-S34 | T31: =S31-R31 | U31: =S31-Q31 | V31: =IF(Q31=0,"***",U31/Q31) | W31: =IF(I31=0,"***",P31/I31) | X31: =IF(J31=0,"***",Q31/J31) | Y31: =IF(K31=0,"***",R31/K31) | Z31: =IF(L31=0,"***",S31/L31) | AA31: =IF(Y31="***","***",Z31-X31) | AB31: =IF(Z31="***","***",Z31-X31)
H32: 包装資材 | I32: =I31-I33 | J32: =J31-J33 | K32: =K31-K33 | L32: =L31-L33 | M32: =L32-K32 | N32: =L32-J32 | O32: =IF(J32=0,"***",N32/J32) | P32: =P31-P33 | Q32: =Q31-Q33 | R32: =R31-R33 | S32: =S31-S33 | T32: =S32-R32 | U32: =S32-Q32 | V32: =IF(Q32=0,"***",U32/Q32) | W32: =IF(I32=0,"***",P32/I32) | X32: =IF(J32=0,"***",Q32/J32) | Y32: =IF(K32=0,"***",R32/K32) | Z32: =IF(L32=0,"***",S32/L32) | AA32: =IF(Y32="***","***",Z32-X32) | AB32: =IF(Z32="***","***",Z32-X32)
H33: 機械 | I33: =BACKDATA上期!CO33+下期!I33 | J33: =BACKDATA上期!CP33+下期!J33 | K33: =BACKDATA上期!CQ33+下期!K33 | L33: =BACKDATA上期!CR33+下期!L33 | M33: =L33-K33 | N33: =L33-J33 | O33: =IF(J33=0,"***",N33/J33) | P33: =BACKDATA上期!CV33+下期!P33 | Q33: =BACKDATA上期!CW33+下期!Q33 | R33: =BACKDATA上期!CX33+下期!R33 | S33: =BACKDATA上期!CY33+下期!S33 | T33: =S33-R33 | U33: =S33-Q33 | V33: =IF(Q33=0,"***",U33/Q33) | W33: =IF(I33=0,"***",P33/I33) | X33: =IF(J33=0,"***",Q33/J33) | Y33: =IF(K33=0,"***",R33/K33) | Z33: =IF(L33=0,"***",S33/L33) | AA33: =IF(Y33="***","***",Z33-X33) | AB33: =IF(Z33="***","***",Z33-X33)
